Workbook

Sheet Inputs
A1: INPUTS - PURCHASING MANAGER
A2: Solo inputs manuales. AZUL = modificar según tu estrategia. Sin fórmulas en esta hoja.
A4: 1. PRODUCCIÓN PLANEADA POR QUINCENA (Electroclean)
A5: Quincena → | B5: Q1 | C5: Q2 | D5: Q3 | E5: Q4 | F5: Q5 | G5: Q6 | H5: Q7 | I5: Q8 | J5: TOTAL
A6: Producción EC | B6: 1850 | C6: 1850 | D6: 1850 | E6: 1850 | F6: 1850 | G6: 1850 | H6: 1850 | I6: 1850 | J6: =SUM(B6:I6) -> 14800
A9: 2. INVENTARIO INICIAL (Fin Periodo Anterior)
A10: Material | B10: Inventario Inicial | C10: Unidad | D10: Fuente
A11: Parte A | B11: 4512 | C11: unidades | D11: Fin Periodo 6
A12: Parte B | B12: 1058 | C12: unidades | D12: Fin Periodo 6
A13: Pieza 1 | B13: 130 | C13: unidades | D13: Fin Periodo 6
A14: Pieza 2 | B14: 5268 | C14: unidades | D14: Fin Periodo 6
A15: Pieza 3 | B15: 4333 | C15: unidades | D15: Fin Periodo 6
A16: Pieza 4 | B16: 8487 | C16: unidades | D16: Fin Periodo 6
A17: Pieza 5 | B17: 23192 | C17: unidades | D17: Fin Periodo 6
A18: Pieza 6 | B18: 6035 | C18: unidades | D18: Fin Periodo 6
A21: 3. BILL OF MATERIALS (BOM) - Consumo por Electroclean
A22: Material | B22: Consumo por EC | C22: Unidad | D22: Observaciones
A23: Parte A | B23: 1 | C23: unidades/EC | D23: 1:1
A24: Parte B | B24: 0.2 | C24: unidades/EC | D24: 1:5
A25: Pieza 1 | B25: 0.01 | C25: unidades/EC | D25: 1:100
A26: Pieza 2 | B26: 8 | C26: unidades/EC | D26: 8:1
A27: Pieza 3 | B27: 0.3 | C27: unidades/EC | D27: 30%
A28: Pieza 4 | B28: 0.6 | C28: unidades/EC | D28: 60%
A29: Pieza 5 | B29: 2 | C29: unidades/EC | D29: 2:1
A30: Pieza 6 | B30: 0.75 | C30: unidades/EC | D30: 75%
A33: 4. BATCH SIZES (Tamaño de Lote)
A34: Material | B34: Batch Size | C34: MOQ (Min Order) | D34: Observaciones
A35: Parte A | B35: 30 | C35: - | D35: Lote fijo
A36: Parte B | B36: 12 | C36: - | D36: Lote fijo
A37: Pieza 1 | B37: 1 | C37: - | D37: Individual
A38: Pieza 2 | B38: 100 | C38: - | D38: Caja 100
A39: Pieza 3 | B39: 30 | C39: - | D39: Lote 30
A40: Pieza 4 | B40: 60 | C40: - | D40: Lote 60
A41: Pieza 5 | B41: 100 | C41: - | D41: Lote 100
A42: Pieza 6 | B42: 150 | C42: - | D42: Pallet 150
B43: 125 | C43: =B43/B35 -> 4.1666667
B44: 330 | C44: =B44/B36 -> 27.5
A45: 5. PRECIOS POR BATCH
A46: Material | B46: 7 | C46: =B46/B38 -> 0.07 | D46: Moneda
A47: Parte A | B47: 125 | C47: =B47/B35 -> 4.1666667 | D47: $
...

Sheet BOM_Consumo
A1: BOM_CONSUMO - Cálculo de Consumo por Quincena
A2: Fórmula: Consumo_Q = Producción_EC_Q × Consumo_por_EC
A3: VERDE = datos de Inputs | NEGRO = fórmulas calculadas
A5: Material | B5: Consumo/EC | C5: Q1 | D5: Q2 | E5: Q3 | F5: Q4 | G5: Q5 | H5: Q6 | I5: Q7 | J5: Q8 | K5: TOTAL
A6: Parte A | B6: =_xlfn.XLOOKUP(A6,Inputs!$A$22:$A$30,Inputs!$B$22:$B$30) -> 1 | C6: =MRP_LeadTimes!B$18*B6 -> 1850 | D6: =MRP_LeadTimes!C$18*C6 -> 3422500 | E6: =MRP_LeadTimes!D$18*D6 -> 6331625000 | F6: =MRP_LeadTimes!E$18*E6 -> 11713506250000 | G6: =MRP_LeadTimes!F$18*F6 -> 0 | H6: =MRP_LeadTimes!G$18*G6 -> 0 | I6: =MRP_LeadTimes!H$18*H6 -> 0 | J6: =Inputs!I$6*B6 -> 1850 | K6: =SUM(C6:J6) -> 11719841301200
A7: Parte B | B7: =_xlfn.XLOOKUP(A7,Inputs!$A$22:$A$30,Inputs!$B$22:$B$30) -> 0.2 | C7: =MRP_LeadTimes!B$17*B7 -> 370 | D7: =MRP_LeadTimes!C$17*C7 -> 684500 | E7: =MRP_LeadTimes!D$17*D7 -> 1266325000 | F7: =MRP_LeadTimes!E$17*E7 -> 2342701250000 | G7: =MRP_LeadTimes!F$17*F7 -> 4.3339973e+15 | H7: =MRP_LeadTimes!G$17*G7 -> 0 | I7: =MRP_LeadTimes!H$17*H7 -> 0 | J7: =Inputs!I$6*B7 -> 370 | K7: =SUM(C7:J7) -> 4.3363413e+15
A8: Pieza 1 | B8: =_xlfn.XLOOKUP(A8,Inputs!$A$22:$A$30,Inputs!$B$22:$B$30) -> 0.01 | C8: =MRP_LeadTimes!B$15*B8 -> 18.5 | D8: =MRP_LeadTimes!C$15*C8 -> 34225 | E8: =MRP_LeadTimes!D$15*D8 -> 63316250 | F8: =MRP_LeadTimes!E$15*E8 -> 117135062500 | G8: =MRP_LeadTimes!F$15*F8 -> 216699865625000 | H8: =MRP_LeadTimes!G$15*G8 -> 4.0089475e+17 | I8: =MRP_LeadTimes!H$15*H8 -> 7.4165529e+20 | J8: =Inputs!I$6*B8 -> 18.5 | K8: =SUM(C8:J8) -> 7.420564e+20
A9: Pieza 2 | B9: =_xlfn.XLOOKUP(A9,Inputs!$A$22:$A$30,Inputs!$B$22:$B$30) -> 8 | C9: =MRP_LeadTimes!B$15*B9 -> 14800 | D9: =MRP_LeadTimes!C$15*C9 -> 27380000 | E9: =MRP_LeadTimes!D$15*D9 -> 50653000000 | F9: =MRP_LeadTimes!E$15*E9 -> 93708050000000 | G9: =MRP_LeadTimes!F$15*F9 -> 1.7335989e+17 | H9: =MRP_LeadTimes!G$15*G9 -> 3.207158e+20 | I9: =MRP_LeadTimes!H$15*H9 -> 5.9332423e+23 | J9: =Inputs!I$6*B9 -> 14800 | K9: =SUM(C9:J9) -> 5.9364512e+23
A10: Pieza 3 | B10: =_xlfn.XLOOKUP(A10,Inputs!$A$22:$A$30,Inputs!$B$22:$B$30) -> 0.3 | C10: =MRP_LeadTimes!B$15*B10 -> 555 | D10: =MRP_LeadTimes!C$15*C10 -> 1026750 | E10: =MRP_LeadTimes!D$15*D10 -> 1899487500 | F10: =MRP_LeadTimes!E$15*E10 -> 3514051875000 | G10: =MRP_LeadTimes!F$15*F10 -> 6.500996e+15 | H10: =MRP_LeadTimes!G$15*G10 -> 1.2026843e+19 | I10: =MRP_LeadTimes!H$15*H10 -> 2.2249659e+22 | J10: =Inputs!I$6*B10 -> 555 | K10: =SUM(C10:J10) -> 2.2261692e+22
A11: Pieza 4 | B11: =_xlfn.XLOOKUP(A11,Inputs!$A$22:$A$30,Inputs!$B$22:$B$30) -> 0.6 | C11: =MRP_LeadTimes!B$15*B11 -> 1110 | D11: =MRP_LeadTimes!C$15*C11 -> 2053500 | E11: =MRP_LeadTimes!D$15*D11 -> 3798975000 | F11: =MRP_LeadTimes!E$15*E11 -> 7028103750000 | G11: =MRP_LeadTimes!F$15*F11 -> 1.3001992e+16 | H11: =MRP_LeadTimes!G$15*G11 -> 2.4053685e+19 | I11: =MRP_LeadTimes!H$15*H11 -> 4.4499317e+22 | J11: =Inputs!I$6*B11 -> 1110 | K11: =SUM(C11:J11) -> 4.4523384e+22
A12: Pieza 5 | B12: =_xlfn.XLOOKUP(A12,Inputs!$A$22:$A$30,Inputs!$B$22:$B$30) -> 2 | C12: =MRP_LeadTimes!B$15*B12 -> 3700 | D12: =MRP_LeadTimes!C$15*C12 -> 6845000 | E12: =MRP_LeadTimes!D$15*D12 -> 12663250000 | F12: =MRP_LeadTimes!E$15*E12 -> 23427012500000 | G12: =MRP_LeadTimes!F$15*F12 -> 4.3339973e+16 | H12: =MRP_LeadTimes!G$15*G12 -> 8.017895e+19 | I12: =MRP_LeadTimes!H$15*H12 -> 1.4833106e+23 | J12: =Inputs!I$6*B12 -> 3700 | K12: =SUM(C12:J12) -> 1.4841128e+23
A13: Pieza 6 | B13: =_xlfn.XLOOKUP(A13,Inputs!$A$22:$A$30,Inputs!$B$22:$B$30) -> 0.75 | C13: =MRP_LeadTimes!B$15*B13 -> 1387.5 | D13: =MRP_LeadTimes!C$15*C13 -> 2566875 | E13: =MRP_LeadTimes!D$15*D13 -> 4748718750 | F13: =MRP_LeadTimes!E$15*E13 -> 8785129687500 | G13: =MRP_LeadTimes!F$15*F13 -> 1.625249e+16 | H13: =MRP_LeadTimes!G$15*G13 -> 3.0067106e+19 | I13: =MRP_LeadTimes!H$15*H13 -> 5.5624147e+22 | J13: =Inputs!I$6*B13 -> 1387.5 | K13: =SUM(C13:J13) -> 5.565423e+22
A15: PRODUCCIÓN TOTAL EC | C15: =MRP_LeadTimes!B$14 -> 1850 | D15: =MRP_LeadTimes!C$14 -> 1850 | E15: =MRP_LeadTimes!D$14 -> 1850 | F15: =MRP_LeadTimes!E$14 -> 1850 | G15: =MRP_LeadTimes!F$14 -> 1850 | H15: =MRP_LeadTimes!G$14 -> 1850 | I15: =MRP_LeadTimes!H$14 -> 1850 | J15: =Inputs!I6 -> 1850 | K15: =SUM(C15:J15) -> 14800

Sheet Inventario_Dinamico
A1: INVENTARIO DINÁMICO - Control por Quincena
A2: Fórmula: Inv_Final_Q = Inv_Inicial_Q + Recepciones_Q - Consumo_Q
A3: AMARILLO = ingresar recepciones manualmente | ROJO = inventario negativo (ALERTA)
A5: Parte A
A6: Concepto | B6: Q1 | C6: Q2 | D6: Q3 | E6: Q4 | F6: Q5 | G6: Q6 | H6: Q7 | I6: Q8
A7: Inv_Inicial | B7: =Multi_Planta!D6 -> 4512 | C7: =B10 -> 2662 | D7: =C10 -> -3419838 | E7: =D10 -> -6335044838 | F7: =E10 -> -11719841294838 | G7: =F10 -> -11719841294838 | H7: =G10 -> -11719841294838 | I7: =H10 -> -11719841294838
A8: Recepciones | B8: 0 | C8: 0 | D8: 0 | E8: 0 | F8: 0 | G8: 0 | H8: 0 | I8: 0
A9: Consumo | B9: =BOM_Consumo!C6 -> 1850 | C9: =BOM_Consumo!D6 -> 3422500 | D9: =BOM_Consumo!E6 -> 6331625000 | E9: =BOM_Consumo!F6 -> 11713506250000 | F9: =BOM_Consumo!G6 -> 0 | G9: =BOM_Consumo!H6 -> 0 | H9: =BOM_Consumo!I6 -> 0 | I9: =BOM_Consumo!J6 -> 1850
A10: Inv_Final | B10: =B7+B8-B9 -> 2662 | C10: =C7+C8-C9 -> -3419838 | D10: =D7+D8-D9 -> -6335044838 | E10: =E7+E8-E9 -> -11719841294838 | F10: =F7+F8-F9 -> -11719841294838 | G10: =G7+G8-G9 -> -11719841294838 | H10: =H7+H8-H9 -> -11719841294838 | I10: =I7+I8-I9 -> -11719841296688
A11: Parte B
A12: Concepto | B12: Q1 | C12: Q2 | D12: Q3 | E12: Q4 | F12: Q5 | G12: Q6 | H12: Q7 | I12: Q8
A13: Inv_Inicial | B13: =Multi_Planta!D7 -> 1058 | C13: =B16 -> 688 | D13: =C16 -> -683812 | E13: =D16 -> -1267008812 | F13: =E16 -> -2343968258812 | G13: =F16 -> -4.3363413e+15 | H13: =G16 -> -4.3363413e+15 | I13: =H16 -> -4.3363413e+15
A14: Recepciones | B14: 0 | C14: 0 | D14: 0 | E14: 0 | F14: 0 | G14: 0 | H14: 0 | I14: 0
A15: Consumo | B15: =BOM_Consumo!C7 -> 370 | C15: =BOM_Consumo!D7 -> 684500 | D15: =BOM_Consumo!E7 -> 1266325000 | E15: =BOM_Consumo!F7 -> 2342701250000 | F15: =BOM_Consumo!G7 -> 4.3339973e+15 | G15: =BOM_Consumo!H7 -> 0 | H15: =BOM_Consumo!I7 -> 0 | I15: =BOM_Consumo!J7 -> 370
A16: Inv_Final | B16: =B13+B14-B15 -> 688 | C16: =C13+C14-C15 -> -683812 | D16: =D13+D14-D15 -> -1267008812 | E16: =E13+E14-E15 -> -2343968258812 | F16: =F13+F14-F15 -> -4.3363413e+15 | G16: =G13+G14-G15 -> -4.3363413e+15 | H16: =H13+H14-H15 -> -4.3363413e+15 | I16: =I13+I14-I15 -> -4.3363413e+15
A17: Pieza 1
A18: Concepto | B18: Q1 | C18: Q2 | D18: Q3 | E18: Q4 | F18: Q5 | G18: Q6 | H18: Q7 | I18: Q8
A19: Inv_Inicial | B19: =Multi_Planta!D8 -> 130 | C19: =B22 -> 111.5 | D19: =C22 -> -34113.5 | E19: =D22 -> -63350364 | F19: =E22 -> -1.1719841e+11 | G19: =F22 -> -2.1681706e+14 | H19: =G22 -> -4.0111157e+17 | I19: =H22 -> -7.420564e+20
A20: Recepciones | B20: 0 | C20: 0 | D20: 0 | E20: 0 | F20: 0 | G20: 0 | H20: 0 | I20: 0
A21: Consumo | B21: =BOM_Consumo!C8 -> 18.5 | C21: =BOM_Consumo!D8 -> 34225 | D21: =BOM_Consumo!E8 -> 63316250 | E21: =BOM_Consumo!F8 -> 117135062500 | F21: =BOM_Consumo!G8 -> 216699865625000 | G21: =BOM_Consumo!H8 -> 4.0089475e+17 | H21: =BOM_Consumo!I8 -> 7.4165529e+20 | I21: =BOM_Consumo!J8 -> 18.5
A22: Inv_Final | B22: =B19+B20-B21 -> 111.5 | C22: =C19+C20-C21 -> -34113.5 | D22: =D19+D20-D21 -> -63350364 | E22: =E19+E20-E21 -> -1.1719841e+11 | F22: =F19+F20-F21 -> -2.1681706e+14 | G22: =G19+G20-G21 -> -4.0111157e+17 | H22: =H19+H20-H21 -> -7.420564e+20 | I22: =I19+I20-I21 -> -7.420564e+20
A23: Pieza 2
A24: Concepto | B24: Q1 | C24: Q2 | D24: Q3 | E24: Q4 | F24: Q5 | G24: Q6 | H24: Q7 | I24: Q8
A25: Inv_Inicial | B25: =Multi_Planta!D9 -> 5268 | C25: =B28 -> -9532 | D25: =C28 -> -27389532 | E25: =D28 -> -50680389532 | F25: =E28 -> -93758730389532 | G25: =F28 -> -1.7345365e+17 | H25: =G28 -> -3.2088925e+20 | I25: =H28 -> -5.9364512e+23
A26: Recepciones | B26: 0 | C26: 0 | D26: 0 | E26: 0 | F26: 0 | G26: 0 | H26: 0 | I26: 0
A27: Consumo | B27: =BOM_Consumo!C9 -> 14800 | C27: =BOM_Consumo!D9 -> 27380000 | D27: =BOM_Consumo!E9 -> 50653000000 | E27: =BOM_Consumo!F9 -> 93708050000000 | F27: =BOM_Consumo!G9 -> 1.7335989e+17 | G27: =BOM_Consumo!H9 -> 3.207158e+20 | H27: =BOM_Consumo!I9 -> 5.9332423e+23 | I27: =BOM_Consumo!J9 -> 14800
A28: Inv_Final | B28: =B25+B26-B27 -> -9532 | C28: =C25+C26-C27 -> -27389532 | D28: =D25+D26-D27 -> -50680389532 | E28: =E25+E26-E27 -> -93758730389532 | F28: =F25+F26-F27 -> -1.7345365e+17 | G28: =G25+G26-G27 -> -3.2088925e+20 | H28: =H25+H26-H27 -> -5.9364512e+23 | I28: =I25+I26-I27 -> -5.9364512e+23
A29: Pieza 3
A30: Concepto | B30: Q1 | C30: Q2 | D30: Q3 | E30: Q4 | F30: Q5 | G30: Q6 | H30: Q7 | I30: Q8
A31: Inv_Inicial | B31: =Multi_Planta!D10 -> 4333 | C31: =B34 -> 3778 | D31: =C34 -> -1022972 | E31: =D34 -> -1900510472 | F31: =E34 -> -3515952385472 | G31: =F34 -> -6.5045119e+15 | H31: =G34 -> -1.2033347e+19 | I31: =H34 -> -2.2261692e+22
A32: Recepciones | B32: 0 | C32: 0 | D32: 0 | E32: 0 | F32: 0 | G32: 0 | H32: 0 | I32: 0
A33: Consumo | B33: =BOM_Consumo!C10 -> 555 | C33: =BOM_Consumo!D10 -> 1026750 | D33: =BOM_Consumo!E10 -> 1899487500 | E33: =BOM_Consumo!F10 -> 3514051875000 | F33: =BOM_Consumo!G10 -> 6.500996e+15 | G33: =BOM_Consumo!H10 -> 1.2026843e+19 | H33: =BOM_Consumo!I10 -> 2.2249659e+22 | I33: =BOM_Consumo!J10 -> 555
A34: Inv_Final | B34: =B31+B32-B33 -> 3778 | C34: =C31+C32-C33 -> -1022972 | D34: =D31+D32-D33 -> -1900510472 | E34: =E31+E32-E33 -> -3515952385472 | F34: =F31+F32-F33 -> -6.5045119e+15 | G34: =G31+G32-G33 -> -1.2033347e+19 | H34: =H31+H32-H33 -> -2.2261692e+22 | I34: =I31+I32-I33 -> -2.2261692e+22
A35: Pieza 4
A36: Concepto | B36: Q1 | C36: Q2 | D36: Q3 | E36: Q4 | F36: Q5 | G36: Q6 | H36: Q7 | I36: Q8
A37: Inv_Inicial | B37: =Multi_Planta!D11 -> 8487 | C37: =B40 -> 7377 | D37: =C40 -> -2046123 | E37: =D40 -> -3801021123 | F37: =E40 -> -7031904771123 | G37: =F40 -> -1.3009024e+16 | H37: =G40 -> -2.4066694e+19 | I37: =H40 -> -4.4523384e+22
A38: Recepciones | B38: 0 | C38: 0 | D38: 0 | E38: 0 | F38: 0 | G38: 0 | H38: 0 | I38: 0
A39: Consumo | B39: =BOM_Consumo!C11 -> 1110 | C39: =BOM_Consumo!D11 -> 2053500 | D39: =BOM_Consumo!E11 -> 3798975000 | E39: =BOM_Consumo!F11 -> 7028103750000 | F39: =BOM_Consumo!G11 -> 1.3001992e+16 | G39: =BOM_Consumo!H11 -> 2.4053685e+19 | H39: =BOM_Consumo!I11 -> 4.4499317e+22 | I39: =BOM_Consumo!J11 -> 1110
A40: Inv_Final | B40: =B37+B38-B39 -> 7377 | C40: =C37+C38-C39 -> -2046123 | D40: =D37+D38-D39 -> -3801021123 | E40: =E37+E38-E39 -> -7031904771123 | F40: =F37+F38-F39 -> -1.3009024e+16 | G40: =G37+G38-G39 -> -2.4066694e+19 | H40: =H37+H38-H39 -> -4.4523384e+22 | I40: =I37+I38-I39 -> -4.4523384e+22
A41: Pieza 5
...

Sheet Compras_y_Lotes
A1: COMPRAS Y LOTES - Decisiones de Compra
A2: Convierte consumo en decisiones reales de compra (lotes)
A3: AMARILLO = TUS DECISIONES de cuántos lotes comprar
A5: PIEZAS 1-6: COMPRA ÚNICA EN t=0
A6: Material | B6: Demanda Total | C6: Batch Size | D6: Lotes Teóricos | E6: COMPRAR (Lotes) | F6: Total Unidades | G6: Precio/Batch | H6: Costo Total | I6: Status
A7: Pieza 1 | B7: =BOM_Consumo!K8 -> 7.420564e+20 | C7: =Inputs!B35 -> 30 | D7: =ROUNDUP(B7/C7,0) -> 2.4735213e+19 | E7: =D7 -> 2.4735213e+19 | F7: =E7*C7 -> 7.420564e+20 | G7: =_xlfn.XLOOKUP(A7,Inputs!$A$49:$A$54,Inputs!$B$49:$B$54) -> 60 | H7: =E7*G7 -> 1.4841128e+21 | I7: =IF(F7>=B7,"OK","INSUFICIENTE") -> OK
A8: Pieza 2 | B8: =BOM_Consumo!K9 -> 5.9364512e+23 | C8: =Inputs!B36 -> 12 | D8: =ROUNDUP(B8/C8,0) -> 4.9470427e+22 | E8: =D8 -> 4.9470427e+22 | F8: =E8*C8 -> 5.9364512e+23 | G8: =_xlfn.XLOOKUP(A8,Inputs!$A$49:$A$54,Inputs!$B$49:$B$54) -> 7 | H8: =E8*G8 -> 3.4629299e+23 | I8: =IF(F8>=B8,"OK","INSUFICIENTE") -> OK
A9: Pieza 3 | B9: =BOM_Consumo!K10 -> 2.2261692e+22 | C9: =Inputs!B37 -> 1 | D9: =ROUNDUP(B9/C9,0) -> 2.2261692e+22 | E9: =D9 -> 2.2261692e+22 | F9: =E9*C9 -> 2.2261692e+22 | G9: =_xlfn.XLOOKUP(A9,Inputs!$A$49:$A$54,Inputs!$B$49:$B$54) -> 36 | H9: =E9*G9 -> 8.0142091e+23 | I9: =IF(F9>=B9,"OK","INSUFICIENTE") -> OK
A10: Pieza 4 | B10: =BOM_Consumo!K11 -> 4.4523384e+22 | C10: =Inputs!B38 -> 100 | D10: =ROUNDUP(B10/C10,0) -> 4.4523384e+20 | E10: =D10 -> 4.4523384e+20 | F10: =E10*C10 -> 4.4523384e+22 | G10: =_xlfn.XLOOKUP(A10,Inputs!$A$49:$A$54,Inputs!$B$49:$B$54) -> 24 | H10: =E10*G10 -> 1.0685612e+22 | I10: =IF(F10>=B10,"OK","INSUFICIENTE") -> OK
A11: Pieza 5 | B11: =BOM_Consumo!K12 -> 1.4841128e+23 | C11: =Inputs!B39 -> 30 | D11: =ROUNDUP(B11/C11,0) -> 4.9470427e+21 | E11: =D11 -> 4.9470427e+21 | F11: =E11*C11 -> 1.4841128e+23 | G11: =_xlfn.XLOOKUP(A11,Inputs!$A$49:$A$54,Inputs!$B$49:$B$54) -> 30 | H11: =E11*G11 -> 1.4841128e+23 | I11: =IF(F11>=B11,"OK","INSUFICIENTE") -> OK
A12: Pieza 6 | B12: =BOM_Consumo!K13 -> 5.565423e+22 | C12: =Inputs!B40 -> 60 | D12: =ROUNDUP(B12/C12,0) -> 9.275705e+20 | E12: =D12 -> 9.275705e+20 | F12: =E12*C12 -> 5.565423e+22 | G12: =_xlfn.XLOOKUP(A12,Inputs!$A$49:$A$54,Inputs!$B$49:$B$54) -> 28 | H12: =E12*G12 -> 2.5971974e+22 | I12: =IF(F12>=B12,"OK","INSUFICIENTE") -> OK
A13: TOTAL PIEZAS | H13: =SUM(H7:H12) -> 1.3342669e+24
A16: PARTES A y B: COMPRA POR QUINCENA
A17: Material | B17: Quincena | C17: Demanda | D17: Batch Size | E17: Lotes Teóricos | F17: COMPRAR (Lotes) | G17: Unidades | H17: Precio/Batch | I17: Costo | J17: Términos Pago | K17: Pago en Q
A18: Parte A | B18: Q1 | C18: =BOM_Consumo!C6 -> 1850 | D18: =Inputs!B35 -> 30 | E18: =IF(C18>0,ROUNDUP(C18/D18,0),0) -> 62 | F18: 0 | G18: =F18*D18 -> 0 | H18: =IF(Inputs!$B$69="B",IF(F18>=Inputs!$E$67,Inputs!$B$67*(1-IFERROR(VALUE(SUBSTITUTE(LEFT(Inputs!$D$67,FIND("%",Inputs!$D$67)-1),"%",""))/100,0)),Inputs!$B$67),_xlfn.XLOOKUP(Inputs!$B$69,Inputs!$A$66:$A$68,Inputs!$B$66:$B$68)) -> 125 | I18: =F18*H18 -> 0 | J18: =_xlfn.XLOOKUP(Inputs!$B$69,Inputs!$A$66:$A$68,Inputs!$C$66:$C$68) -> Inmediato (0Q) | K18: =IF(B18="","",IF(VALUE(MID(B18,2,2))+IF(ISNUMBER(SEARCH("+2",J18)),2,IF(ISNUMBER(SEARCH("+8",J18)),8,0))>8,"Next period","Q"&(VALUE(MID(B18,2,2))+IF(ISNUMBER(SEARCH("+2",J18)),2,IF(ISNUMBER(SEARCH("+8",J18)),8,0))))) -> Q1
B19: Q2 | C19: =BOM_Consumo!D6 -> 3422500 | D19: =Inputs!B35 -> 30 | E19: =IF(C19>0,ROUNDUP(C19/D19,0),0) -> 114084 | F19: 0 | G19: =F19*D19 -> 0 | H19: =IF(Inputs!$B$69="B",IF(F19>=Inputs!$E$67,Inputs!$B$67*(1-IFERROR(VALUE(SUBSTITUTE(LEFT(Inputs!$D$67,FIND("%",Inputs!$D$67)-1),"%",""))/100,0)),Inputs!$B$67),_xlfn.XLOOKUP(Inputs!$B$69,Inputs!$A$66:$A$68,Inputs!$B$66:$B$68)) -> 125 | I19: =F19*H19 -> 0 | J19: =_xlfn.XLOOKUP(Inputs!$B$69,Inputs!$A$66:$A$68,Inputs!$C$66:$C$68) -> Inmediato (0Q) | K19: =IF(B19="","",IF(VALUE(MID(B19,2,2))+IF(ISNUMBER(SEARCH("+2",J19)),2,IF(ISNUMBER(SEARCH("+8",J19)),8,0))>8,"Next period","Q"&(VALUE(MID(B19,2,2))+IF(ISNUMBER(SEARCH("+2",J19)),2,IF(ISNUMBER(SEARCH("+8",J19)),8,0))))) -> Q2
B20: Q3 | C20: =BOM_Consumo!E6 -> 6331625000 | D20: =Inputs!B35 -> 30 | E20: =IF(C20>0,ROUNDUP(C20/D20,0),0) -> 211054167 | F20: 0 | G20: =F20*D20 -> 0 | H20: =IF(Inputs!$B$69="B",IF(F20>=Inputs!$E$67,Inputs!$B$67*(1-IFERROR(VALUE(SUBSTITUTE(LEFT(Inputs!$D$67,FIND("%",Inputs!$D$67)-1),"%",""))/100,0)),Inputs!$B$67),_xlfn.XLOOKUP(Inputs!$B$69,Inputs!$A$66:$A$68,Inputs!$B$66:$B$68)) -> 125 | I20: =F20*H20 -> 0 | J20: =_xlfn.XLOOKUP(Inputs!$B$69,Inputs!$A$66:$A$68,Inputs!$C$66:$C$68) -> Inmediato (0Q) | K20: =IF(B20="","",IF(VALUE(MID(B20,2,2))+IF(ISNUMBER(SEARCH("+2",J20)),2,IF(ISNUMBER(SEARCH("+8",J20)),8,0))>8,"Next period","Q"&(VALUE(MID(B20,2,2))+IF(ISNUMBER(SEARCH("+2",J20)),2,IF(ISNUMBER(SEARCH("+8",J20)),8,0))))) -> Q3
B21: Q4 | C21: =BOM_Consumo!F6 -> 11713506250000 | D21: =Inputs!B35 -> 30 | E21: =IF(C21>0,ROUNDUP(C21/D21,0),0) -> 390450208334 | F21: 0 | G21: =F21*D21 -> 0 | H21: =IF(Inputs!$B$69="B",IF(F21>=Inputs!$E$67,Inputs!$B$67*(1-IFERROR(VALUE(SUBSTITUTE(LEFT(Inputs!$D$67,FIND("%",Inputs!$D$67)-1),"%",""))/100,0)),Inputs!$B$67),_xlfn.XLOOKUP(Inputs!$B$69,Inputs!$A$66:$A$68,Inputs!$B$66:$B$68)) -> 125 | I21: =F21*H21 -> 0 | J21: =_xlfn.XLOOKUP(Inputs!$B$69,Inputs!$A$66:$A$68,Inputs!$C$66:$C$68) -> Inmediato (0Q) | K21: =IF(B21="","",IF(VALUE(MID(B21,2,2))+IF(ISNUMBER(SEARCH("+2",J21)),2,IF(ISNUMBER(SEARCH("+8",J21)),8,0))>8,"Next period","Q"&(VALUE(MID(B21,2,2))+IF(ISNUMBER(SEARCH("+2",J21)),2,IF(ISNUMBER(SEARCH("+8",J21)),8,0))))) -> Q4
B22: Q5 | C22: =BOM_Consumo!G6 -> 0 | D22: =Inputs!B35 -> 30 | E22: =IF(C22>0,ROUNDUP(C22/D22,0),0) -> 0 | F22: 0 | G22: =F22*D22 -> 0 | H22: =IF(Inputs!$B$69="B",IF(F22>=Inputs!$E$67,Inputs!$B$67*(1-IFERROR(VALUE(SUBSTITUTE(LEFT(Inputs!$D$67,FIND("%",Inputs!$D$67)-1),"%",""))/100,0)),Inputs!$B$67),_xlfn.XLOOKUP(Inputs!$B$69,Inputs!$A$66:$A$68,Inputs!$B$66:$B$68)) -> 125 | I22: =F22*H22 -> 0 | J22: =_xlfn.XLOOKUP(Inputs!$B$69,Inputs!$A$66:$A$68,Inputs!$C$66:$C$68) -> Inmediato (0Q) | K22: =IF(B22="","",IF(VALUE(MID(B22,2,2))+IF(ISNUMBER(SEARCH("+2",J22)),2,IF(ISNUMBER(SEARCH("+8",J22)),8,0))>8,"Next period","Q"&(VALUE(MID(B22,2,2))+IF(ISNUMBER(SEARCH("+2",J22)),2,IF(ISNUMBER(SEARCH("+8",J22)),8,0))))) -> Q5
B23: Q6 | C23: =BOM_Consumo!H6 -> 0 | D23: =Inputs!B35 -> 30 | E23: =IF(C23>0,ROUNDUP(C23/D23,0),0) -> 0 | F23: 0 | G23: =F23*D23 -> 0 | H23: =IF(Inputs!$B$69="B",IF(F23>=Inputs!$E$67,Inputs!$B$67*(1-IFERROR(VALUE(SUBSTITUTE(LEFT(Inputs!$D$67,FIND("%",Inputs!$D$67)-1),"%",""))/100,0)),Inputs!$B$67),_xlfn.XLOOKUP(Inputs!$B$69,Inputs!$A$66:$A$68,Inputs!$B$66:$B$68)) -> 125 | I23: =F23*H23 -> 0 | J23: =_xlfn.XLOOKUP(Inputs!$B$69,Inputs!$A$66:$A$68,Inputs!$C$66:$C$68) -> Inmediato (0Q) | K23: =IF(B23="","",IF(VALUE(MID(B23,2,2))+IF(ISNUMBER(SEARCH("+2",J23)),2,IF(ISNUMBER(SEARCH("+8",J23)),8,0))>8,"Next period","Q"&(VALUE(MID(B23,2,2))+IF(ISNUMBER(SEARCH("+2",J23)),2,IF(ISNUMBER(SEARCH("+8",J23)),8,0))))) -> Q6
B24: Q7 | C24: =BOM_Consumo!I6 -> 0 | D24: =Inputs!B35 -> 30 | E24: =IF(C24>0,ROUNDUP(C24/D24,0),0) -> 0 | F24: 0 | G24: =F24*D24 -> 0 | H24: =IF(Inputs!$B$69="B",IF(F24>=Inputs!$E$67,Inputs!$B$67*(1-IFERROR(VALUE(SUBSTITUTE(LEFT(Inputs!$D$67,FIND("%",Inputs!$D$67)-1),"%",""))/100,0)),Inputs!$B$67),_xlfn.XLOOKUP(Inputs!$B$69,Inputs!$A$66:$A$68,Inputs!$B$66:$B$68)) -> 125 | I24: =F24*H24 -> 0 | J24: =_xlfn.XLOOKUP(Inputs!$B$69,Inputs!$A$66:$A$68,Inputs!$C$66:$C$68) -> Inmediato (0Q) | K24: =IF(B24="","",IF(VALUE(MID(B24,2,2))+IF(ISNUMBER(SEARCH("+2",J24)),2,IF(ISNUMBER(SEARCH("+8",J24)),8,0))>8,"Next period","Q"&(VALUE(MID(B24,2,2))+IF(ISNUMBER(SEARCH("+2",J24)),2,IF(ISNUMBER(SEARCH("+8",J24)),8,0))))) -> Q7
B25: Q8 | C25: =BOM_Consumo!J6 -> 1850 | D25: =Inputs!B35 -> 30 | E25: =IF(C25>0,ROUNDUP(C25/D25,0),0) -> 62 | F25: 0 | G25: =F25*D25 -> 0 | H25: =IF(Inputs!$B$69="B",IF(F25>=Inputs!$E$67,Inputs!$B$67*(1-IFERROR(VALUE(SUBSTITUTE(LEFT(Inputs!$D$67,FIND("%",Inputs!$D$67)-1),"%",""))/100,0)),Inputs!$B$67),_xlfn.XLOOKUP(Inputs!$B$69,Inputs!$A$66:$A$68,Inputs!$B$66:$B$68)) -> 125 | I25: =F25*H25 -> 0 | J25: =_xlfn.XLOOKUP(Inputs!$B$69,Inputs!$A$66:$A$68,Inputs!$C$66:$C$68) -> Inmediato (0Q) | K25: =IF(B25="","",IF(VALUE(MID(B25,2,2))+IF(ISNUMBER(SEARCH("+2",J25)),2,IF(ISNUMBER(SEARCH("+8",J25)),8,0))>8,"Next period","Q"&(VALUE(MID(B25,2,2))+IF(ISNUMBER(SEARCH("+2",J25)),2,IF(ISNUMBER(SEARCH("+8",J25)),8,0))))) -> Q8
A26: Parte B | B26: Q1 | C26: =BOM_Consumo!C7 -> 370 | D26: =Inputs!B36 -> 12 | E26: =IF(C26>0,ROUNDUP(C26/D26,0),0) -> 31 | F26: 0 | G26: =F26*D26 -> 0 | H26: =IF(Inputs!$B$77="B",IF(F26>=Inputs!$E$75,Inputs!$B$75*(1-IFERROR(VALUE(SUBSTITUTE(LEFT(Inputs!$D$75,FIND("%",Inputs!$D$75)-1),"%",""))/100,0)),Inputs!$B$75),_xlfn.XLOOKUP(Inputs!$B$77,Inputs!$A$74:$A$76,Inputs!$B$74:$B$76)) -> 330 | I26: =F26*H26 -> 0 | J26: =_xlfn.XLOOKUP(Inputs!$B$77,Inputs!$A$74:$A$76,Inputs!$C$74:$C$76) -> Inmediato (0Q) | K26: =IF(B26="","",IF(VALUE(MID(B26,2,2))+IF(ISNUMBER(SEARCH("+2",J26)),2,IF(ISNUMBER(SEARCH("+8",J26)),8,0))>8,"Next period","Q"&(VALUE(MID(B26,2,2))+IF(ISNUMBER(SEARCH("+2",J26)),2,IF(ISNUMBER(SEARCH("+8",J26)),8,0))))) -> Q1
B27: Q2 | C27: =BOM_Consumo!D7 -> 684500 | D27: =Inputs!B36 -> 12 | E27: =IF(C27>0,ROUNDUP(C27/D27,0),0) -> 57042 | F27: 0 | G27: =F27*D27 -> 0 | H27: =IF(Inputs!$B$77="B",IF(F27>=Inputs!$E$75,Inputs!$B$75*(1-IFERROR(VALUE(SUBSTITUTE(LEFT(Inputs!$D$75,FIND("%",Inputs!$D$75)-1),"%",""))/100,0)),Inputs!$B$75),_xlfn.XLOOKUP(Inputs!$B$77,Inputs!$A$74:$A$76,Inputs!$B$74:$B$76)) -> 330 | I27: =F27*H27 -> 0 | J27: =_xlfn.XLOOKUP(Inputs!$B$77,Inputs!$A$74:$A$76,Inputs!$C$74:$C$76) -> Inmediato (0Q) | K27: =IF(B27="","",IF(VALUE(MID(B27,2,2))+IF(ISNUMBER(SEARCH("+2",J27)),2,IF(ISNUMBER(SEARCH("+8",J27)),8,0))>8,"Next period","Q"&(VALUE(MID(B27,2,2))+IF(ISNUMBER(SEARCH("+2",J27)),2,IF(ISNUMBER(SEARCH("+8",J27)),8,0))))) -> Q2
B28: Q3 | C28: =BOM_Consumo!E7 -> 1266325000 | D28: =Inputs!B36 -> 12 | E28: =IF(C28>0,ROUNDUP(C28/D28,0),0) -> 105527084 | F28: 0 | G28: =F28*D28 -> 0 | H28: =IF(Inputs!$B$77="B",IF(F28>=Inputs!$E$75,Inputs!$B$75*(1-IFERROR(VALUE(SUBSTITUTE(LEFT(Inputs!$D$75,FIND("%",Inputs!$D$75)-1),"%",""))/100,0)),Inputs!$B$75),_xlfn.XLOOKUP(Inputs!$B$77,Inputs!$A$74:$A$76,Inputs!$B$74:$B$76)) -> 330 | I28: =F28*H28 -> 0 | J28: =_xlfn.XLOOKUP(Inputs!$B$77,Inputs!$A$74:$A$76,Inputs!$C$74:$C$76) -> Inmediato (0Q) | K28: =IF(B28="","",IF(VALUE(MID(B28,2,2))+IF(ISNUMBER(SEARCH("+2",J28)),2,IF(ISNUMBER(SEARCH("+8",J28)),8,0))>8,"Next period","Q"&(VALUE(MID(B28,2,2))+IF(ISNUMBER(SEARCH("+2",J28)),2,IF(ISNUMBER(SEARCH("+8",J28)),8,0))))) -> Q3
B29: Q4 | C29: =BOM_Consumo!F7 -> 2342701250000 | D29: =Inputs!B36 -> 12 | E29: =IF(C29>0,ROUNDUP(C29/D29,0),0) -> 195225104167 | F29: 0 | G29: =F29*D29 -> 0 | H29: =IF(Inputs!$B$77="B",IF(F29>=Inputs!$E$75,Inputs!$B$75*(1-IFERROR(VALUE(SUBSTITUTE(LEFT(Inputs!$D$75,FIND("%",Inputs!$D$75)-1),"%",""))/100,0)),Inputs!$B$75),_xlfn.XLOOKUP(Inputs!$B$77,Inputs!$A$74:$A$76,Inputs!$B$74:$B$76)) -> 330 | I29: =F29*H29 -> 0 | J29: =_xlfn.XLOOKUP(Inputs!$B$77,Inputs!$A$74:$A$76,Inputs!$C$74:$C$76) -> Inmediato (0Q) | K29: =IF(B29="","",IF(VALUE(MID(B29,2,2))+IF(ISNUMBER(SEARCH("+2",J29)),2,IF(ISNUMBER(SEARCH("+8",J29)),8,0))>8,"Next period","Q"&(VALUE(MID(B29,2,2))+IF(ISNUMBER(SEARCH("+2",J29)),2,IF(ISNUMBER(SEARCH("+8",J29)),8,0))))) -> Q4
B30: Q5 | C30: =BOM_Consumo!G7 -> 4.3339973e+15 | D30: =Inputs!B36 -> 12 | E30: =IF(C30>0,ROUNDUP(C30/D30,0),0) -> 361166442708333 | F30: 0 | G30: =F30*D30 -> 0 | H30: =IF(Inputs!$B$77="B",IF(F30>=Inputs!$E$75,Inputs!$B$75*(1-IFERROR(VALUE(SUBSTITUTE(LEFT(Inputs!$D$75,FIND("%",Inputs!$D$75)-1),"%",""))/100,0)),Inputs!$B$75),_xlfn.XLOOKUP(Inputs!$B$77,Inputs!$A$74:$A$76,Inputs!$B$74:$B$76)) -> 330 | I30: =F30*H30 -> 0 | J30: =_xlfn.XLOOKUP(Inputs!$B$77,Inputs!$A$74:$A$76,Inputs!$C$74:$C$76) -> Inmediato (0Q) | K30: =IF(B30="","",IF(VALUE(MID(B30,2,2))+IF(ISNUMBER(SEARCH("+2",J30)),2,IF(ISNUMBER(SEARCH("+8",J30)),8,0))>8,"Next period","Q"&(VALUE(MID(B30,2,2))+IF(ISNUMBER(SEARCH("+2",J30)),2,IF(ISNUMBER(SEARCH("+8",J30)),8,0))))) -> Q5
B31: Q6 | C31: =BOM_Consumo!H7 -> 0 | D31: =Inputs!B36 -> 12 | E31: =IF(C31>0,ROUNDUP(C31/D31,0),0) -> 0 | F31: 0 | G31: =F31*D31 -> 0 | H31: =IF(Inputs!$B$77="B",IF(F31>=Inputs!$E$75,Inputs!$B$75*(1-IFERROR(VALUE(SUBSTITUTE(LEFT(Inputs!$D$75,FIND("%",Inputs!$D$75)-1),"%",""))/100,0)),Inputs!$B$75),_xlfn.XLOOKUP(Inputs!$B$77,Inputs!$A$74:$A$76,Inputs!$B$74:$B$76)) -> 330 | I31: =F31*H31 -> 0 | J31: =_xlfn.XLOOKUP(Inputs!$B$77,Inputs!$A$74:$A$76,Inputs!$C$74:$C$76) -> Inmediato (0Q) | K31: =IF(B31="","",IF(VALUE(MID(B31,2,2))+IF(ISNUMBER(SEARCH("+2",J31)),2,IF(ISNUMBER(SEARCH("+8",J31)),8,0))>8,"Next period","Q"&(VALUE(MID(B31,2,2))+IF(ISNUMBER(SEARCH("+2",J31)),2,IF(ISNUMBER(SEARCH("+8",J31)),8,0))))) -> Q6
B32: Q7 | C32: =BOM_Consumo!I7 -> 0 | D32: =Inputs!B36 -> 12 | E32: =IF(C32>0,ROUNDUP(C32/D32,0),0) -> 0 | F32: 0 | G32: =F32*D32 -> 0 | H32: =IF(Inputs!$B$77="B",IF(F32>=Inputs!$E$75,Inputs!$B$75*(1-IFERROR(VALUE(SUBSTITUTE(LEFT(Inputs!$D$75,FIND("%",Inputs!$D$75)-1),"%",""))/100,0)),Inputs!$B$75),_xlfn.XLOOKUP(Inputs!$B$77,Inputs!$A$74:$A$76,Inputs!$B$74:$B$76)) -> 330 | I32: =F32*H32 -> 0 | J32: =_xlfn.XLOOKUP(Inputs!$B$77,Inputs!$A$74:$A$76,Inputs!$C$74:$C$76) -> Inmediato (0Q) | K32: =IF(B32="","",IF(VALUE(MID(B32,2,2))+IF(ISNUMBER(SEARCH("+2",J32)),2,IF(ISNUMBER(SEARCH("+8",J32)),8,0))>8,"Next period","Q"&(VALUE(MID(B32,2,2))+IF(ISNUMBER(SEARCH("+2",J32)),2,IF(ISNUMBER(SEARCH("+8",J32)),8,0))))) -> Q7
B33: Q8 | C33: =BOM_Consumo!J7 -> 370 | D33: =Inputs!B36 -> 12 | E33: =IF(C33>0,ROUNDUP(C33/D33,0),0) -> 31 | F33: 0 | G33: =F33*D33 -> 0 | H33: =IF(Inputs!$B$77="B",IF(F33>=Inputs!$E$75,Inputs!$B$75*(1-IFERROR(VALUE(SUBSTITUTE(LEFT(Inputs!$D$75,FIND("%",Inputs!$D$75)-1),"%",""))/100,0)),Inputs!$B$75),_xlfn.XLOOKUP(Inputs!$B$77,Inputs!$A$74:$A$76,Inputs!$B$74:$B$76)) -> 330 | I33: =F33*H33 -> 0 | J33: =_xlfn.XLOOKUP(Inputs!$B$77,Inputs!$A$74:$A$76,Inputs!$C$74:$C$76) -> Inmediato (0Q) | K33: =IF(B33="","",IF(VALUE(MID(B33,2,2))+IF(ISNUMBER(SEARCH("+2",J33)),2,IF(ISNUMBER(SEARCH("+8",J33)),8,0))>8,"Next period","Q"&(VALUE(MID(B33,2,2))+IF(ISNUMBER(SEARCH("+2",J33)),2,IF(ISNUMBER(SEARCH("+8",J33)),8,0))))) -> Q8

Sheet Costos
A1: COSTOS - Análisis Completo
A2: Costo Total = Costo de Compra + Ordering Cost + Holding Cost
A4: Material | B4: Costo Compra | C4: # Pedidos | D4: Ordering Cost | E4: Holding Cost | F4: Costo Total
A5: Pieza 1 | B5: =Compras_y_Lotes!H7 -> 1.4841128e+21 | C5: 1 | D5: 0 | E5: 0 | F5: =B5+D5+E5 -> 1.4841128e+21
A6: Pieza 2 | B6: =Compras_y_Lotes!H8 -> 3.4629299e+23 | C6: 1 | D6: 0 | E6: 0 | F6: =B6+D6+E6 -> 3.4629299e+23
A7: Pieza 3 | B7: =Compras_y_Lotes!H9 -> 8.0142091e+23 | C7: 1 | D7: 0 | E7: 0 | F7: =B7+D7+E7 -> 8.0142091e+23
A8: Pieza 4 | B8: =Compras_y_Lotes!H10 -> 1.0685612e+22 | C8: 1 | D8: 0 | E8: 0 | F8: =B8+D8+E8 -> 1.0685612e+22
A9: Pieza 5 | B9: =Compras_y_Lotes!H11 -> 1.4841128e+23 | C9: 1 | D9: 0 | E9: 0 | F9: =B9+D9+E9 -> 1.4841128e+23
A10: Pieza 6 | B10: =Compras_y_Lotes!H12 -> 2.5971974e+22 | C10: 1 | D10: 0 | E10: 0 | F10: =B10+D10+E10 -> 2.5971974e+22
A11: Parte A | B11: =SUM(Compras_y_Lotes!I18:I25) -> 0 | C11: =COUNTIF(Compras_y_Lotes!F18:F25,">0") -> 0 | D11: =C11*Inputs!B59 -> 0 | E11: =SUMPRODUCT((Inventario_Dinamico!B7:I7+Inventario_Dinamico!B10:I10)/2)*Inputs!C59 -> -1.5823687e+13 | F11: =B11+D11+E11 -> -1.5823687e+13
A12: Parte B | B12: =SUM(Compras_y_Lotes!I26:I33) -> 0 | C12: =COUNTIF(Compras_y_Lotes!F26:F33,">0") -> 0 | D12: =C12*Inputs!B60 -> 0 | E12: =SUMPRODUCT((Inventario_Dinamico!B13:I13+Inventario_Dinamico!B16:I16)/2)*Inputs!C60 -> -6.8307929e+16 | F12: =B12+D12+E12 -> -6.8307929e+16
A13: COSTO TOTAL | B13: =SUM(B5:B12) -> 1.3342669e+24 | C13: =SUM(C5:C12) -> 6 | D13: =SUM(D5:D12) -> 0 | E13: =SUM(E5:E12) -> -6.8323752e+16 | F13: =SUM(F5:F12) -> 1.3342668e+24

Sheet Cashflow_Compras
A1: CASHFLOW - Pagos por Quincena
A2: Proyección de pagos según términos de cada proveedor
A3: IMPORTANTE: Coordinar con Finanzas para asegurar liquidez
A5: Concepto | B5: Q1 | C5: Q2 | D5: Q3 | E5: Q4 | F5: Q5 | G5: Q6 | H5: Q7 | I5: Q8 | J5: TOTAL
A6: Piezas 1-6 (t=0) | B6: =Compras_y_Lotes!H13 -> 1.3342669e+24 | C6: 0 | D6: 0 | E6: 0 | F6: 0 | G6: 0 | H6: 0 | I6: 0 | J6: =SUM(B6:I6) -> 1.3342669e+24
A7: Parte A | B7: 0 | C7: 0 | D7: 0 | E7: 0 | F7: 0 | G7: 0 | H7: 0 | I7: 0 | J7: =SUM(B7:I7) -> 0
A8: Parte B | B8: 0 | C8: 0 | D8: 0 | E8: 0 | F8: 0 | G8: 0 | H8: 0 | I8: 0 | J8: =SUM(B8:I8) -> 0
A9: TOTAL PAGOS | B9: =SUM(B6:B8) -> 1.3342669e+24 | C9: =SUM(C6:C8) -> 0 | D9: =SUM(D6:D8) -> 0 | E9: =SUM(E6:E8) -> 0 | F9: =SUM(F6:F8) -> 0 | G9: =SUM(G6:G8) -> 0 | H9: =SUM(H6:H8) -> 0 | I9: =SUM(I6:I8) -> 0 | J9: =SUM(B9:I9) -> 1.3342669e+24

Sheet Escenarios
A1: ESCENARIOS - Análisis Comparativo
A2: Compara 3 estrategias: Conservador / Base / Agresivo
A4: SELECCIONAR ESCENARIO: | B4: Base
A6: Parámetro | B6: Conservador | C6: Base | D6: Agresivo | E6: Descripción
A7: Safety Stock | B7: 20% | C7: 10% | D7: 5% | E7: % sobre consumo promedio
A8: Proveedor Parte A | B8: A (seguro) | C8: A | D8: B (descuento) | E8: Estrategia de proveedor
A9: Proveedor Parte B | B9: A (seguro) | C9: A | D9: B (descuento) | E9: Estrategia de proveedor
A10: Frecuencia Pedidos | B10: Cada 4Q | C10: Cada 2Q | D10: Cada Q | E10: Frecuencia de compra
A12: RESULTADOS ESTIMADOS
A13: Costo Total | B13: Alto | C13: Medio | D13: Bajo | E13: Costo de compras + inventario
A14: Riesgo Stockout | B14: Muy Bajo | C14: Bajo | D14: Medio | E14: Probabilidad de quedarse sin stock
A15: Capital Inmovilizado | B15: Alto | C15: Medio | D15: Bajo | E15: Inventario promedio
A16: Cashflow Peak | B16: Distribuido | C16: Medio | D16: Concentrado | E16: Pago máximo en una Q
A20: COMPARACIÓN LADO A LADO - KPIs POR ESCENARIO
A21: KPI | B21: Conservador | C21: Base | D21: Agresivo | E21: Mejor | F21: Diferencia
A22: Costo Total Compras | B22: =Costos!F13 -> 1.3342668e+24 | C22: =Costos!F13 -> 1.3342668e+24 | D22: =Costos!F13*0.9 -> 1.2008401e+24 | E22: =MIN(B22:D22) -> 1.2008401e+24 | F22: =MAX(B22:D22)-MIN(B22:D22) -> 1.3342668e+23
A23: Total Pagos | B23: =Cashflow_Integrado!J33 -> 0 | C23: =Cashflow_Integrado!J33 -> 0 | D23: =Cashflow_Integrado!J33*0.92 -> 0 | E23: =MIN(B23:D23) -> 0 | F23: =MAX(B23:D23)-MIN(B23:D23) -> 0
A24: Pago Peak | B24: =Cashflow_Integrado!B37 -> 0 | C24: =Cashflow_Integrado!B37 -> 0 | D24: =Cashflow_Integrado!B37*1.15 -> 0 | E24: =MIN(B24:D24) -> 0 | F24: =MAX(B24:D24)-MIN(B24:D24) -> 0
A25: # Stockouts Esperados | B25: 0 | C25: 1 | D25: 3 | E25: =MIN(B25:D25) -> 0 | F25: =MAX(B25:D25)-MIN(B25:D25) -> 3
A26: Valor Esperado Pérdida | B26: =Riesgo_Proveedor_B!I14 -> 0 | C26: =Riesgo_Proveedor_B!I14 -> 0 | D26: =Riesgo_Proveedor_B!I14*2.5 -> 0 | E26: =MIN(B26:D26) -> 0 | F26: =MAX(B26:D26)-MIN(B26:D26) -> 0
A27: Buffer Promedio (Q) | B27: 1.5 | C27: 1 | D27: 0.5 | E27: =MAX(B27:D27) -> 1.5 | F27: =MAX(B27:D27)-MIN(B27:D27) -> 1
A29: SENSIBILIDAD DEMANDA | D29: Factor Base | E29: 1
A30: Factor | B30: Costo Total | C30: Pago Peak
B31: =Costos!F13 -> 1.3342668e+24 | C31: =Cashflow_Integrado!B30 -> 1.3342669e+24
A32: 0.9 | B32: 6.3821402e+23 | C32: 6.3821406e+23
A33: 1 | B33: 1.3342668e+24 | C33: 1.3342669e+24
A34: 1.1 | B34: 2.5999807e+24 | C34: 2.5999809e+24

Sheet Analisis_Proveedores
A1: ANÁLISIS DE PROVEEDORES - Herramienta de Decisión
A2: Compara costo total por proveedor según volumen y términos
A4: PARTE A - Análisis Comparativo
A5: Volumen a Comprar (batches): | B5: =SUM(Compras_y_Lotes!F18:F25) -> 0
A7: Proveedor | B7: Precio Base | C7: Descuento | D7: MOQ Desc. | E7: Precio Final | F7: Costo Compra | G7: Términos Pago | H7: Riesgo | I7: Costo Ajustado | J7: Ranking
A8: A | B8: =_xlfn.XLOOKUP(A8,Inputs!$A$66:$A$68,Inputs!$B$66:$B$68) -> 125 | C8: =IF(A8="B",IFERROR(VALUE(SUBSTITUTE(LEFT(Inputs!$D$67,FIND("%",Inputs!$D$67)-1),"%",""))/100,0),0) -> 0 | D8: =IF(A8="B",Inputs!$E$67,0) -> 0 | E8: =B8 -> 125 | F8: =B5*E8 -> 0 | G8: =_xlfn.XLOOKUP(A8,Inputs!$A$66:$A$68,Inputs!$C$66:$C$68) -> Inmediato (0Q) | H8: =1-_xlfn.XLOOKUP(A8,Inputs!$A$66:$A$68,Inputs!$F$66:$F$68) -> 0 | I8: =F8 -> 0 | J8: 0
A9: B | B9: =_xlfn.XLOOKUP(A9,Inputs!$A$66:$A$68,Inputs!$B$66:$B$68) -> 100 | C9: =IF(A9="B",IFERROR(VALUE(SUBSTITUTE(LEFT(Inputs!$D$67,FIND("%",Inputs!$D$67)-1),"%",""))/100,0),0) -> 0.16 | D9: =IF(A9="B",Inputs!$E$67,0) -> 150 | E9: =IF(B5>0,F9/B5,B9) -> 100 | F9: =SUMPRODUCT(Compras_y_Lotes!F18:F25*(B9*(1-C9*(Compras_y_Lotes!F18:F25>=D9)))) -> 0 | G9: =_xlfn.XLOOKUP(A9,Inputs!$A$66:$A$68,Inputs!$C$66:$C$68) -> +2 Quincenas | H9: =1-_xlfn.XLOOKUP(A9,Inputs!$A$66:$A$68,Inputs!$F$66:$F$68) -> 0.2 | I9: =F9*1.05 -> 0 | J9: 0
A10: C | B10: =_xlfn.XLOOKUP(A10,Inputs!$A$66:$A$68,Inputs!$B$66:$B$68) -> 140 | C10: =IF(A10="B",IFERROR(VALUE(SUBSTITUTE(LEFT(Inputs!$D$67,FIND("%",Inputs!$D$67)-1),"%",""))/100,0),0) -> 0 | D10: =IF(A10="B",Inputs!$E$67,0) -> 0 | E10: =B10 -> 140 | F10: =B5*E10 -> 0 | G10: =_xlfn.XLOOKUP(A10,Inputs!$A$66:$A$68,Inputs!$C$66:$C$68) -> +8 Quincenas | H10: =1-_xlfn.XLOOKUP(A10,Inputs!$A$66:$A$68,Inputs!$F$66:$F$68) -> 0 | I10: =F10*0.97 -> 0 | J10: 0
A11: RECOMENDACIÓN: | B11: =INDEX(A8:A10,MATCH(MIN(I8:I10),I8:I10,0)) -> A
A14: PARTE B - Análisis Comparativo
A15: Volumen a Comprar (batches): | B15: =SUM(Compras_y_Lotes!F26:F33) -> 0
A17: Proveedor | B17: Precio Base | C17: Descuento | D17: MOQ Desc. | E17: Precio Final | F17: Costo Compra | G17: Términos Pago | H17: Riesgo | I17: Costo Ajustado | J17: Ranking
A18: A | B18: =_xlfn.XLOOKUP(A18,Inputs!$A$74:$A$76,Inputs!$B$74:$B$76) -> 330 | C18: =IF(A18="B",IFERROR(VALUE(SUBSTITUTE(LEFT(Inputs!$D$75,FIND("%",Inputs!$D$75)-1),"%",""))/100,0),0) -> 0 | D18: =IF(A18="B",Inputs!$E$75,0) -> 0 | E18: =B18 -> 330 | F18: =B15*E18 -> 0 | G18: =_xlfn.XLOOKUP(A18,Inputs!$A$74:$A$76,Inputs!$C$74:$C$76) -> Inmediato (0Q) | H18: =1-_xlfn.XLOOKUP(A18,Inputs!$A$74:$A$76,Inputs!$F$74:$F$76) -> 0 | I18: =F18 -> 0 | J18: 0
A19: B | B19: =_xlfn.XLOOKUP(A19,Inputs!$A$74:$A$76,Inputs!$B$74:$B$76) -> 264 | C19: =IF(A19="B",IFERROR(VALUE(SUBSTITUTE(LEFT(Inputs!$D$75,FIND("%",Inputs!$D$75)-1),"%",""))/100,0),0) -> 0.16 | D19: =IF(A19="B",Inputs!$E$75,0) -> 80 | E19: =IF(B15>0,F19/B15,B19) -> 264 | F19: =SUMPRODUCT(Compras_y_Lotes!F26:F33*(B19*(1-C19*(Compras_y_Lotes!F26:F33>=D19)))) -> 0 | G19: =_xlfn.XLOOKUP(A19,Inputs!$A$74:$A$76,Inputs!$C$74:$C$76) -> +2 Quincenas | H19: =1-_xlfn.XLOOKUP(A19,Inputs!$A$74:$A$76,Inputs!$F$74:$F$76) -> 0.2 | I19: =F19*1.05 -> 0 | J19: 0
A20: C | B20: =_xlfn.XLOOKUP(A20,Inputs!$A$74:$A$76,Inputs!$B$74:$B$76) -> 370 | C20: =IF(A20="B",IFERROR(VALUE(SUBSTITUTE(LEFT(Inputs!$D$75,FIND("%",Inputs!$D$75)-1),"%",""))/100,0),0) -> 0 | D20: =IF(A20="B",Inputs!$E$75,0) -> 0 | E20: =B20 -> 370 | F20: =B15*E20 -> 0 | G20: =_xlfn.XLOOKUP(A20,Inputs!$A$74:$A$76,Inputs!$C$74:$C$76) -> +8 Quincenas | H20: =1-_xlfn.XLOOKUP(A20,Inputs!$A$74:$A$76,Inputs!$F$74:$F$76) -> 0 | I20: =F20*0.97 -> 0 | J20: 0
A21: RECOMENDACIÓN: | B21: =INDEX(A18:A20,MATCH(MIN(I18:I20),I18:I20,0)) -> A

Sheet Dashboard
A1: DASHBOARD - Purchasing Manager
A3: INDICADORES CLAVE (KPIs)
A5: Costo Total de Compras: | B5: =Costos!F13 -> 1.3342668e+24
A6: Total Pagos Periodo: | B6: =Cashflow_Compras!J9 -> 1.3342669e+24
A7: # Pedidos Totales: | B7: =SUM(Costos!C5:C12) -> 6 | C7: pedidos
A8: Pago Pico (Max en una Q): | B8: =MAX(Cashflow_Compras!B9:I9) -> 1.3342669e+24
A10: Inventario Negativo: | B10: TBD | C10: materiales
A11: Stock < Safety: | B11: TBD | C11: materiales
A14: ESTRATEGIA ACTUAL
A16: Proveedor Parte A: | B16: =Inputs!B58 -> Ordering Cost
A17: Proveedor Parte B: | B17: =Inputs!B69 -> A
A18: Escenario: | B18: =Escenarios!B4 -> Base
A25: ⚠️ ALERTAS CRÍTICAS
A27: Materiales con Inv < Buffer: | B27: =COUNTIF(Inventario_Dinamico!J55:J62,"<0") -> 2 | C27: materiales
A28: Riesgo por Proveedor B: | B28: =IF(OR(Inputs!B58="B",Inputs!B69="B"),"SÍ - REVISAR","NO") -> NO
A29: Cashflow Peak > $100k: | B29: =IF(Cashflow_Integrado!B37>100000,"SÍ - ALERTA","NO") -> NO

Sheet Riesgo_Proveedor_B
A1: ANÁLISIS DE RIESGO - PROVEEDOR B
A2: CRÍTICO: Proveedor B tiene 20% probabilidad de NO ENTREGAR (sin pago, pero SIN producción)
A4: PARÁMETROS DE RIESGO
A6: Parámetro | B6: Valor | C6: Fuente
A7: Prob. Incumplimiento Prov. B | B7: 0.2 | C7: EXSIM Rules
A8: Costo Oportunidad ($/EC perdido) | B8: 150 | C8: Margin estimado
A9: Lead time recuperación (Q) | B9: 1 | C9: Assumption
A12: ANÁLISIS DE IMPACTO POR MATERIAL (si usas Proveedor B)
A13: Material | B13: Proveedor Elegido | C13: Total Lotes P7 | D13: Prob. Falla | E13: Lotes Perdidos (Esperado) | F13: Unidades Perdidas | G13: EC Sin Producir | H13: Costo Oportunidad | I13: Valor Esperado Pérdida
A14: Parte A | B14: =Inputs!B69 -> A | C14: =SUM(Compras_y_Lotes!F18:F25) -> 0 | D14: =IF(B14="B",$B$7,0) -> 0 | E14: =C14*D14 -> 0 | F14: =E14*Inputs!B35 -> 0 | G14: =F14/Inputs!B23 -> 0 | H14: =G14*$B$8 -> 0 | I14: =H14 -> 0
A15: Parte B | B15: =Inputs!B77 -> A | C15: =SUM(Compras_y_Lotes!F26:F33) -> 0 | D15: =IF(B15="B",$B$7,0) -> 0 | E15: =C15*D15 -> 0 | F15: =E15*Inputs!B36 -> 0 | G15: =F15/Inputs!B24 -> 0 | H15: =G15*$B$8 -> 0 | I15: =H15 -> 0
A18: DECISIÓN: PROVEEDOR A vs B (Análisis Ajustado por Riesgo)
A19: Material | B19: Proveedor | C19: Costo Compra | D19: Descuento | E19: Ahorro | F19: Valor Esperado Pérdida | G19: Costo Neto Ajustado | H19: Decisión Recomendada
A20: Parte A | B20: A | C20: =SUM(Compras_y_Lotes!I18:I25) -> 0 | D20: 0 | E20: 0 | F20: 0 | G20: =C20+F20 -> 0
B21: B | C21: =IF(SUM(Compras_y_Lotes!F18:F25)>=150,C20*(1-0.16),C20) -> 0 | D21: 0.16 | E21: =C20-C21 -> 0 | F21: =I14 -> 0 | G21: =C21+F21 -> 0
A22: Parte B | B22: A | C22: =SUM(Compras_y_Lotes!I26:I33) -> 0 | D22: 0 | E22: 0 | F22: 0 | G22: =C22+F22 -> 0
B23: B | C23: =IF(SUM(Compras_y_Lotes!F26:F33)>=80,C22*(1-0.2),C22) -> 0 | D23: 0.2 | E23: =C22-C23 -> 0 | F23: =I15 -> 0 | G23: =C23+F23 -> 0
A25: MONTE CARLO - COSTO ESPERADO
A26: Costo Base | B26: =Costos!F13 -> 1.3342668e+24
A27: Stockout si falla A | B27: =IF(B14="B",SUM(Compras_y_Lotes!F18:F25)*Inputs!B35/Inputs!B23*$B$8,0) -> 0
A28: Stockout si falla B | B28: =IF(B15="B",SUM(Compras_y_Lotes!F26:F33)*Inputs!B36/Inputs!B24*$B$8,0) -> 0
A29: Simulacion (100 corridas)
A30: Corrida | B30: Falla A | C30: Falla B | D30: Costo Total
A31: =ROW()-30 -> 1 | B31: =IF($B$14="B",--(RAND()<=$B$7),0) -> 0 | C31: =IF($B$15="B",--(RAND()<=$B$7),0) -> 0 | D31: =$B$26+B31*$B$27+C31*$B$28 -> 1.3342668e+24
A32: =ROW()-30 -> 2 | B32: =IF($B$14="B",--(RAND()<=$B$7),0) -> 0 | C32: =IF($B$15="B",--(RAND()<=$B$7),0) -> 0 | D32: =$B$26+B32*$B$27+C32*$B$28 -> 1.3342668e+24
A33: =ROW()-30 -> 3 | B33: =IF($B$14="B",--(RAND()<=$B$7),0) -> 0 | C33: =IF($B$15="B",--(RAND()<=$B$7),0) -> 0 | D33: =$B$26+B33*$B$27+C33*$B$28 -> 1.3342668e+24
A34: =ROW()-30 -> 4 | B34: =IF($B$14="B",--(RAND()<=$B$7),0) -> 0 | C34: =IF($B$15="B",--(RAND()<=$B$7),0) -> 0 | D34: =$B$26+B34*$B$27+C34*$B$28 -> 1.3342668e+24
A35: =ROW()-30 -> 5 | B35: =IF($B$14="B",--(RAND()<=$B$7),0) -> 0 | C35: =IF($B$15="B",--(RAND()<=$B$7),0) -> 0 | D35: =$B$26+B35*$B$27+C35*$B$28 -> 1.3342668e+24
A36: =ROW()-30 -> 6 | B36: =IF($B$14="B",--(RAND()<=$B$7),0) -> 0 | C36: =IF($B$15="B",--(RAND()<=$B$7),0) -> 0 | D36: =$B$26+B36*$B$27+C36*$B$28 -> 1.3342668e+24
A37: =ROW()-30 -> 7 | B37: =IF($B$14="B",--(RAND()<=$B$7),0) -> 0 | C37: =IF($B$15="B",--(RAND()<=$B$7),0) -> 0 | D37: =$B$26+B37*$B$27+C37*$B$28 -> 1.3342668e+24
A38: =ROW()-30 -> 8 | B38: =IF($B$14="B",--(RAND()<=$B$7),0) -> 0 | C38: =IF($B$15="B",--(RAND()<=$B$7),0) -> 0 | D38: =$B$26+B38*$B$27+C38*$B$28 -> 1.3342668e+24
A39: =ROW()-30 -> 9 | B39: =IF($B$14="B",--(RAND()<=$B$7),0) -> 0 | C39: =IF($B$15="B",--(RAND()<=$B$7),0) -> 0 | D39: =$B$26+B39*$B$27+C39*$B$28 -> 1.3342668e+24
A40: =ROW()-30 -> 10 | B40: =IF($B$14="B",--(RAND()<=$B$7),0) -> 0 | C40: =IF($B$15="B",--(RAND()<=$B$7),0) -> 0 | D40: =$B$26+B40*$B$27+C40*$B$28 -> 1.3342668e+24
A41: =ROW()-30 -> 11 | B41: =IF($B$14="B",--(RAND()<=$B$7),0) -> 0 | C41: =IF($B$15="B",--(RAND()<=$B$7),0) -> 0 | D41: =$B$26+B41*$B$27+C41*$B$28 -> 1.3342668e+24
A42: =ROW()-30 -> 12 | B42: =IF($B$14="B",--(RAND()<=$B$7),0) -> 0 | C42: =IF($B$15="B",--(RAND()<=$B$7),0) -> 0 | D42: =$B$26+B42*$B$27+C42*$B$28 -> 1.3342668e+24
... A130: =ROW()-30 -> 100 | B130: =IF($B$14="B",--(RAND()<=$B$7),0) -> 0 | C130: =IF($B$15="B",--(RAND()<=$B$7),0) -> 0 | D130: =$B$26+B130*$B$27+C130*$B$28 -> 1.3342668e+24
A132: Promedio | D132: =AVERAGE(D31:D130) -> 1.3342668e+24
A133: P90 | D133: =_xlfn.PERCENTILE.INC(D31:D130,0.9) -> 1.3342668e+24

Sheet Cashflow_Integrado
A1: CASHFLOW INTEGRADO - PURCHASING
A2: Pagos REALES por quincena: Compras + Ordering + Holding (para coordinar con Finanzas)
A4: 1. PAGOS DE COMPRAS (según términos de proveedor)
A5: Concepto | B5: Q1 | C5: Q2 | D5: Q3 | E5: Q4 | F5: Q5 | G5: Q6 | H5: Q7 | I5: Q8 | J5: TOTAL
A6: Piezas 1-6 (t=0) | B6: =Compras_y_Lotes!H13 -> 1.3342669e+24 | C6: 0 | D6: 0 | E6: 0 | F6: 0 | G6: 0 | H6: 0 | I6: 0 | J6: =B6 -> 1.3342669e+24
A7: Parte A (según proveedor) | B7: =SUMIFS(Compras_y_Lotes!$I$18:$I$25,Compras_y_Lotes!$K$18:$K$25,B$5) -> 0 | C7: =SUMIFS(Compras_y_Lotes!$I$18:$I$25,Compras_y_Lotes!$K$18:$K$25,C$5) -> 0 | D7: =SUMIFS(Compras_y_Lotes!$I$18:$I$25,Compras_y_Lotes!$K$18:$K$25,D$5) -> 0 | E7: =SUMIFS(Compras_y_Lotes!$I$18:$I$25,Compras_y_Lotes!$K$18:$K$25,E$5) -> 0 | F7: =SUMIFS(Compras_y_Lotes!$I$18:$I$25,Compras_y_Lotes!$K$18:$K$25,F$5) -> 0 | G7: =SUMIFS(Compras_y_Lotes!$I$18:$I$25,Compras_y_Lotes!$K$18:$K$25,G$5) -> 0 | H7: =SUMIFS(Compras_y_Lotes!$I$18:$I$25,Compras_y_Lotes!$K$18:$K$25,H$5) -> 0 | I7: =SUMIFS(Compras_y_Lotes!$I$18:$I$25,Compras_y_Lotes!$K$18:$K$25,I$5) -> 0 | J7: =SUM(B7:I7) -> 0
A8: Parte B (según proveedor) | B8: =SUMIFS(Compras_y_Lotes!$I$26:$I$33,Compras_y_Lotes!$K$26:$K$33,B$5) -> 0 | C8: =SUMIFS(Compras_y_Lotes!$I$26:$I$33,Compras_y_Lotes!$K$26:$K$33,C$5) -> 0 | D8: =SUMIFS(Compras_y_Lotes!$I$26:$I$33,Compras_y_Lotes!$K$26:$K$33,D$5) -> 0 | E8: =SUMIFS(Compras_y_Lotes!$I$26:$I$33,Compras_y_Lotes!$K$26:$K$33,E$5) -> 0 | F8: =SUMIFS(Compras_y_Lotes!$I$26:$I$33,Compras_y_Lotes!$K$26:$K$33,F$5) -> 0 | G8: =SUMIFS(Compras_y_Lotes!$I$26:$I$33,Compras_y_Lotes!$K$26:$K$33,G$5) -> 0 | H8: =SUMIFS(Compras_y_Lotes!$I$26:$I$33,Compras_y_Lotes!$K$26:$K$33,H$5) -> 0 | I8: =SUMIFS(Compras_y_Lotes!$I$26:$I$33,Compras_y_Lotes!$K$26:$K$33,I$5) -> 0 | J8: =SUM(B8:I8) -> 0
A9: SUBTOTAL COMPRAS | B9: =SUM(B6:B8) -> 1.3342669e+24 | C9: =SUM(C6:C8) -> 0 | D9: =SUM(D6:D8) -> 0 | E9: =SUM(E6:E8) -> 0 | F9: =SUM(F6:F8) -> 0 | G9: =SUM(G6:G8) -> 0 | H9: =SUM(H6:H8) -> 0 | I9: =SUM(I6:I8) -> 0 | J9: =SUM(J6:J8) -> 1.3342669e+24
A12: 2. ORDERING COSTS (por pedido realizado)
A13: Concepto | B13: Q1 | C13: Q2 | D13: Q3 | E13: Q4 | F13: Q5 | G13: Q6 | H13: Q7 | I13: Q8 | J13: TOTAL
A14: Parte A | B14: =IF(INDEX(Compras_y_Lotes!$F$18:$F$25,COLUMN(B14)-COLUMN($B$14)+1)>0,Inputs!$B$59,0) -> 0 | C14: =IF(INDEX(Compras_y_Lotes!$F$18:$F$25,COLUMN(C14)-COLUMN($B$14)+1)>0,Inputs!$B$59,0) -> 0 | D14: =IF(INDEX(Compras_y_Lotes!$F$18:$F$25,COLUMN(D14)-COLUMN($B$14)+1)>0,Inputs!$B$59,0) -> 0 | E14: =IF(INDEX(Compras_y_Lotes!$F$18:$F$25,COLUMN(E14)-COLUMN($B$14)+1)>0,Inputs!$B$59,0) -> 0 | F14: =IF(INDEX(Compras_y_Lotes!$F$18:$F$25,COLUMN(F14)-COLUMN($B$14)+1)>0,Inputs!$B$59,0) -> 0 | G14: =IF(INDEX(Compras_y_Lotes!$F$18:$F$25,COLUMN(G14)-COLUMN($B$14)+1)>0,Inputs!$B$59,0) -> 0 | H14: =IF(INDEX(Compras_y_Lotes!$F$18:$F$25,COLUMN(H14)-COLUMN($B$14)+1)>0,Inputs!$B$59,0) -> 0 | I14: =IF(INDEX(Compras_y_Lotes!$F$18:$F$25,COLUMN(I14)-COLUMN($B$14)+1)>0,Inputs!$B$59,0) -> 0 | J14: =SUM(B14:I14) -> 0
A15: Parte B | B15: =IF(INDEX(Compras_y_Lotes!$F$26:$F$33,COLUMN(B15)-COLUMN($B$15)+1)>0,Inputs!$B$60,0) -> 0 | C15: =IF(INDEX(Compras_y_Lotes!$F$26:$F$33,COLUMN(C15)-COLUMN($B$15)+1)>0,Inputs!$B$60,0) -> 0 | D15: =IF(INDEX(Compras_y_Lotes!$F$26:$F$33,COLUMN(D15)-COLUMN($B$15)+1)>0,Inputs!$B$60,0) -> 0 | E15: =IF(INDEX(Compras_y_Lotes!$F$26:$F$33,COLUMN(E15)-COLUMN($B$15)+1)>0,Inputs!$B$60,0) -> 0 | F15: =IF(INDEX(Compras_y_Lotes!$F$26:$F$33,COLUMN(F15)-COLUMN($B$15)+1)>0,Inputs!$B$60,0) -> 0 | G15: =IF(INDEX(Compras_y_Lotes!$F$26:$F$33,COLUMN(G15)-COLUMN($B$15)+1)>0,Inputs!$B$60,0) -> 0 | H15: =IF(INDEX(Compras_y_Lotes!$F$26:$F$33,COLUMN(H15)-COLUMN($B$15)+1)>0,Inputs!$B$60,0) -> 0 | I15: =IF(INDEX(Compras_y_Lotes!$F$26:$F$33,COLUMN(I15)-COLUMN($B$15)+1)>0,Inputs!$B$60,0) -> 0 | J15: =SUM(B15:I15) -> 0
A16: SUBTOTAL ORDERING | B16: =SUM(B14:B15) -> 0 | C16: =SUM(C14:C15) -> 0 | D16: =SUM(D14:D15) -> 0 | E16: =SUM(E14:E15) -> 0 | F16: =SUM(F14:F15) -> 0 | G16: =SUM(G14:G15) -> 0 | H16: =SUM(H14:H15) -> 0 | I16: =SUM(I14:I15) -> 0 | J16: =SUM(J14:J15) -> 0
A19: 3. HOLDING COSTS (por inventario promedio en quincena)
A20: Concepto | B20: Q1 | C20: Q2 | D20: Q3 | E20: Q4 | F20: Q5 | G20: Q6 | H20: Q7 | I20: Q8 | J20: TOTAL
A21: Parte A | B21: =(Inventario_Dinamico!B7+Inventario_Dinamico!B10)/2*Inputs!$C$59 -> 1076.1 | C21: =(Inventario_Dinamico!C7+Inventario_Dinamico!C10)/2*Inputs!$C$59 -> -512576.4 | D21: =(Inventario_Dinamico!D7+Inventario_Dinamico!D10)/2*Inputs!$C$59 -> -9.507697e+08 | E21: =(Inventario_Dinamico!E7+Inventario_Dinamico!E10)/2*Inputs!$C$59 -> -1.7589265e+12 | F21: =(Inventario_Dinamico!F7+Inventario_Dinamico!F10)/2*Inputs!$C$59 -> -3.5159524e+12 | G21: =(Inventario_Dinamico!G7+Inventario_Dinamico!G10)/2*Inputs!$C$59 -> -3.5159524e+12 | H21: =(Inventario_Dinamico!H7+Inventario_Dinamico!H10)/2*Inputs!$C$59 -> -3.5159524e+12 | I21: =(Inventario_Dinamico!I7+Inventario_Dinamico!I10)/2*Inputs!$C$59 -> -3.5159524e+12 | J21: =SUM(B21:I21) -> -1.5823687e+13
A22: Parte B | B22: =(Inventario_Dinamico!B13+Inventario_Dinamico!B16)/2*Inputs!$C$60 -> 3928.5 | C22: =(Inventario_Dinamico!C13+Inventario_Dinamico!C16)/2*Inputs!$C$60 -> -1537029 | D22: =(Inventario_Dinamico!D13+Inventario_Dinamico!D16)/2*Inputs!$C$60 -> -2852308404 | E22: =(Inventario_Dinamico!E13+Inventario_Dinamico!E16)/2*Inputs!$C$60 -> -5276779352154 | F22: =(Inventario_Dinamico!F13+Inventario_Dinamico!F16)/2*Inputs!$C$60 -> -9.7620418e+15 | G22: =(Inventario_Dinamico!G13+Inventario_Dinamico!G16)/2*Inputs!$C$60 -> -1.9513536e+16 | H22: =(Inventario_Dinamico!H13+Inventario_Dinamico!H16)/2*Inputs!$C$60 -> -1.9513536e+16 | I22: =(Inventario_Dinamico!I13+Inventario_Dinamico!I16)/2*Inputs!$C$60 -> -1.9513536e+16 | J22: =SUM(B22:I22) -> -6.8307929e+16
A23: SUBTOTAL HOLDING | B23: =SUM(B21:B22) -> 5004.6 | C23: =SUM(C21:C22) -> -2049605.4 | D23: =SUM(D21:D22) -> -3.8030781e+09 | E23: =SUM(E21:E22) -> -7.0357058e+12 | F23: =SUM(F21:F22) -> -9.7655578e+15 | G23: =SUM(G21:G22) -> -1.9517052e+16 | H23: =SUM(H21:H22) -> -1.9517052e+16 | I23: =SUM(I21:I22) -> -1.9517052e+16 | J23: =SUM(J21:J22) -> -6.8323752e+16
A26: TOTAL OUTFLOW PURCHASING | B26: =B9+B16+B23 -> 1.3342669e+24 | C26: =C9+C16+C23 -> -2049605.4 | D26: =D9+D16+D23 -> -3.8030781e+09 | E26: =E9+E16+E23 -> -7.0357058e+12 | F26: =F9+F16+F23 -> -9.7655578e+15 | G26: =G9+G16+G23 -> -1.9517052e+16 | H26: =H9+H16+H23 -> -1.9517052e+16 | I26: =I9+I16+I23 -> -1.9517052e+16 | J26: =J9+J16+J23 -> 1.3342668e+24
A28: ANÁLISIS
A30: Pago Máximo (Peak): | B30: =MAX(B26:I26) -> 1.3342669e+24 | C30: Quincena más costosa
A31: Pago Mínimo: | B31: =MIN(B26:I26) -> -1.9517052e+16 | C31: Quincena más barata
A32: Pago Promedio: | B32: =AVERAGE(B26:I26) -> 1.6678335e+23 | C32: Promedio por quincena
A33: Desviación Est.: | B33: =STDEV(B26:I26) -> 4.7173458e+23 | C33: Volatilidad del flujo

Sheet EXSIM_Upload
A1: EXSIM UPLOAD - COPIAR DIRECTO A PLATAFORMA
A2: Formato exacto para subir decisiones a EXSIM. Copiar columnas B-E directamente.
A4: PIEZAS 1-6 (Compra única en t=0)
A5: Material | B5: Fortnight | C5: Lots | D5: Supplier | E5: Notes
A6: Pieza 1 | B6: 0 | C6: =Compras_y_Lotes!E7 -> 2.4735213e+19 | D6: Único | E6: =IF(C6>0,"Comprar","NO COMPRAR") -> Comprar
A7: Pieza 2 | B7: 0 | C7: =Compras_y_Lotes!E8 -> 4.9470427e+22 | D7: Único | E7: =IF(C7>0,"Comprar","NO COMPRAR") -> Comprar
A8: Pieza 3 | B8: 0 | C8: =Compras_y_Lotes!E9 -> 2.2261692e+22 | D8: Único | E8: =IF(C8>0,"Comprar","NO COMPRAR") -> Comprar
A9: Pieza 4 | B9: 0 | C9: =Compras_y_Lotes!E10 -> 4.4523384e+20 | D9: Único | E9: =IF(C9>0,"Comprar","NO COMPRAR") -> Comprar
A10: Pieza 5 | B10: 0 | C10: =Compras_y_Lotes!E11 -> 4.9470427e+21 | D10: Único | E10: =IF(C10>0,"Comprar","NO COMPRAR") -> Comprar
A11: Pieza 6 | B11: 0 | C11: =Compras_y_Lotes!E12 -> 9.275705e+20 | D11: Único | E11: =IF(C11>0,"Comprar","NO COMPRAR") -> Comprar
A13: PARTE A (Por Quincena)
A14: Material | B14: Fortnight | C14: Lots | D14: Supplier | E14: Notes
A15: Parte A | B15: 1 | C15: =Compras_y_Lotes!F18 -> 0 | D15: =Inputs!$B$69 -> A | E15: =IF(C15>0,"Comprar","-") -> -
A16: Parte A | B16: 2 | C16: =Compras_y_Lotes!F19 -> 0 | D16: =Inputs!$B$69 -> A | E16: =IF(C16>0,"Comprar","-") -> -
A17: Parte A | B17: 3 | C17: =Compras_y_Lotes!F20 -> 0 | D17: =Inputs!$B$69 -> A | E17: =IF(C17>0,"Comprar","-") -> -
A18: Parte A | B18: 4 | C18: =Compras_y_Lotes!F21 -> 0 | D18: =Inputs!$B$69 -> A | E18: =IF(C18>0,"Comprar","-") -> -
A19: Parte A | B19: 5 | C19: =Compras_y_Lotes!F22 -> 0 | D19: =Inputs!$B$69 -> A | E19: =IF(C19>0,"Comprar","-") -> -
A20: Parte A | B20: 6 | C20: =Compras_y_Lotes!F23 -> 0 | D20: =Inputs!$B$69 -> A | E20: =IF(C20>0,"Comprar","-") -> -
A21: Parte A | B21: 7 | C21: =Compras_y_Lotes!F24 -> 0 | D21: =Inputs!$B$69 -> A | E21: =IF(C21>0,"Comprar","-") -> -
A22: Parte A | B22: 8 | C22: =Compras_y_Lotes!F25 -> 0 | D22: =Inputs!$B$69 -> A | E22: =IF(C22>0,"Comprar","-") -> -
A24: PARTE B (Por Quincena)
A25: Material | B25: Fortnight | C25: Lots | D25: Supplier | E25: Notes
A26: Parte B | B26: 1 | C26: =Compras_y_Lotes!F26 -> 0 | D26: =Inputs!$B$77 -> A | E26: =IF(C26>0,"Comprar","-") -> -
A27: Parte B | B27: 2 | C27: =Compras_y_Lotes!F27 -> 0 | D27: =Inputs!$B$77 -> A | E27: =IF(C27>0,"Comprar","-") -> -
A28: Parte B | B28: 3 | C28: =Compras_y_Lotes!F28 -> 0 | D28: =Inputs!$B$77 -> A | E28: =IF(C28>0,"Comprar","-") -> -
A29: Parte B | B29: 4 | C29: =Compras_y_Lotes!F29 -> 0 | D29: =Inputs!$B$77 -> A | E29: =IF(C29>0,"Comprar","-") -> -
A30: Parte B | B30: 5 | C30: =Compras_y_Lotes!F30 -> 0 | D30: =Inputs!$B$77 -> A | E30: =IF(C30>0,"Comprar","-") -> -
A31: Parte B | B31: 6 | C31: =Compras_y_Lotes!F31 -> 0 | D31: =Inputs!$B$77 -> A | E31: =IF(C31>0,"Comprar","-") -> -
A32: Parte B | B32: 7 | C32: =Compras_y_Lotes!F32 -> 0 | D32: =Inputs!$B$77 -> A | E32: =IF(C32>0,"Comprar","-") -> -
A33: Parte B | B33: 8 | C33: =Compras_y_Lotes!F33 -> 0 | D33: =Inputs!$B$77 -> A | E33: =IF(C33>0,"Comprar","-") -> -

Sheet Multi_Planta
A1: MULTI-PLANTA: CENTRO Y OESTE
A2: Inventarios y producción por región (EXSIM requiere separación)
A4: INVENTARIO POR PLANTA
A5: Material | B5: Centro | C5: Oeste | D5: TOTAL | E5: % Centro
A6: Parte A | B6: 3496 | C6: 1016 | D6: 4512 | E6: =B6/D6 -> 0.7748227
A7: Parte B | B7: 765 | C7: 293 | D7: 1058 | E7: =B7/D7 -> 0.72306238
A8: Pieza 1 | B8: 94 | C8: 36 | D8: 130 | E8: =B8/D8 -> 0.72307692
A9: Pieza 2 | B9: 3844 | C9: 1424 | D9: 5268 | E9: =B9/D9 -> 0.72968869
A10: Pieza 3 | B10: 3125 | C10: 1208 | D10: 4333 | E10: =B10/D10 -> 0.72120932
A11: Pieza 4 | B11: 6131 | C11: 2356 | D11: 8487 | E11: =B11/D11 -> 0.72239896
A12: Pieza 5 | B12: 16736 | C12: 6456 | D12: 23192 | E12: =B12/D12 -> 0.72162815
A13: Pieza 6 | B13: 4439 | C13: 1596 | D13: 6035 | E13: =B13/D13 -> 0.73554267

Sheet MRP_LeadTimes
A1: MRP - PRODUCCIÓN POR SECCIÓN
A2: 5 secciones (S1-S5), cada una tarda 1 quincena. WIP entre secciones.
A4: FLUJO DE PRODUCCIÓN
A5: Sección | B5: Input | C5: Process | D5: Output | E5: Lead Time
A6: S1 | B6: Parte A | C6: Ensambla Piezas | D6: Semi A | E6: 1Q
A7: S2 | B7: Parte B | C7: Ensambla Piezas | D7: Semi B | E7: 1Q
A8: S3 | B8: - | C8: Pieza 3 | D8: Semi C | E8: 1Q
A9: S4 | B9: - | C9: Pieza 6 | D9: Semi D | E9: 1Q
A10: S5 | B10: Semis | C10: Ensambla final | D10: Electroclean | E10: 1Q
A12: CALENDARIO POR SECCION (Lead Time 1Q)
A13: Seccion | B13: Q1 | C13: Q2 | D13: Q3 | E13: Q4 | F13: Q5 | G13: Q6 | H13: Q7 | I13: Q8
A14: S5 - Final (EC) | B14: =Inputs!B6*Inputs!$B$101 -> 1850 | C14: =Inputs!C6*Inputs!$B$101 -> 1850 | D14: =Inputs!D6*Inputs!$B$101 -> 1850 | E14: =Inputs!E6*Inputs!$B$101 -> 1850 | F14: =Inputs!F6*Inputs!$B$101 -> 1850 | G14: =Inputs!G6*Inputs!$B$101 -> 1850 | H14: =Inputs!H6*Inputs!$B$101 -> 1850 | I14: =Inputs!I6*Inputs!$B$101 -> 1850
A15: S4 - Piezas | B15: =IFERROR(C14,0) -> 1850 | C15: =IFERROR(D14,0) -> 1850 | D15: =IFERROR(E14,0) -> 1850 | E15: =IFERROR(F14,0) -> 1850 | F15: =IFERROR(G14,0) -> 1850 | G15: =IFERROR(H14,0) -> 1850 | H15: =IFERROR(I14,0) -> 1850 | I15: =IFERROR(J14,0) -> 0
A16: S3 - Semi | B16: =IFERROR(C15,0) -> 1850 | C16: =IFERROR(D15,0) -> 1850 | D16: =IFERROR(E15,0) -> 1850 | E16: =IFERROR(F15,0) -> 1850 | F16: =IFERROR(G15,0) -> 1850 | G16: =IFERROR(H15,0) -> 1850 | H16: =IFERROR(I15,0) -> 0 | I16: =IFERROR(J15,0) -> 0
A17: S2 - Parte B | B17: =IFERROR(C16,0) -> 1850 | C17: =IFERROR(D16,0) -> 1850 | D17: =IFERROR(E16,0) -> 1850 | E17: =IFERROR(F16,0) -> 1850 | F17: =IFERROR(G16,0) -> 1850 | G17: =IFERROR(H16,0) -> 0 | H17: =IFERROR(I16,0) -> 0 | I17: =IFERROR(J16,0) -> 0
A18: S1 - Parte A | B18: =IFERROR(C17,0) -> 1850 | C18: =IFERROR(D17,0) -> 1850 | D18: =IFERROR(E17,0) -> 1850 | E18: =IFERROR(F17,0) -> 1850 | F18: =IFERROR(G17,0) -> 0 | G18: =IFERROR(H17,0) -> 0 | H18: =IFERROR(I17,0) -> 0 | I18: =IFERROR(J17,0) -> 0

Sheet Reconciliacion
A1: RECONCILIACION CON REPORTES EXSIM
A2: Pega reportes del simulador aqui para comparar
A4: RAW MATERIALS INVENTORY
A5: EXSIM (pegar aqui) | J5: Umbral (abs) | K5: 100
A6: Material | B6: Q1 | C6: Q2 | D6: Q3 | E6: Q4 | F6: Q5 | G6: Q6 | H6: Q7 | I6: Q8
A7: Parte A
A8: Parte B
A9: Pieza 1
A10: Pieza 2
A11: Pieza 3
A12: Pieza 4
A13: Pieza 5
A14: Pieza 6
A16: MODELO (Inv_Final)
A17: Material | B17: Q1 | C17: Q2 | D17: Q3 | E17: Q4 | F17: Q5 | G17: Q6 | H17: Q7 | I17: Q8
A18: Parte A | B18: =Inventario_Dinamico!B10 -> 2662 | C18: =Inventario_Dinamico!C10 -> -3419838 | D18: =Inventario_Dinamico!D10 -> -6335044838 | E18: =Inventario_Dinamico!E10 -> -11719841294838 | F18: =Inventario_Dinamico!F10 -> -11719841294838 | G18: =Inventario_Dinamico!G10 -> -11719841294838 | H18: =Inventario_Dinamico!H10 -> -11719841294838 | I18: =Inventario_Dinamico!I10 -> -11719841296688
A19: Parte B | B19: =Inventario_Dinamico!B16 -> 688 | C19: =Inventario_Dinamico!C16 -> -683812 | D19: =Inventario_Dinamico!D16 -> -1267008812 | E19: =Inventario_Dinamico!E16 -> -2343968258812 | F19: =Inventario_Dinamico!F16 -> -4.3363413e+15 | G19: =Inventario_Dinamico!G16 -> -4.3363413e+15 | H19: =Inventario_Dinamico!H16 -> -4.3363413e+15 | I19: =Inventario_Dinamico!I16 -> -4.3363413e+15
A20: Pieza 1 | B20: =Inventario_Dinamico!B22 -> 111.5 | C20: =Inventario_Dinamico!C22 -> -34113.5 | D20: =Inventario_Dinamico!D22 -> -63350364 | E20: =Inventario_Dinamico!E22 -> -1.1719841e+11 | F20: =Inventario_Dinamico!F22 -> -2.1681706e+14 | G20: =Inventario_Dinamico!G22 -> -4.0111157e+17 | H20: =Inventario_Dinamico!H22 -> -7.420564e+20 | I20: =Inventario_Dinamico!I22 -> -7.420564e+20
A21: Pieza 2 | B21: =Inventario_Dinamico!B28 -> -9532 | C21: =Inventario_Dinamico!C28 -> -27389532 | D21: =Inventario_Dinamico!D28 -> -50680389532 | E21: =Inventario_Dinamico!E28 -> -93758730389532 | F21: =Inventario_Dinamico!F28 -> -1.7345365e+17 | G21: =Inventario_Dinamico!G28 -> -3.2088925e+20 | H21: =Inventario_Dinamico!H28 -> -5.9364512e+23 | I21: =Inventario_Dinamico!I28 -> -5.9364512e+23
A22: Pieza 3 | B22: =Inventario_Dinamico!B34 -> 3778 | C22: =Inventario_Dinamico!C34 -> -1022972 | D22: =Inventario_Dinamico!D34 -> -1900510472 | E22: =Inventario_Dinamico!E34 -> -3515952385472 | F22: =Inventario_Dinamico!F34 -> -6.5045119e+15 | G22: =Inventario_Dinamico!G34 -> -1.2033347e+19 | H22: =Inventario_Dinamico!H34 -> -2.2261692e+22 | I22: =Inventario_Dinamico!I34 -> -2.2261692e+22
A23: Pieza 4 | B23: =Inventario_Dinamico!B40 -> 7377 | C23: =Inventario_Dinamico!C40 -> -2046123 | D23: =Inventario_Dinamico!D40 -> -3801021123 | E23: =Inventario_Dinamico!E40 -> -7031904771123 | F23: =Inventario_Dinamico!F40 -> -1.3009024e+16 | G23: =Inventario_Dinamico!G40 -> -2.4066694e+19 | H23: =Inventario_Dinamico!H40 -> -4.4523384e+22 | I23: =Inventario_Dinamico!I40 -> -4.4523384e+22
A24: Pieza 5 | B24: =Inventario_Dinamico!B46 -> 19492 | C24: =Inventario_Dinamico!C46 -> -6825508 | D24: =Inventario_Dinamico!D46 -> -12670075508 | E24: =Inventario_Dinamico!E46 -> -23439682575508 | F24: =Inventario_Dinamico!F46 -> -4.3363413e+16 | G24: =Inventario_Dinamico!G46 -> -8.0222314e+19 | H24: =Inventario_Dinamico!H46 -> -1.4841128e+23 | I24: =Inventario_Dinamico!I46 -> -1.4841128e+23
A25: Pieza 6 | B25: =Inventario_Dinamico!B52 -> 4647.5 | C25: =Inventario_Dinamico!C52 -> -2562227.5 | D25: =Inventario_Dinamico!D52 -> -4.751281e+09 | E25: =Inventario_Dinamico!E52 -> -8.789881e+12 | F25: =Inventario_Dinamico!F52 -> -1.626128e+16 | G25: =Inventario_Dinamico!G52 -> -3.0083368e+19 | H25: =Inventario_Dinamico!H52 -> -5.565423e+22 | I25: =Inventario_Dinamico!I52 -> -5.565423e+22
A27: DIFERENCIAS (EXSIM - MODELO)
A28: Material | B28: Q1 | C28: Q2 | D28: Q3 | E28: Q4 | F28: Q5 | G28: Q6 | H28: Q7 | I28: Q8 | J28: Error Acum | K28: Semaforo
A29: Parte A | B29: =B7-B18 -> -2662 | C29: =C7-C18 -> 3419838 | D29: =D7-D18 -> 6335044838 | E29: =E7-E18 -> 11719841294838 | F29: =F7-F18 -> 11719841294838 | G29: =G7-G18 -> 11719841294838 | H29: =H7-H18 -> 11719841294838 | I29: =I7-I18 -> 11719841296688 | J29: =SUM(ABS(B29:I29)) -> #VALUE! | K29: =IF(J29>$K$5,"REVISAR","OK") -> #VALUE!
A30: Parte B | B30: =B8-B19 -> -688 | C30: =C8-C19 -> 683812 | D30: =D8-D19 -> 1267008812 | E30: =E8-E19 -> 2343968258812 | F30: =F8-F19 -> 4.3363413e+15 | G30: =G8-G19 -> 4.3363413e+15 | H30: =H8-H19 -> 4.3363413e+15 | I30: =I8-I19 -> 4.3363413e+15 | J30: =SUM(ABS(B30:I30)) -> #VALUE! | K30: =IF(J30>$K$5,"REVISAR","OK") -> #VALUE!
A31: Pieza 1 | B31: =B9-B20 -> -111.5 | C31: =C9-C20 -> 34113.5 | D31: =D9-D20 -> 63350364 | E31: =E9-E20 -> 1.1719841e+11 | F31: =F9-F20 -> 2.1681706e+14 | G31: =G9-G20 -> 4.0111157e+17 | H31: =H9-H20 -> 7.420564e+20 | I31: =I9-I20 -> 7.420564e+20 | J31: =SUM(ABS(B31:I31)) -> #VALUE! | K31: =IF(J31>$K$5,"REVISAR","OK") -> #VALUE!
A32: Pieza 2 | B32: =B10-B21 -> 9532 | C32: =C10-C21 -> 27389532 | D32: =D10-D21 -> 50680389532 | E32: =E10-E21 -> 93758730389532 | F32: =F10-F21 -> 1.7345365e+17 | G32: =G10-G21 -> 3.2088925e+20 | H32: =H10-H21 -> 5.9364512e+23 | I32: =I10-I21 -> 5.9364512e+23 | J32: =SUM(ABS(B32:I32)) -> #VALUE! | K32: =IF(J32>$K$5,"REVISAR","OK") -> #VALUE!
A33: Pieza 3 | B33: =B11-B22 -> -3778 | C33: =C11-C22 -> 1022972 | D33: =D11-D22 -> 1900510472 | E33: =E11-E22 -> 3515952385472 | F33: =F11-F22 -> 6.5045119e+15 | G33: =G11-G22 -> 1.2033347e+19 | H33: =H11-H22 -> 2.2261692e+22 | I33: =I11-I22 -> 2.2261692e+22 | J33: =SUM(ABS(B33:I33)) -> #VALUE! | K33: =IF(J33>$K$5,"REVISAR","OK") -> #VALUE!
