Workbook

Sheet 00_README
A1: MODELO DE DECISIONES - PRODUCTION MANAGER (EXSIM / MEZQUITE)
A3: INSTRUCCIONES DE USO:
A5: PASO 1: Actualizar inventarios iniciales
A6: - Ve a 01_INPUTS_MASTER y pega los inventarios de FG, materiales y assemblies del reporte del simulador
A8: PASO 2: Ingresar demanda forecast
A9: - Ve a 02_DEMAND y captura la demanda esperada por región y subperiodo (pares: 2,4,6,8)
A11: PASO 3: Definir MPS (Master Production Schedule)
A12: - Ve a 03_MPS_S5 y ajusta el target de FG final si deseas colchón de inventario
A14: PASO 4: Verificar flujo de producción
A15: - Ve a 04_FLOW_S1_S5 para ver el plan por sección considerando lead times
A17: PASO 5: Verificar capacidad
A18: - Ve a 05_CAPACITY para identificar cuellos de botella (máquinas/labor/materiales)
... A45: TODO: Campos marcados con 'TODO' deben actualizarse del reporte del simulador

Sheet 01_INPUTS_MASTER
A1: PARÁMETROS MAESTROS DEL MODELO
A3: SUBPERIODOS
A4: Subperiodo | B4: 1 | C4: 2 | D4: 3 | E4: 4 | F4: 5 | G4: 6 | H4: 7 | I4: 8
A5: Es subperiodo de venta? | B5: 0 | C5: 1 | D5: 0 | E5: 1 | F5: 0 | G5: 1 | H5: 0 | I5: 1
A7: PLANTAS / REGIONES
A8: Región | B8: Tiene Planta? | C8: Módulos Planta | D8: Módulos Almacén | E8: Salario Quincena
A9: Center | B9: 1 | C9: 4 | D9: 48 | E9: 27.3
A10: West | B10: 1 | C10: 2 | D10: 25 | E10: 27.3
A11: North | B11: 0 | C11: 0 | D11: 20 | E11: 0
A12: East | B12: 0 | C12: 0 | D12: 0 | E12: 0
A13: South | B13: 0 | C13: 0 | D13: 0 | E13: 0
A15: MÁQUINAS
A16: Tipo | B16: Capacidad/Quinc | C16: Espacios | D16: kW | E16: Costo | F16: Vida Útil | G16: Workers/Máq | H16: Center Qty | I16: West Qty | J16: Sección
A17: M1 | B17: 200 | C17: 1 | D17: 10 | E17: 10600 | F17: 10 | G17: 1 | H17: 7 | I17: 3 | J17: S1
A18: M2 | B18: 70 | C18: 1 | D18: 9 | E18: 7000 | F18: 10 | G18: 1 | H18: 22 | I18: 9 | J18: S2
A19: M3-alpha | B19: 450 | C19: 5 | D19: 15 | E19: 88500 | F19: 20 | G19: 30 | H19: 3 | I19: 1 | J19: S3
A20: M3-beta | B20: 600 | C20: 6 | D20: 16 | E20: 155400 | F20: 20 | G20: 6 | H20: 0 | I20: 0 | J20: S3
A21: M4-S3 | B21: 400 | C21: 1 | D21: 6 | E21: 2500 | F21: 8 | G21: 1 | H21: 4 | I21: 2 | J21: S3
A22: M4-S4 | B22: 150 | C22: 1 | D22: 6 | E22: 2500 | F22: 8 | G22: 1 | H22: 10 | I22: 3 | J22: S4
A23: M4-S5 | B23: 130 | C23: 1 | D23: 6 | E23: 2500 | F23: 8 | G23: 1 | H23: 11 | I23: 3 | J23: S5
A24: Crews-S5 | B24: 50 | C24: 0 | D24: 0 | E24: 0 | F24: 0 | G24: 3 | H24: 25 | I24: 7 | J24: S5
A26: LABOR
A27: Salario mínimo/quincena | B27: 26
A28: Overtime cost/worker/quinc | B28: 12
A29: Hiring cost/worker | B29: 240
A30: Layoff cost/worker | B30: 220
A31: Indirect labor % | B31: 0.5
A33: ENERGÍA
A34: Costo fijo $/kW instalado/periodo | B34: 10
A35: Costo variable $/kWh | B35: 0.06
A36: Horas/subperiodo | B36: 80
A38: MATERIALES - PIECES (Batch, inicio periodo)
A39: Piece | B39: Batch Size | C39: Costo/Batch | D39: Consumo/Electroclean | E39: Inv Inicial Center | F39: Inv Inicial West
A40: Piece 1 | B40: 1 | C40: 60 | D40: 0.01 | E40: 94 | F40: 36
A41: Piece 2 | B41: 100 | C41: 7 | D41: 8 | E41: 3844 | F41: 1424
A42: Piece 3 | B42: 30 | C42: 36 | D42: 0.3 | E42: 3125 | F42: 1208
A43: Piece 4 | B43: 60 | C43: 24 | D43: 0.6 | E43: 6131 | F43: 2356
A44: Piece 5 | B44: 100 | C44: 30 | D44: 2 | E44: 16736 | F44: 6456
A45: Piece 6 | B45: 150 | C45: 28 | D45: 0.75 | E45: 4439 | F45: 1596
A47: MATERIALES - PARTS A/B (Batch, cualquier subperiodo) | L47: PARTS INV INITIAL
...

Sheet 02_DEMAND
A1: DEMANDA Y VENTAS POR REGIÓN Y SUBPERIODO
A3: Región | B3: Concepto | C3: S1 | D3: S2 | E3: S3 | F3: S4 | G3: S5 | H3: S6 | I3: S7 | J3: S8 | K3: TOTAL
A4: Center
B5: Demanda Forecast | C5: 0 | D5: 1000 | E5: 0 | F5: 1000 | G5: 0 | H5: 1000 | I5: 0 | J5: 1000 | K5: =SUM(C5:J5) -> 4000
B6: Es Subperiodo Venta? | C6: ='01_INPUTS_MASTER'!B5 -> 0 | D6: ='01_INPUTS_MASTER'!C5 -> 1 | E6: ='01_INPUTS_MASTER'!D5 -> 0 | F6: ='01_INPUTS_MASTER'!E5 -> 1 | G6: ='01_INPUTS_MASTER'!F5 -> 0 | H6: ='01_INPUTS_MASTER'!G5 -> 1 | I6: ='01_INPUTS_MASTER'!H5 -> 0 | J6: ='01_INPUTS_MASTER'!I5 -> 1
B7: Demanda Real | C7: =IF(C6=1,C5,0) -> 0 | D7: =IF(D6=1,D5,0) -> 1000 | E7: =IF(E6=1,E5,0) -> 0 | F7: =IF(F6=1,F5,0) -> 1000 | G7: =IF(G6=1,G5,0) -> 0 | H7: =IF(H6=1,H5,0) -> 1000 | I7: =IF(I6=1,I5,0) -> 0 | J7: =IF(J6=1,J5,0) -> 1000 | K7: =SUM(C7:J7) -> 4000
B8: FG Inicial | C8: ='01_INPUTS_MASTER'!B67 -> 1737 | D8: =C13 -> 1737 | E8: =D13 -> 1737 | F8: =E13 -> 1737 | G8: =F13 -> 1737 | H8: =G13 -> 1737 | I8: =H13 -> 1737 | J8: =I13 -> 1737
B9: Recepciones (prod+envíos) | C9: ='04_FLOW_S1_S5'!D9 -> 0 | D9: ='04_FLOW_S1_S5'!E9 -> 1000 | E9: ='04_FLOW_S1_S5'!F9 -> 0 | F9: ='04_FLOW_S1_S5'!G9 -> 1000 | G9: ='04_FLOW_S1_S5'!H9 -> 0 | H9: ='04_FLOW_S1_S5'!I9 -> 1000 | I9: ='04_FLOW_S1_S5'!J9 -> 0 | J9: ='04_FLOW_S1_S5'!K9 -> 1000 | K9: =SUM(C9:J9) -> 4000
B10: FG Disponible | C10: =C8+C9 -> 1737 | D10: =D8+D9 -> 2737 | E10: =E8+E9 -> 1737 | F10: =F8+F9 -> 2737 | G10: =G8+G9 -> 1737 | H10: =H8+H9 -> 2737 | I10: =I8+I9 -> 1737 | J10: =J8+J9 -> 2737
B11: Ventas Posibles | C11: =MIN(C7,C10) -> 0 | D11: =MIN(D7,D10) -> 1000 | E11: =MIN(E7,E10) -> 0 | F11: =MIN(F7,F10) -> 1000 | G11: =MIN(G7,G10) -> 0 | H11: =MIN(H7,H10) -> 1000 | I11: =MIN(I7,I10) -> 0 | J11: =MIN(J7,J10) -> 1000 | K11: =SUM(C11:J11) -> 4000
B12: Ventas Perdidas | C12: =MAX(0,C7-C11) -> 0 | D12: =MAX(0,D7-D11) -> 0 | E12: =MAX(0,E7-E11) -> 0 | F12: =MAX(0,F7-F11) -> 0 | G12: =MAX(0,G7-G11) -> 0 | H12: =MAX(0,H7-H11) -> 0 | I12: =MAX(0,I7-I11) -> 0 | J12: =MAX(0,J7-J11) -> 0 | K12: =SUM(C12:J12) -> 0
B13: FG Final | C13: =C10-C11 -> 1737 | D13: =D10-D11 -> 1737 | E13: =E10-E11 -> 1737 | F13: =F10-F11 -> 1737 | G13: =G10-G11 -> 1737 | H13: =H10-H11 -> 1737 | I13: =I10-I11 -> 1737 | J13: =J10-J11 -> 1737
A15: West
B16: Demanda Forecast | C16: 0 | D16: 1000 | E16: 0 | F16: 1000 | G16: 0 | H16: 1000 | I16: 0 | J16: 1000 | K16: =SUM(C16:J16) -> 4000
B17: Es Subperiodo Venta? | C17: ='01_INPUTS_MASTER'!B5 -> 0 | D17: ='01_INPUTS_MASTER'!C5 -> 1 | E17: ='01_INPUTS_MASTER'!D5 -> 0 | F17: ='01_INPUTS_MASTER'!E5 -> 1 | G17: ='01_INPUTS_MASTER'!F5 -> 0 | H17: ='01_INPUTS_MASTER'!G5 -> 1 | I17: ='01_INPUTS_MASTER'!H5 -> 0 | J17: ='01_INPUTS_MASTER'!I5 -> 1
B18: Demanda Real | C18: =IF(C17=1,C16,0) -> 0 | D18: =IF(D17=1,D16,0) -> 1000 | E18: =IF(E17=1,E16,0) -> 0 | F18: =IF(F17=1,F16,0) -> 1000 | G18: =IF(G17=1,G16,0) -> 0 | H18: =IF(H17=1,H16,0) -> 1000 | I18: =IF(I17=1,I16,0) -> 0 | J18: =IF(J17=1,J16,0) -> 1000 | K18: =SUM(C18:J18) -> 4000
B19: FG Inicial | C19: ='01_INPUTS_MASTER'!B68 -> 1299 | D19: =C24 -> 1299 | E19: =D24 -> 1299 | F19: =E24 -> 1299 | G19: =F24 -> 1299 | H19: =G24 -> 1299 | I19: =H24 -> 1299 | J19: =I24 -> 1299
B20: Recepciones (prod+envíos) | C20: ='04_FLOW_S1_S5'!D40 -> 0 | D20: ='04_FLOW_S1_S5'!E40 -> 1000 | E20: ='04_FLOW_S1_S5'!F40 -> 0 | F20: ='04_FLOW_S1_S5'!G40 -> 1000 | G20: ='04_FLOW_S1_S5'!H40 -> 0 | H20: ='04_FLOW_S1_S5'!I40 -> 1000 | I20: ='04_FLOW_S1_S5'!J40 -> 0 | J20: ='04_FLOW_S1_S5'!K40 -> 1000 | K20: =SUM(C20:J20) -> 4000
B21: FG Disponible | C21: =C19+C20 -> 1299 | D21: =D19+D20 -> 2299 | E21: =E19+E20 -> 1299 | F21: =F19+F20 -> 2299 | G21: =G19+G20 -> 1299 | H21: =H19+H20 -> 2299 | I21: =I19+I20 -> 1299 | J21: =J19+J20 -> 2299
B22: Ventas Posibles | C22: =MIN(C18,C21) -> 0 | D22: =MIN(D18,D21) -> 1000 | E22: =MIN(E18,E21) -> 0 | F22: =MIN(F18,F21) -> 1000 | G22: =MIN(G18,G21) -> 0 | H22: =MIN(H18,H21) -> 1000 | I22: =MIN(I18,I21) -> 0 | J22: =MIN(J18,J21) -> 1000 | K22: =SUM(C22:J22) -> 4000
B23: Ventas Perdidas | C23: =MAX(0,C18-C22) -> 0 | D23: =MAX(0,D18-D22) -> 0 | E23: =MAX(0,E18-E22) -> 0 | F23: =MAX(0,F18-F22) -> 0 | G23: =MAX(0,G18-G22) -> 0 | H23: =MAX(0,H18-H22) -> 0 | I23: =MAX(0,I18-I22) -> 0 | J23: =MAX(0,J18-J22) -> 0 | K23: =SUM(C23:J23) -> 0
B24: FG Final | C24: =C21-C22 -> 1299 | D24: =D21-D22 -> 1299 | E24: =E21-E22 -> 1299 | F24: =F21-F22 -> 1299 | G24: =G21-G22 -> 1299 | H24: =H21-H22 -> 1299 | I24: =I21-I22 -> 1299 | J24: =J21-J22 -> 1299
A26: North
B27: Demanda Forecast | C27: 0 | D27: 1000 | E27: 0 | F27: 1000 | G27: 0 | H27: 1000 | I27: 0 | J27: 1000 | K27: =SUM(C27:J27) -> 4000
B28: Es Subperiodo Venta? | C28: ='01_INPUTS_MASTER'!B5 -> 0 | D28: ='01_INPUTS_MASTER'!C5 -> 1 | E28: ='01_INPUTS_MASTER'!D5 -> 0 | F28: ='01_INPUTS_MASTER'!E5 -> 1 | G28: ='01_INPUTS_MASTER'!F5 -> 0 | H28: ='01_INPUTS_MASTER'!G5 -> 1 | I28: ='01_INPUTS_MASTER'!H5 -> 0 | J28: ='01_INPUTS_MASTER'!I5 -> 1
B29: Demanda Real | C29: =IF(C28=1,C27,0) -> 0 | D29: =IF(D28=1,D27,0) -> 1000 | E29: =IF(E28=1,E27,0) -> 0 | F29: =IF(F28=1,F27,0) -> 1000 | G29: =IF(G28=1,G27,0) -> 0 | H29: =IF(H28=1,H27,0) -> 1000 | I29: =IF(I28=1,I27,0) -> 0 | J29: =IF(J28=1,J27,0) -> 1000 | K29: =SUM(C29:J29) -> 4000
B30: FG Inicial | C30: ='01_INPUTS_MASTER'!B69 -> 0 | D30: =C35 -> 0 | E30: =D35 -> 0 | F30: =E35 -> 0 | G30: =F35 -> 0 | H30: =G35 -> 0 | I30: =H35 -> 0 | J30: =I35 -> 0
B31: Recepciones (prod+envíos) | C31: 0 | D31: 0 | E31: 0 | F31: 0 | G31: 0 | H31: 0 | I31: 0 | J31: 0 | K31: =SUM(C31:J31) -> 0
B32: FG Disponible | C32: =C30+C31 -> 0 | D32: =D30+D31 -> 0 | E32: =E30+E31 -> 0 | F32: =F30+F31 -> 0 | G32: =G30+G31 -> 0 | H32: =H30+H31 -> 0 | I32: =I30+I31 -> 0 | J32: =J30+J31 -> 0
B33: Ventas Posibles | C33: =MIN(C29,C32) -> 0 | D33: =MIN(D29,D32) -> 0 | E33: =MIN(E29,E32) -> 0 | F33: =MIN(F29,F32) -> 0 | G33: =MIN(G29,G32) -> 0 | H33: =MIN(H29,H32) -> 0 | I33: =MIN(I29,I32) -> 0 | J33: =MIN(J29,J32) -> 0 | K33: =SUM(C33:J33) -> 0
B34: Ventas Perdidas | C34: =MAX(0,C29-C33) -> 0 | D34: =MAX(0,D29-D33) -> 1000 | E34: =MAX(0,E29-E33) -> 0 | F34: =MAX(0,F29-F33) -> 1000 | G34: =MAX(0,G29-G33) -> 0 | H34: =MAX(0,H29-H33) -> 1000 | I34: =MAX(0,I29-I33) -> 0 | J34: =MAX(0,J29-J33) -> 1000 | K34: =SUM(C34:J34) -> 4000
B35: FG Final | C35: =C32-C33 -> 0 | D35: =D32-D33 -> 0 | E35: =E32-E33 -> 0 | F35: =F32-F33 -> 0 | G35: =G32-G33 -> 0 | H35: =H32-H33 -> 0 | I35: =I32-I33 -> 0 | J35: =J32-J33 -> 0
A37: East
B38: Demanda Forecast | C38: 0 | D38: 1000 | E38: 0 | F38: 1000 | G38: 0 | H38: 1000 | I38: 0 | J38: 1000 | K38: =SUM(C38:J38) -> 4000
B39: Es Subperiodo Venta? | C39: ='01_INPUTS_MASTER'!B5 -> 0 | D39: ='01_INPUTS_MASTER'!C5 -> 1 | E39: ='01_INPUTS_MASTER'!D5 -> 0 | F39: ='01_INPUTS_MASTER'!E5 -> 1 | G39: ='01_INPUTS_MASTER'!F5 -> 0 | H39: ='01_INPUTS_MASTER'!G5 -> 1 | I39: ='01_INPUTS_MASTER'!H5 -> 0 | J39: ='01_INPUTS_MASTER'!I5 -> 1
B40: Demanda Real | C40: =IF(C39=1,C38,0) -> 0 | D40: =IF(D39=1,D38,0) -> 1000 | E40: =IF(E39=1,E38,0) -> 0 | F40: =IF(F39=1,F38,0) -> 1000 | G40: =IF(G39=1,G38,0) -> 0 | H40: =IF(H39=1,H38,0) -> 1000 | I40: =IF(I39=1,I38,0) -> 0 | J40: =IF(J39=1,J38,0) -> 1000 | K40: =SUM(C40:J40) -> 4000
B41: FG Inicial | C41: ='01_INPUTS_MASTER'!B70 -> 0 | D41: =C46 -> 0 | E41: =D46 -> 0 | F41: =E46 -> 0 | G41: =F46 -> 0 | H41: =G46 -> 0 | I41: =H46 -> 0 | J41: =I46 -> 0
B42: Recepciones (prod+envíos) | C42: 0 | D42: 0 | E42: 0 | F42: 0 | G42: 0 | H42: 0 | I42: 0 | J42: 0 | K42: =SUM(C42:J42) -> 0
B43: FG Disponible | C43: =C41+C42 -> 0 | D43: =D41+D42 -> 0 | E43: =E41+E42 -> 0 | F43: =F41+F42 -> 0 | G43: =G41+G42 -> 0 | H43: =H41+H42 -> 0 | I43: =I41+I42 -> 0 | J43: =J41+J42 -> 0
B44: Ventas Posibles | C44: =MIN(C40,C43) -> 0 | D44: =MIN(D40,D43) -> 0 | E44: =MIN(E40,E43) -> 0 | F44: =MIN(F40,F43) -> 0 | G44: =MIN(G40,G43) -> 0 | H44: =MIN(H40,H43) -> 0 | I44: =MIN(I40,I43) -> 0 | J44: =MIN(J40,J43) -> 0 | K44: =SUM(C44:J44) -> 0
...

Sheet 03_MPS_S5
A1: MASTER PRODUCTION SCHEDULE - SECCIÓN 5 (Electroclean)
A3: Target FG Final (colchón) | B3: 0
A5: Región | B5: Concepto | C5: S1 | D5: S2 | E5: S3 | F5: S4 | G5: S5 | H5: S6 | I5: S7 | J5: S8 | K5: TOTAL
A6: Center
B7: Demanda (de 02_DEMAND) | C7: ='02_DEMAND'!C7 -> 0 | D7: ='02_DEMAND'!D7 -> 1000 | E7: ='02_DEMAND'!E7 -> 0 | F7: ='02_DEMAND'!F7 -> 1000 | G7: ='02_DEMAND'!G7 -> 0 | H7: ='02_DEMAND'!H7 -> 1000 | I7: ='02_DEMAND'!I7 -> 0 | J7: ='02_DEMAND'!J7 -> 1000 | K7: =SUM(C7:J7) -> 4000
B8: Target FG Final | C8: =$B$3 -> 0 | D8: =$B$3 -> 0 | E8: =$B$3 -> 0 | F8: =$B$3 -> 0 | G8: =$B$3 -> 0 | H8: =$B$3 -> 0 | I8: =$B$3 -> 0 | J8: =$B$3 -> 0 | K8: =SUM(C8:J8) -> 0
B9: FG Inicial | C9: ='01_INPUTS_MASTER'!B67 -> 1737 | D9: =C8 -> 0 | E9: =D8 -> 0 | F9: =E8 -> 0 | G9: =F8 -> 0 | H9: =G8 -> 0 | I9: =H8 -> 0 | J9: =I8 -> 0 | K9: =SUM(C9:J9) -> 1737
B10: Req_S5 = Demanda + Target - FG Inicial | C10: =MAX(0,C7+C8-C9) -> 0 | D10: =MAX(0,D7+D8-D9) -> 1000 | E10: =MAX(0,E7+E8-E9) -> 0 | F10: =MAX(0,F7+F8-F9) -> 1000 | G10: =MAX(0,G7+G8-G9) -> 0 | H10: =MAX(0,H7+H8-H9) -> 1000 | I10: =MAX(0,I7+I8-I9) -> 0 | J10: =MAX(0,J7+J8-J9) -> 1000 | K10: =SUM(C10:J10) -> 4000
B11: Plan Producción S5 | C11: =C10 -> 0 | D11: =D10 -> 1000 | E11: =E10 -> 0 | F11: =F10 -> 1000 | G11: =G10 -> 0 | H11: =H10 -> 1000 | I11: =I10 -> 0 | J11: =J10 -> 1000 | K11: =SUM(C11:J11) -> 4000
A13: West
B14: Demanda (de 02_DEMAND) | C14: ='02_DEMAND'!C18 -> 0 | D14: ='02_DEMAND'!D18 -> 1000 | E14: ='02_DEMAND'!E18 -> 0 | F14: ='02_DEMAND'!F18 -> 1000 | G14: ='02_DEMAND'!G18 -> 0 | H14: ='02_DEMAND'!H18 -> 1000 | I14: ='02_DEMAND'!I18 -> 0 | J14: ='02_DEMAND'!J18 -> 1000 | K14: =SUM(C14:J14) -> 4000
B15: Target FG Final | C15: =$B$3 -> 0 | D15: =$B$3 -> 0 | E15: =$B$3 -> 0 | F15: =$B$3 -> 0 | G15: =$B$3 -> 0 | H15: =$B$3 -> 0 | I15: =$B$3 -> 0 | J15: =$B$3 -> 0 | K15: =SUM(C15:J15) -> 0
B16: FG Inicial | C16: ='01_INPUTS_MASTER'!B68 -> 1299 | D16: =C15 -> 0 | E16: =D15 -> 0 | F16: =E15 -> 0 | G16: =F15 -> 0 | H16: =G15 -> 0 | I16: =H15 -> 0 | J16: =I15 -> 0 | K16: =SUM(C16:J16) -> 1299
B17: Req_S5 = Demanda + Target - FG Inicial | C17: =MAX(0,C14+C15-C16) -> 0 | D17: =MAX(0,D14+D15-D16) -> 1000 | E17: =MAX(0,E14+E15-E16) -> 0 | F17: =MAX(0,F14+F15-F16) -> 1000 | G17: =MAX(0,G14+G15-G16) -> 0 | H17: =MAX(0,H14+H15-H16) -> 1000 | I17: =MAX(0,I14+I15-I16) -> 0 | J17: =MAX(0,J14+J15-J16) -> 1000 | K17: =SUM(C17:J17) -> 4000
B18: Plan Producción S5 | C18: =C17 -> 0 | D18: =D17 -> 1000 | E18: =E17 -> 0 | F18: =F17 -> 1000 | G18: =G17 -> 0 | H18: =H17 -> 1000 | I18: =I17 -> 0 | J18: =J17 -> 1000 | K18: =SUM(C18:J18) -> 4000
A20: North
B21: Demanda (de 02_DEMAND) | C21: ='02_DEMAND'!C29 -> 0 | D21: ='02_DEMAND'!D29 -> 1000 | E21: ='02_DEMAND'!E29 -> 0 | F21: ='02_DEMAND'!F29 -> 1000 | G21: ='02_DEMAND'!G29 -> 0 | H21: ='02_DEMAND'!H29 -> 1000 | I21: ='02_DEMAND'!I29 -> 0 | J21: ='02_DEMAND'!J29 -> 1000 | K21: =SUM(C21:J21) -> 4000
B22: Target FG Final | C22: =$B$3 -> 0 | D22: =$B$3 -> 0 | E22: =$B$3 -> 0 | F22: =$B$3 -> 0 | G22: =$B$3 -> 0 | H22: =$B$3 -> 0 | I22: =$B$3 -> 0 | J22: =$B$3 -> 0 | K22: =SUM(C22:J22) -> 0
B23: FG Inicial | C23: ='01_INPUTS_MASTER'!B69 -> 0 | D23: =C22 -> 0 | E23: =D22 -> 0 | F23: =E22 -> 0 | G23: =F22 -> 0 | H23: =G22 -> 0 | I23: =H22 -> 0 | J23: =I22 -> 0 | K23: =SUM(C23:J23) -> 0
B24: Req_S5 = Demanda + Target - FG Inicial | C24: =MAX(0,C21+C22-C23) -> 0 | D24: =MAX(0,D21+D22-D23) -> 1000 | E24: =MAX(0,E21+E22-E23) -> 0 | F24: =MAX(0,F21+F22-F23) -> 1000 | G24: =MAX(0,G21+G22-G23) -> 0 | H24: =MAX(0,H21+H22-H23) -> 1000 | I24: =MAX(0,I21+I22-I23) -> 0 | J24: =MAX(0,J21+J22-J23) -> 1000 | K24: =SUM(C24:J24) -> 4000
B25: Plan Producción S5 | C25: =C24 -> 0 | D25: =D24 -> 1000 | E25: =E24 -> 0 | F25: =F24 -> 1000 | G25: =G24 -> 0 | H25: =H24 -> 1000 | I25: =I24 -> 0 | J25: =J24 -> 1000 | K25: =SUM(C25:J25) -> 4000
A27: East
B28: Demanda (de 02_DEMAND) | C28: ='02_DEMAND'!C40 -> 0 | D28: ='02_DEMAND'!D40 -> 1000 | E28: ='02_DEMAND'!E40 -> 0 | F28: ='02_DEMAND'!F40 -> 1000 | G28: ='02_DEMAND'!G40 -> 0 | H28: ='02_DEMAND'!H40 -> 1000 | I28: ='02_DEMAND'!I40 -> 0 | J28: ='02_DEMAND'!J40 -> 1000 | K28: =SUM(C28:J28) -> 4000
B29: Target FG Final | C29: =$B$3 -> 0 | D29: =$B$3 -> 0 | E29: =$B$3 -> 0 | F29: =$B$3 -> 0 | G29: =$B$3 -> 0 | H29: =$B$3 -> 0 | I29: =$B$3 -> 0 | J29: =$B$3 -> 0 | K29: =SUM(C29:J29) -> 0
B30: FG Inicial | C30: ='01_INPUTS_MASTER'!B70 -> 0 | D30: =C29 -> 0 | E30: =D29 -> 0 | F30: =E29 -> 0 | G30: =F29 -> 0 | H30: =G29 -> 0 | I30: =H29 -> 0 | J30: =I29 -> 0 | K30: =SUM(C30:J30) -> 0
B31: Req_S5 = Demanda + Target - FG Inicial | C31: =MAX(0,C28+C29-C30) -> 0 | D31: =MAX(0,D28+D29-D30) -> 1000 | E31: =MAX(0,E28+E29-E30) -> 0 | F31: =MAX(0,F28+F29-F30) -> 1000 | G31: =MAX(0,G28+G29-G30) -> 0 | H31: =MAX(0,H28+H29-H30) -> 1000 | I31: =MAX(0,I28+I29-I30) -> 0 | J31: =MAX(0,J28+J29-J30) -> 1000 | K31: =SUM(C31:J31) -> 4000
B32: Plan Producción S5 | C32: =C31 -> 0 | D32: =D31 -> 1000 | E32: =E31 -> 0 | F32: =F31 -> 1000 | G32: =G31 -> 0 | H32: =H31 -> 1000 | I32: =I31 -> 0 | J32: =J31 -> 1000 | K32: =SUM(C32:J32) -> 4000
A34: South
B35: Demanda (de 02_DEMAND) | C35: ='02_DEMAND'!C51 -> 0 | D35: ='02_DEMAND'!D51 -> 1000 | E35: ='02_DEMAND'!E51 -> 0 | F35: ='02_DEMAND'!F51 -> 1000 | G35: ='02_DEMAND'!G51 -> 0 | H35: ='02_DEMAND'!H51 -> 1000 | I35: ='02_DEMAND'!I51 -> 0 | J35: ='02_DEMAND'!J51 -> 1000 | K35: =SUM(C35:J35) -> 4000
B36: Target FG Final | C36: =$B$3 -> 0 | D36: =$B$3 -> 0 | E36: =$B$3 -> 0 | F36: =$B$3 -> 0 | G36: =$B$3 -> 0 | H36: =$B$3 -> 0 | I36: =$B$3 -> 0 | J36: =$B$3 -> 0 | K36: =SUM(C36:J36) -> 0
B37: FG Inicial | C37: ='01_INPUTS_MASTER'!B71 -> 0 | D37: =C36 -> 0 | E37: =D36 -> 0 | F37: =E36 -> 0 | G37: =F36 -> 0 | H37: =G36 -> 0 | I37: =H36 -> 0 | J37: =I36 -> 0 | K37: =SUM(C37:J37) -> 0
B38: Req_S5 = Demanda + Target - FG Inicial | C38: =MAX(0,C35+C36-C37) -> 0 | D38: =MAX(0,D35+D36-D37) -> 1000 | E38: =MAX(0,E35+E36-E37) -> 0 | F38: =MAX(0,F35+F36-F37) -> 1000 | G38: =MAX(0,G35+G36-G37) -> 0 | H38: =MAX(0,H35+H36-H37) -> 1000 | I38: =MAX(0,I35+I36-I37) -> 0 | J38: =MAX(0,J35+J36-J37) -> 1000 | K38: =SUM(C38:J38) -> 4000
B39: Plan Producción S5 | C39: =C38 -> 0 | D39: =D38 -> 1000 | E39: =E38 -> 0 | F39: =F38 -> 1000 | G39: =G38 -> 0 | H39: =H38 -> 1000 | I39: =I38 -> 0 | J39: =J38 -> 1000 | K39: =SUM(C39:J39) -> 4000

Sheet 04_FLOW_S1_S5
A1: FLUJO DE PRODUCCIÓN POR SECCIÓN (WIP) - BACK-SCHEDULING
A3: Lead time = 1 subperiodo por sección. Plan_S4 alimenta S5, Plan_S3 alimenta S4, etc.
A5: Planta | B5: Sección | C5: Concepto | D5: S1 | E5: S2 | F5: S3 | G5: S4 | H5: S5 | I5: S6 | J5: S7 | K5: S8
A6: Center
B7: S5 | C7: Plan Producción | D7: ='03_MPS_S5'!C11 -> 0 | E7: ='03_MPS_S5'!D11 -> 1000 | F7: ='03_MPS_S5'!E11 -> 0 | G7: ='03_MPS_S5'!F11 -> 1000 | H7: ='03_MPS_S5'!G11 -> 0 | I7: ='03_MPS_S5'!H11 -> 1000 | J7: ='03_MPS_S5'!I11 -> 0 | K7: ='03_MPS_S5'!J11 -> 1000
B8: S5 | C8: Inv Inicial | D8: ='01_INPUTS_MASTER'!B67 -> 1737 | E8: =D11 -> 1737 | F8: =E11 -> 1737 | G8: =F11 -> 1737 | H8: =G11 -> 1737 | I8: =H11 -> 1737 | J8: =I11 -> 1737 | K8: =J11 -> 1737
B9: S5 | C9: Producido | D9: =D7 -> 0 | E9: =E7 -> 1000 | F9: =F7 -> 0 | G9: =G7 -> 1000 | H9: =H7 -> 0 | I9: =I7 -> 1000 | J9: =J7 -> 0 | K9: =K7 -> 1000
B10: S5 | C10: Consumido | D10: ='02_DEMAND'!C11 -> 0 | E10: ='02_DEMAND'!D11 -> 1000 | F10: ='02_DEMAND'!E11 -> 0 | G10: ='02_DEMAND'!F11 -> 1000 | H10: ='02_DEMAND'!G11 -> 0 | I10: ='02_DEMAND'!H11 -> 1000 | J10: ='02_DEMAND'!I11 -> 0 | K10: ='02_DEMAND'!J11 -> 1000
B11: S5 | C11: Inv Final | D11: =D8+D9-D10 -> 1737 | E11: =E8+E9-E10 -> 1737 | F11: =F8+F9-F10 -> 1737 | G11: =G8+G9-G10 -> 1737 | H11: =H8+H9-H10 -> 1737 | I11: =I8+I9-I10 -> 1737 | J11: =J8+J9-J10 -> 1737 | K11: =K8+K9-K10 -> 1737
B13: S4 | C13: Plan Producción | D13: =E7 -> 1000 | E13: =F7 -> 0 | F13: =G7 -> 1000 | G13: =H7 -> 0 | H13: =I7 -> 1000 | I13: =J7 -> 0 | J13: =K7 -> 1000 | K13: =0 -> 0
B14: S4 | C14: Inv Inicial | D14: ='01_INPUTS_MASTER'!C57 -> 0 | E14: =D17 -> 0 | F14: =E17 -> 0 | G14: =F17 -> 0 | H14: =G17 -> 0 | I14: =H17 -> 0 | J14: =I17 -> 0 | K14: =J17 -> 0
B15: S4 | C15: Producido | D15: =D13 -> 1000 | E15: =E13 -> 0 | F15: =F13 -> 1000 | G15: =G13 -> 0 | H15: =H13 -> 1000 | I15: =I13 -> 0 | J15: =J13 -> 1000 | K15: =K13 -> 0
B16: S4 | C16: Consumido | D16: =E7 -> 1000 | E16: =F7 -> 0 | F16: =G7 -> 1000 | G16: =H7 -> 0 | H16: =I7 -> 1000 | I16: =J7 -> 0 | J16: =K7 -> 1000 | K16: =0 -> 0
B17: S4 | C17: Inv Final | D17: =D14+D15-D16 -> 0 | E17: =E14+E15-E16 -> 0 | F17: =F14+F15-F16 -> 0 | G17: =G14+G15-G16 -> 0 | H17: =H14+H15-H16 -> 0 | I17: =I14+I15-I16 -> 0 | J17: =J14+J15-J16 -> 0 | K17: =K14+K15-K16 -> 0
B19: S3 | C19: Plan Producción | D19: =E13 -> 0 | E19: =F13 -> 1000 | F19: =G13 -> 0 | G19: =H13 -> 1000 | H19: =I13 -> 0 | I19: =J13 -> 1000 | J19: =K13 -> 0 | K19: =0 -> 0
B20: S3 | C20: Inv Inicial | D20: ='01_INPUTS_MASTER'!C56 -> 6682 | E20: =D23 -> 6682 | F20: =E23 -> 6682 | G20: =F23 -> 6682 | H20: =G23 -> 6682 | I20: =H23 -> 6682 | J20: =I23 -> 6682 | K20: =J23 -> 6682
B21: S3 | C21: Producido | D21: =D19 -> 0 | E21: =E19 -> 1000 | F21: =F19 -> 0 | G21: =G19 -> 1000 | H21: =H19 -> 0 | I21: =I19 -> 1000 | J21: =J19 -> 0 | K21: =K19 -> 0
B22: S3 | C22: Consumido | D22: =E13 -> 0 | E22: =F13 -> 1000 | F22: =G13 -> 0 | G22: =H13 -> 1000 | H22: =I13 -> 0 | I22: =J13 -> 1000 | J22: =K13 -> 0 | K22: =0 -> 0
B23: S3 | C23: Inv Final | D23: =D20+D21-D22 -> 6682 | E23: =E20+E21-E22 -> 6682 | F23: =F20+F21-F22 -> 6682 | G23: =G20+G21-G22 -> 6682 | H23: =H20+H21-H22 -> 6682 | I23: =I20+I21-I22 -> 6682 | J23: =J20+J21-J22 -> 6682 | K23: =K20+K21-K22 -> 6682
B25: S2 | C25: Plan Producción | D25: =E19 -> 1000 | E25: =F19 -> 0 | F25: =G19 -> 1000 | G25: =H19 -> 0 | H25: =I19 -> 1000 | I25: =J19 -> 0 | J25: =K19 -> 0 | K25: =0 -> 0
B26: S2 | C26: Inv Inicial | D26: ='01_INPUTS_MASTER'!C55 -> 6528 | E26: =D29 -> 6528 | F26: =E29 -> 6528 | G26: =F29 -> 6528 | H26: =G29 -> 6528 | I26: =H29 -> 6528 | J26: =I29 -> 6528 | K26: =J29 -> 6528
B27: S2 | C27: Producido | D27: =D25 -> 1000 | E27: =E25 -> 0 | F27: =F25 -> 1000 | G27: =G25 -> 0 | H27: =H25 -> 1000 | I27: =I25 -> 0 | J27: =J25 -> 0 | K27: =K25 -> 0
B28: S2 | C28: Consumido | D28: =E19 -> 1000 | E28: =F19 -> 0 | F28: =G19 -> 1000 | G28: =H19 -> 0 | H28: =I19 -> 1000 | I28: =J19 -> 0 | J28: =K19 -> 0 | K28: =0 -> 0
B29: S2 | C29: Inv Final | D29: =D26+D27-D28 -> 6528 | E29: =E26+E27-E28 -> 6528 | F29: =F26+F27-F28 -> 6528 | G29: =G26+G27-G28 -> 6528 | H29: =H26+H27-H28 -> 6528 | I29: =I26+I27-I28 -> 6528 | J29: =J26+J27-J28 -> 6528 | K29: =K26+K27-K28 -> 6528
B31: S1 | C31: Plan Producción | D31: =E19 -> 1000 | E31: =F19 -> 0 | F31: =G19 -> 1000 | G31: =H19 -> 0 | H31: =I19 -> 1000 | I31: =J19 -> 0 | J31: =K19 -> 0 | K31: =0 -> 0
B32: S1 | C32: Inv Inicial | D32: ='01_INPUTS_MASTER'!C54 -> 7432 | E32: =D35 -> 7432 | F32: =E35 -> 7432 | G32: =F35 -> 7432 | H32: =G35 -> 7432 | I32: =H35 -> 7432 | J32: =I35 -> 7432 | K32: =J35 -> 7432
B33: S1 | C33: Producido | D33: =D31 -> 1000 | E33: =E31 -> 0 | F33: =F31 -> 1000 | G33: =G31 -> 0 | H33: =H31 -> 1000 | I33: =I31 -> 0 | J33: =J31 -> 0 | K33: =K31 -> 0
B34: S1 | C34: Consumido | D34: =E19 -> 1000 | E34: =F19 -> 0 | F34: =G19 -> 1000 | G34: =H19 -> 0 | H34: =I19 -> 1000 | I34: =J19 -> 0 | J34: =K19 -> 0 | K34: =0 -> 0
B35: S1 | C35: Inv Final | D35: =D32+D33-D34 -> 7432 | E35: =E32+E33-E34 -> 7432 | F35: =F32+F33-F34 -> 7432 | G35: =G32+G33-G34 -> 7432 | H35: =H32+H33-H34 -> 7432 | I35: =I32+I33-I34 -> 7432 | J35: =J32+J33-J34 -> 7432 | K35: =K32+K33-K34 -> 7432
A37: West
B38: S5 | C38: Plan Producción | D38: ='03_MPS_S5'!C18 -> 0 | E38: ='03_MPS_S5'!D18 -> 1000 | F38: ='03_MPS_S5'!E18 -> 0 | G38: ='03_MPS_S5'!F18 -> 1000 | H38: ='03_MPS_S5'!G18 -> 0 | I38: ='03_MPS_S5'!H18 -> 1000 | J38: ='03_MPS_S5'!I18 -> 0 | K38: ='03_MPS_S5'!J18 -> 1000
B39: S5 | C39: Inv Inicial | D39: ='01_INPUTS_MASTER'!B68 -> 1299 | E39: =D42 -> 1299 | F39: =E42 -> 1299 | G39: =F42 -> 1299 | H39: =G42 -> 1299 | I39: =H42 -> 1299 | J39: =I42 -> 1299 | K39: =J42 -> 1299
B40: S5 | C40: Producido | D40: =D38 -> 0 | E40: =E38 -> 1000 | F40: =F38 -> 0 | G40: =G38 -> 1000 | H40: =H38 -> 0 | I40: =I38 -> 1000 | J40: =J38 -> 0 | K40: =K38 -> 1000
B41: S5 | C41: Consumido | D41: ='02_DEMAND'!C22 -> 0 | E41: ='02_DEMAND'!D22 -> 1000 | F41: ='02_DEMAND'!E22 -> 0 | G41: ='02_DEMAND'!F22 -> 1000 | H41: ='02_DEMAND'!G22 -> 0 | I41: ='02_DEMAND'!H22 -> 1000 | J41: ='02_DEMAND'!I22 -> 0 | K41: ='02_DEMAND'!J22 -> 1000
B42: S5 | C42: Inv Final | D42: =D39+D40-D41 -> 1299 | E42: =E39+E40-E41 -> 1299 | F42: =F39+F40-F41 -> 1299 | G42: =G39+G40-G41 -> 1299 | H42: =H39+H40-H41 -> 1299 | I42: =I39+I40-I41 -> 1299 | J42: =J39+J40-J41 -> 1299 | K42: =K39+K40-K41 -> 1299
B44: S4 | C44: Plan Producción | D44: =E38 -> 1000 | E44: =F38 -> 0 | F44: =G38 -> 1000 | G44: =H38 -> 0 | H44: =I38 -> 1000 | I44: =J38 -> 0 | J44: =K38 -> 1000 | K44: =0 -> 0
B45: S4 | C45: Inv Inicial | D45: ='01_INPUTS_MASTER'!D57 -> 0 | E45: =D48 -> 0 | F45: =E48 -> 0 | G45: =F48 -> 0 | H45: =G48 -> 0 | I45: =H48 -> 0 | J45: =I48 -> 0 | K45: =J48 -> 0
B46: S4 | C46: Producido | D46: =D44 -> 1000 | E46: =E44 -> 0 | F46: =F44 -> 1000 | G46: =G44 -> 0 | H46: =H44 -> 1000 | I46: =I44 -> 0 | J46: =J44 -> 1000 | K46: =K44 -> 0
B47: S4 | C47: Consumido | D47: =E38 -> 1000 | E47: =F38 -> 0 | F47: =G38 -> 1000 | G47: =H38 -> 0 | H47: =I38 -> 1000 | I47: =J38 -> 0 | J47: =K38 -> 1000 | K47: =0 -> 0
B48: S4 | C48: Inv Final | D48: =D45+D46-D47 -> 0 | E48: =E45+E46-E47 -> 0 | F48: =F45+F46-F47 -> 0 | G48: =G45+G46-G47 -> 0 | H48: =H45+H46-H47 -> 0 | I48: =I45+I46-I47 -> 0 | J48: =J45+J46-J47 -> 0 | K48: =K45+K46-K47 -> 0
...

Sheet 05_CAPACITY
A1: ANÁLISIS DE CAPACIDAD POR PLANTA, SECCIÓN Y SUBPERIODO
A3: Planta | B3: Sección | C3: Concepto | D3: S1 | E3: S2 | F3: S3 | G3: S4 | H3: S5 | I3: S6 | J3: S7 | K3: S8
A4: Center
B5: S1 | C5: # Máquinas | D5: ='01_INPUTS_MASTER'!H17 -> 7 | E5: 0 | F5: 0 | G5: 0 | H5: 0 | I5: 0 | J5: 0 | K5: 0
B6: S1 | C6: Capacidad/Máquina | D6: ='01_INPUTS_MASTER'!B17 -> 200 | E6: 0 | F6: 0 | G6: 0 | H6: 0 | I6: 0 | J6: 0 | K6: 0
B7: S1 | C7: Capacidad Máquinas | D7: =D5*D6 -> 1400 | E7: =E5*E6 -> 0 | F7: =F5*F6 -> 0 | G7: =G5*G6 -> 0 | H7: =H5*H6 -> 0 | I7: =I5*I6 -> 0 | J7: =J5*J6 -> 0 | K7: =K5*K6 -> 0
B8: S1 | C8: # Workers | D8: ='10_DECISIONS_UPLOAD'!C13 -> 7 | E8: 0 | F8: 0 | G8: 0 | H8: 0 | I8: 0 | J8: 0 | K8: 0
B9: S1 | C9: Workers/Máquina req | D9: ='01_INPUTS_MASTER'!G17 -> 1 | E9: 0 | F9: 0 | G9: 0 | H9: 0 | I9: 0 | J9: 0 | K9: 0
B10: S1 | C10: Capacidad Labor | D10: =IF(D9>0,D8/D9*D6,0) -> 1400 | E10: =IF(E9>0,E8/E9*E6,0) -> 0 | F10: =IF(F9>0,F8/F9*F6,0) -> 0 | G10: =IF(G9>0,G8/G9*G6,0) -> 0 | H10: =IF(H9>0,H8/H9*H6,0) -> 0 | I10: =IF(I9>0,I8/I9*I6,0) -> 0 | J10: =IF(J9>0,J8/J9*J6,0) -> 0 | K10: =IF(K9>0,K8/K9*K6,0) -> 0
B11: S1 | C11: Capacidad Base (MIN) | D11: =MIN(D7,D10) -> 1400 | E11: =MIN(E7,E10) -> 0 | F11: =MIN(F7,F10) -> 0 | G11: =MIN(G7,G10) -> 0 | H11: =MIN(H7,H10) -> 0 | I11: =MIN(I7,I10) -> 0 | J11: =MIN(J7,J10) -> 0 | K11: =MIN(K7,K10) -> 0
B12: S1 | C12: Overtime (0/1) | D12: ='10_DECISIONS_UPLOAD'!C30 -> 0 | E12: ='10_DECISIONS_UPLOAD'!D30 -> 0 | F12: ='10_DECISIONS_UPLOAD'!E30 -> 0 | G12: ='10_DECISIONS_UPLOAD'!F30 -> 0 | H12: ='10_DECISIONS_UPLOAD'!G30 -> 0 | I12: ='10_DECISIONS_UPLOAD'!H30 -> 0 | J12: ='10_DECISIONS_UPLOAD'!I30 -> 0 | K12: ='10_DECISIONS_UPLOAD'!J30 -> 0
B13: S1 | C13: Capacidad c/Overtime | D13: =D11*(1+0.2*D12) -> 1400 | E13: =E11*(1+0.2*E12) -> 0 | F13: =F11*(1+0.2*F12) -> 0 | G13: =G11*(1+0.2*G12) -> 0 | H13: =H11*(1+0.2*H12) -> 0 | I13: =I11*(1+0.2*I12) -> 0 | J13: =J11*(1+0.2*J12) -> 0 | K13: =K11*(1+0.2*K12) -> 0
B14: S1 | C14: Plan Producción | D14: ='04_FLOW_S1_S5'!D31 -> 1000 | E14: ='04_FLOW_S1_S5'!E31 -> 0 | F14: ='04_FLOW_S1_S5'!F31 -> 1000 | G14: ='04_FLOW_S1_S5'!G31 -> 0 | H14: ='04_FLOW_S1_S5'!H31 -> 1000 | I14: ='04_FLOW_S1_S5'!I31 -> 0 | J14: ='04_FLOW_S1_S5'!J31 -> 0 | K14: ='04_FLOW_S1_S5'!K31 -> 0
B15: S1 | C15: Producción Real | D15: =MIN(D13,D14) -> 1000 | E15: =MIN(E13,E14) -> 0 | F15: =MIN(F13,F14) -> 0 | G15: =MIN(G13,G14) -> 0 | H15: =MIN(H13,H14) -> 0 | I15: =MIN(I13,I14) -> 0 | J15: =MIN(J13,J14) -> 0 | K15: =MIN(K13,K14) -> 0
B16: S1 | C16: Bottleneck | D16: =IF(D14>D13,"CAPACITY","OK") -> OK | E16: =IF(E14>E13,"CAPACITY","OK") -> OK | F16: =IF(F14>F13,"CAPACITY","OK") -> CAPACITY | G16: =IF(G14>G13,"CAPACITY","OK") -> OK | H16: =IF(H14>H13,"CAPACITY","OK") -> CAPACITY | I16: =IF(I14>I13,"CAPACITY","OK") -> OK | J16: =IF(J14>J13,"CAPACITY","OK") -> OK | K16: =IF(K14>K13,"CAPACITY","OK") -> OK
B18: S2 | C18: # Máquinas | D18: ='01_INPUTS_MASTER'!H18 -> 22 | E18: 0 | F18: 0 | G18: 0 | H18: 0 | I18: 0 | J18: 0 | K18: 0
B19: S2 | C19: Capacidad/Máquina | D19: ='01_INPUTS_MASTER'!B18 -> 70 | E19: 0 | F19: 0 | G19: 0 | H19: 0 | I19: 0 | J19: 0 | K19: 0
B20: S2 | C20: Capacidad Máquinas | D20: =D18*D19 -> 1540 | E20: =E18*E19 -> 0 | F20: =F18*F19 -> 0 | G20: =G18*G19 -> 0 | H20: =H18*H19 -> 0 | I20: =I18*I19 -> 0 | J20: =J18*J19 -> 0 | K20: =K18*K19 -> 0
B21: S2 | C21: # Workers | D21: ='10_DECISIONS_UPLOAD'!C14 -> 22 | E21: 0 | F21: 0 | G21: 0 | H21: 0 | I21: 0 | J21: 0 | K21: 0
B22: S2 | C22: Workers/Máquina req | D22: ='01_INPUTS_MASTER'!G18 -> 1 | E22: 0 | F22: 0 | G22: 0 | H22: 0 | I22: 0 | J22: 0 | K22: 0
B23: S2 | C23: Capacidad Labor | D23: =IF(D22>0,D21/D22*D19,0) -> 1540 | E23: =IF(E22>0,E21/E22*E19,0) -> 0 | F23: =IF(F22>0,F21/F22*F19,0) -> 0 | G23: =IF(G22>0,G21/G22*G19,0) -> 0 | H23: =IF(H22>0,H21/H22*H19,0) -> 0 | I23: =IF(I22>0,I21/I22*I19,0) -> 0 | J23: =IF(J22>0,J21/J22*J19,0) -> 0 | K23: =IF(K22>0,K21/K22*K19,0) -> 0
B24: S2 | C24: Capacidad Base (MIN) | D24: =MIN(D20,D23) -> 1540 | E24: =MIN(E20,E23) -> 0 | F24: =MIN(F20,F23) -> 0 | G24: =MIN(G20,G23) -> 0 | H24: =MIN(H20,H23) -> 0 | I24: =MIN(I20,I23) -> 0 | J24: =MIN(J20,J23) -> 0 | K24: =MIN(K20,K23) -> 0
B25: S2 | C25: Overtime (0/1) | D25: ='10_DECISIONS_UPLOAD'!C31 -> 0 | E25: ='10_DECISIONS_UPLOAD'!D31 -> 0 | F25: ='10_DECISIONS_UPLOAD'!E31 -> 0 | G25: ='10_DECISIONS_UPLOAD'!F31 -> 0 | H25: ='10_DECISIONS_UPLOAD'!G31 -> 0 | I25: ='10_DECISIONS_UPLOAD'!H31 -> 0 | J25: ='10_DECISIONS_UPLOAD'!I31 -> 0 | K25: ='10_DECISIONS_UPLOAD'!J31 -> 0
B26: S2 | C26: Capacidad c/Overtime | D26: =D24*(1+0.2*D25) -> 1540 | E26: =E24*(1+0.2*E25) -> 0 | F26: =F24*(1+0.2*F25) -> 0 | G26: =G24*(1+0.2*G25) -> 0 | H26: =H24*(1+0.2*H25) -> 0 | I26: =I24*(1+0.2*I25) -> 0 | J26: =J24*(1+0.2*J25) -> 0 | K26: =K24*(1+0.2*K25) -> 0
B27: S2 | C27: Plan Producción | D27: ='04_FLOW_S1_S5'!D25 -> 1000 | E27: ='04_FLOW_S1_S5'!E25 -> 0 | F27: ='04_FLOW_S1_S5'!F25 -> 1000 | G27: ='04_FLOW_S1_S5'!G25 -> 0 | H27: ='04_FLOW_S1_S5'!H25 -> 1000 | I27: ='04_FLOW_S1_S5'!I25 -> 0 | J27: ='04_FLOW_S1_S5'!J25 -> 0 | K27: ='04_FLOW_S1_S5'!K25 -> 0
B28: S2 | C28: Producción Real | D28: =MIN(D26,D27) -> 1000 | E28: =MIN(E26,E27) -> 0 | F28: =MIN(F26,F27) -> 0 | G28: =MIN(G26,G27) -> 0 | H28: =MIN(H26,H27) -> 0 | I28: =MIN(I26,I27) -> 0 | J28: =MIN(J26,J27) -> 0 | K28: =MIN(K26,K27) -> 0
B29: S2 | C29: Bottleneck | D29: =IF(D27>D26,"CAPACITY","OK") -> OK | E29: =IF(E27>E26,"CAPACITY","OK") -> OK | F29: =IF(F27>F26,"CAPACITY","OK") -> CAPACITY | G29: =IF(G27>G26,"CAPACITY","OK") -> OK | H29: =IF(H27>H26,"CAPACITY","OK") -> CAPACITY | I29: =IF(I27>I26,"CAPACITY","OK") -> OK | J29: =IF(J27>J26,"CAPACITY","OK") -> OK | K29: =IF(K27>K26,"CAPACITY","OK") -> OK
B31: S3 | C31: # Máquinas | D31: ='01_INPUTS_MASTER'!H19+'01_INPUTS_MASTER'!H20 -> 3 | E31: 0 | F31: 0 | G31: 0 | H31: 0 | I31: 0 | J31: 0 | K31: 0
B32: S3 | C32: Capacidad/Máquina | D32: =IF(('01_INPUTS_MASTER'!H19+'01_INPUTS_MASTER'!H20)>0,('01_INPUTS_MASTER'!H19*'01_INPUTS_MASTER'!B19+'01_INPUTS_MASTER'!H20*'01_INPUTS_MASTER'!B20)/('01_INPUTS_MASTER'!H19+'01_INPUTS_MASTER'!H20),0) -> 450 | E32: 0 | F32: 0 | G32: 0 | H32: 0 | I32: 0 | J32: 0 | K32: 0
B33: S3 | C33: Capacidad Máquinas | D33: =MIN('01_INPUTS_MASTER'!H19*'01_INPUTS_MASTER'!B19+'01_INPUTS_MASTER'!H20*'01_INPUTS_MASTER'!B20,'01_INPUTS_MASTER'!H21*'01_INPUTS_MASTER'!B21) -> 1350 | E33: =E31*E32 -> 0 | F33: =F31*F32 -> 0 | G33: =G31*G32 -> 0 | H33: =H31*H32 -> 0 | I33: =I31*I32 -> 0 | J33: =J31*J32 -> 0 | K33: =K31*K32 -> 0
B34: S3 | C34: # Workers | D34: ='10_DECISIONS_UPLOAD'!C15 -> 90 | E34: 0 | F34: 0 | G34: 0 | H34: 0 | I34: 0 | J34: 0 | K34: 0
B35: S3 | C35: Workers/Máquina req | D35: ='01_INPUTS_MASTER'!G19 -> 30 | E35: 0 | F35: 0 | G35: 0 | H35: 0 | I35: 0 | J35: 0 | K35: 0
B36: S3 | C36: Capacidad Labor | D36: =IF(D35>0,D34/D35*D32,0) -> 1350 | E36: =IF(E35>0,E34/E35*E32,0) -> 0 | F36: =IF(F35>0,F34/F35*F32,0) -> 0 | G36: =IF(G35>0,G34/G35*G32,0) -> 0 | H36: =IF(H35>0,H34/H35*H32,0) -> 0 | I36: =IF(I35>0,I34/I35*I32,0) -> 0 | J36: =IF(J35>0,J34/J35*J32,0) -> 0 | K36: =IF(K35>0,K34/K35*K32,0) -> 0
B37: S3 | C37: Capacidad Base (MIN) | D37: =MIN(D33,D36) -> 1350 | E37: =MIN(E33,E36) -> 0 | F37: =MIN(F33,F36) -> 0 | G37: =MIN(G33,G36) -> 0 | H37: =MIN(H33,H36) -> 0 | I37: =MIN(I33,I36) -> 0 | J37: =MIN(J33,J36) -> 0 | K37: =MIN(K33,K36) -> 0
B38: S3 | C38: Overtime (0/1) | D38: ='10_DECISIONS_UPLOAD'!C32 -> 0 | E38: ='10_DECISIONS_UPLOAD'!D32 -> 0 | F38: ='10_DECISIONS_UPLOAD'!E32 -> 0 | G38: ='10_DECISIONS_UPLOAD'!F32 -> 0 | H38: ='10_DECISIONS_UPLOAD'!G32 -> 0 | I38: ='10_DECISIONS_UPLOAD'!H32 -> 0 | J38: ='10_DECISIONS_UPLOAD'!I32 -> 0 | K38: ='10_DECISIONS_UPLOAD'!J32 -> 0
B39: S3 | C39: Capacidad c/Overtime | D39: =D37*(1+0.2*D38) -> 1350 | E39: =E37*(1+0.2*E38) -> 0 | F39: =F37*(1+0.2*F38) -> 0 | G39: =G37*(1+0.2*G38) -> 0 | H39: =H37*(1+0.2*H38) -> 0 | I39: =I37*(1+0.2*I38) -> 0 | J39: =J37*(1+0.2*J38) -> 0 | K39: =K37*(1+0.2*K38) -> 0
B40: S3 | C40: Plan Producción | D40: ='04_FLOW_S1_S5'!D19 -> 0 | E40: ='04_FLOW_S1_S5'!E19 -> 1000 | F40: ='04_FLOW_S1_S5'!F19 -> 0 | G40: ='04_FLOW_S1_S5'!G19 -> 1000 | H40: ='04_FLOW_S1_S5'!H19 -> 0 | I40: ='04_FLOW_S1_S5'!I19 -> 1000 | J40: ='04_FLOW_S1_S5'!J19 -> 0 | K40: ='04_FLOW_S1_S5'!K19 -> 0
B41: S3 | C41: Producción Real | D41: =MIN(D39,D40) -> 0 | E41: =MIN(E39,E40) -> 0 | F41: =MIN(F39,F40) -> 0 | G41: =MIN(G39,G40) -> 0 | H41: =MIN(H39,H40) -> 0 | I41: =MIN(I39,I40) -> 0 | J41: =MIN(J39,J40) -> 0 | K41: =MIN(K39,K40) -> 0
B42: S3 | C42: Bottleneck | D42: =IF(D40>D39,"CAPACITY","OK") -> OK | E42: =IF(E40>E39,"CAPACITY","OK") -> CAPACITY | F42: =IF(F40>F39,"CAPACITY","OK") -> OK | G42: =IF(G40>G39,"CAPACITY","OK") -> CAPACITY | H42: =IF(H40>H39,"CAPACITY","OK") -> OK | I42: =IF(I40>I39,"CAPACITY","OK") -> CAPACITY | J42: =IF(J40>J39,"CAPACITY","OK") -> OK | K42: =IF(K40>K39,"CAPACITY","OK") -> OK
B44: S4 | C44: # Máquinas | D44: ='01_INPUTS_MASTER'!H22 -> 10 | E44: 0 | F44: 0 | G44: 0 | H44: 0 | I44: 0 | J44: 0 | K44: 0
...

Sheet 06_MRP_MATERIALS
A1: MRP - PLANIFICACIÓN DE MATERIALES (Parts A/B y Pieces 1-6)
A2: PLANT: CENTER
A3: Material | B3: Concepto | C3: S0 | D3: S1 | E3: S2 | F3: S3 | G3: S4 | H3: S5 | I3: S6 | J3: S7 | K3: S8 | L3: TOTAL
A4: Part A
B5: Batch Size | C5: ='01_INPUTS_MASTER'!B49 -> 30 | D5: ='01_INPUTS_MASTER'!B49 -> 30 | E5: ='01_INPUTS_MASTER'!B49 -> 30 | F5: ='01_INPUTS_MASTER'!B49 -> 30 | G5: ='01_INPUTS_MASTER'!B49 -> 30 | H5: ='01_INPUTS_MASTER'!B49 -> 30 | I5: ='01_INPUTS_MASTER'!B49 -> 30 | J5: ='01_INPUTS_MASTER'!B49 -> 30 | K5: ='01_INPUTS_MASTER'!B49 -> 30
B6: Consumo/EC | C6: ='01_INPUTS_MASTER'!H49 -> 1 | D6: ='01_INPUTS_MASTER'!H49 -> 1 | E6: ='01_INPUTS_MASTER'!H49 -> 1 | F6: ='01_INPUTS_MASTER'!H49 -> 1 | G6: ='01_INPUTS_MASTER'!H49 -> 1 | H6: ='01_INPUTS_MASTER'!H49 -> 1 | I6: ='01_INPUTS_MASTER'!H49 -> 1 | J6: ='01_INPUTS_MASTER'!H49 -> 1 | K6: ='01_INPUTS_MASTER'!H49 -> 1
B7: Producción Plan | C7: =0 -> 0 | D7: ='04_FLOW_S1_S5'!D7 -> 0 | E7: ='04_FLOW_S1_S5'!E7 -> 1000 | F7: ='04_FLOW_S1_S5'!F7 -> 0 | G7: ='04_FLOW_S1_S5'!G7 -> 1000 | H7: ='04_FLOW_S1_S5'!H7 -> 0 | I7: ='04_FLOW_S1_S5'!I7 -> 1000 | J7: ='04_FLOW_S1_S5'!J7 -> 0 | K7: ='04_FLOW_S1_S5'!K7 -> 1000
B8: Req Bruto | C8: =0 -> 0 | D8: =D7*D6 -> 0 | E8: =E7*E6 -> 1000 | F8: =F7*F6 -> 0 | G8: =G7*G6 -> 1000 | H8: =H7*H6 -> 0 | I8: =I7*I6 -> 1000 | J8: =J7*J6 -> 0 | K8: =K7*K6 -> 1000 | L8: =SUM(D8:K8) -> 4000
B9: Inv Inicial | C9: ='01_INPUTS_MASTER'!M49 -> 0 | D9: =C9 -> 0 | E9: =D13 -> 0 | F9: =E13 -> 20 | G9: =F13 -> 20 | H9: =G13 -> 10 | I9: =H13 -> 10 | J9: =I13 -> 0 | K9: =J13 -> 0
B10: Req Neto | C10: =0 -> 0 | D10: =MAX(0,D8-D9) -> 0 | E10: =MAX(0,E8-E9) -> 1000 | F10: =MAX(0,F8-F9) -> 0 | G10: =MAX(0,G8-G9) -> 980 | H10: =MAX(0,H8-H9) -> 0 | I10: =MAX(0,I8-I9) -> 990 | J10: =MAX(0,J8-J9) -> 0 | K10: =MAX(0,K8-K9) -> 1000
B11: Lotes a Pedir | C11: =0 -> 0 | D11: =IF(D5>0,CEILING(D10/D5,1),0) -> 0 | E11: =IF(E5>0,CEILING(E10/E5,1),0) -> 34 | F11: =IF(F5>0,CEILING(F10/F5,1),0) -> 0 | G11: =IF(G5>0,CEILING(G10/G5,1),0) -> 33 | H11: =IF(H5>0,CEILING(H10/H5,1),0) -> 0 | I11: =IF(I5>0,CEILING(I10/I5,1),0) -> 33 | J11: =IF(J5>0,CEILING(J10/J5,1),0) -> 0 | K11: =IF(K5>0,CEILING(K10/K5,1),0) -> 34
B12: Pedido (lotes*batch) | C12: =0 -> 0 | D12: =D11*D5 -> 0 | E12: =E11*E5 -> 1020 | F12: =F11*F5 -> 0 | G12: =G11*G5 -> 990 | H12: =H11*H5 -> 0 | I12: =I11*I5 -> 990 | J12: =J11*J5 -> 0 | K12: =K11*K5 -> 1020 | L12: =SUM(D12:K12) -> 4020
B13: Inv Final | C13: =C9 -> 0 | D13: =D9+D12*(IF('01_INPUTS_MASTER'!M54="B",1-'01_INPUTS_MASTER'!Q54,1))-D8 -> 0 | E13: =E9+E12*(IF('01_INPUTS_MASTER'!M54="B",1-'01_INPUTS_MASTER'!Q54,1))-E8 -> 20 | F13: =F9+F12*(IF('01_INPUTS_MASTER'!M54="B",1-'01_INPUTS_MASTER'!Q54,1))-F8 -> 20 | G13: =G9+G12*(IF('01_INPUTS_MASTER'!M54="B",1-'01_INPUTS_MASTER'!Q54,1))-G8 -> 10 | H13: =H9+H12*(IF('01_INPUTS_MASTER'!M54="B",1-'01_INPUTS_MASTER'!Q54,1))-H8 -> 10 | I13: =I9+I12*(IF('01_INPUTS_MASTER'!M54="B",1-'01_INPUTS_MASTER'!Q54,1))-I8 -> 0 | J13: =J9+J12*(IF('01_INPUTS_MASTER'!M54="B",1-'01_INPUTS_MASTER'!Q54,1))-J8 -> 0 | K13: =K9+K12*(IF('01_INPUTS_MASTER'!M54="B",1-'01_INPUTS_MASTER'!Q54,1))-K8 -> 20
B14: Ordering Cost | C14: =0 -> 0 | D14: =IF(D12>0,'01_INPUTS_MASTER'!F49,0) -> 0 | E14: =IF(E12>0,'01_INPUTS_MASTER'!F49,0) -> 2300 | F14: =IF(F12>0,'01_INPUTS_MASTER'!F49,0) -> 0 | G14: =IF(G12>0,'01_INPUTS_MASTER'!F49,0) -> 2300 | H14: =IF(H12>0,'01_INPUTS_MASTER'!F49,0) -> 0 | I14: =IF(I12>0,'01_INPUTS_MASTER'!F49,0) -> 2300 | J14: =IF(J12>0,'01_INPUTS_MASTER'!F49,0) -> 0 | K14: =IF(K12>0,'01_INPUTS_MASTER'!F49,0) -> 2300 | L14: =SUM(D14:K14) -> 9200
B15: Holding Cost | C15: =0 -> 0 | D15: =D13*'01_INPUTS_MASTER'!G49 -> 0 | E15: =E13*'01_INPUTS_MASTER'!G49 -> 6 | F15: =F13*'01_INPUTS_MASTER'!G49 -> 6 | G15: =G13*'01_INPUTS_MASTER'!G49 -> 3 | H15: =H13*'01_INPUTS_MASTER'!G49 -> 3 | I15: =I13*'01_INPUTS_MASTER'!G49 -> 0 | J15: =J13*'01_INPUTS_MASTER'!G49 -> 0 | K15: =K13*'01_INPUTS_MASTER'!G49 -> 6 | L15: =SUM(D15:K15) -> 24
A17: Part B
B18: Batch Size | C18: ='01_INPUTS_MASTER'!B50 -> 12 | D18: ='01_INPUTS_MASTER'!B50 -> 12 | E18: ='01_INPUTS_MASTER'!B50 -> 12 | F18: ='01_INPUTS_MASTER'!B50 -> 12 | G18: ='01_INPUTS_MASTER'!B50 -> 12 | H18: ='01_INPUTS_MASTER'!B50 -> 12 | I18: ='01_INPUTS_MASTER'!B50 -> 12 | J18: ='01_INPUTS_MASTER'!B50 -> 12 | K18: ='01_INPUTS_MASTER'!B50 -> 12
B19: Consumo/EC | C19: ='01_INPUTS_MASTER'!H50 -> 0.2 | D19: ='01_INPUTS_MASTER'!H50 -> 0.2 | E19: ='01_INPUTS_MASTER'!H50 -> 0.2 | F19: ='01_INPUTS_MASTER'!H50 -> 0.2 | G19: ='01_INPUTS_MASTER'!H50 -> 0.2 | H19: ='01_INPUTS_MASTER'!H50 -> 0.2 | I19: ='01_INPUTS_MASTER'!H50 -> 0.2 | J19: ='01_INPUTS_MASTER'!H50 -> 0.2 | K19: ='01_INPUTS_MASTER'!H50 -> 0.2
B20: Producción Plan | C20: =0 -> 0 | D20: ='04_FLOW_S1_S5'!D7 -> 0 | E20: ='04_FLOW_S1_S5'!E7 -> 1000 | F20: ='04_FLOW_S1_S5'!F7 -> 0 | G20: ='04_FLOW_S1_S5'!G7 -> 1000 | H20: ='04_FLOW_S1_S5'!H7 -> 0 | I20: ='04_FLOW_S1_S5'!I7 -> 1000 | J20: ='04_FLOW_S1_S5'!J7 -> 0 | K20: ='04_FLOW_S1_S5'!K7 -> 1000
B21: Req Bruto | C21: =0 -> 0 | D21: =D20*D19 -> 0 | E21: =E20*E19 -> 200 | F21: =F20*F19 -> 0 | G21: =G20*G19 -> 200 | H21: =H20*H19 -> 0 | I21: =I20*I19 -> 200 | J21: =J20*J19 -> 0 | K21: =K20*K19 -> 200 | L21: =SUM(D21:K21) -> 800
B22: Inv Inicial | C22: ='01_INPUTS_MASTER'!M50 -> 0 | D22: =C22 -> 0 | E22: =D26 -> 0 | F22: =E26 -> 4 | G22: =F26 -> 4 | H22: =G26 -> 8 | I22: =H26 -> 8 | J22: =I26 -> 0 | K22: =J26 -> 0
B23: Req Neto | C23: =0 -> 0 | D23: =MAX(0,D21-D22) -> 0 | E23: =MAX(0,E21-E22) -> 200 | F23: =MAX(0,F21-F22) -> 0 | G23: =MAX(0,G21-G22) -> 196 | H23: =MAX(0,H21-H22) -> 0 | I23: =MAX(0,I21-I22) -> 192 | J23: =MAX(0,J21-J22) -> 0 | K23: =MAX(0,K21-K22) -> 200
B24: Lotes a Pedir | C24: =0 -> 0 | D24: =IF(D18>0,CEILING(D23/D18,1),0) -> 0 | E24: =IF(E18>0,CEILING(E23/E18,1),0) -> 17 | F24: =IF(F18>0,CEILING(F23/F18,1),0) -> 0 | G24: =IF(G18>0,CEILING(G23/G18,1),0) -> 17 | H24: =IF(H18>0,CEILING(H23/H18,1),0) -> 0 | I24: =IF(I18>0,CEILING(I23/I18,1),0) -> 16 | J24: =IF(J18>0,CEILING(J23/J18,1),0) -> 0 | K24: =IF(K18>0,CEILING(K23/K18,1),0) -> 17
B25: Pedido (lotes*batch) | C25: =0 -> 0 | D25: =D24*D18 -> 0 | E25: =E24*E18 -> 204 | F25: =F24*F18 -> 0 | G25: =G24*G18 -> 204 | H25: =H24*H18 -> 0 | I25: =I24*I18 -> 192 | J25: =J24*J18 -> 0 | K25: =K24*K18 -> 204 | L25: =SUM(D25:K25) -> 804
B26: Inv Final | C26: =C22 -> 0 | D26: =D22+D25*(IF('01_INPUTS_MASTER'!N54="B",1-'01_INPUTS_MASTER'!Q54,1))-D21 -> 0 | E26: =E22+E25*(IF('01_INPUTS_MASTER'!N54="B",1-'01_INPUTS_MASTER'!Q54,1))-E21 -> 4 | F26: =F22+F25*(IF('01_INPUTS_MASTER'!N54="B",1-'01_INPUTS_MASTER'!Q54,1))-F21 -> 4 | G26: =G22+G25*(IF('01_INPUTS_MASTER'!N54="B",1-'01_INPUTS_MASTER'!Q54,1))-G21 -> 8 | H26: =H22+H25*(IF('01_INPUTS_MASTER'!N54="B",1-'01_INPUTS_MASTER'!Q54,1))-H21 -> 8 | I26: =I22+I25*(IF('01_INPUTS_MASTER'!N54="B",1-'01_INPUTS_MASTER'!Q54,1))-I21 -> 0 | J26: =J22+J25*(IF('01_INPUTS_MASTER'!N54="B",1-'01_INPUTS_MASTER'!Q54,1))-J21 -> 0 | K26: =K22+K25*(IF('01_INPUTS_MASTER'!N54="B",1-'01_INPUTS_MASTER'!Q54,1))-K21 -> 4
B27: Ordering Cost | C27: =0 -> 0 | D27: =IF(D25>0,'01_INPUTS_MASTER'!F50,0) -> 0 | E27: =IF(E25>0,'01_INPUTS_MASTER'!F50,0) -> 6000 | F27: =IF(F25>0,'01_INPUTS_MASTER'!F50,0) -> 0 | G27: =IF(G25>0,'01_INPUTS_MASTER'!F50,0) -> 6000 | H27: =IF(H25>0,'01_INPUTS_MASTER'!F50,0) -> 0 | I27: =IF(I25>0,'01_INPUTS_MASTER'!F50,0) -> 6000 | J27: =IF(J25>0,'01_INPUTS_MASTER'!F50,0) -> 0 | K27: =IF(K25>0,'01_INPUTS_MASTER'!F50,0) -> 6000 | L27: =SUM(D27:K27) -> 24000
B28: Holding Cost | C28: =0 -> 0 | D28: =D26*'01_INPUTS_MASTER'!G50 -> 0 | E28: =E26*'01_INPUTS_MASTER'!G50 -> 18 | F28: =F26*'01_INPUTS_MASTER'!G50 -> 18 | G28: =G26*'01_INPUTS_MASTER'!G50 -> 36 | H28: =H26*'01_INPUTS_MASTER'!G50 -> 36 | I28: =I26*'01_INPUTS_MASTER'!G50 -> 0 | J28: =J26*'01_INPUTS_MASTER'!G50 -> 0 | K28: =K26*'01_INPUTS_MASTER'!G50 -> 18 | L28: =SUM(D28:K28) -> 126
A30: Piece 1
B31: Batch Size | C31: ='01_INPUTS_MASTER'!B40 -> 1 | D31: ='01_INPUTS_MASTER'!B40 -> 1 | E31: ='01_INPUTS_MASTER'!B40 -> 1 | F31: ='01_INPUTS_MASTER'!B40 -> 1 | G31: ='01_INPUTS_MASTER'!B40 -> 1 | H31: ='01_INPUTS_MASTER'!B40 -> 1 | I31: ='01_INPUTS_MASTER'!B40 -> 1 | J31: ='01_INPUTS_MASTER'!B40 -> 1 | K31: ='01_INPUTS_MASTER'!B40 -> 1
B32: Consumo/EC | C32: ='01_INPUTS_MASTER'!D40 -> 0.01 | D32: ='01_INPUTS_MASTER'!D40 -> 0.01 | E32: ='01_INPUTS_MASTER'!D40 -> 0.01 | F32: ='01_INPUTS_MASTER'!D40 -> 0.01 | G32: ='01_INPUTS_MASTER'!D40 -> 0.01 | H32: ='01_INPUTS_MASTER'!D40 -> 0.01 | I32: ='01_INPUTS_MASTER'!D40 -> 0.01 | J32: ='01_INPUTS_MASTER'!D40 -> 0.01 | K32: ='01_INPUTS_MASTER'!D40 -> 0.01
B33: Producción Plan | C33: =0 -> 0 | D33: ='04_FLOW_S1_S5'!D7 -> 0 | E33: ='04_FLOW_S1_S5'!E7 -> 1000 | F33: ='04_FLOW_S1_S5'!F7 -> 0 | G33: ='04_FLOW_S1_S5'!G7 -> 1000 | H33: ='04_FLOW_S1_S5'!H7 -> 0 | I33: ='04_FLOW_S1_S5'!I7 -> 1000 | J33: ='04_FLOW_S1_S5'!J7 -> 0 | K33: ='04_FLOW_S1_S5'!K7 -> 1000
B34: Req Bruto | C34: =0 -> 0 | D34: =D33*D32 -> 0 | E34: =E33*E32 -> 10 | F34: =F33*F32 -> 0 | G34: =G33*G32 -> 10 | H34: =H33*H32 -> 0 | I34: =I33*I32 -> 10 | J34: =J33*J32 -> 0 | K34: =K33*K32 -> 10 | L34: =SUM(D34:K34) -> 40
B35: Inv Inicial | C35: ='01_INPUTS_MASTER'!E40 -> 94 | D35: =C35 -> 94 | E35: =D39 -> 94 | F35: =E39 -> 84 | G35: =F39 -> 84 | H35: =G39 -> 74 | I35: =H39 -> 74 | J35: =I39 -> 64 | K35: =J39 -> 64
B36: Req Neto | C36: =0 -> 0 | D36: =MAX(0,D34-D35) -> 0 | E36: =MAX(0,E34-E35) -> 0 | F36: =MAX(0,F34-F35) -> 0 | G36: =MAX(0,G34-G35) -> 0 | H36: =MAX(0,H34-H35) -> 0 | I36: =MAX(0,I34-I35) -> 0 | J36: =MAX(0,J34-J35) -> 0 | K36: =MAX(0,K34-K35) -> 0
B37: Lotes a Pedir | C37: =0 -> 0 | D37: =IF(D31>0,CEILING(D36/D31,1),0) -> 0 | E37: =IF(E31>0,CEILING(E36/E31,1),0) -> 0 | F37: =IF(F31>0,CEILING(F36/F31,1),0) -> 0 | G37: =IF(G31>0,CEILING(G36/G31,1),0) -> 0 | H37: =IF(H31>0,CEILING(H36/H31,1),0) -> 0 | I37: =IF(I31>0,CEILING(I36/I31,1),0) -> 0 | J37: =IF(J31>0,CEILING(J36/J31,1),0) -> 0 | K37: =IF(K31>0,CEILING(K36/K31,1),0) -> 0
B38: Pedido (lotes*batch) | C38: =0 -> 0 | D38: =D37*D31 -> 0 | E38: =E37*E31 -> 0 | F38: =F37*F31 -> 0 | G38: =G37*G31 -> 0 | H38: =H37*H31 -> 0 | I38: =I37*I31 -> 0 | J38: =J37*J31 -> 0 | K38: =K37*K31 -> 0 | L38: =SUM(D38:K38) -> 0
B39: Inv Final | C39: =C35 -> 94 | D39: =D35+D38*(1)-D34 -> 94 | E39: =E35+E38*(1)-E34 -> 84 | F39: =F35+F38*(1)-F34 -> 84 | G39: =G35+G38*(1)-G34 -> 74 | H39: =H35+H38*(1)-H34 -> 74 | I39: =I35+I38*(1)-I34 -> 64 | J39: =J35+J38*(1)-J34 -> 64 | K39: =K35+K38*(1)-K34 -> 54
B40: Ordering Cost | C40: =0 -> 0 | D40: =IF(D38>0,0,0) -> 0 | E40: =IF(E38>0,0,0) -> 0 | F40: =IF(F38>0,0,0) -> 0 | G40: =IF(G38>0,0,0) -> 0 | H40: =IF(H38>0,0,0) -> 0 | I40: =IF(I38>0,0,0) -> 0 | J40: =IF(J38>0,0,0) -> 0 | K40: =IF(K38>0,0,0) -> 0 | L40: =SUM(D40:K40) -> 0
B41: Holding Cost | C41: =0 -> 0 | D41: =D39*0 -> 0 | E41: =E39*0 -> 0 | F41: =F39*0 -> 0 | G41: =G39*0 -> 0 | H41: =H39*0 -> 0 | I41: =I39*0 -> 0 | J41: =J39*0 -> 0 | K41: =K39*0 -> 0 | L41: =SUM(D41:K41) -> 0
A43: Piece 2
...

Sheet 07_SPACES
A1: ANÁLISIS DE ESPACIOS Y MÓDULOS
A3: Planta | B3: Concepto | C3: Valor
A4: Center
B5: M1 qty | C5: 7
B6: M1 espacios/maq | C6: 1
B7: M2 qty | C7: 22
B8: M2 espacios/maq | C8: 1
B9: M3a qty | C9: 3
B10: M3a espacios/maq | C10: 5
B11: M3b qty | C11: 0
B12: M3b espacios/maq | C12: 6
B13: M4 qty total | C13: 25
B14: M4 espacios/maq | C14: 1
B15: Espacios Usados | C15: =C5*C6+C7*C8+C9*C10+C11*C12+C13*C14 -> 69
B16: Módulos Actuales | C16: 4
B17: Espacios Disponibles | C17: =C16*18 -> 72
B18: Faltante | C18: =MAX(0,C15-C17) -> 0
B19: Módulos Requeridos | C19: =CEILING(C15/18,1) -> 4
B20: ALERTA | C20: =IF(C18>0,"⚠️ FALTA ESPACIO","✓ OK") -> ✓ OK
A22: West
B23: M1 qty | C23: 3
B24: M1 espacios/maq | C24: 1
B25: M2 qty | C25: 9
B26: M2 espacios/maq | C26: 1
B27: M3a qty | C27: 1
B28: M3a espacios/maq | C28: 5
B29: M3b qty | C29: 0
B30: M3b espacios/maq | C30: 6
B31: M4 qty total | C31: 8
B32: M4 espacios/maq | C32: 1
B33: Espacios Usados | C33: =C23*C24+C25*C26+C27*C28+C29*C30+C31*C32 -> 25
B34: Módulos Actuales | C34: 2
B35: Espacios Disponibles | C35: =C34*18 -> 36
B36: Faltante | C36: =MAX(0,C33-C35) -> 0
B37: Módulos Requeridos | C37: =CEILING(C33/18,1) -> 2
B38: ALERTA | C38: =IF(C36>0,"⚠️ FALTA ESPACIO","✓ OK") -> ✓ OK

Sheet 08_COSTING
A1: ANÁLISIS DE COSTOS DE PRODUCCIÓN
A3: Concepto | B3: S1 | C3: S2 | D3: S3 | E3: S4 | F3: S5 | G3: S6 | H3: S7 | I3: S8 | J3: TOTAL PERIODO
A4: LABOR
A5: # Workers | B5: =SUM('10_DECISIONS_UPLOAD'!C13:C19,'10_DECISIONS_UPLOAD'!C20:C26) -> 290 | C5: =SUM('10_DECISIONS_UPLOAD'!C13:C19,'10_DECISIONS_UPLOAD'!C20:C26) -> 290 | D5: =SUM('10_DECISIONS_UPLOAD'!C13:C19,'10_DECISIONS_UPLOAD'!C20:C26) -> 290 | E5: =SUM('10_DECISIONS_UPLOAD'!C13:C19,'10_DECISIONS_UPLOAD'!C20:C26) -> 290 | F5: =SUM('10_DECISIONS_UPLOAD'!C13:C19,'10_DECISIONS_UPLOAD'!C20:C26) -> 290 | G5: =SUM('10_DECISIONS_UPLOAD'!C13:C19,'10_DECISIONS_UPLOAD'!C20:C26) -> 290 | H5: =SUM('10_DECISIONS_UPLOAD'!C13:C19,'10_DECISIONS_UPLOAD'!C20:C26) -> 290 | I5: =SUM('10_DECISIONS_UPLOAD'!C13:C19,'10_DECISIONS_UPLOAD'!C20:C26) -> 290 | J5: =SUM(B5:I5) -> 2320
A6: Salario/worker/quinc | B6: ='01_INPUTS_MASTER'!B27 -> 26 | C6: ='01_INPUTS_MASTER'!B27 -> 26 | D6: ='01_INPUTS_MASTER'!B27 -> 26 | E6: ='01_INPUTS_MASTER'!B27 -> 26 | F6: ='01_INPUTS_MASTER'!B27 -> 26 | G6: ='01_INPUTS_MASTER'!B27 -> 26 | H6: ='01_INPUTS_MASTER'!B27 -> 26 | I6: ='01_INPUTS_MASTER'!B27 -> 26 | J6: =SUM(B6:I6) -> 208
A7: Total Salarios | B7: =B5*B6 -> 7540 | C7: =C5*C6 -> 7540 | D7: =D5*D6 -> 7540 | E7: =E5*E6 -> 7540 | F7: =F5*F6 -> 7540 | G7: =G5*G6 -> 7540 | H7: =H5*H6 -> 7540 | I7: =I5*I6 -> 7540 | J7: =SUM(B7:I7) -> 60320
A8: # Workers Overtime | B8: ='05_CAPACITY'!D8*'05_CAPACITY'!D12+'05_CAPACITY'!D21*'05_CAPACITY'!D25+'05_CAPACITY'!D34*'05_CAPACITY'!D38+'05_CAPACITY'!D47*'05_CAPACITY'!D51+'05_CAPACITY'!D60*'05_CAPACITY'!D64+'05_CAPACITY'!D74*'05_CAPACITY'!D78+'05_CAPACITY'!D87*'05_CAPACITY'!D91+'05_CAPACITY'!D100*'05_CAPACITY'!D104+'05_CAPACITY'!D113*'05_CAPACITY'!D117+'05_CAPACITY'!D126*'05_CAPACITY'!D130 -> 0 | C8: ='05_CAPACITY'!E8*'05_CAPACITY'!E12+'05_CAPACITY'!E21*'05_CAPACITY'!E25+'05_CAPACITY'!E34*'05_CAPACITY'!E38+'05_CAPACITY'!E47*'05_CAPACITY'!E51+'05_CAPACITY'!E60*'05_CAPACITY'!E64+'05_CAPACITY'!E74*'05_CAPACITY'!E78+'05_CAPACITY'!E87*'05_CAPACITY'!E91+'05_CAPACITY'!E100*'05_CAPACITY'!E104+'05_CAPACITY'!E113*'05_CAPACITY'!E117+'05_CAPACITY'!E126*'05_CAPACITY'!E130 -> 0 | D8: ='05_CAPACITY'!F8*'05_CAPACITY'!F12+'05_CAPACITY'!F21*'05_CAPACITY'!F25+'05_CAPACITY'!F34*'05_CAPACITY'!F38+'05_CAPACITY'!F47*'05_CAPACITY'!F51+'05_CAPACITY'!F60*'05_CAPACITY'!F64+'05_CAPACITY'!F74*'05_CAPACITY'!F78+'05_CAPACITY'!F87*'05_CAPACITY'!F91+'05_CAPACITY'!F100*'05_CAPACITY'!F104+'05_CAPACITY'!F113*'05_CAPACITY'!F117+'05_CAPACITY'!F126*'05_CAPACITY'!F130 -> 0 | E8: ='05_CAPACITY'!G8*'05_CAPACITY'!G12+'05_CAPACITY'!G21*'05_CAPACITY'!G25+'05_CAPACITY'!G34*'05_CAPACITY'!G38+'05_CAPACITY'!G47*'05_CAPACITY'!G51+'05_CAPACITY'!G60*'05_CAPACITY'!G64+'05_CAPACITY'!G74*'05_CAPACITY'!G78+'05_CAPACITY'!G87*'05_CAPACITY'!G91+'05_CAPACITY'!G100*'05_CAPACITY'!G104+'05_CAPACITY'!G113*'05_CAPACITY'!G117+'05_CAPACITY'!G126*'05_CAPACITY'!G130 -> 0 | F8: ='05_CAPACITY'!H8*'05_CAPACITY'!H12+'05_CAPACITY'!H21*'05_CAPACITY'!H25+'05_CAPACITY'!H34*'05_CAPACITY'!H38+'05_CAPACITY'!H47*'05_CAPACITY'!H51+'05_CAPACITY'!H60*'05_CAPACITY'!H64+'05_CAPACITY'!H74*'05_CAPACITY'!H78+'05_CAPACITY'!H87*'05_CAPACITY'!H91+'05_CAPACITY'!H100*'05_CAPACITY'!H104+'05_CAPACITY'!H113*'05_CAPACITY'!H117+'05_CAPACITY'!H126*'05_CAPACITY'!H130 -> 0 | G8: ='05_CAPACITY'!I8*'05_CAPACITY'!I12+'05_CAPACITY'!I21*'05_CAPACITY'!I25+'05_CAPACITY'!I34*'05_CAPACITY'!I38+'05_CAPACITY'!I47*'05_CAPACITY'!I51+'05_CAPACITY'!I60*'05_CAPACITY'!I64+'05_CAPACITY'!I74*'05_CAPACITY'!I78+'05_CAPACITY'!I87*'05_CAPACITY'!I91+'05_CAPACITY'!I100*'05_CAPACITY'!I104+'05_CAPACITY'!I113*'05_CAPACITY'!I117+'05_CAPACITY'!I126*'05_CAPACITY'!I130 -> 0 | H8: ='05_CAPACITY'!J8*'05_CAPACITY'!J12+'05_CAPACITY'!J21*'05_CAPACITY'!J25+'05_CAPACITY'!J34*'05_CAPACITY'!J38+'05_CAPACITY'!J47*'05_CAPACITY'!J51+'05_CAPACITY'!J60*'05_CAPACITY'!J64+'05_CAPACITY'!J74*'05_CAPACITY'!J78+'05_CAPACITY'!J87*'05_CAPACITY'!J91+'05_CAPACITY'!J100*'05_CAPACITY'!J104+'05_CAPACITY'!J113*'05_CAPACITY'!J117+'05_CAPACITY'!J126*'05_CAPACITY'!J130 -> 0 | I8: ='05_CAPACITY'!K8*'05_CAPACITY'!K12+'05_CAPACITY'!K21*'05_CAPACITY'!K25+'05_CAPACITY'!K34*'05_CAPACITY'!K38+'05_CAPACITY'!K47*'05_CAPACITY'!K51+'05_CAPACITY'!K60*'05_CAPACITY'!K64+'05_CAPACITY'!K74*'05_CAPACITY'!K78+'05_CAPACITY'!K87*'05_CAPACITY'!K91+'05_CAPACITY'!K100*'05_CAPACITY'!K104+'05_CAPACITY'!K113*'05_CAPACITY'!K117+'05_CAPACITY'!K126*'05_CAPACITY'!K130 -> 0 | J8: =SUM(B8:I8) -> 0
A9: Overtime cost/worker | B9: ='01_INPUTS_MASTER'!B28 -> 12 | C9: ='01_INPUTS_MASTER'!B28 -> 12 | D9: ='01_INPUTS_MASTER'!B28 -> 12 | E9: ='01_INPUTS_MASTER'!B28 -> 12 | F9: ='01_INPUTS_MASTER'!B28 -> 12 | G9: ='01_INPUTS_MASTER'!B28 -> 12 | H9: ='01_INPUTS_MASTER'!B28 -> 12 | I9: ='01_INPUTS_MASTER'!B28 -> 12 | J9: =SUM(B9:I9) -> 96
A10: Total Overtime | B10: =B8*B9 -> 0 | C10: =C8*C9 -> 0 | D10: =D8*D9 -> 0 | E10: =E8*E9 -> 0 | F10: =F8*F9 -> 0 | G10: =G8*G9 -> 0 | H10: =H8*H9 -> 0 | I10: =I8*I9 -> 0 | J10: =SUM(B10:I10) -> 0
A11: Total Labor | B11: =B7+B10 -> 7540 | C11: =C7+C10 -> 7540 | D11: =D7+D10 -> 7540 | E11: =E7+E10 -> 7540 | F11: =F7+F10 -> 7540 | G11: =G7+G10 -> 7540 | H11: =H7+H10 -> 7540 | I11: =I7+I10 -> 7540 | J11: =SUM(B11:I11) -> 60320
A12: Indirect Labor (50%) | B12: =B11*'01_INPUTS_MASTER'!B31 -> 3770 | C12: =C11*'01_INPUTS_MASTER'!B31 -> 3770 | D12: =D11*'01_INPUTS_MASTER'!B31 -> 3770 | E12: =E11*'01_INPUTS_MASTER'!B31 -> 3770 | F12: =F11*'01_INPUTS_MASTER'!B31 -> 3770 | G12: =G11*'01_INPUTS_MASTER'!B31 -> 3770 | H12: =H11*'01_INPUTS_MASTER'!B31 -> 3770 | I12: =I11*'01_INPUTS_MASTER'!B31 -> 3770 | J12: =SUM(B12:I12) -> 30160
A14: ENERGÍA
A15: kW instalados | B15: ='01_INPUTS_MASTER'!D17*('01_INPUTS_MASTER'!H17+'01_INPUTS_MASTER'!I17)+'01_INPUTS_MASTER'!D18*('01_INPUTS_MASTER'!H18+'01_INPUTS_MASTER'!I18)+'01_INPUTS_MASTER'!D19*('01_INPUTS_MASTER'!H19+'01_INPUTS_MASTER'!I19)+'01_INPUTS_MASTER'!D20*('01_INPUTS_MASTER'!H20+'01_INPUTS_MASTER'!I20)+'01_INPUTS_MASTER'!D21*('01_INPUTS_MASTER'!H21+'01_INPUTS_MASTER'!I21)+'01_INPUTS_MASTER'!D22*('01_INPUTS_MASTER'!H22+'01_INPUTS_MASTER'!I22)+'01_INPUTS_MASTER'!D23*('01_INPUTS_MASTER'!H23+'01_INPUTS_MASTER'!I23) -> 637 | C15: ='01_INPUTS_MASTER'!D17*('01_INPUTS_MASTER'!H17+'01_INPUTS_MASTER'!I17)+'01_INPUTS_MASTER'!D18*('01_INPUTS_MASTER'!H18+'01_INPUTS_MASTER'!I18)+'01_INPUTS_MASTER'!D19*('01_INPUTS_MASTER'!H19+'01_INPUTS_MASTER'!I19)+'01_INPUTS_MASTER'!D20*('01_INPUTS_MASTER'!H20+'01_INPUTS_MASTER'!I20)+'01_INPUTS_MASTER'!D21*('01_INPUTS_MASTER'!H21+'01_INPUTS_MASTER'!I21)+'01_INPUTS_MASTER'!D22*('01_INPUTS_MASTER'!H22+'01_INPUTS_MASTER'!I22)+'01_INPUTS_MASTER'!D23*('01_INPUTS_MASTER'!H23+'01_INPUTS_MASTER'!I23) -> 637 | D15: ='01_INPUTS_MASTER'!D17*('01_INPUTS_MASTER'!H17+'01_INPUTS_MASTER'!I17)+'01_INPUTS_MASTER'!D18*('01_INPUTS_MASTER'!H18+'01_INPUTS_MASTER'!I18)+'01_INPUTS_MASTER'!D19*('01_INPUTS_MASTER'!H19+'01_INPUTS_MASTER'!I19)+'01_INPUTS_MASTER'!D20*('01_INPUTS_MASTER'!H20+'01_INPUTS_MASTER'!I20)+'01_INPUTS_MASTER'!D21*('01_INPUTS_MASTER'!H21+'01_INPUTS_MASTER'!I21)+'01_INPUTS_MASTER'!D22*('01_INPUTS_MASTER'!H22+'01_INPUTS_MASTER'!I22)+'01_INPUTS_MASTER'!D23*('01_INPUTS_MASTER'!H23+'01_INPUTS_MASTER'!I23) -> 637 | E15: ='01_INPUTS_MASTER'!D17*('01_INPUTS_MASTER'!H17+'01_INPUTS_MASTER'!I17)+'01_INPUTS_MASTER'!D18*('01_INPUTS_MASTER'!H18+'01_INPUTS_MASTER'!I18)+'01_INPUTS_MASTER'!D19*('01_INPUTS_MASTER'!H19+'01_INPUTS_MASTER'!I19)+'01_INPUTS_MASTER'!D20*('01_INPUTS_MASTER'!H20+'01_INPUTS_MASTER'!I20)+'01_INPUTS_MASTER'!D21*('01_INPUTS_MASTER'!H21+'01_INPUTS_MASTER'!I21)+'01_INPUTS_MASTER'!D22*('01_INPUTS_MASTER'!H22+'01_INPUTS_MASTER'!I22)+'01_INPUTS_MASTER'!D23*('01_INPUTS_MASTER'!H23+'01_INPUTS_MASTER'!I23) -> 637 | F15: ='01_INPUTS_MASTER'!D17*('01_INPUTS_MASTER'!H17+'01_INPUTS_MASTER'!I17)+'01_INPUTS_MASTER'!D18*('01_INPUTS_MASTER'!H18+'01_INPUTS_MASTER'!I18)+'01_INPUTS_MASTER'!D19*('01_INPUTS_MASTER'!H19+'01_INPUTS_MASTER'!I19)+'01_INPUTS_MASTER'!D20*('01_INPUTS_MASTER'!H20+'01_INPUTS_MASTER'!I20)+'01_INPUTS_MASTER'!D21*('01_INPUTS_MASTER'!H21+'01_INPUTS_MASTER'!I21)+'01_INPUTS_MASTER'!D22*('01_INPUTS_MASTER'!H22+'01_INPUTS_MASTER'!I22)+'01_INPUTS_MASTER'!D23*('01_INPUTS_MASTER'!H23+'01_INPUTS_MASTER'!I23) -> 637 | G15: ='01_INPUTS_MASTER'!D17*('01_INPUTS_MASTER'!H17+'01_INPUTS_MASTER'!I17)+'01_INPUTS_MASTER'!D18*('01_INPUTS_MASTER'!H18+'01_INPUTS_MASTER'!I18)+'01_INPUTS_MASTER'!D19*('01_INPUTS_MASTER'!H19+'01_INPUTS_MASTER'!I19)+'01_INPUTS_MASTER'!D20*('01_INPUTS_MASTER'!H20+'01_INPUTS_MASTER'!I20)+'01_INPUTS_MASTER'!D21*('01_INPUTS_MASTER'!H21+'01_INPUTS_MASTER'!I21)+'01_INPUTS_MASTER'!D22*('01_INPUTS_MASTER'!H22+'01_INPUTS_MASTER'!I22)+'01_INPUTS_MASTER'!D23*('01_INPUTS_MASTER'!H23+'01_INPUTS_MASTER'!I23) -> 637 | H15: ='01_INPUTS_MASTER'!D17*('01_INPUTS_MASTER'!H17+'01_INPUTS_MASTER'!I17)+'01_INPUTS_MASTER'!D18*('01_INPUTS_MASTER'!H18+'01_INPUTS_MASTER'!I18)+'01_INPUTS_MASTER'!D19*('01_INPUTS_MASTER'!H19+'01_INPUTS_MASTER'!I19)+'01_INPUTS_MASTER'!D20*('01_INPUTS_MASTER'!H20+'01_INPUTS_MASTER'!I20)+'01_INPUTS_MASTER'!D21*('01_INPUTS_MASTER'!H21+'01_INPUTS_MASTER'!I21)+'01_INPUTS_MASTER'!D22*('01_INPUTS_MASTER'!H22+'01_INPUTS_MASTER'!I22)+'01_INPUTS_MASTER'!D23*('01_INPUTS_MASTER'!H23+'01_INPUTS_MASTER'!I23) -> 637 | I15: ='01_INPUTS_MASTER'!D17*('01_INPUTS_MASTER'!H17+'01_INPUTS_MASTER'!I17)+'01_INPUTS_MASTER'!D18*('01_INPUTS_MASTER'!H18+'01_INPUTS_MASTER'!I18)+'01_INPUTS_MASTER'!D19*('01_INPUTS_MASTER'!H19+'01_INPUTS_MASTER'!I19)+'01_INPUTS_MASTER'!D20*('01_INPUTS_MASTER'!H20+'01_INPUTS_MASTER'!I20)+'01_INPUTS_MASTER'!D21*('01_INPUTS_MASTER'!H21+'01_INPUTS_MASTER'!I21)+'01_INPUTS_MASTER'!D22*('01_INPUTS_MASTER'!H22+'01_INPUTS_MASTER'!I22)+'01_INPUTS_MASTER'!D23*('01_INPUTS_MASTER'!H23+'01_INPUTS_MASTER'!I23) -> 637 | J15: =SUM(B15:I15) -> 5096
A16: Costo fijo ($/kW/periodo) | B16: ='01_INPUTS_MASTER'!B34 -> 10 | C16: ='01_INPUTS_MASTER'!B34 -> 10 | D16: ='01_INPUTS_MASTER'!B34 -> 10 | E16: ='01_INPUTS_MASTER'!B34 -> 10 | F16: ='01_INPUTS_MASTER'!B34 -> 10 | G16: ='01_INPUTS_MASTER'!B34 -> 10 | H16: ='01_INPUTS_MASTER'!B34 -> 10 | I16: ='01_INPUTS_MASTER'!B34 -> 10 | J16: =SUM(B16:I16) -> 80
A17: Total Costo Fijo | B17: =B15*B16 -> 6370 | C17: =C15*C16 -> 6370 | D17: =D15*D16 -> 6370 | E17: =E15*E16 -> 6370 | F17: =F15*F16 -> 6370 | G17: =G15*G16 -> 6370 | H17: =H15*H16 -> 6370 | I17: =I15*I16 -> 6370 | J17: =SUM(B17:I17) -> 50960
