Workbook

Sheet Inputs_Global
A1: REGIONES | C1: PARÃMETROS GLOBALES (del caso) | F1: INVENTARIO INICIAL (Period 7)
A2: Center | C2: Fortnights | D2: 8 | F2: Region | G2: Inv_Begin_P7
A3: West | C3: Units_per_module | D3: 100 | F3: Center | G3: 2685
A4: North | C4: Cost_per_module | D4: 800 | F4: West | G4: 1299
A5: East | C5: Scenario | D5: Base | F5: North | G5: 620
A6: South | C6: Arrival_Method | D6: EV | F6: East | G6: 0
C7: Alert_Prob_Threshold | D7: 0.8 | F7: South | G7: 0
C8: Price_per_unit | D8: 68

Sheet Demand_Forecast
A1: Region | B1: Fortnight | C1: Demand_Base | D1: Demand_High | E1: Demand_Low | F1: Demand_Active
A2: Center | B2: 1 | C2: 0 | D2: 0 | E2: 0 | F2: =IF(Inputs_Global!$D$5="Base",C2,IF(Inputs_Global!$D$5="High",D2,E2)) -> 0
A3: Center | B3: 2 | C3: 2225 | D3: 2670 | E3: 1780 | F3: =IF(Inputs_Global!$D$5="Base",C3,IF(Inputs_Global!$D$5="High",D3,E3)) -> 2225
A4: Center | B4: 3 | C4: 0 | D4: 0 | E4: 0 | F4: =IF(Inputs_Global!$D$5="Base",C4,IF(Inputs_Global!$D$5="High",D4,E4)) -> 0
A5: Center | B5: 4 | C5: 2225 | D5: 2670 | E5: 1780 | F5: =IF(Inputs_Global!$D$5="Base",C5,IF(Inputs_Global!$D$5="High",D5,E5)) -> 2225
A6: Center | B6: 5 | C6: 0 | D6: 0 | E6: 0 | F6: =IF(Inputs_Global!$D$5="Base",C6,IF(Inputs_Global!$D$5="High",D6,E6)) -> 0
A7: Center | B7: 6 | C7: 2225 | D7: 2670 | E7: 1780 | F7: =IF(Inputs_Global!$D$5="Base",C7,IF(Inputs_Global!$D$5="High",D7,E7)) -> 2225
A8: Center | B8: 7 | C8: 0 | D8: 0 | E8: 0 | F8: =IF(Inputs_Global!$D$5="Base",C8,IF(Inputs_Global!$D$5="High",D8,E8)) -> 0
A9: Center | B9: 8 | C9: 2225 | D9: 2670 | E9: 1780 | F9: =IF(Inputs_Global!$D$5="Base",C9,IF(Inputs_Global!$D$5="High",D9,E9)) -> 2225
A10: West | B10: 1 | C10: 0 | D10: 0 | E10: 0 | F10: =IF(Inputs_Global!$D$5="Base",C10,IF(Inputs_Global!$D$5="High",D10,E10)) -> 0
A11: West | B11: 2 | C11: 1007 | D11: 1208 | E11: 805 | F11: =IF(Inputs_Global!$D$5="Base",C11,IF(Inputs_Global!$D$5="High",D11,E11)) -> 1007
A12: West | B12: 3 | C12: 0 | D12: 0 | E12: 0 | F12: =IF(Inputs_Global!$D$5="Base",C12,IF(Inputs_Global!$D$5="High",D12,E12)) -> 0
A13: West | B13: 4 | C13: 1007 | D13: 1208 | E13: 805 | F13: =IF(Inputs_Global!$D$5="Base",C13,IF(Inputs_Global!$D$5="High",D13,E13)) -> 1007
... A41: South | B41: 8 | C41: 0 | D41: 0 | E41: 0 | F41: =IF(Inputs_Global!$D$5="Base",C41,IF(Inputs_Global!$D$5="High",D41,E41)) -> 0

Sheet Production_Supply
A1: Region | B1: Fortnight | C1: Prod_Out
A2: Center | B2: 1 | C2: 1500
A3: Center | B3: 2 | C3: 1500
A4: Center | B4: 3 | C4: 1500
A5: Center | B5: 4 | C5: 1500
A6: Center | B6: 5 | C6: 1500
A7: Center | B7: 6 | C7: 1500
A8: Center | B8: 7 | C8: 1500
A9: Center | B9: 8 | C9: 1500
A10: West | B10: 1 | C10: 350
A11: West | B11: 2 | C11: 350
A12: West | B12: 3 | C12: 350
A13: West | B13: 4 | C13: 350
... A41: South | B41: 8 | C41: 0

Sheet Transport_Costs
A1: Origin | B1: Dest | C1: Mode | D1: Bracket | E1: Cost_per_unit | G1: BRACKET RULES
A2: Center | B2: West | C2: Air | D2: S | E2: 19.2 | G2: S: < 1000 units
A3: Center | B3: West | C3: Air | D3: M | E3: 19.2 | G3: M: 1000 - 1999
A4: Center | B4: West | C4: Air | D4: L | E4: 19.2 | G4: L: >= 2000
A5: Center | B5: West | C5: Truck | D5: S | E5: 18
A6: Center | B6: West | C6: Truck | D6: M | E6: 16.8
A7: Center | B7: West | C7: Truck | D7: L | E7: 15.6
A8: Center | B8: West | C8: Train | D8: S | E8: 13.2
A9: Center | B9: West | C9: Train | D9: M | E9: 12
A10: Center | B10: West | C10: Train | D10: L | E10: 10.8
A11: Center | B11: North | C11: Air | D11: S | E11: 26.4
A12: Center | B12: North | C12: Air | D12: M | E12: 26.4
A13: Center | B13: North | C13: Air | D13: L | E13: 26.4
A14: Center | B14: North | C14: Truck | D14: S | E14: 20.16
A15: Center | B15: North | C15: Truck | D15: M | E15: 18.96
A16: Center | B16: North | C16: Truck | D16: L | E16: 18.48
... A64: West | B64: South | C64: Train | D64: L | E64: 24

Sheet LeadTime_Probs
A1: Origin | B1: Dest | C1: Mode | D1: LeadTime | E1: Prob | F1: CDF
A2: Center | B2: West | C2: Air | D2: 1 | E2: 1 | F2: =SUMIFS(E:E,A:A,A2,B:B,B2,C:C,C2,D:D,"<="&D2) -> 1
A3: Center | B3: North | C3: Air | D3: 1 | E3: 1 | F3: =SUMIFS(E:E,A:A,A3,B:B,B3,C:C,C3,D:D,"<="&D3) -> 1
A4: Center | B4: East | C4: Air | D4: 1 | E4: 1 | F4: =SUMIFS(E:E,A:A,A4,B:B,B4,C:C,C4,D:D,"<="&D4) -> 1
A5: Center | B5: South | C5: Air | D5: 1 | E5: 1 | F5: =SUMIFS(E:E,A:A,A5,B:B,B5,C:C,C5,D:D,"<="&D5) -> 1
A6: West | B6: North | C6: Air | D6: 1 | E6: 1 | F6: =SUMIFS(E:E,A:A,A6,B:B,B6,C:C,C6,D:D,"<="&D6) -> 1
A7: West | B7: East | C7: Air | D7: 1 | E7: 1 | F7: =SUMIFS(E:E,A:A,A7,B:B,B7,C:C,C7,D:D,"<="&D7) -> 1
A8: West | B8: South | C8: Air | D8: 1 | E8: 1 | F8: =SUMIFS(E:E,A:A,A8,B:B,B8,C:C,C8,D:D,"<="&D8) -> 1
A9: Center | B9: West | C9: Truck | D9: 1 | E9: 0.5 | F9: =SUMIFS(E:E,A:A,A9,B:B,B9,C:C,C9,D:D,"<="&D9) -> 0.5
A10: Center | B10: West | C10: Truck | D10: 2 | E10: 0.5 | F10: =SUMIFS(E:E,A:A,A10,B:B,B10,C:C,C10,D:D,"<="&D10) -> 1
A11: Center | B11: West | C11: Train | D11: 2 | E11: 0.2 | F11: =SUMIFS(E:E,A:A,A11,B:B,B11,C:C,C11,D:D,"<="&D11) -> 0.2
A12: Center | B12: West | C12: Train | D12: 3 | E12: 0.3 | F12: =SUMIFS(E:E,A:A,A12,B:B,B12,C:C,C12,D:D,"<="&D12) -> 0.5
A13: Center | B13: West | C13: Train | D13: 4 | E13: 0.5 | F13: =SUMIFS(E:E,A:A,A13,B:B,B13,C:C,C13,D:D,"<="&D13) -> 1
... A27: West | B27: North | C27: Train | D27: 4 | E27: 0.5 | F27: =SUMIFS(E:E,A:A,A27,B:B,B27,C:C,C27,D:D,"<="&D27) -> 1

Sheet ShipPlan
A1: ShipID | B1: Priority | C1: t_dispatch | D1: Origin | E1: Dest | F1: Mode | G1: Units_Planned | H1: Bracket | I1: Cost_per_unit | J1: Freight_cost_planned | K1: Expected_LT | L1: Expected_arrival_t | M1: Target_t | N1: P_arrive_by_target | O1: Units_Fulfilled | P1: Units_Unfulfilled | Q1: Freight_cost_actual
A2: SHIP001 | B2: 1 | C2: 1 | D2: Center | E2: West | F2: Train | G2: 571 | H2: =IF(G2<1000,"S",IF(G2<2000,"M","L")) -> S | I2: =IFERROR(INDEX(Transport_Costs!E:E,MATCH(1,(Transport_Costs!A:A=D2)*(Transport_Costs!B:B=E2)*(Transport_Costs!C:C=F2)*(Transport_Costs!D:D=H2),0)),0) -> 13.2 | J2: =G2*I2 -> 7537.2 | K2: =IFERROR(SUMPRODUCT((LeadTime_Probs!A$2:A$100=D2)*(LeadTime_Probs!B$2:B$100=E2)*(LeadTime_Probs!C$2:C$100=F2)*LeadTime_Probs!D$2:D$100*LeadTime_Probs!E$2:E$100)/SUMPRODUCT((LeadTime_Probs!A$2:A$100=D2)*(LeadTime_Probs!B$2:B$100=E2)*(LeadTime_Probs!C$2:C$100=F2)*LeadTime_Probs!E$2:E$100),1) -> 3.3 | L2: =C2+ROUND(K2,0) -> 4 | N2: =IF(M2="","",IFERROR(SUMPRODUCT((LeadTime_Probs!A$2:A$100=D2)*(LeadTime_Probs!B$2:B$100=E2)*(LeadTime_Probs!C$2:C$100=F2)*(LeadTime_Probs!D$2:D$100<=(M2-C2))*LeadTime_Probs!E$2:E$100),0)) | O2: =MAX(0,MIN(G2,IFERROR(SUMIFS(Inventory_Flow!G:G,Inventory_Flow!A:A,D2,Inventory_Flow!B:B,C2),0)-SUMIFS(ShipPlan!G:G,ShipPlan!D:D,D2,ShipPlan!C:C,C2,ShipPlan!B:B,"<"&B2))) -> 571 | P2: =G2-O2 -> 0 | Q2: =O2*I2 -> 7537.2
A3: SHIP002 | B3: 2 | C3: 2 | D3: Center | E3: North | F3: Train | G3: 1025 | H3: =IF(G3<1000,"S",IF(G3<2000,"M","L")) -> M | I3: =IFERROR(INDEX(Transport_Costs!E:E,MATCH(1,(Transport_Costs!A:A=D3)*(Transport_Costs!B:B=E3)*(Transport_Costs!C:C=F3)*(Transport_Costs!D:D=H3),0)),0) -> 18.24 | J3: =G3*I3 -> 18696 | K3: =IFERROR(SUMPRODUCT((LeadTime_Probs!A$2:A$100=D3)*(LeadTime_Probs!B$2:B$100=E3)*(LeadTime_Probs!C$2:C$100=F3)*LeadTime_Probs!D$2:D$100*LeadTime_Probs!E$2:E$100)/SUMPRODUCT((LeadTime_Probs!A$2:A$100=D3)*(LeadTime_Probs!B$2:B$100=E3)*(LeadTime_Probs!C$2:C$100=F3)*LeadTime_Probs!E$2:E$100),1) -> 3.5 | L3: =C3+ROUND(K3,0) -> 6 | N3: =IF(M3="","",IFERROR(SUMPRODUCT((LeadTime_Probs!A$2:A$100=D3)*(LeadTime_Probs!B$2:B$100=E3)*(LeadTime_Probs!C$2:C$100=F3)*(LeadTime_Probs!D$2:D$100<=(M3-C3))*LeadTime_Probs!E$2:E$100),0)) | O3: =MAX(0,MIN(G3,IFERROR(SUMIFS(Inventory_Flow!G:G,Inventory_Flow!A:A,D3,Inventory_Flow!B:B,C3),0)-SUMIFS(ShipPlan!G:G,ShipPlan!D:D,D3,ShipPlan!C:C,C3,ShipPlan!B:B,"<"&B3))) -> 1025 | P3: =G3-O3 -> 0 | Q3: =O3*I3 -> 18696
A4: SHIP003 | B4: 3 | C4: 4 | D4: Center | E4: North | F4: Train | G4: 2681 | H4: =IF(G4<1000,"S",IF(G4<2000,"M","L")) -> L | I4: =IFERROR(INDEX(Transport_Costs!E:E,MATCH(1,(Transport_Costs!A:A=D4)*(Transport_Costs!B:B=E4)*(Transport_Costs!C:C=F4)*(Transport_Costs!D:D=H4),0)),0) -> 14.4 | J4: =G4*I4 -> 38606.4 | K4: =IFERROR(SUMPRODUCT((LeadTime_Probs!A$2:A$100=D4)*(LeadTime_Probs!B$2:B$100=E4)*(LeadTime_Probs!C$2:C$100=F4)*LeadTime_Probs!D$2:D$100*LeadTime_Probs!E$2:E$100)/SUMPRODUCT((LeadTime_Probs!A$2:A$100=D4)*(LeadTime_Probs!B$2:B$100=E4)*(LeadTime_Probs!C$2:C$100=F4)*LeadTime_Probs!E$2:E$100),1) -> 3.5 | L4: =C4+ROUND(K4,0) -> 8 | N4: =IF(M4="","",IFERROR(SUMPRODUCT((LeadTime_Probs!A$2:A$100=D4)*(LeadTime_Probs!B$2:B$100=E4)*(LeadTime_Probs!C$2:C$100=F4)*(LeadTime_Probs!D$2:D$100<=(M4-C4))*LeadTime_Probs!E$2:E$100),0)) | O4: =MAX(0,MIN(G4,IFERROR(SUMIFS(Inventory_Flow!G:G,Inventory_Flow!A:A,D4,Inventory_Flow!B:B,C4),0)-SUMIFS(ShipPlan!G:G,ShipPlan!D:D,D4,ShipPlan!C:C,C4,ShipPlan!B:B,"<"&B4))) -> 2681 | P4: =G4-O4 -> 0 | Q4: =O4*I4 -> 38606.4

Sheet Arrivals
A1: Method Switch | B1: =Inputs_Global!D6 -> EV
A2: NOTA: Arrivals usa Units_Fulfilled, no Units_Planned
A4: ARRIVALS_EV (basado en Units_Fulfilled)
A5: Region | B5: FT_1 | C5: FT_2 | D5: FT_3 | E5: FT_4 | F5: FT_5 | G5: FT_6 | H5: FT_7 | I5: FT_8 | J5: In_Transit_End
A6: Center | B6: =SUMIFS(ShipPlan!O:O,ShipPlan!E:E,A6,ShipPlan!L:L,1) -> 0 | C6: =SUMIFS(ShipPlan!O:O,ShipPlan!E:E,A6,ShipPlan!L:L,2) -> 0 | D6: =SUMIFS(ShipPlan!O:O,ShipPlan!E:E,A6,ShipPlan!L:L,3) -> 0 | E6: =SUMIFS(ShipPlan!O:O,ShipPlan!E:E,A6,ShipPlan!L:L,4) -> 0 | F6: =SUMIFS(ShipPlan!O:O,ShipPlan!E:E,A6,ShipPlan!L:L,5) -> 0 | G6: =SUMIFS(ShipPlan!O:O,ShipPlan!E:E,A6,ShipPlan!L:L,6) -> 0 | H6: =SUMIFS(ShipPlan!O:O,ShipPlan!E:E,A6,ShipPlan!L:L,7) -> 0 | I6: =SUMIFS(ShipPlan!O:O,ShipPlan!E:E,A6,ShipPlan!L:L,8) -> 0 | J6: =MAX(0,SUMIFS(ShipPlan!O:O,ShipPlan!E:E,A6)-SUM(B6:I6))
A7: West | B7: =SUMIFS(ShipPlan!O:O,ShipPlan!E:E,A7,ShipPlan!L:L,1) -> 0 | C7: =SUMIFS(ShipPlan!O:O,ShipPlan!E:E,A7,ShipPlan!L:L,2) -> 0 | D7: =SUMIFS(ShipPlan!O:O,ShipPlan!E:E,A7,ShipPlan!L:L,3) -> 0 | E7: =SUMIFS(ShipPlan!O:O,ShipPlan!E:E,A7,ShipPlan!L:L,4) -> 571 | F7: =SUMIFS(ShipPlan!O:O,ShipPlan!E:E,A7,ShipPlan!L:L,5) -> 0 | G7: =SUMIFS(ShipPlan!O:O,ShipPlan!E:E,A7,ShipPlan!L:L,6) -> 0 | H7: =SUMIFS(ShipPlan!O:O,ShipPlan!E:E,A7,ShipPlan!L:L,7) -> 0 | I7: =SUMIFS(ShipPlan!O:O,ShipPlan!E:E,A7,ShipPlan!L:L,8) -> 0 | J7: =MAX(0,SUMIFS(ShipPlan!O:O,ShipPlan!E:E,A7)-SUM(B7:I7))
A8: North | B8: =SUMIFS(ShipPlan!O:O,ShipPlan!E:E,A8,ShipPlan!L:L,1) -> 0 | C8: =SUMIFS(ShipPlan!O:O,ShipPlan!E:E,A8,ShipPlan!L:L,2) -> 0 | D8: =SUMIFS(ShipPlan!O:O,ShipPlan!E:E,A8,ShipPlan!L:L,3) -> 0 | E8: =SUMIFS(ShipPlan!O:O,ShipPlan!E:E,A8,ShipPlan!L:L,4) -> 0 | F8: =SUMIFS(ShipPlan!O:O,ShipPlan!E:E,A8,ShipPlan!L:L,5) -> 0 | G8: =SUMIFS(ShipPlan!O:O,ShipPlan!E:E,A8,ShipPlan!L:L,6) -> 1025 | H8: =SUMIFS(ShipPlan!O:O,ShipPlan!E:E,A8,ShipPlan!L:L,7) -> 0 | I8: =SUMIFS(ShipPlan!O:O,ShipPlan!E:E,A8,ShipPlan!L:L,8) -> 2681 | J8: =MAX(0,SUMIFS(ShipPlan!O:O,ShipPlan!E:E,A8)-SUM(B8:I8))
A9: East | B9: =SUMIFS(ShipPlan!O:O,ShipPlan!E:E,A9,ShipPlan!L:L,1) -> 0 | C9: =SUMIFS(ShipPlan!O:O,ShipPlan!E:E,A9,ShipPlan!L:L,2) -> 0 | D9: =SUMIFS(ShipPlan!O:O,ShipPlan!E:E,A9,ShipPlan!L:L,3) -> 0 | E9: =SUMIFS(ShipPlan!O:O,ShipPlan!E:E,A9,ShipPlan!L:L,4) -> 0 | F9: =SUMIFS(ShipPlan!O:O,ShipPlan!E:E,A9,ShipPlan!L:L,5) -> 0 | G9: =SUMIFS(ShipPlan!O:O,ShipPlan!E:E,A9,ShipPlan!L:L,6) -> 0 | H9: =SUMIFS(ShipPlan!O:O,ShipPlan!E:E,A9,ShipPlan!L:L,7) -> 0 | I9: =SUMIFS(ShipPlan!O:O,ShipPlan!E:E,A9,ShipPlan!L:L,8) -> 0 | J9: =MAX(0,SUMIFS(ShipPlan!O:O,ShipPlan!E:E,A9)-SUM(B9:I9))
A10: South | B10: =SUMIFS(ShipPlan!O:O,ShipPlan!E:E,A10,ShipPlan!L:L,1) -> 0 | C10: =SUMIFS(ShipPlan!O:O,ShipPlan!E:E,A10,ShipPlan!L:L,2) -> 0 | D10: =SUMIFS(ShipPlan!O:O,ShipPlan!E:E,A10,ShipPlan!L:L,3) -> 0 | E10: =SUMIFS(ShipPlan!O:O,ShipPlan!E:E,A10,ShipPlan!L:L,4) -> 0 | F10: =SUMIFS(ShipPlan!O:O,ShipPlan!E:E,A10,ShipPlan!L:L,5) -> 0 | G10: =SUMIFS(ShipPlan!O:O,ShipPlan!E:E,A10,ShipPlan!L:L,6) -> 0 | H10: =SUMIFS(ShipPlan!O:O,ShipPlan!E:E,A10,ShipPlan!L:L,7) -> 0 | I10: =SUMIFS(ShipPlan!O:O,ShipPlan!E:E,A10,ShipPlan!L:L,8) -> 0 | J10: =MAX(0,SUMIFS(ShipPlan!O:O,ShipPlan!E:E,A10)-SUM(B10:I10))
A13: ARRIVALS_PROB (distribuciÃ³n por probabilidad)
A14: Region | B14: FT_1 | C14: FT_2 | D14: FT_3 | E14: FT_4 | F14: FT_5 | G14: FT_6 | H14: FT_7 | I14: FT_8 | J14: In_Transit_End
A15: Center | B15: =SUMPRODUCT((LeadTime_Probs!B$2:B$100=$A15)*LeadTime_Probs!E$2:E$100*SUMIFS(ShipPlan!O:O,ShipPlan!D:D,LeadTime_Probs!A$2:A$100,ShipPlan!E:E,LeadTime_Probs!B$2:B$100,ShipPlan!F:F,LeadTime_Probs!C$2:C$100,ShipPlan!C:C,1-LeadTime_Probs!D$2:D$100)) -> 0 | C15: =SUMPRODUCT((LeadTime_Probs!B$2:B$100=$A15)*LeadTime_Probs!E$2:E$100*SUMIFS(ShipPlan!O:O,ShipPlan!D:D,LeadTime_Probs!A$2:A$100,ShipPlan!E:E,LeadTime_Probs!B$2:B$100,ShipPlan!F:F,LeadTime_Probs!C$2:C$100,ShipPlan!C:C,2-LeadTime_Probs!D$2:D$100)) -> 0 | D15: =SUMPRODUCT((LeadTime_Probs!B$2:B$100=$A15)*LeadTime_Probs!E$2:E$100*SUMIFS(ShipPlan!O:O,ShipPlan!D:D,LeadTime_Probs!A$2:A$100,ShipPlan!E:E,LeadTime_Probs!B$2:B$100,ShipPlan!F:F,LeadTime_Probs!C$2:C$100,ShipPlan!C:C,3-LeadTime_Probs!D$2:D$100)) -> 0 | E15: =SUMPRODUCT((LeadTime_Probs!B$2:B$100=$A15)*LeadTime_Probs!E$2:E$100*SUMIFS(ShipPlan!O:O,ShipPlan!D:D,LeadTime_Probs!A$2:A$100,ShipPlan!E:E,LeadTime_Probs!B$2:B$100,ShipPlan!F:F,LeadTime_Probs!C$2:C$100,ShipPlan!C:C,4-LeadTime_Probs!D$2:D$100)) -> 0 | F15: =SUMPRODUCT((LeadTime_Probs!B$2:B$100=$A15)*LeadTime_Probs!E$2:E$100*SUMIFS(ShipPlan!O:O,ShipPlan!D:D,LeadTime_Probs!A$2:A$100,ShipPlan!E:E,LeadTime_Probs!B$2:B$100,ShipPlan!F:F,LeadTime_Probs!C$2:C$100,ShipPlan!C:C,5-LeadTime_Probs!D$2:D$100)) -> 0 | G15: =SUMPRODUCT((LeadTime_Probs!B$2:B$100=$A15)*LeadTime_Probs!E$2:E$100*SUMIFS(ShipPlan!O:O,ShipPlan!D:D,LeadTime_Probs!A$2:A$100,ShipPlan!E:E,LeadTime_Probs!B$2:B$100,ShipPlan!F:F,LeadTime_Probs!C$2:C$100,ShipPlan!C:C,6-LeadTime_Probs!D$2:D$100)) -> 0 | H15: =SUMPRODUCT((LeadTime_Probs!B$2:B$100=$A15)*LeadTime_Probs!E$2:E$100*SUMIFS(ShipPlan!O:O,ShipPlan!D:D,LeadTime_Probs!A$2:A$100,ShipPlan!E:E,LeadTime_Probs!B$2:B$100,ShipPlan!F:F,LeadTime_Probs!C$2:C$100,ShipPlan!C:C,7-LeadTime_Probs!D$2:D$100)) -> 0 | I15: =SUMPRODUCT((LeadTime_Probs!B$2:B$100=$A15)*LeadTime_Probs!E$2:E$100*SUMIFS(ShipPlan!O:O,ShipPlan!D:D,LeadTime_Probs!A$2:A$100,ShipPlan!E:E,LeadTime_Probs!B$2:B$100,ShipPlan!F:F,LeadTime_Probs!C$2:C$100,ShipPlan!C:C,8-LeadTime_Probs!D$2:D$100)) -> 0 | J15: =MAX(0,SUMIFS(ShipPlan!O:O,ShipPlan!E:E,A15)-SUM(B15:I15))
A16: West | B16: =SUMPRODUCT((LeadTime_Probs!B$2:B$100=$A16)*LeadTime_Probs!E$2:E$100*SUMIFS(ShipPlan!O:O,ShipPlan!D:D,LeadTime_Probs!A$2:A$100,ShipPlan!E:E,LeadTime_Probs!B$2:B$100,ShipPlan!F:F,LeadTime_Probs!C$2:C$100,ShipPlan!C:C,1-LeadTime_Probs!D$2:D$100)) -> 0 | C16: =SUMPRODUCT((LeadTime_Probs!B$2:B$100=$A16)*LeadTime_Probs!E$2:E$100*SUMIFS(ShipPlan!O:O,ShipPlan!D:D,LeadTime_Probs!A$2:A$100,ShipPlan!E:E,LeadTime_Probs!B$2:B$100,ShipPlan!F:F,LeadTime_Probs!C$2:C$100,ShipPlan!C:C,2-LeadTime_Probs!D$2:D$100)) -> 0 | D16: =SUMPRODUCT((LeadTime_Probs!B$2:B$100=$A16)*LeadTime_Probs!E$2:E$100*SUMIFS(ShipPlan!O:O,ShipPlan!D:D,LeadTime_Probs!A$2:A$100,ShipPlan!E:E,LeadTime_Probs!B$2:B$100,ShipPlan!F:F,LeadTime_Probs!C$2:C$100,ShipPlan!C:C,3-LeadTime_Probs!D$2:D$100)) -> 0 | E16: =SUMPRODUCT((LeadTime_Probs!B$2:B$100=$A16)*LeadTime_Probs!E$2:E$100*SUMIFS(ShipPlan!O:O,ShipPlan!D:D,LeadTime_Probs!A$2:A$100,ShipPlan!E:E,LeadTime_Probs!B$2:B$100,ShipPlan!F:F,LeadTime_Probs!C$2:C$100,ShipPlan!C:C,4-LeadTime_Probs!D$2:D$100)) -> 571 | F16: =SUMPRODUCT((LeadTime_Probs!B$2:B$100=$A16)*LeadTime_Probs!E$2:E$100*SUMIFS(ShipPlan!O:O,ShipPlan!D:D,LeadTime_Probs!A$2:A$100,ShipPlan!E:E,LeadTime_Probs!B$2:B$100,ShipPlan!F:F,LeadTime_Probs!C$2:C$100,ShipPlan!C:C,5-LeadTime_Probs!D$2:D$100)) -> 0 | G16: =SUMPRODUCT((LeadTime_Probs!B$2:B$100=$A16)*LeadTime_Probs!E$2:E$100*SUMIFS(ShipPlan!O:O,ShipPlan!D:D,LeadTime_Probs!A$2:A$100,ShipPlan!E:E,LeadTime_Probs!B$2:B$100,ShipPlan!F:F,LeadTime_Probs!C$2:C$100,ShipPlan!C:C,6-LeadTime_Probs!D$2:D$100)) -> 0 | H16: =SUMPRODUCT((LeadTime_Probs!B$2:B$100=$A16)*LeadTime_Probs!E$2:E$100*SUMIFS(ShipPlan!O:O,ShipPlan!D:D,LeadTime_Probs!A$2:A$100,ShipPlan!E:E,LeadTime_Probs!B$2:B$100,ShipPlan!F:F,LeadTime_Probs!C$2:C$100,ShipPlan!C:C,7-LeadTime_Probs!D$2:D$100)) -> 0 | I16: =SUMPRODUCT((LeadTime_Probs!B$2:B$100=$A16)*LeadTime_Probs!E$2:E$100*SUMIFS(ShipPlan!O:O,ShipPlan!D:D,LeadTime_Probs!A$2:A$100,ShipPlan!E:E,LeadTime_Probs!B$2:B$100,ShipPlan!F:F,LeadTime_Probs!C$2:C$100,ShipPlan!C:C,8-LeadTime_Probs!D$2:D$100)) -> 0 | J16: =MAX(0,SUMIFS(ShipPlan!O:O,ShipPlan!E:E,A16)-SUM(B16:I16))
A17: North | B17: =SUMPRODUCT((LeadTime_Probs!B$2:B$100=$A17)*LeadTime_Probs!E$2:E$100*SUMIFS(ShipPlan!O:O,ShipPlan!D:D,LeadTime_Probs!A$2:A$100,ShipPlan!E:E,LeadTime_Probs!B$2:B$100,ShipPlan!F:F,LeadTime_Probs!C$2:C$100,ShipPlan!C:C,1-LeadTime_Probs!D$2:D$100)) -> 0 | C17: =SUMPRODUCT((LeadTime_Probs!B$2:B$100=$A17)*LeadTime_Probs!E$2:E$100*SUMIFS(ShipPlan!O:O,ShipPlan!D:D,LeadTime_Probs!A$2:A$100,ShipPlan!E:E,LeadTime_Probs!B$2:B$100,ShipPlan!F:F,LeadTime_Probs!C$2:C$100,ShipPlan!C:C,2-LeadTime_Probs!D$2:D$100)) -> 0 | D17: =SUMPRODUCT((LeadTime_Probs!B$2:B$100=$A17)*LeadTime_Probs!E$2:E$100*SUMIFS(ShipPlan!O:O,ShipPlan!D:D,LeadTime_Probs!A$2:A$100,ShipPlan!E:E,LeadTime_Probs!B$2:B$100,ShipPlan!F:F,LeadTime_Probs!C$2:C$100,ShipPlan!C:C,3-LeadTime_Probs!D$2:D$100)) -> 0 | E17: =SUMPRODUCT((LeadTime_Probs!B$2:B$100=$A17)*LeadTime_Probs!E$2:E$100*SUMIFS(ShipPlan!O:O,ShipPlan!D:D,LeadTime_Probs!A$2:A$100,ShipPlan!E:E,LeadTime_Probs!B$2:B$100,ShipPlan!F:F,LeadTime_Probs!C$2:C$100,ShipPlan!C:C,4-LeadTime_Probs!D$2:D$100)) -> 0 | F17: =SUMPRODUCT((LeadTime_Probs!B$2:B$100=$A17)*LeadTime_Probs!E$2:E$100*SUMIFS(ShipPlan!O:O,ShipPlan!D:D,LeadTime_Probs!A$2:A$100,ShipPlan!E:E,LeadTime_Probs!B$2:B$100,ShipPlan!F:F,LeadTime_Probs!C$2:C$100,ShipPlan!C:C,5-LeadTime_Probs!D$2:D$100)) -> 0 | G17: =SUMPRODUCT((LeadTime_Probs!B$2:B$100=$A17)*LeadTime_Probs!E$2:E$100*SUMIFS(ShipPlan!O:O,ShipPlan!D:D,LeadTime_Probs!A$2:A$100,ShipPlan!E:E,LeadTime_Probs!B$2:B$100,ShipPlan!F:F,LeadTime_Probs!C$2:C$100,ShipPlan!C:C,6-LeadTime_Probs!D$2:D$100)) -> 1025 | H17: =SUMPRODUCT((LeadTime_Probs!B$2:B$100=$A17)*LeadTime_Probs!E$2:E$100*SUMIFS(ShipPlan!O:O,ShipPlan!D:D,LeadTime_Probs!A$2:A$100,ShipPlan!E:E,LeadTime_Probs!B$2:B$100,ShipPlan!F:F,LeadTime_Probs!C$2:C$100,ShipPlan!C:C,7-LeadTime_Probs!D$2:D$100)) -> 0 | I17: =SUMPRODUCT((LeadTime_Probs!B$2:B$100=$A17)*LeadTime_Probs!E$2:E$100*SUMIFS(ShipPlan!O:O,ShipPlan!D:D,LeadTime_Probs!A$2:A$100,ShipPlan!E:E,LeadTime_Probs!B$2:B$100,ShipPlan!F:F,LeadTime_Probs!C$2:C$100,ShipPlan!C:C,8-LeadTime_Probs!D$2:D$100)) -> 2681 | J17: =MAX(0,SUMIFS(ShipPlan!O:O,ShipPlan!E:E,A17)-SUM(B17:I17))
A18: East | B18: =SUMPRODUCT((LeadTime_Probs!B$2:B$100=$A18)*LeadTime_Probs!E$2:E$100*SUMIFS(ShipPlan!O:O,ShipPlan!D:D,LeadTime_Probs!A$2:A$100,ShipPlan!E:E,LeadTime_Probs!B$2:B$100,ShipPlan!F:F,LeadTime_Probs!C$2:C$100,ShipPlan!C:C,1-LeadTime_Probs!D$2:D$100)) -> 0 | C18: =SUMPRODUCT((LeadTime_Probs!B$2:B$100=$A18)*LeadTime_Probs!E$2:E$100*SUMIFS(ShipPlan!O:O,ShipPlan!D:D,LeadTime_Probs!A$2:A$100,ShipPlan!E:E,LeadTime_Probs!B$2:B$100,ShipPlan!F:F,LeadTime_Probs!C$2:C$100,ShipPlan!C:C,2-LeadTime_Probs!D$2:D$100)) -> 0 | D18: =SUMPRODUCT((LeadTime_Probs!B$2:B$100=$A18)*LeadTime_Probs!E$2:E$100*SUMIFS(ShipPlan!O:O,ShipPlan!D:D,LeadTime_Probs!A$2:A$100,ShipPlan!E:E,LeadTime_Probs!B$2:B$100,ShipPlan!F:F,LeadTime_Probs!C$2:C$100,ShipPlan!C:C,3-LeadTime_Probs!D$2:D$100)) -> 0 | E18: =SUMPRODUCT((LeadTime_Probs!B$2:B$100=$A18)*LeadTime_Probs!E$2:E$100*SUMIFS(ShipPlan!O:O,ShipPlan!D:D,LeadTime_Probs!A$2:A$100,ShipPlan!E:E,LeadTime_Probs!B$2:B$100,ShipPlan!F:F,LeadTime_Probs!C$2:C$100,ShipPlan!C:C,4-LeadTime_Probs!D$2:D$100)) -> 0 | F18: =SUMPRODUCT((LeadTime_Probs!B$2:B$100=$A18)*LeadTime_Probs!E$2:E$100*SUMIFS(ShipPlan!O:O,ShipPlan!D:D,LeadTime_Probs!A$2:A$100,ShipPlan!E:E,LeadTime_Probs!B$2:B$100,ShipPlan!F:F,LeadTime_Probs!C$2:C$100,ShipPlan!C:C,5-LeadTime_Probs!D$2:D$100)) -> 0 | G18: =SUMPRODUCT((LeadTime_Probs!B$2:B$100=$A18)*LeadTime_Probs!E$2:E$100*SUMIFS(ShipPlan!O:O,ShipPlan!D:D,LeadTime_Probs!A$2:A$100,ShipPlan!E:E,LeadTime_Probs!B$2:B$100,ShipPlan!F:F,LeadTime_Probs!C$2:C$100,ShipPlan!C:C,6-LeadTime_Probs!D$2:D$100)) -> 0 | H18: =SUMPRODUCT((LeadTime_Probs!B$2:B$100=$A18)*LeadTime_Probs!E$2:E$100*SUMIFS(ShipPlan!O:O,ShipPlan!D:D,LeadTime_Probs!A$2:A$100,ShipPlan!E:E,LeadTime_Probs!B$2:B$100,ShipPlan!F:F,LeadTime_Probs!C$2:C$100,ShipPlan!C:C,7-LeadTime_Probs!D$2:D$100)) -> 0 | I18: =SUMPRODUCT((LeadTime_Probs!B$2:B$100=$A18)*LeadTime_Probs!E$2:E$100*SUMIFS(ShipPlan!O:O,ShipPlan!D:D,LeadTime_Probs!A$2:A$100,ShipPlan!E:E,LeadTime_Probs!B$2:B$100,ShipPlan!F:F,LeadTime_Probs!C$2:C$100,ShipPlan!C:C,8-LeadTime_Probs!D$2:D$100)) -> 0 | J18: =MAX(0,SUMIFS(ShipPlan!O:O,ShipPlan!E:E,A18)-SUM(B18:I18))
A19: South | B19: =SUMPRODUCT((LeadTime_Probs!B$2:B$100=$A19)*LeadTime_Probs!E$2:E$100*SUMIFS(ShipPlan!O:O,ShipPlan!D:D,LeadTime_Probs!A$2:A$100,ShipPlan!E:E,LeadTime_Probs!B$2:B$100,ShipPlan!F:F,LeadTime_Probs!C$2:C$100,ShipPlan!C:C,1-LeadTime_Probs!D$2:D$100)) -> 0 | C19: =SUMPRODUCT((LeadTime_Probs!B$2:B$100=$A19)*LeadTime_Probs!E$2:E$100*SUMIFS(ShipPlan!O:O,ShipPlan!D:D,LeadTime_Probs!A$2:A$100,ShipPlan!E:E,LeadTime_Probs!B$2:B$100,ShipPlan!F:F,LeadTime_Probs!C$2:C$100,ShipPlan!C:C,2-LeadTime_Probs!D$2:D$100)) -> 0 | D19: =SUMPRODUCT((LeadTime_Probs!B$2:B$100=$A19)*LeadTime_Probs!E$2:E$100*SUMIFS(ShipPlan!O:O,ShipPlan!D:D,LeadTime_Probs!A$2:A$100,ShipPlan!E:E,LeadTime_Probs!B$2:B$100,ShipPlan!F:F,LeadTime_Probs!C$2:C$100,ShipPlan!C:C,3-LeadTime_Probs!D$2:D$100)) -> 0 | E19: =SUMPRODUCT((LeadTime_Probs!B$2:B$100=$A19)*LeadTime_Probs!E$2:E$100*SUMIFS(ShipPlan!O:O,ShipPlan!D:D,LeadTime_Probs!A$2:A$100,ShipPlan!E:E,LeadTime_Probs!B$2:B$100,ShipPlan!F:F,LeadTime_Probs!C$2:C$100,ShipPlan!C:C,4-LeadTime_Probs!D$2:D$100)) -> 0 | F19: =SUMPRODUCT((LeadTime_Probs!B$2:B$100=$A19)*LeadTime_Probs!E$2:E$100*SUMIFS(ShipPlan!O:O,ShipPlan!D:D,LeadTime_Probs!A$2:A$100,ShipPlan!E:E,LeadTime_Probs!B$2:B$100,ShipPlan!F:F,LeadTime_Probs!C$2:C$100,ShipPlan!C:C,5-LeadTime_Probs!D$2:D$100)) -> 0 | G19: =SUMPRODUCT((LeadTime_Probs!B$2:B$100=$A19)*LeadTime_Probs!E$2:E$100*SUMIFS(ShipPlan!O:O,ShipPlan!D:D,LeadTime_Probs!A$2:A$100,ShipPlan!E:E,LeadTime_Probs!B$2:B$100,ShipPlan!F:F,LeadTime_Probs!C$2:C$100,ShipPlan!C:C,6-LeadTime_Probs!D$2:D$100)) -> 0 | H19: =SUMPRODUCT((LeadTime_Probs!B$2:B$100=$A19)*LeadTime_Probs!E$2:E$100*SUMIFS(ShipPlan!O:O,ShipPlan!D:D,LeadTime_Probs!A$2:A$100,ShipPlan!E:E,LeadTime_Probs!B$2:B$100,ShipPlan!F:F,LeadTime_Probs!C$2:C$100,ShipPlan!C:C,7-LeadTime_Probs!D$2:D$100)) -> 0 | I19: =SUMPRODUCT((LeadTime_Probs!B$2:B$100=$A19)*LeadTime_Probs!E$2:E$100*SUMIFS(ShipPlan!O:O,ShipPlan!D:D,LeadTime_Probs!A$2:A$100,ShipPlan!E:E,LeadTime_Probs!B$2:B$100,ShipPlan!F:F,LeadTime_Probs!C$2:C$100,ShipPlan!C:C,8-LeadTime_Probs!D$2:D$100)) -> 0 | J19: =MAX(0,SUMIFS(ShipPlan!O:O,ShipPlan!E:E,A19)-SUM(B19:I19))
A22: ARRIVALS_ACTIVE
A23: Region | B23: FT_1 | C23: FT_2 | D23: FT_3 | E23: FT_4 | F23: FT_5 | G23: FT_6 | H23: FT_7 | I23: FT_8 | J23: In_Transit_End
A24: Center | B24: =IF($B$1="EV",B6,B15) -> 0 | C24: =IF($B$1="EV",C6,C15) -> 0 | D24: =IF($B$1="EV",D6,D15) -> 0 | E24: =IF($B$1="EV",E6,E15) -> 0 | F24: =IF($B$1="EV",F6,F15) -> 0 | G24: =IF($B$1="EV",G6,G15) -> 0 | H24: =IF($B$1="EV",H6,H15) -> 0 | I24: =IF($B$1="EV",I6,I15) -> 0 | J24: =IF($B$1="EV",J6,J15)
A25: West | B25: =IF($B$1="EV",B7,B16) -> 0 | C25: =IF($B$1="EV",C7,C16) -> 0 | D25: =IF($B$1="EV",D7,D16) -> 0 | E25: =IF($B$1="EV",E7,E16) -> 571 | F25: =IF($B$1="EV",F7,F16) -> 0 | G25: =IF($B$1="EV",G7,G16) -> 0 | H25: =IF($B$1="EV",H7,H16) -> 0 | I25: =IF($B$1="EV",I7,I16) -> 0 | J25: =IF($B$1="EV",J7,J16)
A26: North | B26: =IF($B$1="EV",B8,B17) -> 0 | C26: =IF($B$1="EV",C8,C17) -> 0 | D26: =IF($B$1="EV",D8,D17) -> 0 | E26: =IF($B$1="EV",E8,E17) -> 0 | F26: =IF($B$1="EV",F8,F17) -> 0 | G26: =IF($B$1="EV",G8,G17) -> 1025 | H26: =IF($B$1="EV",H8,H17) -> 0 | I26: =IF($B$1="EV",I8,I17) -> 2681 | J26: =IF($B$1="EV",J8,J17)
A27: East | B27: =IF($B$1="EV",B9,B18) -> 0 | C27: =IF($B$1="EV",C9,C18) -> 0 | D27: =IF($B$1="EV",D9,D18) -> 0 | E27: =IF($B$1="EV",E9,E18) -> 0 | F27: =IF($B$1="EV",F9,F18) -> 0 | G27: =IF($B$1="EV",G9,G18) -> 0 | H27: =IF($B$1="EV",H9,H18) -> 0 | I27: =IF($B$1="EV",I9,I18) -> 0 | J27: =IF($B$1="EV",J9,J18)
A28: South | B28: =IF($B$1="EV",B10,B19) -> 0 | C28: =IF($B$1="EV",C10,C19) -> 0 | D28: =IF($B$1="EV",D10,D19) -> 0 | E28: =IF($B$1="EV",E10,E19) -> 0 | F28: =IF($B$1="EV",F10,F19) -> 0 | G28: =IF($B$1="EV",G10,G19) -> 0 | H28: =IF($B$1="EV",H10,H19) -> 0 | I28: =IF($B$1="EV",I10,I19) -> 0 | J28: =IF($B$1="EV",J10,J19)
A30: ARRIVALS_NEXT_PERIOD (ACTIVE)
A31: Region | B31: FT_1 | C31: FT_2 | D31: FT_3 | E31: FT_4 | F31: FT_5 | G31: FT_6 | H31: FT_7 | I31: FT_8
A32: Center | C32: =IF($B$1="EV",SUMIFS(ShipPlan!O:O,ShipPlan!E:E,$A32,ShipPlan!L:L,10),SUMPRODUCT((LeadTime_Probs!B$2:B$100=$A32)*LeadTime_Probs!E$2:E$100*SUMIFS(ShipPlan!O:O,ShipPlan!D:D,LeadTime_Probs!A$2:A$100,ShipPlan!E:E,LeadTime_Probs!B$2:B$100,ShipPlan!F:F,LeadTime_Probs!C$2:C$100,ShipPlan!C:C,10-LeadTime_Probs!D$2:D$100))) | E32: =IF($B$1="EV",SUMIFS(ShipPlan!O:O,ShipPlan!E:E,$A32,ShipPlan!L:L,12),SUMPRODUCT((LeadTime_Probs!B$2:B$100=$A32)*LeadTime_Probs!E$2:E$100*SUMIFS(ShipPlan!O:O,ShipPlan!D:D,LeadTime_Probs!A$2:A$100,ShipPlan!E:E,LeadTime_Probs!B$2:B$100,ShipPlan!F:F,LeadTime_Probs!C$2:C$100,ShipPlan!C:C,12-LeadTime_Probs!D$2:D$100))) | I32: =IF($B$1="EV",SUMIFS(ShipPlan!O:O,ShipPlan!E:E,$A32,ShipPlan!L:L,16),SUMPRODUCT((LeadTime_Probs!B$2:B$100=$A32)*LeadTime_Probs!E$2:E$100*SUMIFS(ShipPlan!O:O,ShipPlan!D:D,LeadTime_Probs!A$2:A$100,ShipPlan!E:E,LeadTime_Probs!B$2:B$100,ShipPlan!F:F,LeadTime_Probs!C$2:C$100,ShipPlan!C:C,16-LeadTime_Probs!D$2:D$100))) | F32: =IF($B$1="EV",SUMIFS(ShipPlan!O:O,ShipPlan!E:E,$A32,ShipPlan!L:L,13),SUMPRODUCT((LeadTime_Probs!B$2:B$100=$A32)*LeadTime_Probs!E$2:E$100*SUMIFS(ShipPlan!O:O,ShipPlan!D:D,LeadTime_Probs!A$2:A$100,ShipPlan!E:E,LeadTime_Probs!B$2:B$100,ShipPlan!F:F,LeadTime_Probs!C$2:C$100,ShipPlan!C:C,13-LeadTime_Probs!D$2:D$100))) | B32: =IF($B$1="EV",SUMIFS(ShipPlan!O:O,ShipPlan!E:E,$A32,ShipPlan!L:L,9),SUMPRODUCT((LeadTime_Probs!B$2:B$100=$A32)*LeadTime_Probs!E$2:E$100*SUMIFS(ShipPlan!O:O,ShipPlan!D:D,LeadTime_Probs!A$2:A$100,ShipPlan!E:E,LeadTime_Probs!B$2:B$100,ShipPlan!F:F,LeadTime_Probs!C$2:C$100,ShipPlan!C:C,9-LeadTime_Probs!D$2:D$100))) | G32: =IF($B$1="EV",SUMIFS(ShipPlan!O:O,ShipPlan!E:E,$A32,ShipPlan!L:L,14),SUMPRODUCT((LeadTime_Probs!B$2:B$100=$A32)*LeadTime_Probs!E$2:E$100*SUMIFS(ShipPlan!O:O,ShipPlan!D:D,LeadTime_Probs!A$2:A$100,ShipPlan!E:E,LeadTime_Probs!B$2:B$100,ShipPlan!F:F,LeadTime_Probs!C$2:C$100,ShipPlan!C:C,14-LeadTime_Probs!D$2:D$100))) | H32: =IF($B$1="EV",SUMIFS(ShipPlan!O:O,ShipPlan!E:E,$A32,ShipPlan!L:L,15),SUMPRODUCT((LeadTime_Probs!B$2:B$100=$A32)*LeadTime_Probs!E$2:E$100*SUMIFS(ShipPlan!O:O,ShipPlan!D:D,LeadTime_Probs!A$2:A$100,ShipPlan!E:E,LeadTime_Probs!B$2:B$100,ShipPlan!F:F,LeadTime_Probs!C$2:C$100,ShipPlan!C:C,15-LeadTime_Probs!D$2:D$100))) | D32: =IF($B$1="EV",SUMIFS(ShipPlan!O:O,ShipPlan!E:E,$A32,ShipPlan!L:L,11),SUMPRODUCT((LeadTime_Probs!B$2:B$100=$A32)*LeadTime_Probs!E$2:E$100*SUMIFS(ShipPlan!O:O,ShipPlan!D:D,LeadTime_Probs!A$2:A$100,ShipPlan!E:E,LeadTime_Probs!B$2:B$100,ShipPlan!F:F,LeadTime_Probs!C$2:C$100,ShipPlan!C:C,11-LeadTime_Probs!D$2:D$100)))
A33: West | C33: =IF($B$1="EV",SUMIFS(ShipPlan!O:O,ShipPlan!E:E,$A33,ShipPlan!L:L,10),SUMPRODUCT((LeadTime_Probs!B$2:B$100=$A33)*LeadTime_Probs!E$2:E$100*SUMIFS(ShipPlan!O:O,ShipPlan!D:D,LeadTime_Probs!A$2:A$100,ShipPlan!E:E,LeadTime_Probs!B$2:B$100,ShipPlan!F:F,LeadTime_Probs!C$2:C$100,ShipPlan!C:C,10-LeadTime_Probs!D$2:D$100))) | E33: =IF($B$1="EV",SUMIFS(ShipPlan!O:O,ShipPlan!E:E,$A33,ShipPlan!L:L,12),SUMPRODUCT((LeadTime_Probs!B$2:B$100=$A33)*LeadTime_Probs!E$2:E$100*SUMIFS(ShipPlan!O:O,ShipPlan!D:D,LeadTime_Probs!A$2:A$100,ShipPlan!E:E,LeadTime_Probs!B$2:B$100,ShipPlan!F:F,LeadTime_Probs!C$2:C$100,ShipPlan!C:C,12-LeadTime_Probs!D$2:D$100))) | I33: =IF($B$1="EV",SUMIFS(ShipPlan!O:O,ShipPlan!E:E,$A33,ShipPlan!L:L,16),SUMPRODUCT((LeadTime_Probs!B$2:B$100=$A33)*LeadTime_Probs!E$2:E$100*SUMIFS(ShipPlan!O:O,ShipPlan!D:D,LeadTime_Probs!A$2:A$100,ShipPlan!E:E,LeadTime_Probs!B$2:B$100,ShipPlan!F:F,LeadTime_Probs!C$2:C$100,ShipPlan!C:C,16-LeadTime_Probs!D$2:D$100))) | F33: =IF($B$1="EV",SUMIFS(ShipPlan!O:O,ShipPlan!E:E,$A33,ShipPlan!L:L,13),SUMPRODUCT((LeadTime_Probs!B$2:B$100=$A33)*LeadTime_Probs!E$2:E$100*SUMIFS(ShipPlan!O:O,ShipPlan!D:D,LeadTime_Probs!A$2:A$100,ShipPlan!E:E,LeadTime_Probs!B$2:B$100,ShipPlan!F:F,LeadTime_Probs!C$2:C$100,ShipPlan!C:C,13-LeadTime_Probs!D$2:D$100))) | B33: =IF($B$1="EV",SUMIFS(ShipPlan!O:O,ShipPlan!E:E,$A33,ShipPlan!L:L,9),SUMPRODUCT((LeadTime_Probs!B$2:B$100=$A33)*LeadTime_Probs!E$2:E$100*SUMIFS(ShipPlan!O:O,ShipPlan!D:D,LeadTime_Probs!A$2:A$100,ShipPlan!E:E,LeadTime_Probs!B$2:B$100,ShipPlan!F:F,LeadTime_Probs!C$2:C$100,ShipPlan!C:C,9-LeadTime_Probs!D$2:D$100))) | G33: =IF($B$1="EV",SUMIFS(ShipPlan!O:O,ShipPlan!E:E,$A33,ShipPlan!L:L,14),SUMPRODUCT((LeadTime_Probs!B$2:B$100=$A33)*LeadTime_Probs!E$2:E$100*SUMIFS(ShipPlan!O:O,ShipPlan!D:D,LeadTime_Probs!A$2:A$100,ShipPlan!E:E,LeadTime_Probs!B$2:B$100,ShipPlan!F:F,LeadTime_Probs!C$2:C$100,ShipPlan!C:C,14-LeadTime_Probs!D$2:D$100))) | H33: =IF($B$1="EV",SUMIFS(ShipPlan!O:O,ShipPlan!E:E,$A33,ShipPlan!L:L,15),SUMPRODUCT((LeadTime_Probs!B$2:B$100=$A33)*LeadTime_Probs!E$2:E$100*SUMIFS(ShipPlan!O:O,ShipPlan!D:D,LeadTime_Probs!A$2:A$100,ShipPlan!E:E,LeadTime_Probs!B$2:B$100,ShipPlan!F:F,LeadTime_Probs!C$2:C$100,ShipPlan!C:C,15-LeadTime_Probs!D$2:D$100))) | D33: =IF($B$1="EV",SUMIFS(ShipPlan!O:O,ShipPlan!E:E,$A33,ShipPlan!L:L,11),SUMPRODUCT((LeadTime_Probs!B$2:B$100=$A33)*LeadTime_Probs!E$2:E$100*SUMIFS(ShipPlan!O:O,ShipPlan!D:D,LeadTime_Probs!A$2:A$100,ShipPlan!E:E,LeadTime_Probs!B$2:B$100,ShipPlan!F:F,LeadTime_Probs!C$2:C$100,ShipPlan!C:C,11-LeadTime_Probs!D$2:D$100)))
A34: North | C34: =IF($B$1="EV",SUMIFS(ShipPlan!O:O,ShipPlan!E:E,$A34,ShipPlan!L:L,10),SUMPRODUCT((LeadTime_Probs!B$2:B$100=$A34)*LeadTime_Probs!E$2:E$100*SUMIFS(ShipPlan!O:O,ShipPlan!D:D,LeadTime_Probs!A$2:A$100,ShipPlan!E:E,LeadTime_Probs!B$2:B$100,ShipPlan!F:F,LeadTime_Probs!C$2:C$100,ShipPlan!C:C,10-LeadTime_Probs!D$2:D$100))) | E34: =IF($B$1="EV",SUMIFS(ShipPlan!O:O,ShipPlan!E:E,$A34,ShipPlan!L:L,12),SUMPRODUCT((LeadTime_Probs!B$2:B$100=$A34)*LeadTime_Probs!E$2:E$100*SUMIFS(ShipPlan!O:O,ShipPlan!D:D,LeadTime_Probs!A$2:A$100,ShipPlan!E:E,LeadTime_Probs!B$2:B$100,ShipPlan!F:F,LeadTime_Probs!C$2:C$100,ShipPlan!C:C,12-LeadTime_Probs!D$2:D$100))) | I34: =IF($B$1="EV",SUMIFS(ShipPlan!O:O,ShipPlan!E:E,$A34,ShipPlan!L:L,16),SUMPRODUCT((LeadTime_Probs!B$2:B$100=$A34)*LeadTime_Probs!E$2:E$100*SUMIFS(ShipPlan!O:O,ShipPlan!D:D,LeadTime_Probs!A$2:A$100,ShipPlan!E:E,LeadTime_Probs!B$2:B$100,ShipPlan!F:F,LeadTime_Probs!C$2:C$100,ShipPlan!C:C,16-LeadTime_Probs!D$2:D$100))) | F34: =IF($B$1="EV",SUMIFS(ShipPlan!O:O,ShipPlan!E:E,$A34,ShipPlan!L:L,13),SUMPRODUCT((LeadTime_Probs!B$2:B$100=$A34)*LeadTime_Probs!E$2:E$100*SUMIFS(ShipPlan!O:O,ShipPlan!D:D,LeadTime_Probs!A$2:A$100,ShipPlan!E:E,LeadTime_Probs!B$2:B$100,ShipPlan!F:F,LeadTime_Probs!C$2:C$100,ShipPlan!C:C,13-LeadTime_Probs!D$2:D$100))) | B34: =IF($B$1="EV",SUMIFS(ShipPlan!O:O,ShipPlan!E:E,$A34,ShipPlan!L:L,9),SUMPRODUCT((LeadTime_Probs!B$2:B$100=$A34)*LeadTime_Probs!E$2:E$100*SUMIFS(ShipPlan!O:O,ShipPlan!D:D,LeadTime_Probs!A$2:A$100,ShipPlan!E:E,LeadTime_Probs!B$2:B$100,ShipPlan!F:F,LeadTime_Probs!C$2:C$100,ShipPlan!C:C,9-LeadTime_Probs!D$2:D$100))) | G34: =IF($B$1="EV",SUMIFS(ShipPlan!O:O,ShipPlan!E:E,$A34,ShipPlan!L:L,14),SUMPRODUCT((LeadTime_Probs!B$2:B$100=$A34)*LeadTime_Probs!E$2:E$100*SUMIFS(ShipPlan!O:O,ShipPlan!D:D,LeadTime_Probs!A$2:A$100,ShipPlan!E:E,LeadTime_Probs!B$2:B$100,ShipPlan!F:F,LeadTime_Probs!C$2:C$100,ShipPlan!C:C,14-LeadTime_Probs!D$2:D$100))) | H34: =IF($B$1="EV",SUMIFS(ShipPlan!O:O,ShipPlan!E:E,$A34,ShipPlan!L:L,15),SUMPRODUCT((LeadTime_Probs!B$2:B$100=$A34)*LeadTime_Probs!E$2:E$100*SUMIFS(ShipPlan!O:O,ShipPlan!D:D,LeadTime_Probs!A$2:A$100,ShipPlan!E:E,LeadTime_Probs!B$2:B$100,ShipPlan!F:F,LeadTime_Probs!C$2:C$100,ShipPlan!C:C,15-LeadTime_Probs!D$2:D$100))) | D34: =IF($B$1="EV",SUMIFS(ShipPlan!O:O,ShipPlan!E:E,$A34,ShipPlan!L:L,11),SUMPRODUCT((LeadTime_Probs!B$2:B$100=$A34)*LeadTime_Probs!E$2:E$100*SUMIFS(ShipPlan!O:O,ShipPlan!D:D,LeadTime_Probs!A$2:A$100,ShipPlan!E:E,LeadTime_Probs!B$2:B$100,ShipPlan!F:F,LeadTime_Probs!C$2:C$100,ShipPlan!C:C,11-LeadTime_Probs!D$2:D$100)))
A35: East | C35: =IF($B$1="EV",SUMIFS(ShipPlan!O:O,ShipPlan!E:E,$A35,ShipPlan!L:L,10),SUMPRODUCT((LeadTime_Probs!B$2:B$100=$A35)*LeadTime_Probs!E$2:E$100*SUMIFS(ShipPlan!O:O,ShipPlan!D:D,LeadTime_Probs!A$2:A$100,ShipPlan!E:E,LeadTime_Probs!B$2:B$100,ShipPlan!F:F,LeadTime_Probs!C$2:C$100,ShipPlan!C:C,10-LeadTime_Probs!D$2:D$100))) | E35: =IF($B$1="EV",SUMIFS(ShipPlan!O:O,ShipPlan!E:E,$A35,ShipPlan!L:L,12),SUMPRODUCT((LeadTime_Probs!B$2:B$100=$A35)*LeadTime_Probs!E$2:E$100*SUMIFS(ShipPlan!O:O,ShipPlan!D:D,LeadTime_Probs!A$2:A$100,ShipPlan!E:E,LeadTime_Probs!B$2:B$100,ShipPlan!F:F,LeadTime_Probs!C$2:C$100,ShipPlan!C:C,12-LeadTime_Probs!D$2:D$100))) | I35: =IF($B$1="EV",SUMIFS(ShipPlan!O:O,ShipPlan!E:E,$A35,ShipPlan!L:L,16),SUMPRODUCT((LeadTime_Probs!B$2:B$100=$A35)*LeadTime_Probs!E$2:E$100*SUMIFS(ShipPlan!O:O,ShipPlan!D:D,LeadTime_Probs!A$2:A$100,ShipPlan!E:E,LeadTime_Probs!B$2:B$100,ShipPlan!F:F,LeadTime_Probs!C$2:C$100,ShipPlan!C:C,16-LeadTime_Probs!D$2:D$100))) | F35: =IF($B$1="EV",SUMIFS(ShipPlan!O:O,ShipPlan!E:E,$A35,ShipPlan!L:L,13),SUMPRODUCT((LeadTime_Probs!B$2:B$100=$A35)*LeadTime_Probs!E$2:E$100*SUMIFS(ShipPlan!O:O,ShipPlan!D:D,LeadTime_Probs!A$2:A$100,ShipPlan!E:E,LeadTime_Probs!B$2:B$100,ShipPlan!F:F,LeadTime_Probs!C$2:C$100,ShipPlan!C:C,13-LeadTime_Probs!D$2:D$100))) | B35: =IF($B$1="EV",SUMIFS(ShipPlan!O:O,ShipPlan!E:E,$A35,ShipPlan!L:L,9),SUMPRODUCT((LeadTime_Probs!B$2:B$100=$A35)*LeadTime_Probs!E$2:E$100*SUMIFS(ShipPlan!O:O,ShipPlan!D:D,LeadTime_Probs!A$2:A$100,ShipPlan!E:E,LeadTime_Probs!B$2:B$100,ShipPlan!F:F,LeadTime_Probs!C$2:C$100,ShipPlan!C:C,9-LeadTime_Probs!D$2:D$100))) | G35: =IF($B$1="EV",SUMIFS(ShipPlan!O:O,ShipPlan!E:E,$A35,ShipPlan!L:L,14),SUMPRODUCT((LeadTime_Probs!B$2:B$100=$A35)*LeadTime_Probs!E$2:E$100*SUMIFS(ShipPlan!O:O,ShipPlan!D:D,LeadTime_Probs!A$2:A$100,ShipPlan!E:E,LeadTime_Probs!B$2:B$100,ShipPlan!F:F,LeadTime_Probs!C$2:C$100,ShipPlan!C:C,14-LeadTime_Probs!D$2:D$100))) | H35: =IF($B$1="EV",SUMIFS(ShipPlan!O:O,ShipPlan!E:E,$A35,ShipPlan!L:L,15),SUMPRODUCT((LeadTime_Probs!B$2:B$100=$A35)*LeadTime_Probs!E$2:E$100*SUMIFS(ShipPlan!O:O,ShipPlan!D:D,LeadTime_Probs!A$2:A$100,ShipPlan!E:E,LeadTime_Probs!B$2:B$100,ShipPlan!F:F,LeadTime_Probs!C$2:C$100,ShipPlan!C:C,15-LeadTime_Probs!D$2:D$100))) | D35: =IF($B$1="EV",SUMIFS(ShipPlan!O:O,ShipPlan!E:E,$A35,ShipPlan!L:L,11),SUMPRODUCT((LeadTime_Probs!B$2:B$100=$A35)*LeadTime_Probs!E$2:E$100*SUMIFS(ShipPlan!O:O,ShipPlan!D:D,LeadTime_Probs!A$2:A$100,ShipPlan!E:E,LeadTime_Probs!B$2:B$100,ShipPlan!F:F,LeadTime_Probs!C$2:C$100,ShipPlan!C:C,11-LeadTime_Probs!D$2:D$100)))
A36: South | C36: =IF($B$1="EV",SUMIFS(ShipPlan!O:O,ShipPlan!E:E,$A36,ShipPlan!L:L,10),SUMPRODUCT((LeadTime_Probs!B$2:B$100=$A36)*LeadTime_Probs!E$2:E$100*SUMIFS(ShipPlan!O:O,ShipPlan!D:D,LeadTime_Probs!A$2:A$100,ShipPlan!E:E,LeadTime_Probs!B$2:B$100,ShipPlan!F:F,LeadTime_Probs!C$2:C$100,ShipPlan!C:C,10-LeadTime_Probs!D$2:D$100))) | E36: =IF($B$1="EV",SUMIFS(ShipPlan!O:O,ShipPlan!E:E,$A36,ShipPlan!L:L,12),SUMPRODUCT((LeadTime_Probs!B$2:B$100=$A36)*LeadTime_Probs!E$2:E$100*SUMIFS(ShipPlan!O:O,ShipPlan!D:D,LeadTime_Probs!A$2:A$100,ShipPlan!E:E,LeadTime_Probs!B$2:B$100,ShipPlan!F:F,LeadTime_Probs!C$2:C$100,ShipPlan!C:C,12-LeadTime_Probs!D$2:D$100))) | I36: =IF($B$1="EV",SUMIFS(ShipPlan!O:O,ShipPlan!E:E,$A36,ShipPlan!L:L,16),SUMPRODUCT((LeadTime_Probs!B$2:B$100=$A36)*LeadTime_Probs!E$2:E$100*SUMIFS(ShipPlan!O:O,ShipPlan!D:D,LeadTime_Probs!A$2:A$100,ShipPlan!E:E,LeadTime_Probs!B$2:B$100,ShipPlan!F:F,LeadTime_Probs!C$2:C$100,ShipPlan!C:C,16-LeadTime_Probs!D$2:D$100))) | F36: =IF($B$1="EV",SUMIFS(ShipPlan!O:O,ShipPlan!E:E,$A36,ShipPlan!L:L,13),SUMPRODUCT((LeadTime_Probs!B$2:B$100=$A36)*LeadTime_Probs!E$2:E$100*SUMIFS(ShipPlan!O:O,ShipPlan!D:D,LeadTime_Probs!A$2:A$100,ShipPlan!E:E,LeadTime_Probs!B$2:B$100,ShipPlan!F:F,LeadTime_Probs!C$2:C$100,ShipPlan!C:C,13-LeadTime_Probs!D$2:D$100))) | B36: =IF($B$1="EV",SUMIFS(ShipPlan!O:O,ShipPlan!E:E,$A36,ShipPlan!L:L,9),SUMPRODUCT((LeadTime_Probs!B$2:B$100=$A36)*LeadTime_Probs!E$2:E$100*SUMIFS(ShipPlan!O:O,ShipPlan!D:D,LeadTime_Probs!A$2:A$100,ShipPlan!E:E,LeadTime_Probs!B$2:B$100,ShipPlan!F:F,LeadTime_Probs!C$2:C$100,ShipPlan!C:C,9-LeadTime_Probs!D$2:D$100))) | G36: =IF($B$1="EV",SUMIFS(ShipPlan!O:O,ShipPlan!E:E,$A36,ShipPlan!L:L,14),SUMPRODUCT((LeadTime_Probs!B$2:B$100=$A36)*LeadTime_Probs!E$2:E$100*SUMIFS(ShipPlan!O:O,ShipPlan!D:D,LeadTime_Probs!A$2:A$100,ShipPlan!E:E,LeadTime_Probs!B$2:B$100,ShipPlan!F:F,LeadTime_Probs!C$2:C$100,ShipPlan!C:C,14-LeadTime_Probs!D$2:D$100))) | H36: =IF($B$1="EV",SUMIFS(ShipPlan!O:O,ShipPlan!E:E,$A36,ShipPlan!L:L,15),SUMPRODUCT((LeadTime_Probs!B$2:B$100=$A36)*LeadTime_Probs!E$2:E$100*SUMIFS(ShipPlan!O:O,ShipPlan!D:D,LeadTime_Probs!A$2:A$100,ShipPlan!E:E,LeadTime_Probs!B$2:B$100,ShipPlan!F:F,LeadTime_Probs!C$2:C$100,ShipPlan!C:C,15-LeadTime_Probs!D$2:D$100))) | D36: =IF($B$1="EV",SUMIFS(ShipPlan!O:O,ShipPlan!E:E,$A36,ShipPlan!L:L,11),SUMPRODUCT((LeadTime_Probs!B$2:B$100=$A36)*LeadTime_Probs!E$2:E$100*SUMIFS(ShipPlan!O:O,ShipPlan!D:D,LeadTime_Probs!A$2:A$100,ShipPlan!E:E,LeadTime_Probs!B$2:B$100,ShipPlan!F:F,LeadTime_Probs!C$2:C$100,ShipPlan!C:C,11-LeadTime_Probs!D$2:D$100)))

Sheet Warehouse_Capacity
A1: Region | B1: Modules_Rented | C1: Capacity_Units
A2: Center | B2: 48 | C2: =B2*Inputs_Global!$D$3 -> 4800
A3: West | B3: 25 | C3: =B3*Inputs_Global!$D$3 -> 2500
A4: North | B4: 20 | C4: =B4*Inputs_Global!$D$3 -> 2000
A5: East | B5: 0 | C5: =B5*Inputs_Global!$D$3 -> 0
A6: South | B6: 0 | C6: =B6*Inputs_Global!$D$3 -> 0

Sheet Inventory_Flow
A1: Region | B1: Fortnight | C1: Inv_Begin | D1: Prod_Out | E1: Arrivals | F1: Receipts | G1: Available | H1: Ship_Out_Planned | I1: Ship_Out_Fulfilled | J1: Post_Ship | K1: Demand | L1: Sales | M1: Lost_Sales | N1: Inv_End_PreCap | O1: Capacity | P1: Scrap | Q1: Inv_End_Effective
A2: Center | B2: 1 | C2: =Inputs_Global!G3 -> 2685 | D2: =SUMIFS(Production_Supply!C:C,Production_Supply!A:A,A2,Production_Supply!B:B,B2) -> 1500 | E2: =Arrivals!B24 -> 0 | F2: =D2+E2 -> 1500 | G2: =C2+F2 -> 4185 | H2: =SUMIFS(ShipPlan!G:G,ShipPlan!D:D,A2,ShipPlan!C:C,B2) -> 571 | I2: =SUMIFS(ShipPlan!O:O,ShipPlan!D:D,A2,ShipPlan!C:C,B2) -> 571 | J2: =G2-I2 -> 3614 | K2: =SUMIFS(Demand_Forecast!F:F,Demand_Forecast!A:A,A2,Demand_Forecast!B:B,B2) -> 0 | L2: =MIN(K2,J2) -> 0 | M2: =MAX(0,K2-J2) -> 0 | N2: =J2-L2 -> 3614 | O2: =Warehouse_Capacity!C2 -> 4800 | P2: =MAX(0,N2-O2) -> 0 | Q2: =N2-P2 -> 3614
A3: Center | B3: 2 | C3: =Q2 -> 3614 | D3: =SUMIFS(Production_Supply!C:C,Production_Supply!A:A,A3,Production_Supply!B:B,B3) -> 1500 | E3: =Arrivals!C24 -> 0 | F3: =D3+E3 -> 1500 | G3: =C3+F3 -> 5114 | H3: =SUMIFS(ShipPlan!G:G,ShipPlan!D:D,A3,ShipPlan!C:C,B3) -> 1025 | I3: =SUMIFS(ShipPlan!O:O,ShipPlan!D:D,A3,ShipPlan!C:C,B3) -> 1025 | J3: =G3-I3 -> 4089 | K3: =SUMIFS(Demand_Forecast!F:F,Demand_Forecast!A:A,A3,Demand_Forecast!B:B,B3) -> 2225 | L3: =MIN(K3,J3) -> 2225 | M3: =MAX(0,K3-J3) -> 0 | N3: =J3-L3 -> 1864 | O3: =Warehouse_Capacity!C2 -> 4800 | P3: =MAX(0,N3-O3) -> 0 | Q3: =N3-P3 -> 1864
A4: Center | B4: 3 | C4: =Q3 -> 1864 | D4: =SUMIFS(Production_Supply!C:C,Production_Supply!A:A,A4,Production_Supply!B:B,B4) -> 1500 | E4: =Arrivals!D24 -> 0 | F4: =D4+E4 -> 1500 | G4: =C4+F4 -> 3364 | H4: =SUMIFS(ShipPlan!G:G,ShipPlan!D:D,A4,ShipPlan!C:C,B4) -> 0 | I4: =SUMIFS(ShipPlan!O:O,ShipPlan!D:D,A4,ShipPlan!C:C,B4) -> 0 | J4: =G4-I4 -> 3364 | K4: =SUMIFS(Demand_Forecast!F:F,Demand_Forecast!A:A,A4,Demand_Forecast!B:B,B4) -> 0 | L4: =MIN(K4,J4) -> 0 | M4: =MAX(0,K4-J4) -> 0 | N4: =J4-L4 -> 3364 | O4: =Warehouse_Capacity!C2 -> 4800 | P4: =MAX(0,N4-O4) -> 0 | Q4: =N4-P4 -> 3364
A5: Center | B5: 4 | C5: =Q4 -> 3364 | D5: =SUMIFS(Production_Supply!C:C,Production_Supply!A:A,A5,Production_Supply!B:B,B5) -> 1500 | E5: =Arrivals!E24 -> 0 | F5: =D5+E5 -> 1500 | G5: =C5+F5 -> 4864 | H5: =SUMIFS(ShipPlan!G:G,ShipPlan!D:D,A5,ShipPlan!C:C,B5) -> 2681 | I5: =SUMIFS(ShipPlan!O:O,ShipPlan!D:D,A5,ShipPlan!C:C,B5) -> 2681 | J5: =G5-I5 -> 2183 | K5: =SUMIFS(Demand_Forecast!F:F,Demand_Forecast!A:A,A5,Demand_Forecast!B:B,B5) -> 2225 | L5: =MIN(K5,J5) -> 2183 | M5: =MAX(0,K5-J5) -> 42 | N5: =J5-L5 -> 0 | O5: =Warehouse_Capacity!C2 -> 4800 | P5: =MAX(0,N5-O5) -> 0 | Q5: =N5-P5 -> 0
A6: Center | B6: 5 | C6: =Q5 -> 0 | D6: =SUMIFS(Production_Supply!C:C,Production_Supply!A:A,A6,Production_Supply!B:B,B6) -> 1500 | E6: =Arrivals!F24 -> 0 | F6: =D6+E6 -> 1500 | G6: =C6+F6 -> 1500 | H6: =SUMIFS(ShipPlan!G:G,ShipPlan!D:D,A6,ShipPlan!C:C,B6) -> 0 | I6: =SUMIFS(ShipPlan!O:O,ShipPlan!D:D,A6,ShipPlan!C:C,B6) -> 0 | J6: =G6-I6 -> 1500 | K6: =SUMIFS(Demand_Forecast!F:F,Demand_Forecast!A:A,A6,Demand_Forecast!B:B,B6) -> 0 | L6: =MIN(K6,J6) -> 0 | M6: =MAX(0,K6-J6) -> 0 | N6: =J6-L6 -> 1500 | O6: =Warehouse_Capacity!C2 -> 4800 | P6: =MAX(0,N6-O6) -> 0 | Q6: =N6-P6 -> 1500
A7: Center | B7: 6 | C7: =Q6 -> 1500 | D7: =SUMIFS(Production_Supply!C:C,Production_Supply!A:A,A7,Production_Supply!B:B,B7) -> 1500 | E7: =Arrivals!G24 -> 0 | F7: =D7+E7 -> 1500 | G7: =C7+F7 -> 3000 | H7: =SUMIFS(ShipPlan!G:G,ShipPlan!D:D,A7,ShipPlan!C:C,B7) -> 0 | I7: =SUMIFS(ShipPlan!O:O,ShipPlan!D:D,A7,ShipPlan!C:C,B7) -> 0 | J7: =G7-I7 -> 3000 | K7: =SUMIFS(Demand_Forecast!F:F,Demand_Forecast!A:A,A7,Demand_Forecast!B:B,B7) -> 2225 | L7: =MIN(K7,J7) -> 2225 | M7: =MAX(0,K7-J7) -> 0 | N7: =J7-L7 -> 775 | O7: =Warehouse_Capacity!C2 -> 4800 | P7: =MAX(0,N7-O7) -> 0 | Q7: =N7-P7 -> 775
A8: Center | B8: 7 | C8: =Q7 -> 775 | D8: =SUMIFS(Production_Supply!C:C,Production_Supply!A:A,A8,Production_Supply!B:B,B8) -> 1500 | E8: =Arrivals!H24 -> 0 | F8: =D8+E8 -> 1500 | G8: =C8+F8 -> 2275 | H8: =SUMIFS(ShipPlan!G:G,ShipPlan!D:D,A8,ShipPlan!C:C,B8) -> 0 | I8: =SUMIFS(ShipPlan!O:O,ShipPlan!D:D,A8,ShipPlan!C:C,B8) -> 0 | J8: =G8-I8 -> 2275 | K8: =SUMIFS(Demand_Forecast!F:F,Demand_Forecast!A:A,A8,Demand_Forecast!B:B,B8) -> 0 | L8: =MIN(K8,J8) -> 0 | M8: =MAX(0,K8-J8) -> 0 | N8: =J8-L8 -> 2275 | O8: =Warehouse_Capacity!C2 -> 4800 | P8: =MAX(0,N8-O8) -> 0 | Q8: =N8-P8 -> 2275
A9: Center | B9: 8 | C9: =Q8 -> 2275 | D9: =SUMIFS(Production_Supply!C:C,Production_Supply!A:A,A9,Production_Supply!B:B,B9) -> 1500 | E9: =Arrivals!I24 -> 0 | F9: =D9+E9 -> 1500 | G9: =C9+F9 -> 3775 | H9: =SUMIFS(ShipPlan!G:G,ShipPlan!D:D,A9,ShipPlan!C:C,B9) -> 0 | I9: =SUMIFS(ShipPlan!O:O,ShipPlan!D:D,A9,ShipPlan!C:C,B9) -> 0 | J9: =G9-I9 -> 3775 | K9: =SUMIFS(Demand_Forecast!F:F,Demand_Forecast!A:A,A9,Demand_Forecast!B:B,B9) -> 2225 | L9: =MIN(K9,J9) -> 2225 | M9: =MAX(0,K9-J9) -> 0 | N9: =J9-L9 -> 1550 | O9: =Warehouse_Capacity!C2 -> 4800 | P9: =MAX(0,N9-O9) -> 0 | Q9: =N9-P9 -> 1550
A10: West | B10: 1 | C10: =Inputs_Global!G4 -> 1299 | D10: =SUMIFS(Production_Supply!C:C,Production_Supply!A:A,A10,Production_Supply!B:B,B10) -> 350 | E10: =Arrivals!B25 -> 0 | F10: =D10+E10 -> 350 | G10: =C10+F10 -> 1649 | H10: =SUMIFS(ShipPlan!G:G,ShipPlan!D:D,A10,ShipPlan!C:C,B10) -> 0 | I10: =SUMIFS(ShipPlan!O:O,ShipPlan!D:D,A10,ShipPlan!C:C,B10) -> 0 | J10: =G10-I10 -> 1649 | K10: =SUMIFS(Demand_Forecast!F:F,Demand_Forecast!A:A,A10,Demand_Forecast!B:B,B10) -> 0 | L10: =MIN(K10,J10) -> 0 | M10: =MAX(0,K10-J10) -> 0 | N10: =J10-L10 -> 1649 | O10: =Warehouse_Capacity!C3 -> 2500 | P10: =MAX(0,N10-O10) -> 0 | Q10: =N10-P10 -> 1649
A11: West | B11: 2 | C11: =Q10 -> 1649 | D11: =SUMIFS(Production_Supply!C:C,Production_Supply!A:A,A11,Production_Supply!B:B,B11) -> 350 | E11: =Arrivals!C25 -> 0 | F11: =D11+E11 -> 350 | G11: =C11+F11 -> 1999 | H11: =SUMIFS(ShipPlan!G:G,ShipPlan!D:D,A11,ShipPlan!C:C,B11) -> 0 | I11: =SUMIFS(ShipPlan!O:O,ShipPlan!D:D,A11,ShipPlan!C:C,B11) -> 0 | J11: =G11-I11 -> 1999 | K11: =SUMIFS(Demand_Forecast!F:F,Demand_Forecast!A:A,A11,Demand_Forecast!B:B,B11) -> 1007 | L11: =MIN(K11,J11) -> 1007 | M11: =MAX(0,K11-J11) -> 0 | N11: =J11-L11 -> 992 | O11: =Warehouse_Capacity!C3 -> 2500 | P11: =MAX(0,N11-O11) -> 0 | Q11: =N11-P11 -> 992
A12: West | B12: 3 | C12: =Q11 -> 992 | D12: =SUMIFS(Production_Supply!C:C,Production_Supply!A:A,A12,Production_Supply!B:B,B12) -> 350 | E12: =Arrivals!D25 -> 0 | F12: =D12+E12 -> 350 | G12: =C12+F12 -> 1342 | H12: =SUMIFS(ShipPlan!G:G,ShipPlan!D:D,A12,ShipPlan!C:C,B12) -> 0 | I12: =SUMIFS(ShipPlan!O:O,ShipPlan!D:D,A12,ShipPlan!C:C,B12) -> 0 | J12: =G12-I12 -> 1342 | K12: =SUMIFS(Demand_Forecast!F:F,Demand_Forecast!A:A,A12,Demand_Forecast!B:B,B12) -> 0 | L12: =MIN(K12,J12) -> 0 | M12: =MAX(0,K12-J12) -> 0 | N12: =J12-L12 -> 1342 | O12: =Warehouse_Capacity!C3 -> 2500 | P12: =MAX(0,N12-O12) -> 0 | Q12: =N12-P12 -> 1342
A13: West | B13: 4 | C13: =Q12 -> 1342 | D13: =SUMIFS(Production_Supply!C:C,Production_Supply!A:A,A13,Production_Supply!B:B,B13) -> 350 | E13: =Arrivals!E25 -> 571 | F13: =D13+E13 -> 921 | G13: =C13+F13 -> 2263 | H13: =SUMIFS(ShipPlan!G:G,ShipPlan!D:D,A13,ShipPlan!C:C,B13) -> 0 | I13: =SUMIFS(ShipPlan!O:O,ShipPlan!D:D,A13,ShipPlan!C:C,B13) -> 0 | J13: =G13-I13 -> 2263 | K13: =SUMIFS(Demand_Forecast!F:F,Demand_Forecast!A:A,A13,Demand_Forecast!B:B,B13) -> 1007 | L13: =MIN(K13,J13) -> 1007 | M13: =MAX(0,K13-J13) -> 0 | N13: =J13-L13 -> 1256 | O13: =Warehouse_Capacity!C3 -> 2500 | P13: =MAX(0,N13-O13) -> 0 | Q13: =N13-P13 -> 1256
A14: West | B14: 5 | C14: =Q13 -> 1256 | D14: =SUMIFS(Production_Supply!C:C,Production_Supply!A:A,A14,Production_Supply!B:B,B14) -> 350 | E14: =Arrivals!F25 -> 0 | F14: =D14+E14 -> 350 | G14: =C14+F14 -> 1606 | H14: =SUMIFS(ShipPlan!G:G,ShipPlan!D:D,A14,ShipPlan!C:C,B14) -> 0 | I14: =SUMIFS(ShipPlan!O:O,ShipPlan!D:D,A14,ShipPlan!C:C,B14) -> 0 | J14: =G14-I14 -> 1606 | K14: =SUMIFS(Demand_Forecast!F:F,Demand_Forecast!A:A,A14,Demand_Forecast!B:B,B14) -> 0 | L14: =MIN(K14,J14) -> 0 | M14: =MAX(0,K14-J14) -> 0 | N14: =J14-L14 -> 1606 | O14: =Warehouse_Capacity!C3 -> 2500 | P14: =MAX(0,N14-O14) -> 0 | Q14: =N14-P14 -> 1606
A15: West | B15: 6 | C15: =Q14 -> 1606 | D15: =SUMIFS(Production_Supply!C:C,Production_Supply!A:A,A15,Production_Supply!B:B,B15) -> 350 | E15: =Arrivals!G25 -> 0 | F15: =D15+E15 -> 350 | G15: =C15+F15 -> 1956 | H15: =SUMIFS(ShipPlan!G:G,ShipPlan!D:D,A15,ShipPlan!C:C,B15) -> 0 | I15: =SUMIFS(ShipPlan!O:O,ShipPlan!D:D,A15,ShipPlan!C:C,B15) -> 0 | J15: =G15-I15 -> 1956 | K15: =SUMIFS(Demand_Forecast!F:F,Demand_Forecast!A:A,A15,Demand_Forecast!B:B,B15) -> 1007 | L15: =MIN(K15,J15) -> 1007 | M15: =MAX(0,K15-J15) -> 0 | N15: =J15-L15 -> 949 | O15: =Warehouse_Capacity!C3 -> 2500 | P15: =MAX(0,N15-O15) -> 0 | Q15: =N15-P15 -> 949
A16: West | B16: 7 | C16: =Q15 -> 949 | D16: =SUMIFS(Production_Supply!C:C,Production_Supply!A:A,A16,Production_Supply!B:B,B16) -> 350 | E16: =Arrivals!H25 -> 0 | F16: =D16+E16 -> 350 | G16: =C16+F16 -> 1299 | H16: =SUMIFS(ShipPlan!G:G,ShipPlan!D:D,A16,ShipPlan!C:C,B16) -> 0 | I16: =SUMIFS(ShipPlan!O:O,ShipPlan!D:D,A16,ShipPlan!C:C,B16) -> 0 | J16: =G16-I16 -> 1299 | K16: =SUMIFS(Demand_Forecast!F:F,Demand_Forecast!A:A,A16,Demand_Forecast!B:B,B16) -> 0 | L16: =MIN(K16,J16) -> 0 | M16: =MAX(0,K16-J16) -> 0 | N16: =J16-L16 -> 1299 | O16: =Warehouse_Capacity!C3 -> 2500 | P16: =MAX(0,N16-O16) -> 0 | Q16: =N16-P16 -> 1299
A17: West | B17: 8 | C17: =Q16 -> 1299 | D17: =SUMIFS(Production_Supply!C:C,Production_Supply!A:A,A17,Production_Supply!B:B,B17) -> 350 | E17: =Arrivals!I25 -> 0 | F17: =D17+E17 -> 350 | G17: =C17+F17 -> 1649 | H17: =SUMIFS(ShipPlan!G:G,ShipPlan!D:D,A17,ShipPlan!C:C,B17) -> 0 | I17: =SUMIFS(ShipPlan!O:O,ShipPlan!D:D,A17,ShipPlan!C:C,B17) -> 0 | J17: =G17-I17 -> 1649 | K17: =SUMIFS(Demand_Forecast!F:F,Demand_Forecast!A:A,A17,Demand_Forecast!B:B,B17) -> 1007 | L17: =MIN(K17,J17) -> 1007 | M17: =MAX(0,K17-J17) -> 0 | N17: =J17-L17 -> 642 | O17: =Warehouse_Capacity!C3 -> 2500 | P17: =MAX(0,N17-O17) -> 0 | Q17: =N17-P17 -> 642
A18: North | B18: 1 | C18: =Inputs_Global!G5 -> 620 | D18: =SUMIFS(Production_Supply!C:C,Production_Supply!A:A,A18,Production_Supply!B:B,B18) -> 0 | E18: =Arrivals!B26 -> 0 | F18: =D18+E18 -> 0 | G18: =C18+F18 -> 620 | H18: =SUMIFS(ShipPlan!G:G,ShipPlan!D:D,A18,ShipPlan!C:C,B18) -> 0 | I18: =SUMIFS(ShipPlan!O:O,ShipPlan!D:D,A18,ShipPlan!C:C,B18) -> 0 | J18: =G18-I18 -> 620 | K18: =SUMIFS(Demand_Forecast!F:F,Demand_Forecast!A:A,A18,Demand_Forecast!B:B,B18) -> 0 | L18: =MIN(K18,J18) -> 0 | M18: =MAX(0,K18-J18) -> 0 | N18: =J18-L18 -> 620 | O18: =Warehouse_Capacity!C4 -> 2000 | P18: =MAX(0,N18-O18) -> 0 | Q18: =N18-P18 -> 620
A19: North | B19: 2 | C19: =Q18 -> 620 | D19: =SUMIFS(Production_Supply!C:C,Production_Supply!A:A,A19,Production_Supply!B:B,B19) -> 0 | E19: =Arrivals!C26 -> 0 | F19: =D19+E19 -> 0 | G19: =C19+F19 -> 620 | H19: =SUMIFS(ShipPlan!G:G,ShipPlan!D:D,A19,ShipPlan!C:C,B19) -> 0 | I19: =SUMIFS(ShipPlan!O:O,ShipPlan!D:D,A19,ShipPlan!C:C,B19) -> 0 | J19: =G19-I19 -> 620 | K19: =SUMIFS(Demand_Forecast!F:F,Demand_Forecast!A:A,A19,Demand_Forecast!B:B,B19) -> 1100 | L19: =MIN(K19,J19) -> 620 | M19: =MAX(0,K19-J19) -> 480 | N19: =J19-L19 -> 0 | O19: =Warehouse_Capacity!C4 -> 2000 | P19: =MAX(0,N19-O19) -> 0 | Q19: =N19-P19 -> 0
A20: North | B20: 3 | C20: =Q19 -> 0 | D20: =SUMIFS(Production_Supply!C:C,Production_Supply!A:A,A20,Production_Supply!B:B,B20) -> 0 | E20: =Arrivals!D26 -> 0 | F20: =D20+E20 -> 0 | G20: =C20+F20 -> 0 | H20: =SUMIFS(ShipPlan!G:G,ShipPlan!D:D,A20,ShipPlan!C:C,B20) -> 0 | I20: =SUMIFS(ShipPlan!O:O,ShipPlan!D:D,A20,ShipPlan!C:C,B20) -> 0 | J20: =G20-I20 -> 0 | K20: =SUMIFS(Demand_Forecast!F:F,Demand_Forecast!A:A,A20,Demand_Forecast!B:B,B20) -> 0 | L20: =MIN(K20,J20) -> 0 | M20: =MAX(0,K20-J20) -> 0 | N20: =J20-L20 -> 0 | O20: =Warehouse_Capacity!C4 -> 2000 | P20: =MAX(0,N20-O20) -> 0 | Q20: =N20-P20 -> 0
A21: North | B21: 4 | C21: =Q20 -> 0 | D21: =SUMIFS(Production_Supply!C:C,Production_Supply!A:A,A21,Production_Supply!B:B,B21) -> 0 | E21: =Arrivals!E26 -> 0 | F21: =D21+E21 -> 0 | G21: =C21+F21 -> 0 | H21: =SUMIFS(ShipPlan!G:G,ShipPlan!D:D,A21,ShipPlan!C:C,B21) -> 0 | I21: =SUMIFS(ShipPlan!O:O,ShipPlan!D:D,A21,ShipPlan!C:C,B21) -> 0 | J21: =G21-I21 -> 0 | K21: =SUMIFS(Demand_Forecast!F:F,Demand_Forecast!A:A,A21,Demand_Forecast!B:B,B21) -> 1100 | L21: =MIN(K21,J21) -> 0 | M21: =MAX(0,K21-J21) -> 1100 | N21: =J21-L21 -> 0 | O21: =Warehouse_Capacity!C4 -> 2000 | P21: =MAX(0,N21-O21) -> 0 | Q21: =N21-P21 -> 0
A22: North | B22: 5 | C22: =Q21 -> 0 | D22: =SUMIFS(Production_Supply!C:C,Production_Supply!A:A,A22,Production_Supply!B:B,B22) -> 0 | E22: =Arrivals!F26 -> 0 | F22: =D22+E22 -> 0 | G22: =C22+F22 -> 0 | H22: =SUMIFS(ShipPlan!G:G,ShipPlan!D:D,A22,ShipPlan!C:C,B22) -> 0 | I22: =SUMIFS(ShipPlan!O:O,ShipPlan!D:D,A22,ShipPlan!C:C,B22) -> 0 | J22: =G22-I22 -> 0 | K22: =SUMIFS(Demand_Forecast!F:F,Demand_Forecast!A:A,A22,Demand_Forecast!B:B,B22) -> 0 | L22: =MIN(K22,J22) -> 0 | M22: =MAX(0,K22-J22) -> 0 | N22: =J22-L22 -> 0 | O22: =Warehouse_Capacity!C4 -> 2000 | P22: =MAX(0,N22-O22) -> 0 | Q22: =N22-P22 -> 0
A23: North | B23: 6 | C23: =Q22 -> 0 | D23: =SUMIFS(Production_Supply!C:C,Production_Supply!A:A,A23,Production_Supply!B:B,B23) -> 0 | E23: =Arrivals!G26 -> 1025 | F23: =D23+E23 -> 1025 | G23: =C23+F23 -> 1025 | H23: =SUMIFS(ShipPlan!G:G,ShipPlan!D:D,A23,ShipPlan!C:C,B23) -> 0 | I23: =SUMIFS(ShipPlan!O:O,ShipPlan!D:D,A23,ShipPlan!C:C,B23) -> 0 | J23: =G23-I23 -> 1025 | K23: =SUMIFS(Demand_Forecast!F:F,Demand_Forecast!A:A,A23,Demand_Forecast!B:B,B23) -> 1100 | L23: =MIN(K23,J23) -> 1025 | M23: =MAX(0,K23-J23) -> 75 | N23: =J23-L23 -> 0 | O23: =Warehouse_Capacity!C4 -> 2000 | P23: =MAX(0,N23-O23) -> 0 | Q23: =N23-P23 -> 0
A24: North | B24: 7 | C24: =Q23 -> 0 | D24: =SUMIFS(Production_Supply!C:C,Production_Supply!A:A,A24,Production_Supply!B:B,B24) -> 0 | E24: =Arrivals!H26 -> 0 | F24: =D24+E24 -> 0 | G24: =C24+F24 -> 0 | H24: =SUMIFS(ShipPlan!G:G,ShipPlan!D:D,A24,ShipPlan!C:C,B24) -> 0 | I24: =SUMIFS(ShipPlan!O:O,ShipPlan!D:D,A24,ShipPlan!C:C,B24) -> 0 | J24: =G24-I24 -> 0 | K24: =SUMIFS(Demand_Forecast!F:F,Demand_Forecast!A:A,A24,Demand_Forecast!B:B,B24) -> 0 | L24: =MIN(K24,J24) -> 0 | M24: =MAX(0,K24-J24) -> 0 | N24: =J24-L24 -> 0 | O24: =Warehouse_Capacity!C4 -> 2000 | P24: =MAX(0,N24-O24) -> 0 | Q24: =N24-P24 -> 0
A25: North | B25: 8 | C25: =Q24 -> 0 | D25: =SUMIFS(Production_Supply!C:C,Production_Supply!A:A,A25,Production_Supply!B:B,B25) -> 0 | E25: =Arrivals!I26 -> 2681 | F25: =D25+E25 -> 2681 | G25: =C25+F25 -> 2681 | H25: =SUMIFS(ShipPlan!G:G,ShipPlan!D:D,A25,ShipPlan!C:C,B25) -> 0 | I25: =SUMIFS(ShipPlan!O:O,ShipPlan!D:D,A25,ShipPlan!C:C,B25) -> 0 | J25: =G25-I25 -> 2681 | K25: =SUMIFS(Demand_Forecast!F:F,Demand_Forecast!A:A,A25,Demand_Forecast!B:B,B25) -> 1100 | L25: =MIN(K25,J25) -> 1100 | M25: =MAX(0,K25-J25) -> 0 | N25: =J25-L25 -> 1581 | O25: =Warehouse_Capacity!C4 -> 2000 | P25: =MAX(0,N25-O25) -> 0 | Q25: =N25-P25 -> 1581
A26: East | B26: 1 | C26: =Inputs_Global!G6 -> 0 | D26: =SUMIFS(Production_Supply!C:C,Production_Supply!A:A,A26,Production_Supply!B:B,B26) -> 0 | E26: =Arrivals!B27 -> 0 | F26: =D26+E26 -> 0 | G26: =C26+F26 -> 0 | H26: =SUMIFS(ShipPlan!G:G,ShipPlan!D:D,A26,ShipPlan!C:C,B26) -> 0 | I26: =SUMIFS(ShipPlan!O:O,ShipPlan!D:D,A26,ShipPlan!C:C,B26) -> 0 | J26: =G26-I26 -> 0 | K26: =SUMIFS(Demand_Forecast!F:F,Demand_Forecast!A:A,A26,Demand_Forecast!B:B,B26) -> 0 | L26: =MIN(K26,J26) -> 0 | M26: =MAX(0,K26-J26) -> 0 | N26: =J26-L26 -> 0 | O26: =Warehouse_Capacity!C5 -> 0 | P26: =MAX(0,N26-O26) -> 0 | Q26: =N26-P26 -> 0
A27: East | B27: 2 | C27: =Q26 -> 0 | D27: =SUMIFS(Production_Supply!C:C,Production_Supply!A:A,A27,Production_Supply!B:B,B27) -> 0 | E27: =Arrivals!C27 -> 0 | F27: =D27+E27 -> 0 | G27: =C27+F27 -> 0 | H27: =SUMIFS(ShipPlan!G:G,ShipPlan!D:D,A27,ShipPlan!C:C,B27) -> 0 | I27: =SUMIFS(ShipPlan!O:O,ShipPlan!D:D,A27,ShipPlan!C:C,B27) -> 0 | J27: =G27-I27 -> 0 | K27: =SUMIFS(Demand_Forecast!F:F,Demand_Forecast!A:A,A27,Demand_Forecast!B:B,B27) -> 0 | L27: =MIN(K27,J27) -> 0 | M27: =MAX(0,K27-J27) -> 0 | N27: =J27-L27 -> 0 | O27: =Warehouse_Capacity!C5 -> 0 | P27: =MAX(0,N27-O27) -> 0 | Q27: =N27-P27 -> 0
A28: East | B28: 3 | C28: =Q27 -> 0 | D28: =SUMIFS(Production_Supply!C:C,Production_Supply!A:A,A28,Production_Supply!B:B,B28) -> 0 | E28: =Arrivals!D27 -> 0 | F28: =D28+E28 -> 0 | G28: =C28+F28 -> 0 | H28: =SUMIFS(ShipPlan!G:G,ShipPlan!D:D,A28,ShipPlan!C:C,B28) -> 0 | I28: =SUMIFS(ShipPlan!O:O,ShipPlan!D:D,A28,ShipPlan!C:C,B28) -> 0 | J28: =G28-I28 -> 0 | K28: =SUMIFS(Demand_Forecast!F:F,Demand_Forecast!A:A,A28,Demand_Forecast!B:B,B28) -> 0 | L28: =MIN(K28,J28) -> 0 | M28: =MAX(0,K28-J28) -> 0 | N28: =J28-L28 -> 0 | O28: =Warehouse_Capacity!C5 -> 0 | P28: =MAX(0,N28-O28) -> 0 | Q28: =N28-P28 -> 0
A29: East | B29: 4 | C29: =Q28 -> 0 | D29: =SUMIFS(Production_Supply!C:C,Production_Supply!A:A,A29,Production_Supply!B:B,B29) -> 0 | E29: =Arrivals!E27 -> 0 | F29: =D29+E29 -> 0 | G29: =C29+F29 -> 0 | H29: =SUMIFS(ShipPlan!G:G,ShipPlan!D:D,A29,ShipPlan!C:C,B29) -> 0 | I29: =SUMIFS(ShipPlan!O:O,ShipPlan!D:D,A29,ShipPlan!C:C,B29) -> 0 | J29: =G29-I29 -> 0 | K29: =SUMIFS(Demand_Forecast!F:F,Demand_Forecast!A:A,A29,Demand_Forecast!B:B,B29) -> 0 | L29: =MIN(K29,J29) -> 0 | M29: =MAX(0,K29-J29) -> 0 | N29: =J29-L29 -> 0 | O29: =Warehouse_Capacity!C5 -> 0 | P29: =MAX(0,N29-O29) -> 0 | Q29: =N29-P29 -> 0
A30: East | B30: 5 | C30: =Q29 -> 0 | D30: =SUMIFS(Production_Supply!C:C,Production_Supply!A:A,A30,Production_Supply!B:B,B30) -> 0 | E30: =Arrivals!F27 -> 0 | F30: =D30+E30 -> 0 | G30: =C30+F30 -> 0 | H30: =SUMIFS(ShipPlan!G:G,ShipPlan!D:D,A30,ShipPlan!C:C,B30) -> 0 | I30: =SUMIFS(ShipPlan!O:O,ShipPlan!D:D,A30,ShipPlan!C:C,B30) -> 0 | J30: =G30-I30 -> 0 | K30: =SUMIFS(Demand_Forecast!F:F,Demand_Forecast!A:A,A30,Demand_Forecast!B:B,B30) -> 0 | L30: =MIN(K30,J30) -> 0 | M30: =MAX(0,K30-J30) -> 0 | N30: =J30-L30 -> 0 | O30: =Warehouse_Capacity!C5 -> 0 | P30: =MAX(0,N30-O30) -> 0 | Q30: =N30-P30 -> 0
A31: East | B31: 6 | C31: =Q30 -> 0 | D31: =SUMIFS(Production_Supply!C:C,Production_Supply!A:A,A31,Production_Supply!B:B,B31) -> 0 | E31: =Arrivals!G27 -> 0 | F31: =D31+E31 -> 0 | G31: =C31+F31 -> 0 | H31: =SUMIFS(ShipPlan!G:G,ShipPlan!D:D,A31,ShipPlan!C:C,B31) -> 0 | I31: =SUMIFS(ShipPlan!O:O,ShipPlan!D:D,A31,ShipPlan!C:C,B31) -> 0 | J31: =G31-I31 -> 0 | K31: =SUMIFS(Demand_Forecast!F:F,Demand_Forecast!A:A,A31,Demand_Forecast!B:B,B31) -> 0 | L31: =MIN(K31,J31) -> 0 | M31: =MAX(0,K31-J31) -> 0 | N31: =J31-L31 -> 0 | O31: =Warehouse_Capacity!C5 -> 0 | P31: =MAX(0,N31-O31) -> 0 | Q31: =N31-P31 -> 0
A32: East | B32: 7 | C32: =Q31 -> 0 | D32: =SUMIFS(Production_Supply!C:C,Production_Supply!A:A,A32,Production_Supply!B:B,B32) -> 0 | E32: =Arrivals!H27 -> 0 | F32: =D32+E32 -> 0 | G32: =C32+F32 -> 0 | H32: =SUMIFS(ShipPlan!G:G,ShipPlan!D:D,A32,ShipPlan!C:C,B32) -> 0 | I32: =SUMIFS(ShipPlan!O:O,ShipPlan!D:D,A32,ShipPlan!C:C,B32) -> 0 | J32: =G32-I32 -> 0 | K32: =SUMIFS(Demand_Forecast!F:F,Demand_Forecast!A:A,A32,Demand_Forecast!B:B,B32) -> 0 | L32: =MIN(K32,J32) -> 0 | M32: =MAX(0,K32-J32) -> 0 | N32: =J32-L32 -> 0 | O32: =Warehouse_Capacity!C5 -> 0 | P32: =MAX(0,N32-O32) -> 0 | Q32: =N32-P32 -> 0
A33: East | B33: 8 | C33: =Q32 -> 0 | D33: =SUMIFS(Production_Supply!C:C,Production_Supply!A:A,A33,Production_Supply!B:B,B33) -> 0 | E33: =Arrivals!I27 -> 0 | F33: =D33+E33 -> 0 | G33: =C33+F33 -> 0 | H33: =SUMIFS(ShipPlan!G:G,ShipPlan!D:D,A33,ShipPlan!C:C,B33) -> 0 | I33: =SUMIFS(ShipPlan!O:O,ShipPlan!D:D,A33,ShipPlan!C:C,B33) -> 0 | J33: =G33-I33 -> 0 | K33: =SUMIFS(Demand_Forecast!F:F,Demand_Forecast!A:A,A33,Demand_Forecast!B:B,B33) -> 0 | L33: =MIN(K33,J33) -> 0 | M33: =MAX(0,K33-J33) -> 0 | N33: =J33-L33 -> 0 | O33: =Warehouse_Capacity!C5 -> 0 | P33: =MAX(0,N33-O33) -> 0 | Q33: =N33-P33 -> 0
A34: South | B34: 1 | C34: =Inputs_Global!G7 -> 0 | D34: =SUMIFS(Production_Supply!C:C,Production_Supply!A:A,A34,Production_Supply!B:B,B34) -> 0 | E34: =Arrivals!B28 -> 0 | F34: =D34+E34 -> 0 | G34: =C34+F34 -> 0 | H34: =SUMIFS(ShipPlan!G:G,ShipPlan!D:D,A34,ShipPlan!C:C,B34) -> 0 | I34: =SUMIFS(ShipPlan!O:O,ShipPlan!D:D,A34,ShipPlan!C:C,B34) -> 0 | J34: =G34-I34 -> 0 | K34: =SUMIFS(Demand_Forecast!F:F,Demand_Forecast!A:A,A34,Demand_Forecast!B:B,B34) -> 0 | L34: =MIN(K34,J34) -> 0 | M34: =MAX(0,K34-J34) -> 0 | N34: =J34-L34 -> 0 | O34: =Warehouse_Capacity!C6 -> 0 | P34: =MAX(0,N34-O34) -> 0 | Q34: =N34-P34 -> 0
A35: South | B35: 2 | C35: =Q34 -> 0 | D35: =SUMIFS(Production_Supply!C:C,Production_Supply!A:A,A35,Production_Supply!B:B,B35) -> 0 | E35: =Arrivals!C28 -> 0 | F35: =D35+E35 -> 0 | G35: =C35+F35 -> 0 | H35: =SUMIFS(ShipPlan!G:G,ShipPlan!D:D,A35,ShipPlan!C:C,B35) -> 0 | I35: =SUMIFS(ShipPlan!O:O,ShipPlan!D:D,A35,ShipPlan!C:C,B35) -> 0 | J35: =G35-I35 -> 0 | K35: =SUMIFS(Demand_Forecast!F:F,Demand_Forecast!A:A,A35,Demand_Forecast!B:B,B35) -> 0 | L35: =MIN(K35,J35) -> 0 | M35: =MAX(0,K35-J35) -> 0 | N35: =J35-L35 -> 0 | O35: =Warehouse_Capacity!C6 -> 0 | P35: =MAX(0,N35-O35) -> 0 | Q35: =N35-P35 -> 0
A36: South | B36: 3 | C36: =Q35 -> 0 | D36: =SUMIFS(Production_Supply!C:C,Production_Supply!A:A,A36,Production_Supply!B:B,B36) -> 0 | E36: =Arrivals!D28 -> 0 | F36: =D36+E36 -> 0 | G36: =C36+F36 -> 0 | H36: =SUMIFS(ShipPlan!G:G,ShipPlan!D:D,A36,ShipPlan!C:C,B36) -> 0 | I36: =SUMIFS(ShipPlan!O:O,ShipPlan!D:D,A36,ShipPlan!C:C,B36) -> 0 | J36: =G36-I36 -> 0 | K36: =SUMIFS(Demand_Forecast!F:F,Demand_Forecast!A:A,A36,Demand_Forecast!B:B,B36) -> 0 | L36: =MIN(K36,J36) -> 0 | M36: =MAX(0,K36-J36) -> 0 | N36: =J36-L36 -> 0 | O36: =Warehouse_Capacity!C6 -> 0 | P36: =MAX(0,N36-O36) -> 0 | Q36: =N36-P36 -> 0
