Workbook

Sheet Inputs
A1: INPUTS - PURCHASING MANAGER
A2: Solo inputs manuales. AZUL = modificar según tu estrategia. Sin fórmulas en esta hoja.
A4: 1. PRODUCCIÓN PLANEADA POR QUINCENA (Assembly A)
A5: Quincena → | B5: Q1 | C5: Q2 | D5: Q3 | E5: Q4 | F5: Q5 | G5: Q6 | H5: Q7 | I5: Q8 | J5: TOTAL
A6: Producción EC Planta Central | B6: 1850 | C6: 1850 | D6: 1850 | E6: 1850 | F6: 1850 | G6: 1850 | H6: 1850 | I6: 1850 | J6: =SUM(B6:I6) -> 14800
A7: Producción EC Planta West | B7: 1850 | C7: 1850 | D7: 1850 | E7: 1850 | F7: 1850 | G7: 1850 | H7: 1850 | I7: 1850 | J7: =SUM(B7:I7) -> 14800
A8: Producción EC Planta East | B8: 0 | C8: 0 | D8: 0 | E8: 0 | F8: 0 | G8: 0 | H8: 0 | I8: 0 | J8: =SUM(B8:I8) -> 0
A9: Producción EC Planta North | B9: 0 | C9: 0 | D9: 0 | E9: 0 | F9: 0 | G9: 0 | H9: 0 | I9: 0 | J9: =SUM(B9:I9) -> 0
A10: Producción EC Planta South | B10: 0 | C10: 0 | D10: 0 | E10: 0 | F10: 0 | G10: 0 | H10: 0 | I10: 0 | J10: =SUM(B10:I10) -> 0
A11: Total | B11: =+SUM(B6:B10) -> 3700 | C11: =+SUM(C6:C10) -> 3700 | D11: =+SUM(D6:D10) -> 3700 | E11: =+SUM(E6:E10) -> 3700 | F11: =+SUM(F6:F10) -> 3700 | G11: =+SUM(G6:G10) -> 3700 | H11: =+SUM(H6:H10) -> 3700 | I11: =+SUM(I6:I10) -> 3700 | J11: =+SUM(J6:J10) -> 29600
A13: 1. PRODUCCIÓN PLANEADA POR QUINCENA (Assembly B)
A14: Quincena → | B14: Q1 | C14: Q2 | D14: Q3 | E14: Q4 | F14: Q5 | G14: Q6 | H14: Q7 | I14: Q8 | J14: TOTAL
A15: Producción EC Planta Central | B15: 1850 | C15: 1850 | D15: 1850 | E15: 1850 | F15: 1850 | G15: 1850 | H15: 1850 | I15: 1850 | J15: =SUM(B15:I15) -> 14800
A16: Producción EC Planta West | B16: 1850 | C16: 1850 | D16: 1850 | E16: 1850 | F16: 1850 | G16: 1850 | H16: 1850 | I16: 1850 | J16: =SUM(B16:I16) -> 14800
A17: Producción EC Planta East | B17: 0 | C17: 0 | D17: 0 | E17: 0 | F17: 0 | G17: 0 | H17: 0 | I17: 0 | J17: =SUM(B17:I17) -> 0
A18: Producción EC Planta North | B18: 0 | C18: 0 | D18: 0 | E18: 0 | F18: 0 | G18: 0 | H18: 0 | I18: 0 | J18: =SUM(B18:I18) -> 0
A19: Producción EC Planta South | B19: 0 | C19: 0 | D19: 0 | E19: 0 | F19: 0 | G19: 0 | H19: 0 | I19: 0 | J19: =SUM(B19:I19) -> 0
A20: Total | B20: =+SUM(B15:B19) -> 3700 | C20: =+SUM(C15:C19) -> 3700 | D20: =+SUM(D15:D19) -> 3700 | E20: =+SUM(E15:E19) -> 3700 | F20: =+SUM(F15:F19) -> 3700 | G20: =+SUM(G15:G19) -> 3700 | H20: =+SUM(H15:H19) -> 3700 | I20: =+SUM(I15:I19) -> 3700 | J20: =+SUM(J15:J19) -> 29600
A22: 1. PRODUCCIÓN PLANEADA POR QUINCENA (Assembly D)
A23: Quincena → | B23: Q1 | C23: Q2 | D23: Q3 | E23: Q4 | F23: Q5 | G23: Q6 | H23: Q7 | I23: Q8 | J23: TOTAL
A24: Producción EC Planta Central | B24: 1850 | C24: 1850 | D24: 1850 | E24: 1850 | F24: 1850 | G24: 1850 | H24: 1850 | I24: 1850 | J24: =SUM(B24:I24) -> 14800
A25: Producción EC Planta West | B25: 1850 | C25: 1850 | D25: 1850 | E25: 1850 | F25: 1850 | G25: 1850 | H25: 1850 | I25: 1850 | J25: =SUM(B25:I25) -> 14800
A26: Producción EC Planta East | B26: 0 | C26: 0 | D26: 0 | E26: 0 | F26: 0 | G26: 0 | H26: 0 | I26: 0 | J26: =SUM(B26:I26) -> 0
A27: Producción EC Planta North | B27: 0 | C27: 0 | D27: 0 | E27: 0 | F27: 0 | G27: 0 | H27: 0 | I27: 0 | J27: =SUM(B27:I27) -> 0
A28: Producción EC Planta South | B28: 0 | C28: 0 | D28: 0 | E28: 0 | F28: 0 | G28: 0 | H28: 0 | I28: 0 | J28: =SUM(B28:I28) -> 0
A29: Total | B29: =+SUM(B24:B28) -> 3700 | C29: =+SUM(C24:C28) -> 3700 | D29: =+SUM(D24:D28) -> 3700 | E29: =+SUM(E24:E28) -> 3700 | F29: =+SUM(F24:F28) -> 3700 | G29: =+SUM(G24:G28) -> 3700 | H29: =+SUM(H24:H28) -> 3700 | I29: =+SUM(I24:I28) -> 3700 | J29: =+SUM(J24:J28) -> 29600
A31: Material | B31: Inventario Inicial Planta Central | C31: Inventario Inicial Planta West | D31: Inventario Inicial Planta East | E31: Inventario Inicial Planta North | F31: Inventario Inicial Planta South | G31: Unidad | H31: Fuente
A32: Parte A | B32: 3496 | C32: 1016 | D32: 0 | E32: 0 | F32: 0 | G32: unidades | H32: Fin Periodo 6
A33: Parte B | B33: 765 | C33: 293 | D33: 0 | E33: 0 | F33: 0 | G33: unidades | H33: Fin Periodo 6
A34: Pieza 1 | B34: 94 | C34: 36 | D34: 0 | E34: 0 | F34: 0 | G34: unidades | H34: Fin Periodo 6
A35: Pieza 2 | B35: 3844 | C35: 1424 | D35: 0 | E35: 0 | F35: 0 | G35: unidades | H35: Fin Periodo 6
A36: Pieza 3 | B36: 3125 | C36: 1208 | D36: 0 | E36: 0 | F36: 0 | G36: unidades | H36: Fin Periodo 6
A37: Pieza 4 | B37: 6131 | C37: 2356 | D37: 0 | E37: 0 | F37: 0 | G37: unidades | H37: Fin Periodo 6
A38: Pieza 5 | B38: 16736 | C38: 6456 | D38: 0 | E38: 0 | F38: 0 | G38: unidades | H38: Fin Periodo 6
A39: Pieza 6 | B39: 4439 | C39: 1596 | D39: 0 | E39: 0 | F39: 0 | G39: unidades | H39: Fin Periodo 6
A40: Assembly A | B40: 7432 | C40: 3622 | D40: 0 | E40: 0 | F40: 0 | G40: unidades | H40: Fin Periodo 6
A41: Assembly B | B41: 5392 | C41: 2210 | D41: 0 | E41: 0 | F41: 0 | G41: unidades | H41: Fin Periodo 6
A42: Assembly C | B42: 3766 | C42: 2416 | D42: 0 | E42: 0 | F42: 0 | G42: unidades | H42: Fin Periodo 6
A43: Assembly D | B43: 6606 | C43: 2266 | D43: 0 | E43: 0 | F43: 0 | G43: unidades | H43: Fin Periodo 6
A46: 3. BILL OF MATERIALS (BOM) - Consumo por Electroclean
...

Sheet BOM_Consumo
A1: BOM_CONSUMO - Cálculo de Consumo por Quincena
A2: Fórmula: Consumo_Q = Producción_EC_Q × Consumo_por_EC
A3: VERDE = datos de Inputs | NEGRO = fórmulas calculadas
A4: Planta Centro
A5: Material | B5: Consumo/EC | C5: Q1 | D5: Q2 | E5: Q3 | F5: Q4 | G5: Q5 | H5: Q6 | I5: Q7 | J5: Q8 | K5: TOTAL
A6: Parte A | B6: =XLOOKUP(A6,Inputs!$A$48:$A$55,Inputs!$B$48:$B$55) | C6: =Inputs!B$6*B6 -> 1850 | D6: =Inputs!C$6*B6 -> 1850 | E6: =Inputs!D$6*B6 -> 1850 | F6: =Inputs!E$6*B6 -> 1850 | G6: =Inputs!F$6*B6 -> 1850 | H6: =Inputs!G$6*B6 -> 1850 | I6: =Inputs!H$6*B6 -> 1850 | J6: =Inputs!I$6*B6 -> 1850 | K6: =SUM(C6:J6) -> 14800
A7: Parte B | B7: =XLOOKUP(A7,Inputs!$A$48:$A$55,Inputs!$B$48:$B$55) | C7: =Inputs!B$6*B7 -> 370 | D7: =Inputs!C$6*B7 -> 370 | E7: =Inputs!D$6*B7 -> 370 | F7: =Inputs!E$6*B7 -> 370 | G7: =Inputs!F$6*B7 -> 370 | H7: =Inputs!G$6*B7 -> 370 | I7: =Inputs!H$6*B7 -> 370 | J7: =Inputs!I$6*B7 -> 370 | K7: =SUM(C7:J7) -> 2960
A8: Pieza 1 | B8: =XLOOKUP(A8,Inputs!$A$48:$A$55,Inputs!$B$48:$B$55) | C8: =Inputs!B$6*B8 -> 18.5 | D8: =Inputs!C$6*B8 -> 18.5 | E8: =Inputs!D$6*B8 -> 18.5 | F8: =Inputs!E$6*B8 -> 18.5 | G8: =Inputs!F$6*B8 -> 18.5 | H8: =Inputs!G$6*B8 -> 18.5 | I8: =Inputs!H$6*B8 -> 18.5 | J8: =Inputs!I$6*B8 -> 18.5 | K8: =SUM(C8:J8) -> 148
A9: Pieza 2 | B9: =XLOOKUP(A9,Inputs!$A$48:$A$55,Inputs!$B$48:$B$55) | C9: =Inputs!B$6*B9 -> 14800 | D9: =Inputs!C$6*B9 -> 14800 | E9: =Inputs!D$6*B9 -> 14800 | F9: =Inputs!E$6*B9 -> 14800 | G9: =Inputs!F$6*B9 -> 14800 | H9: =Inputs!G$6*B9 -> 14800 | I9: =Inputs!H$6*B9 -> 14800 | J9: =Inputs!I$6*B9 -> 14800 | K9: =SUM(C9:J9) -> 118400
A10: Pieza 3 | B10: =XLOOKUP(A10,Inputs!$A$48:$A$55,Inputs!$B$48:$B$55) | C10: =Inputs!B$6*B10 -> 555 | D10: =Inputs!C$6*B10 -> 555 | E10: =Inputs!D$6*B10 -> 555 | F10: =Inputs!E$6*B10 -> 555 | G10: =Inputs!F$6*B10 -> 555 | H10: =Inputs!G$6*B10 -> 555 | I10: =Inputs!H$6*B10 -> 555 | J10: =Inputs!I$6*B10 -> 555 | K10: =SUM(C10:J10) -> 4440
A11: Pieza 4 | B11: =XLOOKUP(A11,Inputs!$A$48:$A$55,Inputs!$B$48:$B$55) | C11: =Inputs!B$6*B11 -> 1110 | D11: =Inputs!C$6*B11 -> 1110 | E11: =Inputs!D$6*B11 -> 1110 | F11: =Inputs!E$6*B11 -> 1110 | G11: =Inputs!F$6*B11 -> 1110 | H11: =Inputs!G$6*B11 -> 1110 | I11: =Inputs!H$6*B11 -> 1110 | J11: =Inputs!I$6*B11 -> 1110 | K11: =SUM(C11:J11) -> 8880
A12: Pieza 5 | B12: =XLOOKUP(A12,Inputs!$A$48:$A$55,Inputs!$B$48:$B$55) | C12: =Inputs!B$6*B12 -> 3700 | D12: =Inputs!C$6*B12 -> 3700 | E12: =Inputs!D$6*B12 -> 3700 | F12: =Inputs!E$6*B12 -> 3700 | G12: =Inputs!F$6*B12 -> 3700 | H12: =Inputs!G$6*B12 -> 3700 | I12: =Inputs!H$6*B12 -> 3700 | J12: =Inputs!I$6*B12 -> 3700 | K12: =SUM(C12:J12) -> 29600
A13: Pieza 6 | B13: =XLOOKUP(A13,Inputs!$A$48:$A$55,Inputs!$B$48:$B$55) | C13: =Inputs!B$6*B13 -> 1387.5 | D13: =Inputs!C$6*B13 -> 1387.5 | E13: =Inputs!D$6*B13 -> 1387.5 | F13: =Inputs!E$6*B13 -> 1387.5 | G13: =Inputs!F$6*B13 -> 1387.5 | H13: =Inputs!G$6*B13 -> 1387.5 | I13: =Inputs!H$6*B13 -> 1387.5 | J13: =Inputs!I$6*B13 -> 1387.5 | K13: =SUM(C13:J13) -> 11100
A14: PRODUCCIÓN TOTAL EC | C14: =Inputs!B6 -> 1850 | D14: =Inputs!C6 -> 1850 | E14: =Inputs!D6 -> 1850 | F14: =Inputs!E6 -> 1850 | G14: =Inputs!F6 -> 1850 | H14: =Inputs!G6 -> 1850 | I14: =Inputs!H6 -> 1850 | J14: =Inputs!I6 -> 1850 | K14: =Inputs!J6 -> 14800
A16: Planta West
A17: Material | B17: Consumo/EC | C17: Q1 | D17: Q2 | E17: Q3 | F17: Q4 | G17: Q5 | H17: Q6 | I17: Q7 | J17: Q8 | K17: TOTAL
A18: Parte A | B18: 1 | C18: =Inputs!B$6*B18 -> 1850 | D18: =Inputs!C$6*B18 -> 1850 | E18: =Inputs!D$6*B18 -> 1850 | F18: =Inputs!E$6*B18 -> 1850 | G18: =Inputs!F$6*B18 -> 1850 | H18: =Inputs!G$6*B18 -> 1850 | I18: =Inputs!H$6*B18 -> 1850 | J18: =Inputs!I$6*B18 -> 1850 | K18: =SUM(C18:J18) -> 14800
A19: Parte B | B19: 0.2 | C19: =Inputs!B$6*B19 -> 370 | D19: =Inputs!C$6*B19 -> 370 | E19: =Inputs!D$6*B19 -> 370 | F19: =Inputs!E$6*B19 -> 370 | G19: =Inputs!F$6*B19 -> 370 | H19: =Inputs!G$6*B19 -> 370 | I19: =Inputs!H$6*B19 -> 370 | J19: =Inputs!I$6*B19 -> 370 | K19: =SUM(C19:J19) -> 2960
A20: Pieza 1 | B20: 0.01 | C20: =Inputs!B$6*B20 -> 18.5 | D20: =Inputs!C$6*B20 -> 18.5 | E20: =Inputs!D$6*B20 -> 18.5 | F20: =Inputs!E$6*B20 -> 18.5 | G20: =Inputs!F$6*B20 -> 18.5 | H20: =Inputs!G$6*B20 -> 18.5 | I20: =Inputs!H$6*B20 -> 18.5 | J20: =Inputs!I$6*B20 -> 18.5 | K20: =SUM(C20:J20) -> 148
A21: Pieza 2 | B21: 8 | C21: =Inputs!B$6*B21 -> 14800 | D21: =Inputs!C$6*B21 -> 14800 | E21: =Inputs!D$6*B21 -> 14800 | F21: =Inputs!E$6*B21 -> 14800 | G21: =Inputs!F$6*B21 -> 14800 | H21: =Inputs!G$6*B21 -> 14800 | I21: =Inputs!H$6*B21 -> 14800 | J21: =Inputs!I$6*B21 -> 14800 | K21: =SUM(C21:J21) -> 118400
A22: Pieza 3 | B22: 0.3 | C22: =Inputs!B$6*B22 -> 555 | D22: =Inputs!C$6*B22 -> 555 | E22: =Inputs!D$6*B22 -> 555 | F22: =Inputs!E$6*B22 -> 555 | G22: =Inputs!F$6*B22 -> 555 | H22: =Inputs!G$6*B22 -> 555 | I22: =Inputs!H$6*B22 -> 555 | J22: =Inputs!I$6*B22 -> 555 | K22: =SUM(C22:J22) -> 4440
A23: Pieza 4 | B23: 0.6 | C23: =Inputs!B$6*B23 -> 1110 | D23: =Inputs!C$6*B23 -> 1110 | E23: =Inputs!D$6*B23 -> 1110 | F23: =Inputs!E$6*B23 -> 1110 | G23: =Inputs!F$6*B23 -> 1110 | H23: =Inputs!G$6*B23 -> 1110 | I23: =Inputs!H$6*B23 -> 1110 | J23: =Inputs!I$6*B23 -> 1110 | K23: =SUM(C23:J23) -> 8880
A24: Pieza 5 | B24: 2 | C24: =Inputs!B$6*B24 -> 3700 | D24: =Inputs!C$6*B24 -> 3700 | E24: =Inputs!D$6*B24 -> 3700 | F24: =Inputs!E$6*B24 -> 3700 | G24: =Inputs!F$6*B24 -> 3700 | H24: =Inputs!G$6*B24 -> 3700 | I24: =Inputs!H$6*B24 -> 3700 | J24: =Inputs!I$6*B24 -> 3700 | K24: =SUM(C24:J24) -> 29600
A25: Pieza 6 | B25: 0.75 | C25: =Inputs!B$6*B25 -> 1387.5 | D25: =Inputs!C$6*B25 -> 1387.5 | E25: =Inputs!D$6*B25 -> 1387.5 | F25: =Inputs!E$6*B25 -> 1387.5 | G25: =Inputs!F$6*B25 -> 1387.5 | H25: =Inputs!G$6*B25 -> 1387.5 | I25: =Inputs!H$6*B25 -> 1387.5 | J25: =Inputs!I$6*B25 -> 1387.5 | K25: =SUM(C25:J25) -> 11100
A26: PRODUCCIÓN TOTAL EC | C26: =Inputs!B7 -> 1850 | D26: =Inputs!C7 -> 1850 | E26: =Inputs!D7 -> 1850 | F26: =Inputs!E7 -> 1850 | G26: =Inputs!F7 -> 1850 | H26: =Inputs!G7 -> 1850 | I26: =Inputs!H7 -> 1850 | J26: =Inputs!I7 -> 1850 | K26: =Inputs!J7 -> 14800
A28: Planta East
A29: Material | B29: Consumo/EC | C29: Q1 | D29: Q2 | E29: Q3 | F29: Q4 | G29: Q5 | H29: Q6 | I29: Q7 | J29: Q8 | K29: TOTAL
A30: Parte A | B30: 1 | C30: =Inputs!B$6*B30 -> 1850 | D30: =Inputs!C$6*B30 -> 1850 | E30: =Inputs!D$6*B30 -> 1850 | F30: =Inputs!E$6*B30 -> 1850 | G30: =Inputs!F$6*B30 -> 1850 | H30: =Inputs!G$6*B30 -> 1850 | I30: =Inputs!H$6*B30 -> 1850 | J30: =Inputs!I$6*B30 -> 1850 | K30: =SUM(C30:J30) -> 14800
A31: Parte B | B31: 0.2 | C31: =Inputs!B$6*B31 -> 370 | D31: =Inputs!C$6*B31 -> 370 | E31: =Inputs!D$6*B31 -> 370 | F31: =Inputs!E$6*B31 -> 370 | G31: =Inputs!F$6*B31 -> 370 | H31: =Inputs!G$6*B31 -> 370 | I31: =Inputs!H$6*B31 -> 370 | J31: =Inputs!I$6*B31 -> 370 | K31: =SUM(C31:J31) -> 2960
A32: Pieza 1 | B32: 0.01 | C32: =Inputs!B$6*B32 -> 18.5 | D32: =Inputs!C$6*B32 -> 18.5 | E32: =Inputs!D$6*B32 -> 18.5 | F32: =Inputs!E$6*B32 -> 18.5 | G32: =Inputs!F$6*B32 -> 18.5 | H32: =Inputs!G$6*B32 -> 18.5 | I32: =Inputs!H$6*B32 -> 18.5 | J32: =Inputs!I$6*B32 -> 18.5 | K32: =SUM(C32:J32) -> 148
A33: Pieza 2 | B33: 8 | C33: =Inputs!B$6*B33 -> 14800 | D33: =Inputs!C$6*B33 -> 14800 | E33: =Inputs!D$6*B33 -> 14800 | F33: =Inputs!E$6*B33 -> 14800 | G33: =Inputs!F$6*B33 -> 14800 | H33: =Inputs!G$6*B33 -> 14800 | I33: =Inputs!H$6*B33 -> 14800 | J33: =Inputs!I$6*B33 -> 14800 | K33: =SUM(C33:J33) -> 118400
A34: Pieza 3 | B34: 0.3 | C34: =Inputs!B$6*B34 -> 555 | D34: =Inputs!C$6*B34 -> 555 | E34: =Inputs!D$6*B34 -> 555 | F34: =Inputs!E$6*B34 -> 555 | G34: =Inputs!F$6*B34 -> 555 | H34: =Inputs!G$6*B34 -> 555 | I34: =Inputs!H$6*B34 -> 555 | J34: =Inputs!I$6*B34 -> 555 | K34: =SUM(C34:J34) -> 4440
A35: Pieza 4 | B35: 0.6 | C35: =Inputs!B$6*B35 -> 1110 | D35: =Inputs!C$6*B35 -> 1110 | E35: =Inputs!D$6*B35 -> 1110 | F35: =Inputs!E$6*B35 -> 1110 | G35: =Inputs!F$6*B35 -> 1110 | H35: =Inputs!G$6*B35 -> 1110 | I35: =Inputs!H$6*B35 -> 1110 | J35: =Inputs!I$6*B35 -> 1110 | K35: =SUM(C35:J35) -> 8880
A36: Pieza 5 | B36: 2 | C36: =Inputs!B$6*B36 -> 3700 | D36: =Inputs!C$6*B36 -> 3700 | E36: =Inputs!D$6*B36 -> 3700 | F36: =Inputs!E$6*B36 -> 3700 | G36: =Inputs!F$6*B36 -> 3700 | H36: =Inputs!G$6*B36 -> 3700 | I36: =Inputs!H$6*B36 -> 3700 | J36: =Inputs!I$6*B36 -> 3700 | K36: =SUM(C36:J36) -> 29600
A37: Pieza 6 | B37: 0.75 | C37: =Inputs!B$6*B37 -> 1387.5 | D37: =Inputs!C$6*B37 -> 1387.5 | E37: =Inputs!D$6*B37 -> 1387.5 | F37: =Inputs!E$6*B37 -> 1387.5 | G37: =Inputs!F$6*B37 -> 1387.5 | H37: =Inputs!G$6*B37 -> 1387.5 | I37: =Inputs!H$6*B37 -> 1387.5 | J37: =Inputs!I$6*B37 -> 1387.5 | K37: =SUM(C37:J37) -> 11100
A38: PRODUCCIÓN TOTAL EC | C38: =Inputs!B8 -> 0 | D38: =Inputs!C8 -> 0 | E38: =Inputs!D8 -> 0 | F38: =Inputs!E8 -> 0 | G38: =Inputs!F8 -> 0 | H38: =Inputs!G8 -> 0 | I38: =Inputs!H8 -> 0 | J38: =Inputs!I8 -> 0 | K38: =Inputs!J8 -> 0
A40: Planta North
A41: Material | B41: Consumo/EC | C41: Q1 | D41: Q2 | E41: Q3 | F41: Q4 | G41: Q5 | H41: Q6 | I41: Q7 | J41: Q8 | K41: TOTAL
A42: Parte A | B42: 1 | C42: =Inputs!B$6*B42 -> 1850 | D42: =Inputs!C$6*B42 -> 1850 | E42: =Inputs!D$6*B42 -> 1850 | F42: =Inputs!E$6*B42 -> 1850 | G42: =Inputs!F$6*B42 -> 1850 | H42: =Inputs!G$6*B42 -> 1850 | I42: =Inputs!H$6*B42 -> 1850 | J42: =Inputs!I$6*B42 -> 1850 | K42: =SUM(C42:J42) -> 14800
A43: Parte B | B43: 0.2 | C43: =Inputs!B$6*B43 -> 370 | D43: =Inputs!C$6*B43 -> 370 | E43: =Inputs!D$6*B43 -> 370 | F43: =Inputs!E$6*B43 -> 370 | G43: =Inputs!F$6*B43 -> 370 | H43: =Inputs!G$6*B43 -> 370 | I43: =Inputs!H$6*B43 -> 370 | J43: =Inputs!I$6*B43 -> 370 | K43: =SUM(C43:J43) -> 2960
...

Sheet Inventario_Dinamico
A1: INVENTARIO DINÁMICO - Control por Quincena
A2: Fórmula: Inv_Final_Q = Inv_Inicial_Q + Recepciones_Q - Consumo_Q
A3: AMARILLO = ingresar recepciones manualmente | ROJO = inventario negativo (ALERTA)
A5: Parte A
A6: Concepto | B6: Q1 | C6: Q2 | D6: Q3 | E6: Q4 | F6: Q5 | G6: Q6 | H6: Q7 | I6: Q8
A7: Inv_Inicial | B7: =Multi_Planta!D6 | C7: =B10 -> -1756 | D7: =C10 -> -3606 | E7: =D10 -> -5456 | F7: =E10 -> -7306 | G7: =F10 -> -9156 | H7: =G10 -> -11006 | I7: =H10 -> -12856
A8: Recepciones | B8: 0 | C8: 0 | D8: 0 | E8: 0 | F8: 0 | G8: 0 | H8: 0 | I8: 0
A9: Consumo | B9: =BOM_Consumo!C6 -> 1850 | C9: =BOM_Consumo!D6 -> 1850 | D9: =BOM_Consumo!E6 -> 1850 | E9: =BOM_Consumo!F6 -> 1850 | F9: =BOM_Consumo!G6 -> 1850 | G9: =BOM_Consumo!H6 -> 1850 | H9: =BOM_Consumo!I6 -> 1850 | I9: =BOM_Consumo!J6 -> 1850
A10: Inv_Final | B10: =B7+B8-B9 -> -1756 | C10: =C7+C8-C9 -> -3606 | D10: =D7+D8-D9 -> -5456 | E10: =E7+E8-E9 -> -7306 | F10: =F7+F8-F9 -> -9156 | G10: =G7+G8-G9 -> -11006 | H10: =H7+H8-H9 -> -12856 | I10: =I7+I8-I9 -> -14706
A11: Parte B
A12: Concepto | B12: Q1 | C12: Q2 | D12: Q3 | E12: Q4 | F12: Q5 | G12: Q6 | H12: Q7 | I12: Q8
A13: Inv_Inicial | B13: =Multi_Planta!D7 | C13: =B16 -> 3474 | D13: =C16 -> 3104 | E13: =D16 -> 2734 | F13: =E16 -> 2364 | G13: =F16 -> 1994 | H13: =G16 -> 1624 | I13: =H16 -> 1254
A14: Recepciones | B14: 0 | C14: 0 | D14: 0 | E14: 0 | F14: 0 | G14: 0 | H14: 0 | I14: 0
A15: Consumo | B15: =BOM_Consumo!C7 -> 370 | C15: =BOM_Consumo!D7 -> 370 | D15: =BOM_Consumo!E7 -> 370 | E15: =BOM_Consumo!F7 -> 370 | F15: =BOM_Consumo!G7 -> 370 | G15: =BOM_Consumo!H7 -> 370 | H15: =BOM_Consumo!I7 -> 370 | I15: =BOM_Consumo!J7 -> 370
A16: Inv_Final | B16: =B13+B14-B15 -> 3474 | C16: =C13+C14-C15 -> 3104 | D16: =D13+D14-D15 -> 2734 | E16: =E13+E14-E15 -> 2364 | F16: =F13+F14-F15 -> 1994 | G16: =G13+G14-G15 -> 1624 | H16: =H13+H14-H15 -> 1254 | I16: =I13+I14-I15 -> 884
A17: Pieza 1
A18: Concepto | B18: Q1 | C18: Q2 | D18: Q3 | E18: Q4 | F18: Q5 | G18: Q6 | H18: Q7 | I18: Q8
A19: Inv_Inicial | B19: =Multi_Planta!D8 | C19: =B22 -> 3106.5 | D19: =C22 -> 3088 | E19: =D22 -> 3069.5 | F19: =E22 -> 3051 | G19: =F22 -> 3032.5 | H19: =G22 -> 3014 | I19: =H22 -> 2995.5
A20: Recepciones | B20: 0 | C20: 0 | D20: 0 | E20: 0 | F20: 0 | G20: 0 | H20: 0 | I20: 0
A21: Consumo | B21: =BOM_Consumo!C8 -> 18.5 | C21: =BOM_Consumo!D8 -> 18.5 | D21: =BOM_Consumo!E8 -> 18.5 | E21: =BOM_Consumo!F8 -> 18.5 | F21: =BOM_Consumo!G8 -> 18.5 | G21: =BOM_Consumo!H8 -> 18.5 | H21: =BOM_Consumo!I8 -> 18.5 | I21: =BOM_Consumo!J8 -> 18.5
A22: Inv_Final | B22: =B19+B20-B21 -> 3106.5 | C22: =C19+C20-C21 -> 3088 | D22: =D19+D20-D21 -> 3069.5 | E22: =E19+E20-E21 -> 3051 | F22: =F19+F20-F21 -> 3032.5 | G22: =G19+G20-G21 -> 3014 | H22: =H19+H20-H21 -> 2995.5 | I22: =I19+I20-I21 -> 2977
A23: Pieza 2
A24: Concepto | B24: Q1 | C24: Q2 | D24: Q3 | E24: Q4 | F24: Q5 | G24: Q6 | H24: Q7 | I24: Q8
A25: Inv_Inicial | B25: =Multi_Planta!D9 | C25: =B28 -> -8669 | D25: =C28 -> -23469 | E25: =D28 -> -38269 | F25: =E28 -> -53069 | G25: =F28 -> -67869 | H25: =G28 -> -82669 | I25: =H28 -> -97469
A26: Recepciones | B26: 0 | C26: 0 | D26: 0 | E26: 0 | F26: 0 | G26: 0 | H26: 0 | I26: 0
A27: Consumo | B27: =BOM_Consumo!C9 -> 14800 | C27: =BOM_Consumo!D9 -> 14800 | D27: =BOM_Consumo!E9 -> 14800 | E27: =BOM_Consumo!F9 -> 14800 | F27: =BOM_Consumo!G9 -> 14800 | G27: =BOM_Consumo!H9 -> 14800 | H27: =BOM_Consumo!I9 -> 14800 | I27: =BOM_Consumo!J9 -> 14800
A28: Inv_Final | B28: =B25+B26-B27 -> -8669 | C28: =C25+C26-C27 -> -23469 | D28: =D25+D26-D27 -> -38269 | E28: =E25+E26-E27 -> -53069 | F28: =F25+F26-F27 -> -67869 | G28: =G25+G26-G27 -> -82669 | H28: =H25+H26-H27 -> -97469 | I28: =I25+I26-I27 -> -112269
A29: Pieza 3
A30: Concepto | B30: Q1 | C30: Q2 | D30: Q3 | E30: Q4 | F30: Q5 | G30: Q6 | H30: Q7 | I30: Q8
A31: Inv_Inicial | B31: =Multi_Planta!D10 | C31: =B34 -> 16181 | D31: =C34 -> 15626 | E31: =D34 -> 15071 | F31: =E34 -> 14516 | G31: =F34 -> 13961 | H31: =G34 -> 13406 | I31: =H34 -> 12851
A32: Recepciones | B32: 0 | C32: 0 | D32: 0 | E32: 0 | F32: 0 | G32: 0 | H32: 0 | I32: 0
A33: Consumo | B33: =BOM_Consumo!C10 -> 555 | C33: =BOM_Consumo!D10 -> 555 | D33: =BOM_Consumo!E10 -> 555 | E33: =BOM_Consumo!F10 -> 555 | F33: =BOM_Consumo!G10 -> 555 | G33: =BOM_Consumo!H10 -> 555 | H33: =BOM_Consumo!I10 -> 555 | I33: =BOM_Consumo!J10 -> 555
A34: Inv_Final | B34: =B31+B32-B33 -> 16181 | C34: =C31+C32-C33 -> 15626 | D34: =D31+D32-D33 -> 15071 | E34: =E31+E32-E33 -> 14516 | F34: =F31+F32-F33 -> 13961 | G34: =G31+G32-G33 -> 13406 | H34: =H31+H32-H33 -> 12851 | I34: =I31+I32-I33 -> 12296
A35: Pieza 4
A36: Concepto | B36: Q1 | C36: Q2 | D36: Q3 | E36: Q4 | F36: Q5 | G36: Q6 | H36: Q7 | I36: Q8
A37: Inv_Inicial | B37: =Multi_Planta!D11 | C37: =B40 -> 3329 | D37: =C40 -> 2219 | E37: =D40 -> 1109 | F37: =E40 -> -1 | G37: =F40 -> -1111 | H37: =G40 -> -2221 | I37: =H40 -> -3331
A38: Recepciones | B38: 0 | C38: 0 | D38: 0 | E38: 0 | F38: 0 | G38: 0 | H38: 0 | I38: 0
A39: Consumo | B39: =BOM_Consumo!C11 -> 1110 | C39: =BOM_Consumo!D11 -> 1110 | D39: =BOM_Consumo!E11 -> 1110 | E39: =BOM_Consumo!F11 -> 1110 | F39: =BOM_Consumo!G11 -> 1110 | G39: =BOM_Consumo!H11 -> 1110 | H39: =BOM_Consumo!I11 -> 1110 | I39: =BOM_Consumo!J11 -> 1110
A40: Inv_Final | B40: =B37+B38-B39 -> 3329 | C40: =C37+C38-C39 -> 2219 | D40: =D37+D38-D39 -> 1109 | E40: =E37+E38-E39 -> -1 | F40: =F37+F38-F39 -> -1111 | G40: =G37+G38-G39 -> -2221 | H40: =H37+H38-H39 -> -3331 | I40: =I37+I38-I39 -> -4441
A41: Pieza 5
...

Sheet Compras_y_Lotes
A1: COMPRAS Y LOTES - Decisiones de Compra
A2: Convierte consumo en decisiones reales de compra (lotes)
A3: AMARILLO = TUS DECISIONES de cuántos lotes comprar
A5: PIEZAS 1-6: COMPRA ÚNICA EN t=0
A6: Material | B6: Demanda Total | C6: Batch Size | D6: Lotes Teóricos | E6: COMPRAR (Lotes) | F6: Total Unidades | G6: Precio/Batch | H6: Costo Total | I6: Status
A7: Pieza 1 | B7: =BOM_Consumo!K8 -> 148 | C7: =XLOOKUP(A7,Inputs!$A$66:$A$73,Inputs!$B$66:$B$73) | D7: =ROUNDUP(B7/C7,0) -> 5 | E7: =D7 -> 5 | F7: =E7*C7 -> 150 | G7: =XLOOKUP(A7,Inputs!$A$82:$A$90,Inputs!$B$82:$B$90) | H7: =E7*G7 -> 0 | I7: =IF(F7>=B7,"OK","INSUFICIENTE") -> OK
A8: Pieza 2 | B8: =BOM_Consumo!K9 -> 118400 | C8: =XLOOKUP(A8,Inputs!$A$66:$A$73,Inputs!$B$66:$B$73) | D8: =ROUNDUP(B8/C8,0) -> 9867 | E8: =D8 -> 9867 | F8: =E8*C8 -> 118404 | G8: =XLOOKUP(A8,Inputs!$A$82:$A$90,Inputs!$B$82:$B$90) | H8: =E8*G8 -> #VALUE! | I8: =IF(F8>=B8,"OK","INSUFICIENTE") -> OK
A9: Pieza 3 | B9: =BOM_Consumo!K10 -> 4440 | C9: =XLOOKUP(A9,Inputs!$A$66:$A$73,Inputs!$B$66:$B$73) | D9: =ROUNDUP(B9/C9,0) -> 4440 | E9: =D9 -> 4440 | F9: =E9*C9 -> 4440 | G9: =XLOOKUP(A9,Inputs!$A$82:$A$90,Inputs!$B$82:$B$90) | H9: =E9*G9 -> 555000 | I9: =IF(F9>=B9,"OK","INSUFICIENTE") -> OK
A10: Pieza 4 | B10: =BOM_Consumo!K11 -> 8880 | C10: =XLOOKUP(A10,Inputs!$A$66:$A$73,Inputs!$B$66:$B$73) | D10: =ROUNDUP(B10/C10,0) -> 89 | E10: =D10 -> 89 | F10: =E10*C10 -> 8900 | G10: =XLOOKUP(A10,Inputs!$A$82:$A$90,Inputs!$B$82:$B$90) | H10: =E10*G10 -> 29370 | I10: =IF(F10>=B10,"OK","INSUFICIENTE") -> OK
A11: Pieza 5 | B11: =BOM_Consumo!K12 -> 29600 | C11: =XLOOKUP(A11,Inputs!$A$66:$A$73,Inputs!$B$66:$B$73) | D11: =ROUNDUP(B11/C11,0) -> 987 | E11: =D11 -> 987 | F11: =E11*C11 -> 29610 | G11: =XLOOKUP(A11,Inputs!$A$82:$A$90,Inputs!$B$82:$B$90) | H11: =E11*G11 -> 59220 | I11: =IF(F11>=B11,"OK","INSUFICIENTE") -> OK
A12: Pieza 6 | B12: =BOM_Consumo!K13 -> 11100 | C12: =XLOOKUP(A12,Inputs!$A$66:$A$73,Inputs!$B$66:$B$73) | D12: =ROUNDUP(B12/C12,0) -> 185 | E12: =D12 -> 185 | F12: =E12*C12 -> 11100 | G12: =XLOOKUP(A12,Inputs!$A$82:$A$90,Inputs!$B$82:$B$90) | H12: =E12*G12 -> 1295 | I12: =IF(F12>=B12,"OK","INSUFICIENTE") -> OK
A13: TOTAL PIEZAS | H13: =SUM(H7:H12) -> #VALUE!
A16: PARTES A y B: COMPRA POR QUINCENA
A17: Material | B17: Quincena | C17: Demanda | D17: Batch Size | E17: Lotes Teóricos | F17: COMPRAR (Lotes) | G17: Unidades | H17: Precio/Batch | I17: Costo | J17: Términos Pago | K17: Pago en Q
A18: Parte A | B18: Q1 | C18: =BOM_Consumo!C6 -> 1850 | D18: =Inputs!B66 -> 30 | E18: =IF(C18>0,ROUNDUP(C18/D18,0),0) -> 62 | F18: 0 | G18: =F18*D18 -> 0 | H18: =IF(XLOOKUP("PROVEEDOR ELEGIDO*",Inputs!$A$105:$A$110,Inputs!$B$105:$B$110,"",2)="B",IF(SUM($F$18:$F$25)>=XLOOKUP("B",Inputs!$A$107:$A$109,Inputs!$E$107:$E$109),XLOOKUP("B",Inputs!$A$107:$A$109,Inputs!$B$107:$B$109)*(1-0.16),XLOOKUP("B",Inputs!$A$107:$A$109,Inputs!$B$107:$B$109)),XLOOKUP(XLOOKUP("PROVEEDOR ELEGIDO*",Inputs!$A$105:$A$110,Inputs!$B$105:$B$110,"",2),Inputs!$A$107:$A$109,Inputs!$B$107:$B$109)) | I18: =F18*H18 -> 0 | J18: =XLOOKUP(XLOOKUP("PROVEEDOR ELEGIDO*",Inputs!$A$105:$A$110,Inputs!$B$105:$B$110,"",2),Inputs!$A$107:$A$109,Inputs!$C$107:$C$109) | K18: ="Q"&(VALUE(MID(B18,2,10))+IF(ISNUMBER(SEARCH("+2",J18)),2,IF(ISNUMBER(SEARCH("+8",J18)),8,0)))
B19: Q2 | C19: =BOM_Consumo!D6 -> 1850 | D19: =Inputs!B66 -> 30 | E19: =IF(C19>0,ROUNDUP(C19/D19,0),0) -> 62 | F19: 0 | G19: =F19*D19 -> 0 | H19: =IF(XLOOKUP("PROVEEDOR ELEGIDO*",Inputs!$A$105:$A$110,Inputs!$B$105:$B$110,"",2)="B",IF(SUM($F$18:$F$25)>=XLOOKUP("B",Inputs!$A$107:$A$109,Inputs!$E$107:$E$109),XLOOKUP("B",Inputs!$A$107:$A$109,Inputs!$B$107:$B$109)*(1-0.16),XLOOKUP("B",Inputs!$A$107:$A$109,Inputs!$B$107:$B$109)),XLOOKUP(XLOOKUP("PROVEEDOR ELEGIDO*",Inputs!$A$105:$A$110,Inputs!$B$105:$B$110,"",2),Inputs!$A$107:$A$109,Inputs!$B$107:$B$109)) | I19: =F19*H19 -> 0 | J19: =XLOOKUP(XLOOKUP("PROVEEDOR ELEGIDO*",Inputs!$A$105:$A$110,Inputs!$B$105:$B$110,"",2),Inputs!$A$107:$A$109,Inputs!$C$107:$C$109) | K19: ="Q"&(VALUE(MID(B19,2,10))+IF(ISNUMBER(SEARCH("+2",J19)),2,IF(ISNUMBER(SEARCH("+8",J19)),8,0)))
B20: Q3 | C20: =BOM_Consumo!E6 -> 1850 | D20: =Inputs!B66 -> 30 | E20: =IF(C20>0,ROUNDUP(C20/D20,0),0) -> 62 | F20: 0 | G20: =F20*D20 -> 0 | H20: =IF(XLOOKUP("PROVEEDOR ELEGIDO*",Inputs!$A$105:$A$110,Inputs!$B$105:$B$110,"",2)="B",IF(SUM($F$18:$F$25)>=XLOOKUP("B",Inputs!$A$107:$A$109,Inputs!$E$107:$E$109),XLOOKUP("B",Inputs!$A$107:$A$109,Inputs!$B$107:$B$109)*(1-0.16),XLOOKUP("B",Inputs!$A$107:$A$109,Inputs!$B$107:$B$109)),XLOOKUP(XLOOKUP("PROVEEDOR ELEGIDO*",Inputs!$A$105:$A$110,Inputs!$B$105:$B$110,"",2),Inputs!$A$107:$A$109,Inputs!$B$107:$B$109)) | I20: =F20*H20 -> 0 | J20: =XLOOKUP(XLOOKUP("PROVEEDOR ELEGIDO*",Inputs!$A$105:$A$110,Inputs!$B$105:$B$110,"",2),Inputs!$A$107:$A$109,Inputs!$C$107:$C$109) | K20: ="Q"&(VALUE(MID(B20,2,10))+IF(ISNUMBER(SEARCH("+2",J20)),2,IF(ISNUMBER(SEARCH("+8",J20)),8,0)))
B21: Q4 | C21: =BOM_Consumo!F6 -> 1850 | D21: =Inputs!B66 -> 30 | E21: =IF(C21>0,ROUNDUP(C21/D21,0),0) -> 62 | F21: 0 | G21: =F21*D21 -> 0 | H21: =IF(XLOOKUP("PROVEEDOR ELEGIDO*",Inputs!$A$105:$A$110,Inputs!$B$105:$B$110,"",2)="B",IF(SUM($F$18:$F$25)>=XLOOKUP("B",Inputs!$A$107:$A$109,Inputs!$E$107:$E$109),XLOOKUP("B",Inputs!$A$107:$A$109,Inputs!$B$107:$B$109)*(1-0.16),XLOOKUP("B",Inputs!$A$107:$A$109,Inputs!$B$107:$B$109)),XLOOKUP(XLOOKUP("PROVEEDOR ELEGIDO*",Inputs!$A$105:$A$110,Inputs!$B$105:$B$110,"",2),Inputs!$A$107:$A$109,Inputs!$B$107:$B$109)) | I21: =F21*H21 -> 0 | J21: =XLOOKUP(XLOOKUP("PROVEEDOR ELEGIDO*",Inputs!$A$105:$A$110,Inputs!$B$105:$B$110,"",2),Inputs!$A$107:$A$109,Inputs!$C$107:$C$109) | K21: ="Q"&(VALUE(MID(B21,2,10))+IF(ISNUMBER(SEARCH("+2",J21)),2,IF(ISNUMBER(SEARCH("+8",J21)),8,0)))
B22: Q5 | C22: =BOM_Consumo!G6 -> 1850 | D22: =Inputs!B66 -> 30 | E22: =IF(C22>0,ROUNDUP(C22/D22,0),0) -> 62 | F22: 0 | G22: =F22*D22 -> 0 | H22: =IF(XLOOKUP("PROVEEDOR ELEGIDO*",Inputs!$A$105:$A$110,Inputs!$B$105:$B$110,"",2)="B",IF(SUM($F$18:$F$25)>=XLOOKUP("B",Inputs!$A$107:$A$109,Inputs!$E$107:$E$109),XLOOKUP("B",Inputs!$A$107:$A$109,Inputs!$B$107:$B$109)*(1-0.16),XLOOKUP("B",Inputs!$A$107:$A$109,Inputs!$B$107:$B$109)),XLOOKUP(XLOOKUP("PROVEEDOR ELEGIDO*",Inputs!$A$105:$A$110,Inputs!$B$105:$B$110,"",2),Inputs!$A$107:$A$109,Inputs!$B$107:$B$109)) | I22: =F22*H22 -> 0 | J22: =XLOOKUP(XLOOKUP("PROVEEDOR ELEGIDO*",Inputs!$A$105:$A$110,Inputs!$B$105:$B$110,"",2),Inputs!$A$107:$A$109,Inputs!$C$107:$C$109) | K22: ="Q"&(VALUE(MID(B22,2,10))+IF(ISNUMBER(SEARCH("+2",J22)),2,IF(ISNUMBER(SEARCH("+8",J22)),8,0)))
B23: Q6 | C23: =BOM_Consumo!H6 -> 1850 | D23: =Inputs!B66 -> 30 | E23: =IF(C23>0,ROUNDUP(C23/D23,0),0) -> 62 | F23: 0 | G23: =F23*D23 -> 0 | H23: =IF(XLOOKUP("PROVEEDOR ELEGIDO*",Inputs!$A$105:$A$110,Inputs!$B$105:$B$110,"",2)="B",IF(SUM($F$18:$F$25)>=XLOOKUP("B",Inputs!$A$107:$A$109,Inputs!$E$107:$E$109),XLOOKUP("B",Inputs!$A$107:$A$109,Inputs!$B$107:$B$109)*(1-0.16),XLOOKUP("B",Inputs!$A$107:$A$109,Inputs!$B$107:$B$109)),XLOOKUP(XLOOKUP("PROVEEDOR ELEGIDO*",Inputs!$A$105:$A$110,Inputs!$B$105:$B$110,"",2),Inputs!$A$107:$A$109,Inputs!$B$107:$B$109)) | I23: =F23*H23 -> 0 | J23: =XLOOKUP(XLOOKUP("PROVEEDOR ELEGIDO*",Inputs!$A$105:$A$110,Inputs!$B$105:$B$110,"",2),Inputs!$A$107:$A$109,Inputs!$C$107:$C$109) | K23: ="Q"&(VALUE(MID(B23,2,10))+IF(ISNUMBER(SEARCH("+2",J23)),2,IF(ISNUMBER(SEARCH("+8",J23)),8,0)))
B24: Q7 | C24: =BOM_Consumo!I6 -> 1850 | D24: =Inputs!B66 -> 30 | E24: =IF(C24>0,ROUNDUP(C24/D24,0),0) -> 62 | F24: 0 | G24: =F24*D24 -> 0 | H24: =IF(XLOOKUP("PROVEEDOR ELEGIDO*",Inputs!$A$105:$A$110,Inputs!$B$105:$B$110,"",2)="B",IF(SUM($F$18:$F$25)>=XLOOKUP("B",Inputs!$A$107:$A$109,Inputs!$E$107:$E$109),XLOOKUP("B",Inputs!$A$107:$A$109,Inputs!$B$107:$B$109)*(1-0.16),XLOOKUP("B",Inputs!$A$107:$A$109,Inputs!$B$107:$B$109)),XLOOKUP(XLOOKUP("PROVEEDOR ELEGIDO*",Inputs!$A$105:$A$110,Inputs!$B$105:$B$110,"",2),Inputs!$A$107:$A$109,Inputs!$B$107:$B$109)) | I24: =F24*H24 -> 0 | J24: =XLOOKUP(XLOOKUP("PROVEEDOR ELEGIDO*",Inputs!$A$105:$A$110,Inputs!$B$105:$B$110,"",2),Inputs!$A$107:$A$109,Inputs!$C$107:$C$109) | K24: ="Q"&(VALUE(MID(B24,2,10))+IF(ISNUMBER(SEARCH("+2",J24)),2,IF(ISNUMBER(SEARCH("+8",J24)),8,0)))
B25: Q8 | C25: =BOM_Consumo!J6 -> 1850 | D25: =Inputs!B66 -> 30 | E25: =IF(C25>0,ROUNDUP(C25/D25,0),0) -> 62 | F25: 0 | G25: =F25*D25 -> 0 | H25: =IF(XLOOKUP("PROVEEDOR ELEGIDO*",Inputs!$A$105:$A$110,Inputs!$B$105:$B$110,"",2)="B",IF(SUM($F$18:$F$25)>=XLOOKUP("B",Inputs!$A$107:$A$109,Inputs!$E$107:$E$109),XLOOKUP("B",Inputs!$A$107:$A$109,Inputs!$B$107:$B$109)*(1-0.16),XLOOKUP("B",Inputs!$A$107:$A$109,Inputs!$B$107:$B$109)),XLOOKUP(XLOOKUP("PROVEEDOR ELEGIDO*",Inputs!$A$105:$A$110,Inputs!$B$105:$B$110,"",2),Inputs!$A$107:$A$109,Inputs!$B$107:$B$109)) | I25: =F25*H25 -> 0 | J25: =XLOOKUP(XLOOKUP("PROVEEDOR ELEGIDO*",Inputs!$A$105:$A$110,Inputs!$B$105:$B$110,"",2),Inputs!$A$107:$A$109,Inputs!$C$107:$C$109) | K25: ="Q"&(VALUE(MID(B25,2,10))+IF(ISNUMBER(SEARCH("+2",J25)),2,IF(ISNUMBER(SEARCH("+8",J25)),8,0)))
A26: Parte B | B26: Q1 | C26: =BOM_Consumo!C7 -> 370 | D26: =Inputs!B67 -> 12 | E26: =IF(C26>0,ROUNDUP(C26/D26,0),0) -> 31 | F26: 0 | G26: =F26*D26 -> 0 | H26: =IF(XLOOKUP("PROVEEDOR ELEGIDO*",Inputs!$A$113:$A$118,Inputs!$B$113:$B$118,"",2)="B",IF(SUM($F$26:$F$33)>=XLOOKUP("B",Inputs!$A$115:$A$117,Inputs!$E$115:$E$117),XLOOKUP("B",Inputs!$A$115:$A$117,Inputs!$B$115:$B$117)*(1-0.16),XLOOKUP("B",Inputs!$A$115:$A$117,Inputs!$B$115:$B$117)),XLOOKUP(XLOOKUP("PROVEEDOR ELEGIDO*",Inputs!$A$113:$A$118,Inputs!$B$113:$B$118,"",2),Inputs!$A$115:$A$117,Inputs!$B$115:$B$117)) | I26: =F26*H26 -> 0 | J26: =XLOOKUP(XLOOKUP("PROVEEDOR ELEGIDO*",Inputs!$A$113:$A$118,Inputs!$B$113:$B$118,"",2),Inputs!$A$115:$A$117,Inputs!$C$115:$C$117) | K26: ="Q"&(VALUE(MID(B26,2,10))+IF(ISNUMBER(SEARCH("+2",J26)),2,IF(ISNUMBER(SEARCH("+8",J26)),8,0)))
B27: Q2 | C27: =BOM_Consumo!D7 -> 370 | D27: =Inputs!B67 -> 12 | E27: =IF(C27>0,ROUNDUP(C27/D27,0),0) -> 31 | F27: 0 | G27: =F27*D27 -> 0 | H27: =IF(XLOOKUP("PROVEEDOR ELEGIDO*",Inputs!$A$113:$A$118,Inputs!$B$113:$B$118,"",2)="B",IF(SUM($F$26:$F$33)>=XLOOKUP("B",Inputs!$A$115:$A$117,Inputs!$E$115:$E$117),XLOOKUP("B",Inputs!$A$115:$A$117,Inputs!$B$115:$B$117)*(1-0.16),XLOOKUP("B",Inputs!$A$115:$A$117,Inputs!$B$115:$B$117)),XLOOKUP(XLOOKUP("PROVEEDOR ELEGIDO*",Inputs!$A$113:$A$118,Inputs!$B$113:$B$118,"",2),Inputs!$A$115:$A$117,Inputs!$B$115:$B$117)) | I27: =F27*H27 -> 0 | J27: =XLOOKUP(XLOOKUP("PROVEEDOR ELEGIDO*",Inputs!$A$113:$A$118,Inputs!$B$113:$B$118,"",2),Inputs!$A$115:$A$117,Inputs!$C$115:$C$117) | K27: ="Q"&(VALUE(MID(B27,2,10))+IF(ISNUMBER(SEARCH("+2",J27)),2,IF(ISNUMBER(SEARCH("+8",J27)),8,0)))
B28: Q3 | C28: =BOM_Consumo!E7 -> 370 | D28: =Inputs!B67 -> 12 | E28: =IF(C28>0,ROUNDUP(C28/D28,0),0) -> 31 | F28: 0 | G28: =F28*D28 -> 0 | H28: =IF(XLOOKUP("PROVEEDOR ELEGIDO*",Inputs!$A$113:$A$118,Inputs!$B$113:$B$118,"",2)="B",IF(SUM($F$26:$F$33)>=XLOOKUP("B",Inputs!$A$115:$A$117,Inputs!$E$115:$E$117),XLOOKUP("B",Inputs!$A$115:$A$117,Inputs!$B$115:$B$117)*(1-0.16),XLOOKUP("B",Inputs!$A$115:$A$117,Inputs!$B$115:$B$117)),XLOOKUP(XLOOKUP("PROVEEDOR ELEGIDO*",Inputs!$A$113:$A$118,Inputs!$B$113:$B$118,"",2),Inputs!$A$115:$A$117,Inputs!$B$115:$B$117)) | I28: =F28*H28 -> 0 | J28: =XLOOKUP(XLOOKUP("PROVEEDOR ELEGIDO*",Inputs!$A$113:$A$118,Inputs!$B$113:$B$118,"",2),Inputs!$A$115:$A$117,Inputs!$C$115:$C$117) | K28: ="Q"&(VALUE(MID(B28,2,10))+IF(ISNUMBER(SEARCH("+2",J28)),2,IF(ISNUMBER(SEARCH("+8",J28)),8,0)))
B29: Q4 | C29: =BOM_Consumo!F7 -> 370 | D29: =Inputs!B67 -> 12 | E29: =IF(C29>0,ROUNDUP(C29/D29,0),0) -> 31 | F29: 0 | G29: =F29*D29 -> 0 | H29: =IF(XLOOKUP("PROVEEDOR ELEGIDO*",Inputs!$A$113:$A$118,Inputs!$B$113:$B$118,"",2)="B",IF(SUM($F$26:$F$33)>=XLOOKUP("B",Inputs!$A$115:$A$117,Inputs!$E$115:$E$117),XLOOKUP("B",Inputs!$A$115:$A$117,Inputs!$B$115:$B$117)*(1-0.16),XLOOKUP("B",Inputs!$A$115:$A$117,Inputs!$B$115:$B$117)),XLOOKUP(XLOOKUP("PROVEEDOR ELEGIDO*",Inputs!$A$113:$A$118,Inputs!$B$113:$B$118,"",2),Inputs!$A$115:$A$117,Inputs!$B$115:$B$117)) | I29: =F29*H29 -> 0 | J29: =XLOOKUP(XLOOKUP("PROVEEDOR ELEGIDO*",Inputs!$A$113:$A$118,Inputs!$B$113:$B$118,"",2),Inputs!$A$115:$A$117,Inputs!$C$115:$C$117) | K29: ="Q"&(VALUE(MID(B29,2,10))+IF(ISNUMBER(SEARCH("+2",J29)),2,IF(ISNUMBER(SEARCH("+8",J29)),8,0)))
B30: Q5 | C30: =BOM_Consumo!G7 -> 370 | D30: =Inputs!B67 -> 12 | E30: =IF(C30>0,ROUNDUP(C30/D30,0),0) -> 31 | F30: 0 | G30: =F30*D30 -> 0 | H30: =IF(XLOOKUP("PROVEEDOR ELEGIDO*",Inputs!$A$113:$A$118,Inputs!$B$113:$B$118,"",2)="B",IF(SUM($F$26:$F$33)>=XLOOKUP("B",Inputs!$A$115:$A$117,Inputs!$E$115:$E$117),XLOOKUP("B",Inputs!$A$115:$A$117,Inputs!$B$115:$B$117)*(1-0.16),XLOOKUP("B",Inputs!$A$115:$A$117,Inputs!$B$115:$B$117)),XLOOKUP(XLOOKUP("PROVEEDOR ELEGIDO*",Inputs!$A$113:$A$118,Inputs!$B$113:$B$118,"",2),Inputs!$A$115:$A$117,Inputs!$B$115:$B$117)) | I30: =F30*H30 -> 0 | J30: =XLOOKUP(XLOOKUP("PROVEEDOR ELEGIDO*",Inputs!$A$113:$A$118,Inputs!$B$113:$B$118,"",2),Inputs!$A$115:$A$117,Inputs!$C$115:$C$117) | K30: ="Q"&(VALUE(MID(B30,2,10))+IF(ISNUMBER(SEARCH("+2",J30)),2,IF(ISNUMBER(SEARCH("+8",J30)),8,0)))
B31: Q6 | C31: =BOM_Consumo!H7 -> 370 | D31: =Inputs!B67 -> 12 | E31: =IF(C31>0,ROUNDUP(C31/D31,0),0) -> 31 | F31: 0 | G31: =F31*D31 -> 0 | H31: =IF(XLOOKUP("PROVEEDOR ELEGIDO*",Inputs!$A$113:$A$118,Inputs!$B$113:$B$118,"",2)="B",IF(SUM($F$26:$F$33)>=XLOOKUP("B",Inputs!$A$115:$A$117,Inputs!$E$115:$E$117),XLOOKUP("B",Inputs!$A$115:$A$117,Inputs!$B$115:$B$117)*(1-0.16),XLOOKUP("B",Inputs!$A$115:$A$117,Inputs!$B$115:$B$117)),XLOOKUP(XLOOKUP("PROVEEDOR ELEGIDO*",Inputs!$A$113:$A$118,Inputs!$B$113:$B$118,"",2),Inputs!$A$115:$A$117,Inputs!$B$115:$B$117)) | I31: =F31*H31 -> 0 | J31: =XLOOKUP(XLOOKUP("PROVEEDOR ELEGIDO*",Inputs!$A$113:$A$118,Inputs!$B$113:$B$118,"",2),Inputs!$A$115:$A$117,Inputs!$C$115:$C$117) | K31: ="Q"&(VALUE(MID(B31,2,10))+IF(ISNUMBER(SEARCH("+2",J31)),2,IF(ISNUMBER(SEARCH("+8",J31)),8,0)))
B32: Q7 | C32: =BOM_Consumo!I7 -> 370 | D32: =Inputs!B67 -> 12 | E32: =IF(C32>0,ROUNDUP(C32/D32,0),0) -> 31 | F32: 0 | G32: =F32*D32 -> 0 | H32: =IF(XLOOKUP("PROVEEDOR ELEGIDO*",Inputs!$A$113:$A$118,Inputs!$B$113:$B$118,"",2)="B",IF(SUM($F$26:$F$33)>=XLOOKUP("B",Inputs!$A$115:$A$117,Inputs!$E$115:$E$117),XLOOKUP("B",Inputs!$A$115:$A$117,Inputs!$B$115:$B$117)*(1-0.16),XLOOKUP("B",Inputs!$A$115:$A$117,Inputs!$B$115:$B$117)),XLOOKUP(XLOOKUP("PROVEEDOR ELEGIDO*",Inputs!$A$113:$A$118,Inputs!$B$113:$B$118,"",2),Inputs!$A$115:$A$117,Inputs!$B$115:$B$117)) | I32: =F32*H32 -> 0 | J32: =XLOOKUP(XLOOKUP("PROVEEDOR ELEGIDO*",Inputs!$A$113:$A$118,Inputs!$B$113:$B$118,"",2),Inputs!$A$115:$A$117,Inputs!$C$115:$C$117) | K32: ="Q"&(VALUE(MID(B32,2,10))+IF(ISNUMBER(SEARCH("+2",J32)),2,IF(ISNUMBER(SEARCH("+8",J32)),8,0)))
B33: Q8 | C33: =BOM_Consumo!J7 -> 370 | D33: =Inputs!B67 -> 12 | E33: =IF(C33>0,ROUNDUP(C33/D33,0),0) -> 31 | F33: 0 | G33: =F33*D33 -> 0 | H33: =IF(XLOOKUP("PROVEEDOR ELEGIDO*",Inputs!$A$113:$A$118,Inputs!$B$113:$B$118,"",2)="B",IF(SUM($F$26:$F$33)>=XLOOKUP("B",Inputs!$A$115:$A$117,Inputs!$E$115:$E$117),XLOOKUP("B",Inputs!$A$115:$A$117,Inputs!$B$115:$B$117)*(1-0.16),XLOOKUP("B",Inputs!$A$115:$A$117,Inputs!$B$115:$B$117)),XLOOKUP(XLOOKUP("PROVEEDOR ELEGIDO*",Inputs!$A$113:$A$118,Inputs!$B$113:$B$118,"",2),Inputs!$A$115:$A$117,Inputs!$B$115:$B$117)) | I33: =F33*H33 -> 0 | J33: =XLOOKUP(XLOOKUP("PROVEEDOR ELEGIDO*",Inputs!$A$113:$A$118,Inputs!$B$113:$B$118,"",2),Inputs!$A$115:$A$117,Inputs!$C$115:$C$117) | K33: ="Q"&(VALUE(MID(B33,2,10))+IF(ISNUMBER(SEARCH("+2",J33)),2,IF(ISNUMBER(SEARCH("+8",J33)),8,0)))

Sheet Assemblies
A1: Assembly | B1: Holding Cost
A2: A | B2: 0.2
A3: B | B3: 0.4
A4: C | B4: 0.6
A5: D | B5: 0.2

Sheet Costos
A1: COSTOS - Análisis Completo
A2: Costo Total = Costo de Compra + Ordering Cost + Holding Cost
A4: Material | B4: Costo Compra | C4: # Pedidos | D4: Ordering Cost | E4: Holding Cost | F4: Costo Total
A5: Pieza 1 | B5: =Compras_y_Lotes!H7 -> 0 | C5: 1 | D5: 0 | E5: 0 | F5: =B5+D5+E5 -> 0
A6: Pieza 2 | B6: =Compras_y_Lotes!H8 -> #VALUE! | C6: 1 | D6: 0 | E6: 0 | F6: =B6+D6+E6 -> #VALUE!
A7: Pieza 3 | B7: =Compras_y_Lotes!H9 -> 555000 | C7: 1 | D7: 0 | E7: 0 | F7: =B7+D7+E7 -> 555000
A8: Pieza 4 | B8: =Compras_y_Lotes!H10 -> 29370 | C8: 1 | D8: 0 | E8: 0 | F8: =B8+D8+E8 -> 29370
A9: Pieza 5 | B9: =Compras_y_Lotes!H11 -> 59220 | C9: 1 | D9: 0 | E9: 0 | F9: =B9+D9+E9 -> 59220
A10: Pieza 6 | B10: =Compras_y_Lotes!H12 -> 1295 | C10: 1 | D10: 0 | E10: 0 | F10: =B10+D10+E10 -> 1295
A11: Parte A | B11: =SUM(Compras_y_Lotes!I18:I25) -> 0 | C11: =COUNTIF(Compras_y_Lotes!F18:F25,">0") -> 0 | D11: =C11*XLOOKUP(A11,Inputs!$A$95:$A$101,Inputs!$B$95:$B$101) | E11: =SUMPRODUCT((Inventario_Dinamico!B7:I7+Inventario_Dinamico!B10:I10)/2)*XLOOKUP(A11,Inputs!$A$95:$A$101,Inputs!$C$95:$C$101) | F11: =B11+D11+E11 -> 0
A12: Parte B | B12: =SUM(Compras_y_Lotes!I26:I33) -> 0 | C12: =COUNTIF(Compras_y_Lotes!F26:F33,">0") -> 0 | D12: =C12*XLOOKUP(A12,Inputs!$A$95:$A$101,Inputs!$B$95:$B$101) | E12: =SUMPRODUCT((Inventario_Dinamico!B13:I13+Inventario_Dinamico!B16:I16)/2)*XLOOKUP(A12,Inputs!$A$95:$A$101,Inputs!$C$95:$C$101) | F12: =B12+D12+E12 -> 0
A13: COSTO TOTAL | B13: =SUM(B5:B12) -> #VALUE! | C13: =SUM(C5:C12) -> 6 | D13: =SUM(D5:D12) -> 0 | E13: =SUM(E5:E12) -> 0 | F13: =SUM(F5:F12) -> #VALUE!

Sheet Cashflow_Compras
A1: CASHFLOW - Pagos por Quincena
A2: Proyección de pagos según términos de cada proveedor
A3: IMPORTANTE: Coordinar con Finanzas para asegurar liquidez
A5: Concepto | B5: Q1 | C5: Q2 | D5: Q3 | E5: Q4 | F5: Q5 | G5: Q6 | H5: Q7 | I5: Q8 | J5: TOTAL
A6: Piezas 1-6 (t=0) | B6: =Compras_y_Lotes!H13 -> #VALUE! | C6: 0 | D6: 0 | E6: 0 | F6: 0 | G6: 0 | H6: 0 | I6: 0 | J6: =SUM(B6:I6) -> #VALUE!
A7: Parte A | B7: 0 | C7: 0 | D7: 0 | E7: 0 | F7: 0 | G7: 0 | H7: 0 | I7: 0 | J7: =SUM(B7:I7) -> 0
A8: Parte B | B8: 0 | C8: 0 | D8: 0 | E8: 0 | F8: 0 | G8: 0 | H8: 0 | I8: 0 | J8: =SUM(B8:I8) -> 0
A9: TOTAL PAGOS | B9: =SUM(B6:B8) -> #VALUE! | C9: =SUM(C6:C8) -> 0 | D9: =SUM(D6:D8) -> 0 | E9: =SUM(E6:E8) -> 0 | F9: =SUM(F6:F8) -> 0 | G9: =SUM(G6:G8) -> 0 | H9: =SUM(H6:H8) -> 0 | I9: =SUM(I6:I8) -> 0 | J9: =SUM(B9:I9) -> #VALUE!

Sheet Escenarios
A1: ESCENARIOS - Análisis Comparativo
A2: Compara 3 estrategias: Conservador / Base / Agresivo
A4: SELECCIONAR ESCENARIO: | B4: Base
A6: Parámetro | B6: Conservador | C6: Base | D6: Agresivo | E6: Descripción
A7: Safety Stock | B7: 20% | C7: 10% | D7: 5% | E7: % sobre consumo promedio
A8: Proveedor Parte A | B8: A (seguro) | C8: A | D8: B (descuento) | E8: Estrategia de proveedor
A9: Proveedor Parte B | B9: A (seguro) | C9: A | D9: B (descuento) | E9: Estrategia de proveedor
A10: Frecuencia Pedidos | B10: Cada 4Q | C10: Cada 2Q | D10: Cada Q | E10: Frecuencia de compra
A12: RESULTADOS ESTIMADOS
A13: Costo Total | B13: Alto | C13: Medio | D13: Bajo | E13: Costo de compras + inventario
A14: Riesgo Stockout | B14: Muy Bajo | C14: Bajo | D14: Medio | E14: Probabilidad de quedarse sin stock
A15: Capital Inmovilizado | B15: Alto | C15: Medio | D15: Bajo | E15: Inventario promedio
A16: Cashflow Peak | B16: Distribuido | C16: Medio | D16: Concentrado | E16: Pago máximo en una Q
A20: COMPARACIÓN LADO A LADO - KPIs POR ESCENARIO
A21: KPI | B21: Conservador | C21: Base | D21: Agresivo | E21: Mejor | F21: Diferencia
A22: Costo Total Compras | B22: =Costos!F13 -> #VALUE! | C22: =Costos!F13 -> #VALUE! | D22: =Costos!F13*0.9 -> #VALUE! | E22: =MIN(B22:D22) -> #VALUE! | F22: =MAX(B22:D22)-MIN(B22:D22) -> #VALUE!
A23: Total Pagos | B23: =Cashflow_Integrado!J33 -> 0 | C23: =Cashflow_Integrado!J33 -> 0 | D23: =Cashflow_Integrado!J33*0.92 -> 0 | E23: =MIN(B23:D23) -> 0 | F23: =MAX(B23:D23)-MIN(B23:D23) -> 0
A24: Pago Peak | B24: =Cashflow_Integrado!B37 -> 0 | C24: =Cashflow_Integrado!B37 -> 0 | D24: =Cashflow_Integrado!B37*1.15 -> 0 | E24: =MIN(B24:D24) -> 0 | F24: =MAX(B24:D24)-MIN(B24:D24) -> 0
A25: # Stockouts Esperados | B25: 0 | C25: 1 | D25: 3 | E25: =MIN(B25:D25) -> 0 | F25: =MAX(B25:D25)-MIN(B25:D25) -> 3
A26: Valor Esperado Pérdida | B26: =Riesgo_Proveedor_B!I14 -> 0 | C26: =Riesgo_Proveedor_B!I14 -> 0 | D26: =Riesgo_Proveedor_B!I14*2.5 -> 0 | E26: =MIN(B26:D26) -> 0 | F26: =MAX(B26:D26)-MIN(B26:D26) -> 0
A27: Buffer Promedio (Q) | B27: 1.5 | C27: 1 | D27: 0.5 | E27: =MAX(B27:D27) -> 1.5 | F27: =MAX(B27:D27)-MIN(B27:D27) -> 1

Sheet Analisis_Proveedores
A1: ANÁLISIS DE PROVEEDORES - Herramienta de Decisión
A2: Compara costo total por proveedor según volumen y términos
A4: PARTE A - Análisis Comparativo
A5: Volumen a Comprar (batches): | B5: =SUM(Compras_y_Lotes!F18:F25)
A7: Proveedor | B7: Precio Base | C7: Descuento | D7: MOQ Desc. | E7: Precio Final | F7: Costo Compra | G7: Términos Pago | H7: Riesgo | I7: Costo Ajustado | J7: Ranking
A8: A | B8: =XLOOKUP(A8,Inputs!$A$107:$A$109,Inputs!$B$107:$B$109) | C8: =LET(txt,XLOOKUP(A8,Inputs!$A$107:$A$109,Inputs!$D$107:$D$109),IFERROR(VALUE(LEFT(txt,FIND("%",txt)-1))/100,0)) | D8: =IFERROR(--XLOOKUP(A8,Inputs!$A$107:$A$109,Inputs!$E$107:$E$109),0) | E8: =B8 -> 125 | F8: =B5*E8 -> 68750 | G8: =XLOOKUP(A8,Inputs!$A$107:$A$109,Inputs!$C$107:$C$109) | H8: =LET(txt,XLOOKUP(A8,Inputs!$A$107:$A$109,Inputs!$F$107:$F$109),IFERROR(1-VALUE(LEFT(txt,FIND("%",txt)-1))/100,0)) | I8: =F8 -> 68750 | J8: 0
A9: B | B9: =XLOOKUP(A9,Inputs!$A$107:$A$109,Inputs!$B$107:$B$109) | C9: =LET(txt,XLOOKUP(A9,Inputs!$A$107:$A$109,Inputs!$D$107:$D$109),IFERROR(VALUE(LEFT(txt,FIND("%",txt)-1))/100,0)) | D9: =IFERROR(--XLOOKUP(A9,Inputs!$A$107:$A$109,Inputs!$E$107:$E$109),0) | E9: =IF(B5>=D9,B9*(1-C9),B9) -> 105 | F9: =B5*E9 -> 57750 | G9: =XLOOKUP(A9,Inputs!$A$107:$A$109,Inputs!$C$107:$C$109) | H9: =LET(txt,XLOOKUP(A9,Inputs!$A$107:$A$109,Inputs!$F$107:$F$109),IFERROR(1-VALUE(LEFT(txt,FIND("%",txt)-1))/100,0)) | I9: =F9*1.05 -> 60637.5 | J9: 0
A10: C | B10: =XLOOKUP(A10,Inputs!$A$107:$A$109,Inputs!$B$107:$B$109) | C10: =LET(txt,XLOOKUP(A10,Inputs!$A$107:$A$109,Inputs!$D$107:$D$109),IFERROR(VALUE(LEFT(txt,FIND("%",txt)-1))/100,0)) | D10: =IFERROR(--XLOOKUP(A10,Inputs!$A$107:$A$109,Inputs!$E$107:$E$109),0) | E10: =B10 -> 140 | F10: =B5*E10 -> 77000 | G10: =XLOOKUP(A10,Inputs!$A$107:$A$109,Inputs!$C$107:$C$109) | H10: =LET(txt,XLOOKUP(A10,Inputs!$A$107:$A$109,Inputs!$F$107:$F$109),IFERROR(1-VALUE(LEFT(txt,FIND("%",txt)-1))/100,0)) | I10: =F10*0.97 -> 74690 | J10: 0
A11: RECOMENDACIÓN: | B11: =INDEX(A8:A10,MATCH(MIN(I8:I10),I8:I10,0)) -> B
A14: PARTE B - Análisis Comparativo
A15: Volumen a Comprar (batches): | B15: =SUM(Compras_y_Lotes!F26:F33)
A17: Proveedor | B17: 330 | C17: Descuento | D17: MOQ Desc. | E17: Precio Final | F17: Costo Compra | G17: Términos Pago | H17: Riesgo | I17: Costo Ajustado | J17: Ranking
A18: A | B18: =XLOOKUP(A18,Inputs!$A$115:$A$117,Inputs!$B$115:$B$117) | C18: =LET(txt,XLOOKUP(A18,Inputs!$A$115:$A$117,Inputs!$D$115:$D$117),IFERROR(VALUE(LEFT(txt,FIND("%",txt)-1))/100,0)) | D18: =IFERROR(--XLOOKUP(A18,Inputs!$A$115:$A$117,Inputs!$E$115:$E$117),0) | E18: =B18 -> 264 | F18: =B15*E18 -> 50160 | G18: =XLOOKUP(A18,Inputs!$A$115:$A$117,Inputs!$C$115:$C$117) | H18: =LET(txt,XLOOKUP(A18,Inputs!$A$115:$A$117,Inputs!$F$115:$F$117),IFERROR(1-VALUE(LEFT(txt,FIND("%",txt)-1))/100,0)) | I18: =F17 -> Costo Compra | J18: 0
A19: B | B19: =XLOOKUP(A19,Inputs!$A$115:$A$117,Inputs!$B$115:$B$117) | C19: =LET(txt,XLOOKUP(A19,Inputs!$A$115:$A$117,Inputs!$D$115:$D$117),IFERROR(VALUE(LEFT(txt,FIND("%",txt)-1))/100,0)) | D19: =IFERROR(--XLOOKUP(A19,Inputs!$A$115:$A$117,Inputs!$E$115:$E$117),0) | E19: =IF(B15>=D19,B19*(1-C19),B19) -> 296 | F19: =B15*E19 -> 56240 | G19: =XLOOKUP(A19,Inputs!$A$115:$A$117,Inputs!$C$115:$C$117) | H19: =LET(txt,XLOOKUP(A19,Inputs!$A$115:$A$117,Inputs!$F$115:$F$117),IFERROR(1-VALUE(LEFT(txt,FIND("%",txt)-1))/100,0)) | I19: =F19*1.05 -> 59052 | J19: 0
A20: C | B20: =XLOOKUP(A20,Inputs!$A$115:$A$117,Inputs!$B$115:$B$117) | C20: =LET(txt,XLOOKUP(A20,Inputs!$A$115:$A$117,Inputs!$D$115:$D$117),IFERROR(VALUE(LEFT(txt,FIND("%",txt)-1))/100,0)) | D20: =IFERROR(--XLOOKUP(A20,Inputs!$A$115:$A$117,Inputs!$E$115:$E$117),0) | E20: =B20 -> 370 | F20: =B15*E20 -> 70300 | G20: =XLOOKUP(A20,Inputs!$A$115:$A$117,Inputs!$C$115:$C$117) | H20: =LET(txt,XLOOKUP(A20,Inputs!$A$115:$A$117,Inputs!$F$115:$F$117),IFERROR(1-VALUE(LEFT(txt,FIND("%",txt)-1))/100,0)) | I20: =F20*0.97 -> 68191 | J20: 0
A21: RECOMENDACIÓN: | B21: =INDEX(A18:A20,MATCH(MIN(I18:I20),I18:I20,0)) -> B

Sheet Dashboard
A1: DASHBOARD - Purchasing Manager
A3: INDICADORES CLAVE (KPIs)
A5: Costo Total de Compras: | B5: =Costos!F13 -> #VALUE!
A6: Total Pagos Periodo: | B6: =Cashflow_Compras!J9 -> #VALUE!
A7: # Pedidos Totales: | B7: =SUM(Costos!C5:C12) -> 6 | C7: pedidos
A8: Pago Pico (Max en una Q): | B8: =MAX(Cashflow_Compras!B9:I9) -> #VALUE!
A10: Inventario Negativo: | B10: TBD | C10: materiales
A11: Stock < Safety: | B11: TBD | C11: materiales
A14: ESTRATEGIA ACTUAL
A16: Proveedor Parte A: | B16: =Inputs!B94 -> Ordering Cost
A17: Proveedor Parte B: | B17: =Inputs!B110 -> C
A18: Escenario: | B18: =Escenarios!B4 -> Base
A25: ⚠️ ALERTAS CRÍTICAS
A27: Materiales con Inv < Buffer: | B27: =COUNTIF(Inventario_Dinamico!J52:J59,"<0") -> 0 | C27: materiales
A28: Riesgo por Proveedor B: | B28: =IF(OR(Inputs!B94="B",Inputs!B110="B"),"SÍ - REVISAR","NO") -> NO
A29: Cashflow Peak > $100k: | B29: =IF(Cashflow_Integrado!B37>100000,"SÍ - ALERTA","NO") -> NO

Sheet Riesgo_Proveedor_B
A1: ANÁLISIS DE RIESGO - PROVEEDOR B
A2: CRÍTICO: Proveedor B tiene 20% probabilidad de NO ENTREGAR (sin pago, pero SIN producción)
A4: PARÁMETROS DE RIESGO
A6: Parámetro | B6: Valor | C6: Fuente
A7: Prob. Incumplimiento Prov. B | B7: 0.2 | C7: EXSIM Rules
A8: Costo Oportunidad ($/EC perdido) | B8: 150 | C8: Margin estimado
A9: Lead time recuperación (Q) | B9: 1 | C9: Assumption
A12: ANÁLISIS DE IMPACTO POR MATERIAL (si usas Proveedor B)
A13: Material | B13: Proveedor Elegido | C13: Total Lotes P7 | D13: Prob. Falla | E13: Lotes Perdidos (Esperado) | F13: Unidades Perdidas | G13: EC Sin Producir | H13: Costo Oportunidad | I13: Valor Esperado Pérdida
A14: Parte A | B14: =XLOOKUP("PROVEEDOR ELEGIDO*",Inputs!$A$105:$A$110,Inputs!$B$105:$B$110,"",2) | C14: =SUM(Compras_y_Lotes!F18:F25) -> 0 | D14: =IF(B14="B",$B$7,0) -> 0 | E14: =C14*D14 -> 0 | F14: =E14*XLOOKUP(A14,Inputs!$A$66:$A$73,Inputs!$B$66:$B$73) | G14: =F14/XLOOKUP(A14,Inputs!$A$48:$A$55,Inputs!$B$48:$B$55) | H14: =G14*$B$8 -> 0 | I14: =H14 -> 0
A15: Parte B | B15: =XLOOKUP("PROVEEDOR ELEGIDO*",Inputs!$A$113:$A$118,Inputs!$B$113:$B$118,"",2) | C15: =SUM(Compras_y_Lotes!F26:F33) -> 0 | D15: =IF(B15="B",$B$7,0) -> 0 | E15: =C15*D15 -> 0 | F15: =E15*XLOOKUP(A15,Inputs!$A$66:$A$73,Inputs!$B$66:$B$73) | G15: =F15/XLOOKUP(A15,Inputs!$A$48:$A$55,Inputs!$B$48:$B$55) | H15: =G15*$B$8 -> 0 | I15: =H15 -> 0
A18: DECISIÓN: PROVEEDOR A vs B (Análisis Ajustado por Riesgo)
A19: Material | B19: Proveedor | C19: Costo Compra | D19: Descuento | E19: Ahorro | F19: Valor Esperado Pérdida | G19: Costo Neto Ajustado | H19: Decisión Recomendada
A20: Parte A | B20: A | C20: =SUM(Compras_y_Lotes!I18:I25) -> 0 | D20: 0 | E20: 0 | F20: 0 | G20: =C20+F20 -> 0
B21: B | C21: =IF(SUM(Compras_y_Lotes!F18:F25)>=150,C20*(1-0.16),C20) -> 0 | D21: 0.16 | E21: =C20-C21 -> 0 | F21: =I14 -> 0 | G21: =C21+F21 -> 0
A22: Parte B | B22: A | C22: =SUM(Compras_y_Lotes!I26:I33) -> 0 | D22: 0 | E22: 0 | F22: 0 | G22: =C22+F22 -> 0
B23: B | C23: =IF(SUM(Compras_y_Lotes!F26:F33)>=80,C22*(1-0.16),C22) | D23: 0.2 | E23: =C22-C23 -> 0 | F23: =I15 -> 0 | G23: =C23+F23 -> 0

Sheet Cashflow_Integrado
A1: CASHFLOW INTEGRADO - PURCHASING
A2: Pagos REALES por quincena: Compras + Ordering + Holding (para coordinar con Finanzas)
A4: 1. PAGOS DE COMPRAS (según términos de proveedor)
A5: Concepto | B5: Q1 | C5: Q2 | D5: Q3 | E5: Q4 | F5: Q5 | G5: Q6 | H5: Q7 | I5: Q8 | J5: TOTAL
A6: Piezas 1-6 (t=0) | B6: =Compras_y_Lotes!H13 -> #VALUE! | C6: 0 | D6: 0 | E6: 0 | F6: 0 | G6: 0 | H6: 0 | I6: 0 | J6: =B6 -> #VALUE!
A7: Parte A (según proveedor) | B7: =SUMIFS(Compras_y_Lotes!$I$18:$I$25,Compras_y_Lotes!$K$18:$K$25,B$5) | C7: =SUMIFS(Compras_y_Lotes!$I$18:$I$25,Compras_y_Lotes!$K$18:$K$25,C$5) | D7: =SUMIFS(Compras_y_Lotes!$I$18:$I$25,Compras_y_Lotes!$K$18:$K$25,D$5) | E7: =SUMIFS(Compras_y_Lotes!$I$18:$I$25,Compras_y_Lotes!$K$18:$K$25,E$5) | F7: =SUMIFS(Compras_y_Lotes!$I$18:$I$25,Compras_y_Lotes!$K$18:$K$25,F$5) | G7: =SUMIFS(Compras_y_Lotes!$I$18:$I$25,Compras_y_Lotes!$K$18:$K$25,G$5) | H7: =SUMIFS(Compras_y_Lotes!$I$18:$I$25,Compras_y_Lotes!$K$18:$K$25,H$5) | I7: =SUMIFS(Compras_y_Lotes!$I$18:$I$25,Compras_y_Lotes!$K$18:$K$25,I$5) | J7: =SUM(B7:I7) -> 0
A8: Parte B (según proveedor) | B8: =SUMIFS(Compras_y_Lotes!$I$26:$I$33,Compras_y_Lotes!$K$26:$K$33,B$5) | C8: =SUMIFS(Compras_y_Lotes!$I$26:$I$33,Compras_y_Lotes!$K$26:$K$33,C$5) | D8: =SUMIFS(Compras_y_Lotes!$I$26:$I$33,Compras_y_Lotes!$K$26:$K$33,D$5) | E8: =SUMIFS(Compras_y_Lotes!$I$26:$I$33,Compras_y_Lotes!$K$26:$K$33,E$5) | F8: =SUMIFS(Compras_y_Lotes!$I$26:$I$33,Compras_y_Lotes!$K$26:$K$33,F$5) | G8: =SUMIFS(Compras_y_Lotes!$I$26:$I$33,Compras_y_Lotes!$K$26:$K$33,G$5) | H8: =SUMIFS(Compras_y_Lotes!$I$26:$I$33,Compras_y_Lotes!$K$26:$K$33,H$5) | I8: =SUMIFS(Compras_y_Lotes!$I$26:$I$33,Compras_y_Lotes!$K$26:$K$33,I$5) | J8: =SUM(B8:I8) -> 0
A9: SUBTOTAL COMPRAS | B9: =SUM(B6:B8) -> #VALUE! | C9: =SUM(C6:C8) -> 0 | D9: =SUM(D6:D8) -> 0 | E9: =SUM(E6:E8) -> 0 | F9: =SUM(F6:F8) -> 0 | G9: =SUM(G6:G8) -> 0 | H9: =SUM(H6:H8) -> 0 | I9: =SUM(I6:I8) -> 0 | J9: =SUM(J6:J8) -> #VALUE!
A12: 2. ORDERING COSTS (por pedido realizado)
A13: Concepto | B13: Q1 | C13: Q2 | D13: Q3 | E13: Q4 | F13: Q5 | G13: Q6 | H13: Q7 | I13: Q8 | J13: TOTAL
A14: Parte A | B14: =IF(Compras_y_Lotes!F18>0,XLOOKUP($A14,Inputs!$A$95:$A$101,Inputs!$B$95:$B$101),0) | C14: =IF(Compras_y_Lotes!F19>0,XLOOKUP($A14,Inputs!$A$95:$A$101,Inputs!$B$95:$B$101),0) | D14: =IF(Compras_y_Lotes!F20>0,XLOOKUP($A14,Inputs!$A$95:$A$101,Inputs!$B$95:$B$101),0) | E14: =IF(Compras_y_Lotes!F21>0,XLOOKUP($A14,Inputs!$A$95:$A$101,Inputs!$B$95:$B$101),0) | F14: =IF(Compras_y_Lotes!F22>0,XLOOKUP($A14,Inputs!$A$95:$A$101,Inputs!$B$95:$B$101),0) | G14: =IF(Compras_y_Lotes!F23>0,XLOOKUP($A14,Inputs!$A$95:$A$101,Inputs!$B$95:$B$101),0) | H14: =IF(Compras_y_Lotes!F24>0,XLOOKUP($A14,Inputs!$A$95:$A$101,Inputs!$B$95:$B$101),0) | I14: =IF(Compras_y_Lotes!F25>0,XLOOKUP($A14,Inputs!$A$95:$A$101,Inputs!$B$95:$B$101),0) | J14: =SUM(B14:I14) -> 0
A15: Parte B | B15: =IF(Compras_y_Lotes!F26>0,XLOOKUP($A15,Inputs!$A$95:$A$101,Inputs!$B$95:$B$101),0) | C15: =IF(Compras_y_Lotes!F27>0,XLOOKUP($A15,Inputs!$A$95:$A$101,Inputs!$B$95:$B$101),0) | D15: =IF(Compras_y_Lotes!F28>0,XLOOKUP($A15,Inputs!$A$95:$A$101,Inputs!$B$95:$B$101),0) | E15: =IF(Compras_y_Lotes!F29>0,XLOOKUP($A15,Inputs!$A$95:$A$101,Inputs!$B$95:$B$101),0) | F15: =IF(Compras_y_Lotes!F30>0,XLOOKUP($A15,Inputs!$A$95:$A$101,Inputs!$B$95:$B$101),0) | G15: =IF(Compras_y_Lotes!F31>0,XLOOKUP($A15,Inputs!$A$95:$A$101,Inputs!$B$95:$B$101),0) | H15: =IF(Compras_y_Lotes!F32>0,XLOOKUP($A15,Inputs!$A$95:$A$101,Inputs!$B$95:$B$101),0) | I15: =IF(Compras_y_Lotes!F33>0,XLOOKUP($A15,Inputs!$A$95:$A$101,Inputs!$B$95:$B$101),0) | J15: =SUM(B15:I15) -> 0
A16: SUBTOTAL ORDERING | B16: =SUM(B14:B15) -> 0 | C16: =SUM(C14:C15) -> 0 | D16: =SUM(D14:D15) -> 0 | E16: =SUM(E14:E15) -> 0 | F16: =SUM(F14:F15) -> 0 | G16: =SUM(G14:G15) -> 0 | H16: =SUM(H14:H15) -> 0 | I16: =SUM(I14:I15) -> 0 | J16: =SUM(J14:J15) -> 0
A19: 3. HOLDING COSTS (por inventario promedio en quincena)
A20: Concepto | B20: Q1 | C20: Q2 | D20: Q3 | E20: Q4 | F20: Q5 | G20: Q6 | H20: Q7 | I20: Q8 | J20: TOTAL
A21: Parte A | B21: =(Inventario_Dinamico!B7+Inventario_Dinamico!B10)/2*XLOOKUP($A21,Inputs!$A$95:$A$101,Inputs!$C$95:$C$101) | C21: =(Inventario_Dinamico!C7+Inventario_Dinamico!C10)/2*XLOOKUP($A21,Inputs!$A$95:$A$101,Inputs!$C$95:$C$101) | D21: =(Inventario_Dinamico!D7+Inventario_Dinamico!D10)/2*XLOOKUP($A21,Inputs!$A$95:$A$101,Inputs!$C$95:$C$101) | E21: =(Inventario_Dinamico!E7+Inventario_Dinamico!E10)/2*XLOOKUP($A21,Inputs!$A$95:$A$101,Inputs!$C$95:$C$101) | F21: =(Inventario_Dinamico!F7+Inventario_Dinamico!F10)/2*XLOOKUP($A21,Inputs!$A$95:$A$101,Inputs!$C$95:$C$101) | G21: =(Inventario_Dinamico!G7+Inventario_Dinamico!G10)/2*XLOOKUP($A21,Inputs!$A$95:$A$101,Inputs!$C$95:$C$101) | H21: =(Inventario_Dinamico!H7+Inventario_Dinamico!H10)/2*XLOOKUP($A21,Inputs!$A$95:$A$101,Inputs!$C$95:$C$101) | I21: =(Inventario_Dinamico!I7+Inventario_Dinamico!I10)/2*XLOOKUP($A21,Inputs!$A$95:$A$101,Inputs!$C$95:$C$101) | J21: =SUM(B21:I21) -> -23379.2
A22: Parte B | B22: =(Inventario_Dinamico!B13+Inventario_Dinamico!B16)/2*XLOOKUP($A22,Inputs!$A$95:$A$101,Inputs!$C$95:$C$101) | C22: =(Inventario_Dinamico!C13+Inventario_Dinamico!C16)/2*XLOOKUP($A22,Inputs!$A$95:$A$101,Inputs!$C$95:$C$101) | D22: =(Inventario_Dinamico!D13+Inventario_Dinamico!D16)/2*XLOOKUP($A22,Inputs!$A$95:$A$101,Inputs!$C$95:$C$101) | E22: =(Inventario_Dinamico!E13+Inventario_Dinamico!E16)/2*XLOOKUP($A22,Inputs!$A$95:$A$101,Inputs!$C$95:$C$101) | F22: =(Inventario_Dinamico!F13+Inventario_Dinamico!F16)/2*XLOOKUP($A22,Inputs!$A$95:$A$101,Inputs!$C$95:$C$101) | G22: =(Inventario_Dinamico!G13+Inventario_Dinamico!G16)/2*XLOOKUP($A22,Inputs!$A$95:$A$101,Inputs!$C$95:$C$101) | H22: =(Inventario_Dinamico!H13+Inventario_Dinamico!H16)/2*XLOOKUP($A22,Inputs!$A$95:$A$101,Inputs!$C$95:$C$101) | I22: =(Inventario_Dinamico!I13+Inventario_Dinamico!I16)/2*XLOOKUP($A22,Inputs!$A$95:$A$101,Inputs!$C$95:$C$101) | J22: =SUM(B22:I22) -> 5673.6
A23: SUBTOTAL HOLDING | B23: =SUM(B21:B22) -> 765.3 | C23: =SUM(C21:C22) -> -85.7 | D23: =SUM(D21:D22) -> -936.7 | E23: =SUM(E21:E22) -> -1787.7 | F23: =SUM(F21:F22) -> -2638.7 | G23: =SUM(G21:G22) -> -3489.7 | H23: =SUM(H21:H22) -> -4340.7 | I23: =SUM(I21:I22) -> -5191.7 | J23: =SUM(J21:J22) -> -17705.6
A26: TOTAL OUTFLOW PURCHASING | B26: =B9+B16+B23 -> #VALUE! | C26: =C9+C16+C23 -> -85.7 | D26: =D9+D16+D23 -> -936.7 | E26: =E9+E16+E23 -> -1787.7 | F26: =F9+F16+F23 -> -2638.7 | G26: =G9+G16+G23 -> -3489.7 | H26: =H9+H16+H23 -> -4340.7 | I26: =I9+I16+I23 -> -5191.7 | J26: =J9+J16+J23 -> #VALUE!
A28: ANÁLISIS
A30: Pago Máximo (Peak): | B30: =MAX(B26:I26) -> #VALUE! | C30: Quincena más costosa
A31: Pago Mínimo: | B31: =MIN(B26:I26) -> #VALUE! | C31: Quincena más barata
A32: Pago Promedio: | B32: =AVERAGE(B26:I26) -> #VALUE! | C32: Promedio por quincena
A33: Desviación Est.: | B33: =STDEV(B26:I26) -> #VALUE! | C33: Volatilidad del flujo

Sheet EXSIM_Upload
A1: EXSIM UPLOAD - COPIAR DIRECTO A PLATAFORMA
A2: Formato exacto para subir decisiones a EXSIM. Copiar columnas B-E directamente.
A4: PIEZAS 1-6 (Compra única en t=0)
A5: Material | B5: Fortnight | C5: Lots | D5: Supplier | E5: Notes
A6: Pieza 1 | B6: 0 | C6: =Compras_y_Lotes!E7 -> 5 | D6: Único | E6: =IF(C6>0,"Comprar","NO COMPRAR") -> Comprar
A7: Pieza 2 | B7: 0 | C7: =Compras_y_Lotes!E8 -> 9867 | D7: Único | E7: =IF(C7>0,"Comprar","NO COMPRAR") -> Comprar
A8: Pieza 3 | B8: 0 | C8: =Compras_y_Lotes!E9 -> 4440 | D8: Único | E8: =IF(C8>0,"Comprar","NO COMPRAR") -> Comprar
A9: Pieza 4 | B9: 0 | C9: =Compras_y_Lotes!E10 -> 89 | D9: Único | E9: =IF(C9>0,"Comprar","NO COMPRAR") -> Comprar
A10: Pieza 5 | B10: 0 | C10: =Compras_y_Lotes!E11 -> 987 | D10: Único | E10: =IF(C10>0,"Comprar","NO COMPRAR") -> Comprar
A11: Pieza 6 | B11: 0 | C11: =Compras_y_Lotes!E12 -> 185 | D11: Único | E11: =IF(C11>0,"Comprar","NO COMPRAR") -> Comprar
A13: PARTE A (Por Quincena)
A14: Material | B14: Fortnight | C14: Lots | D14: Supplier | E14: Notes
A15: Parte A | B15: 1 | C15: =Compras_y_Lotes!F18 -> 0 | D15: =XLOOKUP("PROVEEDOR ELEGIDO*",Inputs!$A$105:$A$110,Inputs!$B$105:$B$110,"",2) | E15: =IF(C15>0,"Comprar","-") -> -
A16: Parte A | B16: 2 | C16: =Compras_y_Lotes!F19 -> 0 | D16: =XLOOKUP("PROVEEDOR ELEGIDO*",Inputs!$A$105:$A$110,Inputs!$B$105:$B$110,"",2) | E16: =IF(C16>0,"Comprar","-") -> -
A17: Parte A | B17: 3 | C17: =Compras_y_Lotes!F20 -> 0 | D17: =XLOOKUP("PROVEEDOR ELEGIDO*",Inputs!$A$105:$A$110,Inputs!$B$105:$B$110,"",2) | E17: =IF(C17>0,"Comprar","-") -> -
A18: Parte A | B18: 4 | C18: =Compras_y_Lotes!F21 -> 0 | D18: =Inputs!B94 -> Ordering Cost | E18: =IF(C18>0,"Comprar","-") -> -
A19: Parte A | B19: 5 | C19: =Compras_y_Lotes!F22 -> 0 | D19: =Inputs!B94 -> Ordering Cost | E19: =IF(C19>0,"Comprar","-") -> -
A20: Parte A | B20: 6 | C20: =Compras_y_Lotes!F23 -> 0 | D20: =Inputs!B94 -> Ordering Cost | E20: =IF(C20>0,"Comprar","-") -> -
A21: Parte A | B21: 7 | C21: =Compras_y_Lotes!F24 -> 0 | D21: =Inputs!B94 -> Ordering Cost | E21: =IF(C21>0,"Comprar","-") -> -
A22: Parte A | B22: 8 | C22: =Compras_y_Lotes!F25 -> 0 | D22: =Inputs!B94 -> Ordering Cost | E22: =IF(C22>0,"Comprar","-") -> -
A24: PARTE B (Por Quincena)
A25: Material | B25: Fortnight | C25: Lots | D25: Supplier | E25: Notes
A26: Parte B | B26: 1 | C26: =Compras_y_Lotes!F26 -> 0 | D26: =Inputs!B110 -> C | E26: =IF(C26>0,"Comprar","-") -> -
A27: Parte B | B27: 2 | C27: =Compras_y_Lotes!F27 -> 0 | D27: =Inputs!B110 -> C | E27: =IF(C27>0,"Comprar","-") -> -
A28: Parte B | B28: 3 | C28: =Compras_y_Lotes!F28 -> 0 | D28: =Inputs!B110 -> C | E28: =IF(C28>0,"Comprar","-") -> -
A29: Parte B | B29: 4 | C29: =Compras_y_Lotes!F29 -> 0 | D29: =Inputs!B110 -> C | E29: =IF(C29>0,"Comprar","-") -> -
A30: Parte B | B30: 5 | C30: =Compras_y_Lotes!F30 -> 0 | D30: =Inputs!B110 -> C | E30: =IF(C30>0,"Comprar","-") -> -
A31: Parte B | B31: 6 | C31: =Compras_y_Lotes!F31 -> 0 | D31: =Inputs!B110 -> C | E31: =IF(C31>0,"Comprar","-") -> -
A32: Parte B | B32: 7 | C32: =Compras_y_Lotes!F32 -> 0 | D32: =Inputs!B110 -> C | E32: =IF(C32>0,"Comprar","-") -> -
A33: Parte B | B33: 8 | C33: =Compras_y_Lotes!F33 -> 0 | D33: =Inputs!B110 -> C | E33: =IF(C33>0,"Comprar","-") -> -

Sheet Multi_Planta
A1: MULTI-PLANTA: CENTRO Y OESTE
A2: Inventarios y producción por región (EXSIM requiere separación)
A4: INVENTARIO POR PLANTA
A5: Material | B5: Centro | C5: Oeste | D5: TOTAL | E5: % Centro
A6: Parte A | B6: 3496 | C6: 1016 | D6: 4512 | E6: =B6/D6 -> 0.7748227
A7: Parte B | B7: 765 | C7: 293 | D7: 1058 | E7: =B7/D7 -> 0.72306238
A8: Pieza 1 | B8: 94 | C8: 36 | D8: 130 | E8: =B8/D8 -> 0.72307692
A9: Pieza 2 | B9: 3844 | C9: 1424 | D9: 5268 | E9: =B9/D9 -> 0.72968869
A10: Pieza 3 | B10: 3125 | C10: 1208 | D10: 4333 | E10: =B10/D10 -> 0.72120932
A11: Pieza 4 | B11: 6131 | C11: 2356 | D11: 8487 | E11: =B11/D11 -> 0.72239896
A12: Pieza 5 | B12: 16736 | C12: 6456 | D12: 23192 | E12: =B12/D12 -> 0.72162815
A13: Pieza 6 | B13: 4439 | C13: 1596 | D13: 6035 | E13: =B13/D13 -> 0.73554267

Sheet MRP_LeadTimes
A1: MRP - PRODUCCIÓN POR SECCIÓN
A2: 5 secciones (S1-S5), cada una tarda 1 quincena. WIP entre secciones.
A4: FLUJO DE PRODUCCIÓN
A5: Sección | B5: Input | C5: Process | D5: Output | E5: Lead Time
A6: S1 | B6: Parte A | C6: Ensambla Piezas | D6: Semi A | E6: 1Q
A7: S2 | B7: Parte B | C7: Ensambla Piezas | D7: Semi B | E7: 1Q
A8: S3 | B8: - | C8: Pieza 3 | D8: Semi C | E8: 1Q
A9: S4 | B9: - | C9: Pieza 6 | D9: Semi D | E9: 1Q
A10: S5 | B10: Semis | C10: Ensambla final | D10: Electroclean | E10: 1Q

Sheet Reconciliacion
A1: RECONCILIACIÓN CON REPORTES EXSIM
A2: Pega reportes del simulador aquí para comparar
A4: RAW MATERIALS INVENTORY
A5: Material | B5: EXSIM Q1 | C5: Modelo Q1 | D5: Diff | E5: Status
A6: Parte A | B6: 0 | C6: =Inventario_Dinamico!B10 -> -1756 | D6: =IFERROR(B6-C6,0) -> 1756 | E6: =IF(ABS(D6)>100,"REVISAR","OK") -> REVISAR
A7: Parte B | B7: 0 | C7: =Inventario_Dinamico!B15 -> 370 | D7: =IFERROR(B7-C7,0) -> -370 | E7: =IF(ABS(D7)>100,"REVISAR","OK") -> REVISAR
A8: Pieza 1 | B8: 0 | C8: =Inventario_Dinamico!B20 -> 0 | D8: =IFERROR(B8-C8,0) -> 0 | E8: =IF(ABS(D8)>100,"REVISAR","OK") -> OK
A9: Pieza 2 | B9: 0 | C9: =Inventario_Dinamico!B25 -> 6131 | D9: =IFERROR(B9-C9,0) -> -6131 | E9: =IF(ABS(D9)>100,"REVISAR","OK") -> REVISAR
