Workbook

Sheet Inputs
A1: INPUTS - PURCHASING MANAGER
A2: Solo inputs manuales. AZUL = modificar según tu estrategia. Sin fórmulas en esta hoja.
A4: 1. PRODUCCIÓN PLANEADA POR QUINCENA (Assembly A)
A5: Quincena → | B5: Q1 | C5: Q2 | D5: Q3 | E5: Q4 | F5: Q5 | G5: Q6 | H5: Q7 | I5: Q8 | J5: TOTAL
A6: Producción EC Planta Central | B6: 1864 | C6: 1864 | D6: 1864 | E6: 1864 | F6: 1864 | G6: 1864 | H6: 1864 | I6: 1864 | J6: =SUM(B6:I6) -> 14912
A7: Producción EC Planta West | B7: 1164 | C7: 1164 | D7: 1164 | E7: 1164 | F7: 1164 | G7: 1164 | H7: 1164 | I7: 1164 | J7: =SUM(B7:I7) -> 9312 | N7: =1401/1.08 -> 1297.2222
A8: Producción EC Planta East | B8: 0 | C8: 0 | D8: 0 | E8: 0 | F8: 0 | G8: 0 | H8: 0 | I8: 0 | J8: =SUM(B8:I8) -> 0
A9: Producción EC Planta North | B9: 0 | C9: 0 | D9: 0 | E9: 0 | F9: 0 | G9: 0 | H9: 0 | I9: 0 | J9: =SUM(B9:I9) -> 0 | L9: 1512 | M9: =L9/B6 -> 0.8111588
A10: Producción EC Planta South | B10: 0 | C10: 0 | D10: 0 | E10: 0 | F10: 0 | G10: 0 | H10: 0 | I10: 0 | J10: =SUM(B10:I10) -> 0
A11: Total | B11: =+SUM(B6:B10) -> 3028 | C11: =+SUM(C6:C10) -> 3028 | D11: =+SUM(D6:D10) -> 3028 | E11: =+SUM(E6:E10) -> 3028 | F11: =+SUM(F6:F10) -> 3028 | G11: =+SUM(G6:G10) -> 3028 | H11: =+SUM(H6:H10) -> 3028 | I11: =+SUM(I6:I10) -> 3028 | J11: =+SUM(J6:J10) -> 24224 | N11: =745*0.97 -> 722.65
A13: 1. PRODUCCIÓN PLANEADA POR QUINCENA (Assembly B)
A14: Quincena → | B14: Q1 | C14: Q2 | D14: Q3 | E14: Q4 | F14: Q5 | G14: Q6 | H14: Q7 | I14: Q8 | J14: TOTAL
A15: Producción EC Planta Central | B15: 1863 | C15: 1863 | D15: 1863 | E15: 1863 | F15: 1863 | G15: 1863 | H15: 1863 | I15: 1863 | J15: =SUM(B15:I15) -> 14904
A16: Producción EC Planta West | B16: 1163 | C16: 1163 | D16: 1163 | E16: 1163 | F16: 1163 | G16: 1163 | H16: 1163 | I16: 1163 | J16: =SUM(B16:I16) -> 9304 | L16: =I16*0.2 -> 232.6
A17: Producción EC Planta East | B17: 0 | C17: 0 | D17: 0 | E17: 0 | F17: 0 | G17: 0 | H17: 0 | I17: 0 | J17: =SUM(B17:I17) -> 0
A18: Producción EC Planta North | B18: 0 | C18: 0 | D18: 0 | E18: 0 | F18: 0 | G18: 0 | H18: 0 | I18: 0 | J18: =SUM(B18:I18) -> 0
A19: Producción EC Planta South | B19: 0 | C19: 0 | D19: 0 | E19: 0 | F19: 0 | G19: 0 | H19: 0 | I19: 0 | J19: =SUM(B19:I19) -> 0
A20: Total | B20: =+SUM(B15:B19) -> 3026 | C20: =+SUM(C15:C19) -> 3026 | D20: =+SUM(D15:D19) -> 3026 | E20: =+SUM(E15:E19) -> 3026 | F20: =+SUM(F15:F19) -> 3026 | G20: =+SUM(G15:G19) -> 3026 | H20: =+SUM(H15:H19) -> 3026 | I20: =+SUM(I15:I19) -> 3026 | J20: =+SUM(J15:J19) -> 24208
A22: 1. PRODUCCIÓN PLANEADA POR QUINCENA (Assembly D)
A23: Quincena → | B23: Q1 | C23: Q2 | D23: Q3 | E23: Q4 | F23: Q5 | G23: Q6 | H23: Q7 | I23: Q8 | J23: TOTAL
A24: Producción EC Planta Central | B24: 1863 | C24: 1863 | D24: 1863 | E24: 1863 | F24: 1863 | G24: 1863 | H24: 1863 | I24: 1863 | J24: =SUM(B24:I24) -> 14904
A25: Producción EC Planta West | B25: 1163 | C25: 1163 | D25: 1163 | E25: 1163 | F25: 1163 | G25: 1163 | H25: 1163 | I25: 1163 | J25: =SUM(B25:I25) -> 9304
A26: Producción EC Planta East | B26: 0 | C26: 0 | D26: 0 | E26: 0 | F26: 0 | G26: 0 | H26: 0 | I26: 0 | J26: =SUM(B26:I26) -> 0
A27: Producción EC Planta North | B27: 0 | C27: 0 | D27: 0 | E27: 0 | F27: 0 | G27: 0 | H27: 0 | I27: 0 | J27: =SUM(B27:I27) -> 0
A28: Producción EC Planta South | B28: 0 | C28: 0 | D28: 0 | E28: 0 | F28: 0 | G28: 0 | H28: 0 | I28: 0 | J28: =SUM(B28:I28) -> 0
A29: Total | B29: =+SUM(B24:B28) -> 3026 | C29: =+SUM(C24:C28) -> 3026 | D29: =+SUM(D24:D28) -> 3026 | E29: =+SUM(E24:E28) -> 3026 | F29: =+SUM(F24:F28) -> 3026 | G29: =+SUM(G24:G28) -> 3026 | H29: =+SUM(H24:H28) -> 3026 | I29: =+SUM(I24:I28) -> 3026 | J29: =+SUM(J24:J28) -> 24208
A31: Material | B31: Inventario Inicial Planta Central | C31: Inventario Inicial Planta West | D31: Inventario Inicial Planta East | E31: Inventario Inicial Planta North | F31: Inventario Inicial Planta South | G31: Unidad | H31: Fuente
A32: Parte A | B32: 19552 | C32: 14864 | D32: 0 | E32: 0 | F32: 0 | G32: unidades | H32: Fin Periodo 6
A33: Parte B | B33: 4467 | C33: 19 | D33: 0 | E33: 0 | F33: 0 | G33: unidades | H33: Fin Periodo 6
A34: Pieza 1 | B34: 2 | C34: 1 | D34: 0 | E34: 0 | F34: 0 | G34: unidades | H34: Fin Periodo 6
A35: Pieza 2 | B35: 1380 | C35: 1076 | D35: 0 | E35: 0 | F35: 0 | G35: unidades | H35: Fin Periodo 6
A36: Pieza 3 | B36: 18 | C36: 29 | D36: 0 | E36: 0 | F36: 0 | G36: unidades | H36: Fin Periodo 6
A37: Pieza 4 | B37: 36 | C37: 58 | D37: 0 | E37: 0 | F37: 0 | G37: unidades | H37: Fin Periodo 6
A38: Pieza 5 | B38: 20 | C38: 94 | D38: 0 | E38: 0 | F38: 0 | G38: unidades | H38: Fin Periodo 6
A39: Pieza 6 | B39: 46 | C39: 148 | D39: 0 | E39: 0 | F39: 0 | G39: unidades | H39: Fin Periodo 6
A40: Assembly A | B40: 0 | C40: 0 | D40: 0 | E40: 0 | F40: 0 | G40: unidades | H40: Fin Periodo 6
A41: Assembly B | B41: 0 | C41: 0 | D41: 0 | E41: 0 | F41: 0 | G41: unidades | H41: Fin Periodo 6
A42: Assembly C | B42: 0 | C42: 0 | D42: 0 | E42: 0 | F42: 0 | G42: unidades | H42: Fin Periodo 6
A43: Assembly D | B43: 0 | C43: 0 | D43: 0 | E43: 0 | F43: 0 | G43: unidades | H43: Fin Periodo 6
A46: 3. BILL OF MATERIALS (BOM) - Consumo por Electroclean
...

Sheet Politica_Inventarios
A1: Políticas de Inventario (referenciado)
A3: Parámetros
A4: Service level (0-1) | B4: 0.95
A5: z | B5: =_xlfn.NORM.S.INV(B4) -> 1.6448536
A6: CV demanda (σ/μ) | C6: (si lo dejas vacío, SS=0)
A7: Quincenas por periodo | B7: 8
A8: Demanda total EC | B8: =Inputs!J11 -> 24224
A10: Planta Centro
A11: Material | B11: Consumo/EC | C11: Demanda periodo (unid) | D11: Batch Size | E11: σ periodo | F11: Safety Stock (periodo) | G11: ROP t0 (piezas) | H11: Demanda por quincena | I11: SS por quincena | J11: ROP por quincena (A/B) | K11: Ordering Cost | L11: Holding Cost (por unid-quincena) | M11: EOQ (unid) | N11: EOQ (lotes)
A12: Parte A | B12: =Inputs!B48 -> 1 | C12: =Inputs!J6 -> 14912 | D12: =Inputs!B66 -> 30 | E12: =IF($B$6="",0,C12*$B$6) -> 0 | F12: =$B$5*E12 -> 0 | G12: =IF(LEFT(A12,5)="Pieza",C12+F12,"") | H12: =B12*(C12/8) -> 1864 | I12: =IF($B$6="",0,$B$5*H12*$B$6) -> 0 | J12: =IF(LEFT(A12,5)="Parte",H12+I12,"") -> 1864 | K12: =Inputs!$B$95 -> 2300 | L12: =Inputs!$C$95 -> 0.3 | M12: =IF(AND(K12>0,L12>0),SQRT(2*H12*K12/L12),"") -> 5346.1513 | N12: =IF(M12="","",ROUNDUP(M12/D12,0)) -> 179
A13: Parte B | B13: =Inputs!B49 -> 0.2 | C13: =Inputs!J15 -> 14904 | D13: =Inputs!B67 -> 12 | E13: =IF($B$6="",0,C13*$B$6) -> 0 | F13: =$B$5*E13 -> 0 | G13: =IF(LEFT(A13,5)="Pieza",C13+F13,"") | H13: =B13*(C13/8) -> 372.6 | I13: =IF($B$6="",0,$B$5*H13*$B$6) -> 0 | J13: =IF(LEFT(A13,5)="Parte",H13+I13,"") -> 372.6 | K13: =Inputs!$B$96 -> 6000 | L13: =Inputs!$C$96 -> 4.5 | M13: =IF(AND(K13>0,L13>0),SQRT(2*H13*K13/L13),"") -> 996.79486 | N13: =IF(M13="","",ROUNDUP(M13/D13,0)) -> 84
A14: Pieza 1 | B14: =Inputs!B50 -> 0.01 | C14: =B14*Inputs!$J$15 -> 149.04 | D14: =Inputs!B68 -> 1 | E14: =IF($B$6="",0,C14*$B$6) -> 0 | F14: =$B$5*E14 -> 0 | G14: =IF(LEFT(A14,5)="Pieza",C14+F14,"") -> 149.04 | H14: =B14*(C14/8) -> 0.1863 | I14: =IF($B$6="",0,$B$5*H14*$B$6) -> 0 | J14: =IF(LEFT(A14,5)="Parte",H14+I14,"") | K14: =IF(LEFT(A14,5)="Parte",_xludf.XLOOKUP(A14,Inputs!$A$95:$A$96,Inputs!$B$95:$B$96,0,0),0) -> 0 | L14: =IF(LEFT(A14,5)="Parte",_xludf.XLOOKUP(A14,Inputs!$A$95:$A$96,Inputs!$C$95:$C$96,0,0),0) -> 0 | M14: =IF(AND(K14>0,L14>0),SQRT(2*H14*K14/L14),"") | N14: =IF(M14="","",ROUNDUP(M14/D14,0))
A15: Pieza 2 | B15: =Inputs!B51 -> 8 | C15: =B15*Inputs!$J$15 -> 119232 | D15: =Inputs!B69 -> 100 | E15: =IF($B$6="",0,C15*$B$6) -> 0 | F15: =$B$5*E15 -> 0 | G15: =IF(LEFT(A15,5)="Pieza",C15+F15,"") -> 119232 | H15: =B15*(C15/8) -> 119232 | I15: =IF($B$6="",0,$B$5*H15*$B$6) -> 0 | J15: =IF(LEFT(A15,5)="Parte",H15+I15,"") | K15: =IF(LEFT(A15,5)="Parte",_xludf.XLOOKUP(A15,Inputs!$A$95:$A$96,Inputs!$B$95:$B$96,0,0),0) -> 0 | L15: =IF(LEFT(A15,5)="Parte",_xludf.XLOOKUP(A15,Inputs!$A$95:$A$96,Inputs!$C$95:$C$96,0,0),0) -> 0 | M15: =IF(AND(K15>0,L15>0),SQRT(2*H15*K15/L15),"") | N15: =IF(M15="","",ROUNDUP(M15/D15,0))
A16: Pieza 3 | B16: =Inputs!B52 -> 0.3 | C16: =B16*Inputs!$J$24 -> 4471.2 | D16: =Inputs!B70 -> 30 | E16: =IF($B$6="",0,C16*$B$6) -> 0 | F16: =$B$5*E16 -> 0 | G16: =IF(LEFT(A16,5)="Pieza",C16+F16,"") -> 4471.2 | H16: =B16*(C16/8) -> 167.67 | I16: =IF($B$6="",0,$B$5*H16*$B$6) -> 0 | J16: =IF(LEFT(A16,5)="Parte",H16+I16,"") | K16: =IF(LEFT(A16,5)="Parte",_xludf.XLOOKUP(A16,Inputs!$A$95:$A$96,Inputs!$B$95:$B$96,0,0),0) -> 0 | L16: =IF(LEFT(A16,5)="Parte",_xludf.XLOOKUP(A16,Inputs!$A$95:$A$96,Inputs!$C$95:$C$96,0,0),0) -> 0 | M16: =IF(AND(K16>0,L16>0),SQRT(2*H16*K16/L16),"") | N16: =IF(M16="","",ROUNDUP(M16/D16,0))
A17: Pieza 4 | B17: =Inputs!B53 -> 0.6 | C17: =B17*Inputs!$J$24 -> 8942.4 | D17: =Inputs!B71 -> 60 | E17: =IF($B$6="",0,C17*$B$6) -> 0 | F17: =$B$5*E17 -> 0 | G17: =IF(LEFT(A17,5)="Pieza",C17+F17,"") -> 8942.4 | H17: =B17*(C17/8) -> 670.68 | I17: =IF($B$6="",0,$B$5*H17*$B$6) -> 0 | J17: =IF(LEFT(A17,5)="Parte",H17+I17,"") | K17: =IF(LEFT(A17,5)="Parte",_xludf.XLOOKUP(A17,Inputs!$A$95:$A$96,Inputs!$B$95:$B$96,0,0),0) -> 0 | L17: =IF(LEFT(A17,5)="Parte",_xludf.XLOOKUP(A17,Inputs!$A$95:$A$96,Inputs!$C$95:$C$96,0,0),0) -> 0 | M17: =IF(AND(K17>0,L17>0),SQRT(2*H17*K17/L17),"") | N17: =IF(M17="","",ROUNDUP(M17/D17,0))
A18: Pieza 5 | B18: =Inputs!B54 -> 2 | C18: =B18*Inputs!$J$24 -> 29808 | D18: =Inputs!B72 -> 100 | E18: =IF($B$6="",0,C18*$B$6) -> 0 | F18: =$B$5*E18 -> 0 | G18: =IF(LEFT(A18,5)="Pieza",C18+F18,"") -> 29808 | H18: =B18*(C18/8) -> 7452 | I18: =IF($B$6="",0,$B$5*H18*$B$6) -> 0 | J18: =IF(LEFT(A18,5)="Parte",H18+I18,"") | K18: =IF(LEFT(A18,5)="Parte",_xludf.XLOOKUP(A18,Inputs!$A$95:$A$96,Inputs!$B$95:$B$96,0,0),0) -> 0 | L18: =IF(LEFT(A18,5)="Parte",_xludf.XLOOKUP(A18,Inputs!$A$95:$A$96,Inputs!$C$95:$C$96,0,0),0) -> 0 | M18: =IF(AND(K18>0,L18>0),SQRT(2*H18*K18/L18),"") | N18: =IF(M18="","",ROUNDUP(M18/D18,0))
A19: Pieza 6 | B19: =Inputs!B55 -> 0.75 | C19: =B19*Inputs!$J$24 -> 11178 | D19: =Inputs!B73 -> 150 | E19: =IF($B$6="",0,C19*$B$6) -> 0 | F19: =$B$5*E19 -> 0 | G19: =IF(LEFT(A19,5)="Pieza",C19+F19,"") -> 11178 | H19: =B19*(C19/8) -> 1047.9375 | I19: =IF($B$6="",0,$B$5*H19*$B$6) -> 0 | J19: =IF(LEFT(A19,5)="Parte",H19+I19,"") | K19: =IF(LEFT(A19,5)="Parte",_xludf.XLOOKUP(A19,Inputs!$A$95:$A$96,Inputs!$B$95:$B$96,0,0),0) -> 0 | L19: =IF(LEFT(A19,5)="Parte",_xludf.XLOOKUP(A19,Inputs!$A$95:$A$96,Inputs!$C$95:$C$96,0,0),0) -> 0 | M19: =IF(AND(K19>0,L19>0),SQRT(2*H19*K19/L19),"") | N19: =IF(M19="","",ROUNDUP(M19/D19,0))
A21: Planta West
A22: Material | B22: Consumo/EC | C22: Demanda periodo (unid) | D22: Batch Size | E22: σ periodo | F22: Safety Stock (periodo) | G22: ROP t0 (piezas) | H22: Demanda por quincena | I22: SS por quincena | J22: ROP por quincena (A/B) | K22: Ordering Cost | L22: Holding Cost (por unid-quincena) | M22: EOQ (unid) | N22: EOQ (lotes)
A23: Parte A | B23: =Inputs!B48 -> 1 | C23: =Inputs!J7 -> 9312 | D23: =Inputs!B66 -> 30 | E23: =IF($B$6="",0,C23*$B$6) -> 0 | F23: =$B$5*E23 -> 0 | G23: =IF(LEFT(A23,5)="Pieza",C23+F23,"") | H23: =B23*(C23/8) -> 1164 | I23: =IF($B$6="",0,$B$5*H23*$B$6) -> 0 | J23: =IF(LEFT(A23,5)="Parte",H23+I23,"") -> 1164 | K23: =Inputs!$B$95 -> 2300 | L23: =Inputs!$C$95 -> 0.3 | M23: =IF(AND(K23>0,L23>0),SQRT(2*H23*K23/L23),"") -> 4224.6893 | N23: =IF(M23="","",ROUNDUP(M23/D23,0)) -> 141
A24: Parte B | B24: =Inputs!B49 -> 0.2 | C24: =Inputs!J16 -> 9304 | D24: =Inputs!B67 -> 12 | E24: =IF($B$6="",0,C24*$B$6) -> 0 | F24: =$B$5*E24 -> 0 | G24: =IF(LEFT(A24,5)="Pieza",C24+F24,"") | H24: =B24*(C24/8) -> 232.6 | I24: =IF($B$6="",0,$B$5*H24*$B$6) -> 0 | J24: =IF(LEFT(A24,5)="Parte",H24+I24,"") -> 232.6 | K24: =Inputs!$B$96 -> 6000 | L24: =Inputs!$C$96 -> 4.5 | M24: =IF(AND(K24>0,L24>0),SQRT(2*H24*K24/L24),"") -> 787.5701 | N24: =IF(M24="","",ROUNDUP(M24/D24,0)) -> 66
A25: Pieza 1 | B25: =Inputs!B50 -> 0.01 | C25: =B25*Inputs!$J$16 -> 93.04 | D25: =Inputs!B68 -> 1 | E25: =IF($B$6="",0,C25*$B$6) -> 0 | F25: =$B$5*E25 -> 0 | G25: =IF(LEFT(A25,5)="Pieza",C25+F25,"") -> 93.04 | H25: =B25*(C25/8) -> 0.1163 | I25: =IF($B$6="",0,$B$5*H25*$B$6) -> 0 | J25: =IF(LEFT(A25,5)="Parte",H25+I25,"") | K25: =IF(LEFT(A25,5)="Parte",_xludf.XLOOKUP(A25,Inputs!$A$95:$A$96,Inputs!$B$95:$B$96,0,0),0) -> 0 | L25: 0 | M25: =IF(AND(K25>0,L25>0),SQRT(2*H25*K25/L25),"") | N25: =IF(M25="","",ROUNDUP(M25/D25,0))
A26: Pieza 2 | B26: =Inputs!B51 -> 8 | C26: =B26*Inputs!$J$25 -> 74432 | D26: =Inputs!B69 -> 100 | E26: =IF($B$6="",0,C26*$B$6) -> 0 | F26: =$B$5*E26 -> 0 | G26: =IF(LEFT(A26,5)="Pieza",C26+F26,"") -> 74432 | H26: =B26*(C26/8) -> 74432 | I26: =IF($B$6="",0,$B$5*H26*$B$6) -> 0 | J26: =IF(LEFT(A26,5)="Parte",H26+I26,"") | K26: =IF(LEFT(A26,5)="Parte",_xludf.XLOOKUP(A26,Inputs!$A$95:$A$96,Inputs!$B$95:$B$96,0,0),0) -> 0 | L26: =IF(LEFT(A26,5)="Parte",_xludf.XLOOKUP(A26,Inputs!$A$95:$A$96,Inputs!$C$95:$C$96,0,0),0) -> 0 | M26: =IF(AND(K26>0,L26>0),SQRT(2*H26*K26/L26),"") | N26: =IF(M26="","",ROUNDUP(M26/D26,0))
A27: Pieza 3 | B27: =Inputs!B52 -> 0.3 | C27: =B27*Inputs!$J$25 -> 2791.2 | D27: =Inputs!B70 -> 30 | E27: =IF($B$6="",0,C27*$B$6) -> 0 | F27: =$B$5*E27 -> 0 | G27: =IF(LEFT(A27,5)="Pieza",C27+F27,"") -> 2791.2 | H27: =B27*(C27/8) -> 104.67 | I27: =IF($B$6="",0,$B$5*H27*$B$6) -> 0 | J27: =IF(LEFT(A27,5)="Parte",H27+I27,"") | K27: =IF(LEFT(A27,5)="Parte",_xludf.XLOOKUP(A27,Inputs!$A$95:$A$96,Inputs!$B$95:$B$96,0,0),0) -> 0 | L27: =IF(LEFT(A27,5)="Parte",_xludf.XLOOKUP(A27,Inputs!$A$95:$A$96,Inputs!$C$95:$C$96,0,0),0) -> 0 | M27: =IF(AND(K27>0,L27>0),SQRT(2*H27*K27/L27),"") | N27: =IF(M27="","",ROUNDUP(M27/D27,0))
A28: Pieza 4 | B28: =Inputs!B53 -> 0.6 | C28: =B28*Inputs!$J$25 -> 5582.4 | D28: =Inputs!B71 -> 60 | E28: =IF($B$6="",0,C28*$B$6) -> 0 | F28: =$B$5*E28 -> 0 | G28: =IF(LEFT(A28,5)="Pieza",C28+F28,"") -> 5582.4 | H28: =B28*(C28/8) -> 418.68 | I28: =IF($B$6="",0,$B$5*H28*$B$6) -> 0 | J28: =IF(LEFT(A28,5)="Parte",H28+I28,"") | K28: =IF(LEFT(A28,5)="Parte",_xludf.XLOOKUP(A28,Inputs!$A$95:$A$96,Inputs!$B$95:$B$96,0,0),0) -> 0 | L28: =IF(LEFT(A28,5)="Parte",_xludf.XLOOKUP(A28,Inputs!$A$95:$A$96,Inputs!$C$95:$C$96,0,0),0) -> 0 | M28: =IF(AND(K28>0,L28>0),SQRT(2*H28*K28/L28),"") | N28: =IF(M28="","",ROUNDUP(M28/D28,0))
A29: Pieza 5 | B29: =Inputs!B54 -> 2 | C29: =B29*Inputs!$J$25 -> 18608 | D29: =Inputs!B72 -> 100 | E29: =IF($B$6="",0,C29*$B$6) -> 0 | F29: =$B$5*E29 -> 0 | G29: =IF(LEFT(A29,5)="Pieza",C29+F29,"") -> 18608 | H29: =B29*(C29/8) -> 4652 | I29: =IF($B$6="",0,$B$5*H29*$B$6) -> 0 | J29: =IF(LEFT(A29,5)="Parte",H29+I29,"") | K29: =IF(LEFT(A29,5)="Parte",_xludf.XLOOKUP(A29,Inputs!$A$95:$A$96,Inputs!$B$95:$B$96,0,0),0) -> 0 | L29: =IF(LEFT(A29,5)="Parte",_xludf.XLOOKUP(A29,Inputs!$A$95:$A$96,Inputs!$C$95:$C$96,0,0),0) -> 0 | M29: =IF(AND(K29>0,L29>0),SQRT(2*H29*K29/L29),"") | N29: =IF(M29="","",ROUNDUP(M29/D29,0))
A30: Pieza 6 | B30: =Inputs!B55 -> 0.75 | C30: =B30*Inputs!$J$25 -> 6978 | D30: =Inputs!B73 -> 150 | E30: =IF($B$6="",0,C30*$B$6) -> 0 | F30: =$B$5*E30 -> 0 | G30: =IF(LEFT(A30,5)="Pieza",C30+F30,"") -> 6978 | H30: =B30*(C30/8) -> 654.1875 | I30: =IF($B$6="",0,$B$5*H30*$B$6) -> 0 | J30: =IF(LEFT(A30,5)="Parte",H30+I30,"") | K30: =IF(LEFT(A30,5)="Parte",_xludf.XLOOKUP(A30,Inputs!$A$95:$A$96,Inputs!$B$95:$B$96,0,0),0) -> 0 | L30: =IF(LEFT(A30,5)="Parte",_xludf.XLOOKUP(A30,Inputs!$A$95:$A$96,Inputs!$C$95:$C$96,0,0),0) -> 0 | M30: =IF(AND(K30>0,L30>0),SQRT(2*H30*K30/L30),"") | N30: =IF(M30="","",ROUNDUP(M30/D30,0))
A32: Planta East
A33: Material | B33: Consumo/EC | C33: Demanda periodo (unid) | D33: Batch Size | E33: σ periodo | F33: Safety Stock (periodo) | G33: ROP t0 (piezas) | H33: Demanda por quincena | I33: SS por quincena | J33: ROP por quincena (A/B) | K33: Ordering Cost | L33: Holding Cost (por unid-quincena) | M33: EOQ (unid) | N33: EOQ (lotes)
A34: Parte A | B34: =Inputs!B48 -> 1 | C34: =Inputs!J8 -> 0 | D34: =Inputs!B66 -> 30 | E34: =IF($B$6="",0,C34*$B$6) -> 0 | F34: =$B$5*E34 -> 0 | G34: =IF(LEFT(A34,5)="Pieza",C34+F34,"") | H34: =B34*(C34/8) -> 0 | I34: =IF($B$6="",0,$B$5*H34*$B$6) -> 0 | J34: =IF(LEFT(A34,5)="Parte",H34+I34,"") -> 0 | K34: =Inputs!$B$95 -> 2300 | L34: =Inputs!$C$95 -> 0.3 | M34: =IF(AND(K34>0,L34>0),SQRT(2*H34*K34/L34),"") -> 0 | N34: =IF(M34="","",ROUNDUP(M34/D34,0)) -> 0
A35: Parte B | B35: =Inputs!B49 -> 0.2 | C35: =Inputs!$J$17 -> 0 | D35: =Inputs!B67 -> 12 | E35: =IF($B$6="",0,C35*$B$6) -> 0 | F35: =$B$5*E35 -> 0 | G35: =IF(LEFT(A35,5)="Pieza",C35+F35,"") | H35: =B35*(C35/8) -> 0 | I35: =IF($B$6="",0,$B$5*H35*$B$6) -> 0 | J35: =IF(LEFT(A35,5)="Parte",H35+I35,"") -> 0 | K35: =Inputs!$B$96 -> 6000 | L35: =Inputs!$C$96 -> 4.5 | M35: =IF(AND(K35>0,L35>0),SQRT(2*H35*K35/L35),"") -> 0 | N35: =IF(M35="","",ROUNDUP(M35/D35,0)) -> 0
A36: Pieza 1 | B36: =Inputs!B50 -> 0.01 | C36: =B36*Inputs!$J$17 -> 0 | D36: =Inputs!B68 -> 1 | E36: =IF($B$6="",0,C36*$B$6) -> 0 | F36: =$B$5*E36 -> 0 | G36: =IF(LEFT(A36,5)="Pieza",C36+F36,"") -> 0 | H36: =B36*(C36/8) -> 0 | I36: =IF($B$6="",0,$B$5*H36*$B$6) -> 0 | J36: =IF(LEFT(A36,5)="Parte",H36+I36,"") | K36: =IF(LEFT(A36,5)="Parte",_xludf.XLOOKUP(A36,Inputs!$A$95:$A$96,Inputs!$B$95:$B$96,0,0),0) -> 0 | L36: 0 | M36: =IF(AND(K36>0,L36>0),SQRT(2*H36*K36/L36),"") | N36: =IF(M36="","",ROUNDUP(M36/D36,0))
A37: Pieza 2 | B37: =Inputs!B51 -> 8 | C37: =B37*Inputs!$J$26 -> 0 | D37: =Inputs!B69 -> 100 | E37: =IF($B$6="",0,C37*$B$6) -> 0 | F37: =$B$5*E37 -> 0 | G37: =IF(LEFT(A37,5)="Pieza",C37+F37,"") -> 0 | H37: =B37*(C37/8) -> 0 | I37: =IF($B$6="",0,$B$5*H37*$B$6) -> 0 | J37: =IF(LEFT(A37,5)="Parte",H37+I37,"") | K37: =IF(LEFT(A37,5)="Parte",_xludf.XLOOKUP(A37,Inputs!$A$95:$A$96,Inputs!$B$95:$B$96,0,0),0) -> 0 | L37: =IF(LEFT(A37,5)="Parte",_xludf.XLOOKUP(A37,Inputs!$A$95:$A$96,Inputs!$C$95:$C$96,0,0),0) -> 0 | M37: =IF(AND(K37>0,L37>0),SQRT(2*H37*K37/L37),"") | N37: =IF(M37="","",ROUNDUP(M37/D37,0))
A38: Pieza 3 | B38: =Inputs!B52 -> 0.3 | C38: =B38*Inputs!$J$26 -> 0 | D38: =Inputs!B70 -> 30 | E38: =IF($B$6="",0,C38*$B$6) -> 0 | F38: =$B$5*E38 -> 0 | G38: =IF(LEFT(A38,5)="Pieza",C38+F38,"") -> 0 | H38: =B38*(C38/8) -> 0 | I38: =IF($B$6="",0,$B$5*H38*$B$6) -> 0 | J38: =IF(LEFT(A38,5)="Parte",H38+I38,"") | K38: =IF(LEFT(A38,5)="Parte",_xludf.XLOOKUP(A38,Inputs!$A$95:$A$96,Inputs!$B$95:$B$96,0,0),0) -> 0 | L38: =IF(LEFT(A38,5)="Parte",_xludf.XLOOKUP(A38,Inputs!$A$95:$A$96,Inputs!$C$95:$C$96,0,0),0) -> 0 | M38: =IF(AND(K38>0,L38>0),SQRT(2*H38*K38/L38),"") | N38: =IF(M38="","",ROUNDUP(M38/D38,0))
A39: Pieza 4 | B39: =Inputs!B53 -> 0.6 | C39: =B39*Inputs!$J$26 -> 0 | D39: =Inputs!B71 -> 60 | E39: =IF($B$6="",0,C39*$B$6) -> 0 | F39: =$B$5*E39 -> 0 | G39: =IF(LEFT(A39,5)="Pieza",C39+F39,"") -> 0 | H39: =B39*(C39/8) -> 0 | I39: =IF($B$6="",0,$B$5*H39*$B$6) -> 0 | J39: =IF(LEFT(A39,5)="Parte",H39+I39,"") | K39: =IF(LEFT(A39,5)="Parte",_xludf.XLOOKUP(A39,Inputs!$A$95:$A$96,Inputs!$B$95:$B$96,0,0),0) -> 0 | L39: =IF(LEFT(A39,5)="Parte",_xludf.XLOOKUP(A39,Inputs!$A$95:$A$96,Inputs!$C$95:$C$96,0,0),0) -> 0 | M39: =IF(AND(K39>0,L39>0),SQRT(2*H39*K39/L39),"") | N39: =IF(M39="","",ROUNDUP(M39/D39,0))
A40: Pieza 5 | B40: =Inputs!B54 -> 2 | C40: =B40*Inputs!$J$26 -> 0 | D40: =Inputs!B72 -> 100 | E40: =IF($B$6="",0,C40*$B$6) -> 0 | F40: =$B$5*E40 -> 0 | G40: =IF(LEFT(A40,5)="Pieza",C40+F40,"") -> 0 | H40: =B40*(C40/8) -> 0 | I40: =IF($B$6="",0,$B$5*H40*$B$6) -> 0 | J40: =IF(LEFT(A40,5)="Parte",H40+I40,"") | K40: =IF(LEFT(A40,5)="Parte",_xludf.XLOOKUP(A40,Inputs!$A$95:$A$96,Inputs!$B$95:$B$96,0,0),0) -> 0 | L40: =IF(LEFT(A40,5)="Parte",_xludf.XLOOKUP(A40,Inputs!$A$95:$A$96,Inputs!$C$95:$C$96,0,0),0) -> 0 | M40: =IF(AND(K40>0,L40>0),SQRT(2*H40*K40/L40),"") | N40: =IF(M40="","",ROUNDUP(M40/D40,0))
A41: Pieza 6 | B41: =Inputs!B55 -> 0.75 | C41: =B41*Inputs!$J$26 -> 0 | D41: =Inputs!B73 -> 150 | E41: =IF($B$6="",0,C41*$B$6) -> 0 | F41: =$B$5*E41 -> 0 | G41: =IF(LEFT(A41,5)="Pieza",C41+F41,"") -> 0 | H41: =B41*(C41/8) -> 0 | I41: =IF($B$6="",0,$B$5*H41*$B$6) -> 0 | J41: =IF(LEFT(A41,5)="Parte",H41+I41,"") | K41: =IF(LEFT(A41,5)="Parte",_xludf.XLOOKUP(A41,Inputs!$A$95:$A$96,Inputs!$B$95:$B$96,0,0),0) -> 0 | L41: =IF(LEFT(A41,5)="Parte",_xludf.XLOOKUP(A41,Inputs!$A$95:$A$96,Inputs!$C$95:$C$96,0,0),0) -> 0 | M41: =IF(AND(K41>0,L41>0),SQRT(2*H41*K41/L41),"") | N41: =IF(M41="","",ROUNDUP(M41/D41,0))
A43: Planta North
A44: Material | B44: Consumo/EC | C44: Demanda periodo (unid) | D44: Batch Size | E44: σ periodo | F44: Safety Stock (periodo) | G44: ROP t0 (piezas) | H44: Demanda por quincena | I44: SS por quincena | J44: ROP por quincena (A/B) | K44: Ordering Cost | L44: Holding Cost (por unid-quincena) | M44: EOQ (unid) | N44: EOQ (lotes)
A45: Parte A | B45: =Inputs!B48 -> 1 | C45: =Inputs!J9 -> 0 | D45: =Inputs!B66 -> 30 | E45: =IF($B$6="",0,C45*$B$6) -> 0 | F45: =$B$5*E45 -> 0 | G45: =IF(LEFT(A45,5)="Pieza",C45+F45,"") | H45: =B45*(C45/8) -> 0 | I45: =IF($B$6="",0,$B$5*H45*$B$6) -> 0 | J45: =IF(LEFT(A45,5)="Parte",H45+I45,"") -> 0 | K45: =Inputs!$B$95 -> 2300 | L45: =Inputs!$C$95 -> 0.3 | M45: =IF(AND(K45>0,L45>0),SQRT(2*H45*K45/L45),"") -> 0 | N45: =IF(M45="","",ROUNDUP(M45/D45,0)) -> 0
...

Sheet BOM_Consumo_Piezas
A1: BOM_CONSUMO - Cálculo de Consumo por Quincena
A2: Fórmula: Consumo_Q = Producción_EC_Q × Consumo_por_EC
A3: VERDE = datos de Inputs | NEGRO = fórmulas calculadas
A4: Planta Centro
A5: Material | B5: Consumo/EC | C5: Q1 | D5: Q2 | E5: Q3 | F5: Q4 | G5: Q5 | H5: Q6 | I5: Q7 | J5: Q8 | K5: TOTAL | L5: SS | M5: II | N5: A pedir | O5: Lotes a pedir | P5: Costo
A6: Pieza 1 | B6: =Inputs!B50 -> 0.01 | C6: =Inputs!$B$15*$B$6 -> 18.63 | D6: =Inputs!$B$15*$B$6 -> 18.63 | E6: =Inputs!$B$15*$B$6 -> 18.63 | F6: =Inputs!$B$15*$B$6 -> 18.63 | G6: =Inputs!$B$15*$B$6 -> 18.63 | H6: =Inputs!$B$15*$B$6 -> 18.63 | I6: =Inputs!$B$15*$B$6 -> 18.63 | J6: =Inputs!$B$15*$B$6 -> 18.63 | K6: =Inputs!J6*B6 -> 149.12 | L6: =Politica_Inventarios!F14 -> 0 | M6: =Inputs!B34 -> 2 | N6: =K6+L6-M6 -> 147.12 | O6: =IF(ROUNDUP(N6/Inputs!$B$68,0)<0,0,ROUNDUP(N6/Inputs!$B$68,0))+1 -> 149 | P6: =O6*Inputs!$B$85 -> 8940
A7: Pieza 2 | B7: =Inputs!B51 -> 8 | C7: =Inputs!$B$24*$B$7 -> 14904 | D7: =Inputs!$B$24*$B$7 -> 14904 | E7: =Inputs!$B$24*$B$7 -> 14904 | F7: =Inputs!$B$24*$B$7 -> 14904 | G7: =Inputs!$B$24*$B$7 -> 14904 | H7: =Inputs!$B$24*$B$7 -> 14904 | I7: =Inputs!$B$24*$B$7 -> 14904 | J7: =Inputs!$B$24*$B$7 -> 14904 | K7: =SUM(C7:J7) -> 119232 | L7: =Politica_Inventarios!F15 -> 0 | M7: =Inputs!B35 -> 1380 | N7: =K7+L7-M7 -> 117852 | O7: =IF(ROUNDUP(N7/Inputs!$B$69,0)<0,0,ROUNDUP(N7/Inputs!$B$69,0)) -> 1179 | P7: =O7*Inputs!$B$86 -> 8253
A8: Pieza 3 | B8: =Inputs!B52 -> 0.3 | C8: =Inputs!$B$24*$B$8 -> 558.9 | D8: =Inputs!$B$24*$B$8 -> 558.9 | E8: =Inputs!$B$24*$B$8 -> 558.9 | F8: =Inputs!$B$24*$B$8 -> 558.9 | G8: =Inputs!$B$24*$B$8 -> 558.9 | H8: =Inputs!$B$24*$B$8 -> 558.9 | I8: =Inputs!$B$24*$B$8 -> 558.9 | J8: =Inputs!$B$24*$B$8 -> 558.9 | K8: =Inputs!$J$24*B8 -> 4471.2 | L8: =Politica_Inventarios!F16 -> 0 | M8: =Inputs!B36 -> 18 | N8: =K8+L8-M8 -> 4453.2 | O8: =IF(ROUNDUP(N8/Inputs!$B$70,0)<0,0,ROUNDUP(N8/Inputs!$B$70,0)) -> 149 | P8: =O8*Inputs!$B$87 -> 5364
A9: Pieza 4 | B9: =Inputs!B53 -> 0.6 | C9: =Inputs!$B$24*$B$9 -> 1117.8 | D9: =Inputs!$B$24*$B$9 -> 1117.8 | E9: =Inputs!$B$24*$B$9 -> 1117.8 | F9: =Inputs!$B$24*$B$9 -> 1117.8 | G9: =Inputs!$B$24*$B$9 -> 1117.8 | H9: =Inputs!$B$24*$B$9 -> 1117.8 | I9: =Inputs!$B$24*$B$9 -> 1117.8 | J9: =Inputs!$B$24*$B$9 -> 1117.8 | K9: =Inputs!$J$24*B9 -> 8942.4 | L9: =Politica_Inventarios!F17 -> 0 | M9: =Inputs!B37 -> 36 | N9: =K9+L9-M9 -> 8906.4 | O9: =IF(ROUNDUP(N9/Inputs!$B$71,0)<0,0,ROUNDUP(N9/Inputs!$B$71,0)) -> 149 | P9: =O9*Inputs!$B$88 -> 3576 | S9: =R11-R12 -> 36
A10: Pieza 5 | B10: =Inputs!B54 -> 2 | C10: =Inputs!$B$24*$B$10 -> 3726 | D10: =Inputs!$B$24*$B$10 -> 3726 | E10: =Inputs!$B$24*$B$10 -> 3726 | F10: =Inputs!$B$24*$B$10 -> 3726 | G10: =Inputs!$B$24*$B$10 -> 3726 | H10: =Inputs!$B$24*$B$10 -> 3726 | I10: =Inputs!$B$24*$B$10 -> 3726 | J10: =Inputs!$B$24*$B$10 -> 3726 | K10: =Inputs!$J$24*B10 -> 29808 | L10: =Politica_Inventarios!F18 -> 0 | M10: =Inputs!B38 -> 20 | N10: =K10+L10-M10 -> 29788 | O10: =IF(ROUNDUP(N10/Inputs!$B$72,0)<0,0,ROUNDUP(N10/Inputs!$B$72,0)) -> 298 | P10: =O10*Inputs!$B$89 -> 8940
A11: Pieza 6 | B11: =Inputs!B55 -> 0.75 | C11: =Inputs!$B$24*$B$11 -> 1397.25 | D11: =Inputs!$B$24*$B$11 -> 1397.25 | E11: =Inputs!$B$24*$B$11 -> 1397.25 | F11: =Inputs!$B$24*$B$11 -> 1397.25 | G11: =Inputs!$B$24*$B$11 -> 1397.25 | H11: =Inputs!$B$24*$B$11 -> 1397.25 | I11: =Inputs!$B$24*$B$11 -> 1397.25 | J11: =Inputs!$B$24*$B$11 -> 1397.25 | K11: =Inputs!$J$24*B11 -> 11178 | L11: =Politica_Inventarios!F19 -> 0 | M11: =Inputs!B39 -> 46 | N11: =K11+L11-M11 -> 11132 | O11: =IF(ROUNDUP(N11/Inputs!$B$73,0)<0,0,ROUNDUP(N11/Inputs!$B$73,0)) -> 75 | P11: =O11*Inputs!$B$90 -> 2100 | R11: 3732 | W11: 14928
A12: PRODUCCIÓN TOTAL EC | C12: =Inputs!B6 -> 1864 | D12: =Inputs!C6 -> 1864 | E12: =Inputs!D6 -> 1864 | F12: =Inputs!E6 -> 1864 | G12: =Inputs!F6 -> 1864 | H12: =Inputs!G6 -> 1864 | I12: =Inputs!H6 -> 1864 | J12: =Inputs!I6 -> 1864 | K12: =Inputs!J6 -> 14912 | P12: =SUM(P6:P11) -> 37173 | R12: 3696 | V12: 117900 | W12: 14784
A14: Planta West | V14: =W11-W12 -> 144
A15: Material | B15: Consumo/EC | C15: Q1 | D15: Q2 | E15: Q3 | F15: Q4 | G15: Q5 | H15: Q6 | I15: Q7 | J15: Q8 | K15: TOTAL | L15: SS | M15: II | N15: A pedir | O15: Lotes | P15: Costo
A16: Pieza 1 | B16: 0.01 | C16: =Inputs!$B$16*$B$16 -> 11.63 | D16: =Inputs!$B$16*$B$16 -> 11.63 | E16: =Inputs!$B$16*$B$16 -> 11.63 | F16: =Inputs!$B$16*$B$16 -> 11.63 | G16: =Inputs!$B$16*$B$16 -> 11.63 | H16: =Inputs!$B$16*$B$16 -> 11.63 | I16: =Inputs!$B$16*$B$16 -> 11.63 | J16: =Inputs!$B$16*$B$16 -> 11.63 | K16: =SUM(C16:J16) -> 93.04 | L16: =Politica_Inventarios!F25 -> 0 | M16: =Inputs!C34 -> 1 | N16: =K16+L16-M16 -> 92.04 | O16: =IF(ROUNDUP(N16/Inputs!$B$68,0)<0,0,ROUNDUP(N16/Inputs!$B$68,0))+1 -> 94 | P16: =O16*Inputs!$B$85 -> 5640 | T16: =298+S9 -> 334
A17: Pieza 2 | B17: 8 | C17: =Inputs!$B$25*$B$17 -> 9304 | D17: =Inputs!$B$25*$B$17 -> 9304 | E17: =Inputs!$B$25*$B$17 -> 9304 | F17: =Inputs!$B$25*$B$17 -> 9304 | G17: =Inputs!$B$25*$B$17 -> 9304 | H17: =Inputs!$B$25*$B$17 -> 9304 | I17: =Inputs!$B$25*$B$17 -> 9304 | J17: =Inputs!$B$25*$B$17 -> 9304 | K17: =SUM(C17:J17) -> 74432 | L17: =Politica_Inventarios!F26 -> 0 | M17: =Inputs!C35 -> 1076 | N17: =K17+L17-M17 -> 73356 | O17: =IF(ROUNDUP(N17/Inputs!$B$69,0)<0,0,ROUNDUP(N17/Inputs!$B$69,0)) -> 734 | P17: =O17*Inputs!$B$86 -> 5138
A18: Pieza 3 | B18: 0.3 | C18: =Inputs!$B$25*$B$18 -> 348.9 | D18: =Inputs!$B$25*$B$18 -> 348.9 | E18: =Inputs!$B$25*$B$18 -> 348.9 | F18: =Inputs!$B$25*$B$18 -> 348.9 | G18: =Inputs!$B$25*$B$18 -> 348.9 | H18: =Inputs!$B$25*$B$18 -> 348.9 | I18: =Inputs!$B$25*$B$18 -> 348.9 | J18: =Inputs!$B$25*$B$18 -> 348.9 | K18: =SUM(C18:J18) -> 2791.2 | L18: =Politica_Inventarios!F27 -> 0 | M18: =Inputs!C36 -> 29 | N18: =K18+L18-M18 -> 2762.2 | O18: =IF(ROUNDUP(N18/Inputs!$B$70,0)<0,0,ROUNDUP(N18/Inputs!$B$70,0)) -> 93 | P18: =O18*Inputs!$B$87 -> 3348 | V18: =V12+V14 -> 118044
A19: Pieza 4 | B19: 0.6 | C19: =Inputs!$B$25*$B$19 -> 697.8 | D19: =Inputs!$B$25*$B$19 -> 697.8 | E19: =Inputs!$B$25*$B$19 -> 697.8 | F19: =Inputs!$B$25*$B$19 -> 697.8 | G19: =Inputs!$B$25*$B$19 -> 697.8 | H19: =Inputs!$B$25*$B$19 -> 697.8 | I19: =Inputs!$B$25*$B$19 -> 697.8 | J19: =Inputs!$B$25*$B$19 -> 697.8 | K19: =SUM(C19:J19) -> 5582.4 | L19: =Politica_Inventarios!F28 -> 0 | M19: =Inputs!C37 -> 58 | N19: =K19+L19-M19 -> 5524.4 | O19: =IF(ROUNDUP(N19/Inputs!$B$71,0)<0,0,ROUNDUP(N19/Inputs!$B$71,0)) -> 93 | P19: =O19*Inputs!$B$88 -> 2232 | R19: =117900/8 -> 14737.5
A20: Pieza 5 | B20: 2 | C20: =Inputs!$B$25*$B$20 -> 2326 | D20: =Inputs!$B$25*$B$20 -> 2326 | E20: =Inputs!$B$25*$B$20 -> 2326 | F20: =Inputs!$B$25*$B$20 -> 2326 | G20: =Inputs!$B$25*$B$20 -> 2326 | H20: =Inputs!$B$25*$B$20 -> 2326 | I20: =Inputs!$B$25*$B$20 -> 2326 | J20: =Inputs!$B$25*$B$20 -> 2326 | K20: =SUM(C20:J20) -> 18608 | L20: =Politica_Inventarios!F29 -> 0 | M20: =Inputs!C38 -> 94 | N20: =K20+L20-M20 -> 18514 | O20: =IF(ROUNDUP(N20/Inputs!$B$72,0)<0,0,ROUNDUP(N20/Inputs!$B$72,0)) -> 186 | P20: =O20*Inputs!$B$89 -> 5580 | V20: =+V18/8 -> 14755.5
A21: Pieza 6 | B21: 0.75 | C21: =Inputs!$B$25*$B$21 -> 872.25 | D21: =Inputs!$B$25*$B$21 -> 872.25 | E21: =Inputs!$B$25*$B$21 -> 872.25 | F21: =Inputs!$B$25*$B$21 -> 872.25 | G21: =Inputs!$B$25*$B$21 -> 872.25 | H21: =Inputs!$B$25*$B$21 -> 872.25 | I21: =Inputs!$B$25*$B$21 -> 872.25 | J21: =Inputs!$B$25*$B$21 -> 872.25 | K21: =SUM(C21:J21) -> 6978 | L21: =Politica_Inventarios!F30 -> 0 | M21: =Inputs!C39 -> 148 | N21: =K21+L21-M21 -> 6830 | O21: =IF(ROUNDUP(N21/Inputs!$B$73,0)<0,0,ROUNDUP(N21/Inputs!$B$73,0)) -> 46 | P21: =O21*Inputs!$B$90 -> 1288
A22: PRODUCCIÓN TOTAL EC | C22: =Inputs!B7 -> 1164 | D22: =Inputs!C7 -> 1164 | E22: =Inputs!D7 -> 1164 | F22: =Inputs!E7 -> 1164 | G22: =Inputs!F7 -> 1164 | H22: =Inputs!G7 -> 1164 | I22: =Inputs!H7 -> 1164 | J22: =Inputs!I7 -> 1164 | K22: =Inputs!J7 -> 9312 | P22: =SUM(P16:P21) -> 23226
A24: Planta East
A25: Material | B25: Consumo/EC | C25: Q1 | D25: Q2 | E25: Q3 | F25: Q4 | G25: Q5 | H25: Q6 | I25: Q7 | J25: Q8 | K25: TOTAL | L25: SS | M25: II | N25: A pedir | O25: Lotes | P25: Costo
A26: Pieza 1 | B26: 0.01 | C26: =Inputs!$B$17*$B$26 -> 0 | D26: =Inputs!$B$17*$B$26 -> 0 | E26: =Inputs!$B$17*$B$26 -> 0 | F26: =Inputs!$B$17*$B$26 -> 0 | G26: =Inputs!$B$17*$B$26 -> 0 | H26: =Inputs!$B$17*$B$26 -> 0 | I26: =Inputs!$B$17*$B$26 -> 0 | J26: =Inputs!$B$17*$B$26 -> 0 | K26: =SUM(C26:J26) -> 0 | L26: =Politica_Inventarios!F36 -> 0 | M26: =Inputs!D34 -> 0 | N26: =K26+L26-M26 -> 0 | O26: =IF(ROUNDUP(N26/Inputs!$B$68,0)<0,0,ROUNDUP(N26/Inputs!$B$68,0))*1.1+0 -> 0 | P26: =O26*Inputs!$B$85 -> 0
A27: Pieza 2 | B27: 8 | C27: =Inputs!B26*$B$27 -> 0 | D27: =Inputs!C17*$B$27 -> 0 | E27: =Inputs!D17*$B$27 -> 0 | F27: =Inputs!E17*$B$27 -> 0 | G27: =Inputs!F17*$B$27 -> 0 | H27: =Inputs!G17*$B$27 -> 0 | I27: =Inputs!H17*$B$27 -> 0 | J27: =Inputs!I17*$B$27 -> 0 | K27: =SUM(C27:J27) -> 0 | L27: =Politica_Inventarios!F37 -> 0 | M27: =Inputs!D35 -> 0 | N27: =K27+L27-M27 -> 0 | O27: =IF(ROUNDUP(N27/Inputs!$B$69,0)<0,0,ROUNDUP(N27/Inputs!$B$69,0)) -> 0 | P27: =O27*Inputs!$B$86 -> 0
A28: Pieza 3 | B28: 0.3 | C28: =Inputs!$B$26*$B$28 -> 0 | D28: =Inputs!$B$26*$B$28 -> 0 | E28: =Inputs!$B$26*$B$28 -> 0 | F28: =Inputs!$B$26*$B$28 -> 0 | G28: =Inputs!$B$26*$B$28 -> 0 | H28: =Inputs!$B$26*$B$28 -> 0 | I28: =Inputs!$B$26*$B$28 -> 0 | J28: =Inputs!$B$26*$B$28 -> 0 | K28: =SUM(C28:J28) -> 0 | L28: =Politica_Inventarios!F38 -> 0 | M28: =Inputs!D36 -> 0 | N28: =K28+L28-M28 -> 0 | O28: =IF(ROUNDUP(N28/Inputs!$B$70,0)<0,0,ROUNDUP(N28/Inputs!$B$70,0)) -> 0 | P28: =O28*Inputs!$B$87 -> 0
A29: Pieza 4 | B29: 0.6 | C29: =Inputs!$B$26*$B$29 -> 0 | D29: =Inputs!$B$26*$B$29 -> 0 | E29: =Inputs!$B$26*$B$29 -> 0 | F29: =Inputs!$B$26*$B$29 -> 0 | G29: =Inputs!$B$26*$B$29 -> 0 | H29: =Inputs!$B$26*$B$29 -> 0 | I29: =Inputs!$B$26*$B$29 -> 0 | J29: =Inputs!$B$26*$B$29 -> 0 | K29: =SUM(C29:J29) -> 0 | L29: =Politica_Inventarios!F39 -> 0 | M29: =Inputs!D37 -> 0 | N29: =K29+L29-M29 -> 0 | O29: =IF(ROUNDUP(N29/Inputs!$B$71,0)<0,0,ROUNDUP(N29/Inputs!$B$71,0)) -> 0 | P29: =O29*Inputs!$B$88 -> 0
A30: Pieza 5 | B30: 2 | C30: =Inputs!$B$26*$B$30 -> 0 | D30: =Inputs!$B$26*$B$30 -> 0 | E30: =Inputs!$B$26*$B$30 -> 0 | F30: =Inputs!$B$26*$B$30 -> 0 | G30: =Inputs!$B$26*$B$30 -> 0 | H30: =Inputs!$B$26*$B$30 -> 0 | I30: =Inputs!$B$26*$B$30 -> 0 | J30: =Inputs!$B$26*$B$30 -> 0 | K30: =SUM(C30:J30) -> 0 | L30: =Politica_Inventarios!F40 -> 0 | M30: =Inputs!D38 -> 0 | N30: =K30+L30-M30 -> 0 | O30: =IF(ROUNDUP(N30/Inputs!$B$72,0)<0,0,ROUNDUP(N30/Inputs!$B$72,0)) -> 0 | P30: =O30*Inputs!$B$89 -> 0
A31: Pieza 6 | B31: 0.75 | C31: =Inputs!$B$26*$B$31 -> 0 | D31: =Inputs!$B$26*$B$31 -> 0 | E31: =Inputs!$B$26*$B$31 -> 0 | F31: =Inputs!$B$26*$B$31 -> 0 | G31: =Inputs!$B$26*$B$31 -> 0 | H31: =Inputs!$B$26*$B$31 -> 0 | I31: =Inputs!$B$26*$B$31 -> 0 | J31: =Inputs!$B$26*$B$31 -> 0 | K31: =SUM(C31:J31) -> 0 | L31: =Politica_Inventarios!F41 -> 0 | M31: =Inputs!D39 -> 0 | N31: =K31+L31-M31 -> 0 | O31: =IF(ROUNDUP(N31/Inputs!$B$73,0)<0,0,ROUNDUP(N31/Inputs!$B$73,0)) -> 0 | P31: =O31*Inputs!$B$90 -> 0
A32: PRODUCCIÓN TOTAL EC | C32: =Inputs!B8 -> 0 | D32: =Inputs!C8 -> 0 | E32: =Inputs!D8 -> 0 | F32: =Inputs!E8 -> 0 | G32: =Inputs!F8 -> 0 | H32: =Inputs!G8 -> 0 | I32: =Inputs!H8 -> 0 | J32: =Inputs!I8 -> 0 | K32: =Inputs!J8 -> 0 | P32: =SUM(P26:P31) -> 0
A34: Planta North
A35: Material | B35: Consumo/EC | C35: Q1 | D35: Q2 | E35: Q3 | F35: Q4 | G35: Q5 | H35: Q6 | I35: Q7 | J35: Q8 | K35: TOTAL | L35: SS | M35: II | N35: A pedir | O35: Lotes | P35: Costo
A36: Pieza 1 | B36: 0.01 | C36: =Inputs!$B$18*$B$36 -> 0 | D36: =Inputs!$B$18*$B$36 -> 0 | E36: =Inputs!$B$18*$B$36 -> 0 | F36: =Inputs!$B$18*$B$36 -> 0 | G36: =Inputs!$B$18*$B$36 -> 0 | H36: =Inputs!$B$18*$B$36 -> 0 | I36: =Inputs!$B$18*$B$36 -> 0 | J36: =Inputs!$B$18*$B$36 -> 0 | K36: =SUM(C36:J36) -> 0 | L36: =Politica_Inventarios!F47 -> 0 | M36: =Inputs!E34 -> 0 | N36: =K36+L36-M36 -> 0 | O36: =IF(ROUNDUP(N36/Inputs!$B$68,0)<0,0,ROUNDUP(N36/Inputs!$B$68,0))*1.1+0 -> 0 | P36: =O36*Inputs!$B$85 -> 0
A37: Pieza 2 | B37: 8 | C37: =Inputs!$B$27*$B$37 -> 0 | D37: =Inputs!$B$27*$B$37 -> 0 | E37: =Inputs!$B$27*$B$37 -> 0 | F37: =Inputs!$B$27*$B$37 -> 0 | G37: =Inputs!$B$27*$B$37 -> 0 | H37: =Inputs!$B$27*$B$37 -> 0 | I37: =Inputs!$B$27*$B$37 -> 0 | J37: =Inputs!$B$27*$B$37 -> 0 | K37: =SUM(C37:J37) -> 0 | L37: =Politica_Inventarios!F48 -> 0 | M37: =Inputs!E35 -> 0 | N37: =K37+L37-M37 -> 0 | O37: =IF(ROUNDUP(N37/Inputs!$B$69,0)<0,0,ROUNDUP(N37/Inputs!$B$69,0)) -> 0 | P37: =O37*Inputs!$B$86 -> 0
A38: Pieza 3 | B38: 0.3 | C38: =Inputs!$B$27*$B$38 -> 0 | D38: =Inputs!$B$27*$B$38 -> 0 | E38: =Inputs!$B$27*$B$38 -> 0 | F38: =Inputs!$B$27*$B$38 -> 0 | G38: =Inputs!$B$27*$B$38 -> 0 | H38: =Inputs!$B$27*$B$38 -> 0 | I38: =Inputs!$B$27*$B$38 -> 0 | J38: =Inputs!$B$27*$B$38 -> 0 | K38: =SUM(C38:J38) -> 0 | L38: =Politica_Inventarios!F49 -> 0 | M38: =Inputs!E36 -> 0 | N38: =K38+L38-M38 -> 0 | O38: =IF(ROUNDUP(N38/Inputs!$B$70,0)<0,0,ROUNDUP(N38/Inputs!$B$70,0)) -> 0 | P38: =O38*Inputs!$B$87 -> 0
A39: Pieza 4 | B39: 0.6 | C39: =Inputs!$B$27*$B$39 -> 0 | D39: =Inputs!$B$27*$B$39 -> 0 | E39: =Inputs!$B$27*$B$39 -> 0 | F39: =Inputs!$B$27*$B$39 -> 0 | G39: =Inputs!$B$27*$B$39 -> 0 | H39: =Inputs!$B$27*$B$39 -> 0 | I39: =Inputs!$B$27*$B$39 -> 0 | J39: =Inputs!$B$27*$B$39 -> 0 | K39: =SUM(C39:J39) -> 0 | L39: =Politica_Inventarios!F50 -> 0 | M39: =Inputs!E37 -> 0 | N39: =K39+L39-M39 -> 0 | O39: =IF(ROUNDUP(N39/Inputs!$B$71,0)<0,0,ROUNDUP(N39/Inputs!$B$71,0)) -> 0 | P39: =O39*Inputs!$B$88 -> 0
A40: Pieza 5 | B40: 2 | C40: =Inputs!$B$27*$B$40 -> 0 | D40: =Inputs!$B$27*$B$40 -> 0 | E40: =Inputs!$B$27*$B$40 -> 0 | F40: =Inputs!$B$27*$B$40 -> 0 | G40: =Inputs!$B$27*$B$40 -> 0 | H40: =Inputs!$B$27*$B$40 -> 0 | I40: =Inputs!$B$27*$B$40 -> 0 | J40: =Inputs!$B$27*$B$40 -> 0 | K40: =SUM(C40:J40) -> 0 | L40: =Politica_Inventarios!F51 -> 0 | M40: =Inputs!E38 -> 0 | N40: =K40+L40-M40 -> 0 | O40: =IF(ROUNDUP(N40/Inputs!$B$72,0)<0,0,ROUNDUP(N40/Inputs!$B$72,0)) -> 0 | P40: =O40*Inputs!$B$89 -> 0
A41: Pieza 6 | B41: 0.75 | C41: =Inputs!$B$27*$B$41 -> 0 | D41: =Inputs!$B$27*$B$41 -> 0 | E41: =Inputs!$B$27*$B$41 -> 0 | F41: =Inputs!$B$27*$B$41 -> 0 | G41: =Inputs!$B$27*$B$41 -> 0 | H41: =Inputs!$B$27*$B$41 -> 0 | I41: =Inputs!$B$27*$B$41 -> 0 | J41: =Inputs!$B$27*$B$41 -> 0 | K41: =SUM(C41:J41) -> 0 | L41: =Politica_Inventarios!F52 -> 0 | M41: =Inputs!E39 -> 0 | N41: =K41+L41-M41 -> 0 | O41: =IF(ROUNDUP(N41/Inputs!$B$73,0)<0,0,ROUNDUP(N41/Inputs!$B$73,0)) -> 0 | P41: =O41*Inputs!$B$90 -> 0
A42: PRODUCCIÓN TOTAL EC | C42: =Inputs!B9 -> 0 | D42: =Inputs!C9 -> 0 | E42: =Inputs!D9 -> 0 | F42: =Inputs!E9 -> 0 | G42: =Inputs!F9 -> 0 | H42: =Inputs!G9 -> 0 | I42: =Inputs!H9 -> 0 | J42: =Inputs!I9 -> 0 | K42: =Inputs!J9 -> 0 | P42: =SUM(P36:P41) -> 0
A44: Planta South
...

Sheet Inventario_Dinamico
A1: INVENTARIO DINÁMICO - Control por Quincena
J3: EOQ | K3: ROP | X3: EOQ | Y3: ROP
A4: Parte A | J4: Ordenar esta cantidad | K4: Siempre mantener | L4: Lotes | M4: Costo total | O4: Parte B | X4: Ordenar esta cantidad | Y4: Siempre mantener | Z4: Lotes | AA4: Costo Total
A5: Planta Center | O5: Planta Center
A6: Concepto | B6: Q1 | C6: Q2 | D6: Q3 | E6: Q4 | F6: Q5 | G6: Q6 | H6: Q7 | I6: Q8 | O6: Concepto | P6: Q1 | Q6: Q2 | R6: Q3 | S6: Q4 | T6: Q5 | U6: Q6 | V6: Q7 | W6: Q8
A7: Inv_Inicial | B7: =Inputs!B32 -> 19552 | C7: =B10 -> 17688 | D7: =C10 -> 15824 | E7: =D10 -> 13960 | F7: =E10 -> 12096 | G7: =F10 -> 10232 | H7: =G10 -> 8368 | I7: =H10 -> 6504 | J7: =Politica_Inventarios!N12 -> 179 | K7: =Politica_Inventarios!J12 -> 1864 | L7: =Inputs!B66 -> 30 | O7: Inv_Inicial | P7: =Inputs!B33 -> 4467 | Q7: =P10 -> 4094.4 | R7: =Q10 -> 3721.8 | S7: =R10 -> 3349.2 | T7: =S10 -> 2976.6 | U7: =T10 -> 2604 | V7: =U10 -> 2231.4 | W7: =V10 -> 1858.8 | X7: =Politica_Inventarios!N13 -> 84 | Y7: =Politica_Inventarios!J13 -> 372.6 | Z7: =Inputs!B67 -> 12
A8: Recepciones | B8: 0 | C8: 0 | D8: 0 | E8: 0 | F8: 0 | G8: 0 | H8: 0 | I8: 0 | M8: =SUM(B8:I8)*VLOOKUP(Inputs!B110,Inputs!A107:B109,2,FALSE) -> 0 | O8: Recepciones | P8: 0 | Q8: 0 | R8: 0 | S8: 0 | T8: 0 | U8: 0 | V8: 0 | W8: 0 | AA8: =SUM(P8:W8)*VLOOKUP(Inputs!B118,Inputs!A114:B117,2,FALSE) -> 0
A9: Consumo | B9: =Inputs!B6*Inputs!$B$48 -> 1864 | C9: =Inputs!C6*Inputs!$B$48 -> 1864 | D9: =Inputs!D6*Inputs!$B$48 -> 1864 | E9: =Inputs!E6*Inputs!$B$48 -> 1864 | F9: =Inputs!F6*Inputs!$B$48 -> 1864 | G9: =Inputs!G6*Inputs!$B$48 -> 1864 | H9: =Inputs!H6*Inputs!$B$48 -> 1864 | I9: =Inputs!I6*Inputs!$B$48 -> 1864 | J9: =SUM(B9:I9)-I10 -> 10272 | O9: Consumo | P9: =Inputs!$B$15*Inputs!$B$49 -> 372.6 | Q9: =Inputs!$B$15*Inputs!$B$49 -> 372.6 | R9: =Inputs!$B$15*Inputs!$B$49 -> 372.6 | S9: =Inputs!$B$15*Inputs!$B$49 -> 372.6 | T9: =Inputs!$B$15*Inputs!$B$49 -> 372.6 | U9: =Inputs!$B$15*Inputs!$B$49 -> 372.6 | V9: =Inputs!$B$15*Inputs!$B$49 -> 372.6 | W9: =Inputs!$B$15*Inputs!$B$49 -> 372.6 | X9: =SUM(P9:W9)-W10 -> 1494.6 | Y9: =X7/2 -> 42
A10: Inv_Final | B10: =B7+(B8*$L$7)-B9 -> 17688 | C10: =C7+(C8*$L$7)-C9 -> 15824 | D10: =D7+(D8*$L$7)-D9 -> 13960 | E10: =E7+(E8*$L$7)-E9 -> 12096 | F10: =F7+(F8*$L$7)-F9 -> 10232 | G10: =G7+(G8*$L$7)-G9 -> 8368 | H10: =H7+(H8*$L$7)-H9 -> 6504 | I10: =I7+(I8*$L$7)-I9 -> 4640 | J10: 380.8 | K10: =J9/L7 -> 342.4 | O10: Inv_Final | P10: =P7+(P8*$Z$7)-P9 -> 4094.4 | Q10: =Q7+(Q8*$Z$7)-Q9 -> 3721.8 | R10: =R7+(R8*$Z$7)-R9 -> 3349.2 | S10: =S7+(S8*$Z$7)-S9 -> 2976.6 | T10: =T7+(T8*$Z$7)-T9 -> 2604 | U10: =U7+(U8*$Z$7)-U9 -> 2231.4 | V10: =V7+(V8*$Z$7)-V9 -> 1858.8 | W10: =W7+(W8*$Z$7)-W9 -> 1486.2 | X10: 144 | Y10: =X9/Z7 -> 124.55
A11: Planta West | O11: Planta West
A12: Concepto | B12: Q1 | C12: Q2 | D12: Q3 | E12: Q4 | F12: Q5 | G12: Q6 | H12: Q7 | I12: Q8 | O12: Concepto | P12: Q1 | Q12: Q2 | R12: Q3 | S12: Q4 | T12: Q5 | U12: Q6 | V12: Q7 | W12: Q8
A13: Inv_Inicial | B13: =Inputs!C32 -> 14864 | C13: =B16 -> 13700 | D13: =C16 -> 12536 | E13: =D16 -> 11372 | F13: =E16 -> 10208 | G13: =F16 -> 9044 | H13: =G16 -> 7880 | I13: =H16 -> 6716 | J13: =Politica_Inventarios!N23 -> 141 | K13: =Politica_Inventarios!J23 -> 1164 | L13: 30 | O13: Inv_Inicial | P13: =Inputs!C32 -> 14864 | Q13: =P16 -> 15435.4 | R13: =Q16 -> 15202.8 | S13: =R16 -> 14970.2 | T13: =S16 -> 15541.6 | U13: =T16 -> 15309 | V13: =U16 -> 15076.4 | W13: =V16 -> 15647.8 | X13: =Politica_Inventarios!N24 -> 66 | Y13: =Politica_Inventarios!J24 -> 232.6 | Z13: 12
A14: Recepciones | B14: 0 | C14: 0 | D14: 0 | E14: 0 | F14: 0 | G14: 0 | H14: 0 | I14: 0 | M14: =SUM(B14:I14)*VLOOKUP(Inputs!B110,Inputs!A107:B109,2,FALSE) -> 0 | O14: Recepciones | P14: 67 | Q14: 0 | R14: 0 | S14: 67 | T14: 0 | U14: 0 | V14: 67 | W14: 0 | AA14: =SUM(P14:W14)*VLOOKUP(Inputs!B118,Inputs!A114:B117,2,FALSE) -> 66330
A15: Consumo | B15: =Inputs!B7*Inputs!$B$48 -> 1164 | C15: =Inputs!C7*Inputs!$B$48 -> 1164 | D15: =Inputs!D7*Inputs!$B$48 -> 1164 | E15: =Inputs!E7*Inputs!$B$48 -> 1164 | F15: =Inputs!F7*Inputs!$B$48 -> 1164 | G15: =Inputs!G7*Inputs!$B$48 -> 1164 | H15: =Inputs!H7*Inputs!$B$48 -> 1164 | I15: =Inputs!I7*Inputs!$B$48 -> 1164 | J15: =SUM(B15:I15)-I16 -> 3760 | K15: =J13/2 -> 70.5 | O15: Consumo | P15: =Inputs!$B$16*Inputs!$B$49 -> 232.6 | Q15: =Inputs!$B$16*Inputs!$B$49 -> 232.6 | R15: =Inputs!$B$16*Inputs!$B$49 -> 232.6 | S15: =Inputs!$B$16*Inputs!$B$49 -> 232.6 | T15: =Inputs!$B$16*Inputs!$B$49 -> 232.6 | U15: =Inputs!$B$16*Inputs!$B$49 -> 232.6 | V15: =Inputs!$B$16*Inputs!$B$49 -> 232.6 | W15: =Inputs!$B$16*Inputs!$B$49 -> 232.6 | X15: =SUM(P15:W15)-W16 -> -13554.4 | Y15: =X13/2 -> 33
A16: Inv_Final | B16: =B13+(B14*$L$13)-B15 -> 13700 | C16: =C13+(C14*$L$7)-C15 -> 12536 | D16: =D13+(D14*$L$7)-D15 -> 11372 | E16: =E13+(E14*$L$7)-E15 -> 10208 | F16: =F13+(F14*$L$7)-F15 -> 9044 | G16: =G13+(G14*$L$7)-G15 -> 7880 | H16: =H13+(H14*$L$7)-H15 -> 6716 | I16: =I13+(I14*$L$7)-I15 -> 5552 | J16: 149.33333 | K16: =J15/L13 -> 125.33333 | O16: Inv_Final | P16: =P13+(P14*$Z$7)-P15 -> 15435.4 | Q16: =Q13+(Q14*$Z$7)-Q15 -> 15202.8 | R16: =R13+(R14*$Z$7)-R15 -> 14970.2 | S16: =S13+(S14*$Z$7)-S15 -> 15541.6 | T16: =T13+(T14*$Z$7)-T15 -> 15309 | U16: =U13+(U14*$Z$7)-U15 -> 15076.4 | V16: =V13+(V14*$Z$7)-V15 -> 15647.8 | W16: =W13+(W14*$Z$7)-W15 -> 15415.2 | X16: 120 | Y16: =X15/Z13 -> -1129.5333
A17: Pieza Planta East | O17: Pieza Planta East
A18: Concepto | B18: Q1 | C18: Q2 | D18: Q3 | E18: Q4 | F18: Q5 | G18: Q6 | H18: Q7 | I18: Q8 | O18: Concepto | P18: Q1 | Q18: Q2 | R18: Q3 | S18: Q4 | T18: Q5 | U18: Q6 | V18: Q7 | W18: Q8
A19: Inv_Inicial | B19: =Inputs!D32 -> 0 | C19: =B22 -> 0 | D19: =C22 -> 0 | E19: =D22 -> 0 | F19: =E22 -> 0 | G19: =F22 -> 0 | H19: =G22 -> 0 | I19: =H22 -> 0 | O19: Inv_Inicial | P19: =Inputs!D33 -> 0 | Q19: =P22 -> 0 | R19: =Q22 -> 0 | S19: =R22 -> 0 | T19: =S22 -> 0 | U19: =T22 -> 0 | V19: =U22 -> 0 | W19: =V22 -> 0
A20: Recepciones | B20: 0 | C20: 0 | D20: 0 | E20: 0 | F20: 0 | G20: 0 | H20: 0 | I20: 0 | O20: Recepciones | P20: 0 | Q20: 0 | R20: 0 | S20: 0 | T20: 0 | U20: 0 | V20: 0 | W20: 0
A21: Consumo | B21: =Inputs!B8*Inputs!$B$48 -> 0 | C21: =Inputs!C8*Inputs!$B$48 -> 0 | D21: =Inputs!D8*Inputs!$B$48 -> 0 | E21: =Inputs!E8*Inputs!$B$48 -> 0 | F21: =Inputs!F8*Inputs!$B$48 -> 0 | G21: =Inputs!G8*Inputs!$B$48 -> 0 | H21: =Inputs!H8*Inputs!$B$48 -> 0 | I21: =Inputs!I8*Inputs!$B$48 -> 0 | O21: Consumo | P21: =Inputs!$B$17*Inputs!$B$49 -> 0 | Q21: =Inputs!$B$17*Inputs!$B$49 -> 0 | R21: =Inputs!$B$17*Inputs!$B$49 -> 0 | S21: =Inputs!$B$17*Inputs!$B$49 -> 0 | T21: =Inputs!$B$17*Inputs!$B$49 -> 0 | U21: =Inputs!$B$17*Inputs!$B$49 -> 0 | V21: =Inputs!$B$17*Inputs!$B$49 -> 0 | W21: =Inputs!$B$17*Inputs!$B$49 -> 0
A22: Inv_Final | B22: =B19+(B20*$L$13)-B21 -> 0 | C22: =C19+(C20*$L$13)-C21 -> 0 | D22: =D19+(D20*$L$13)-D21 -> 0 | E22: =E19+(E20*$L$13)-E21 -> 0 | F22: =F19+(F20*$L$13)-F21 -> 0 | G22: =G19+(G20*$L$13)-G21 -> 0 | H22: =H19+(H20*$L$13)-H21 -> 0 | I22: =I19+(I20*$L$13)-I21 -> 0 | O22: Inv_Final | P22: =P19+(P20*$Z$7)-P21 -> 0 | Q22: =Q19+(Q20*$Z$7)-Q21 -> 0 | R22: =R19+(R20*$Z$7)-R21 -> 0 | S22: =S19+(S20*$Z$7)-S21 -> 0 | T22: =T19+(T20*$Z$7)-T21 -> 0 | U22: =U19+(U20*$Z$7)-U21 -> 0 | V22: =V19+(V20*$Z$7)-V21 -> 0 | W22: =W19+(W20*$Z$7)-W21 -> 0
A23: Planta North | O23: Planta North
A24: Concepto | B24: Q1 | C24: Q2 | D24: Q3 | E24: Q4 | F24: Q5 | G24: Q6 | H24: Q7 | I24: Q8 | O24: Concepto | P24: Q1 | Q24: Q2 | R24: Q3 | S24: Q4 | T24: Q5 | U24: Q6 | V24: Q7 | W24: Q8
A25: Inv_Inicial | B25: =Inputs!E32 -> 0 | C25: =B28 -> 0 | D25: =C28 -> 0 | E25: =D28 -> 0 | F25: =E28 -> 0 | G25: =F28 -> 0 | H25: =G28 -> 0 | I25: =H28 -> 0 | J25: =Politica_Inventarios!N45 -> 0 | K25: =Politica_Inventarios!J45 -> 0 | L25: 30 | O25: Inv_Inicial | P25: =Inputs!E33 -> 0 | Q25: =P28 -> 0 | R25: =Q28 -> 0 | S25: =R28 -> 0 | T25: =S28 -> 0 | U25: =T28 -> 0 | V25: =U28 -> 0 | W25: =V28 -> 0 | X25: =Politica_Inventarios!N46 -> 0 | Y25: =Politica_Inventarios!J46 -> 0 | Z25: 12
A26: Recepciones | B26: 0 | C26: 0 | D26: 0 | E26: 0 | F26: 0 | G26: 0 | H26: 0 | I26: 0 | O26: Recepciones | P26: 0 | Q26: 0 | R26: 0 | S26: 0 | T26: 0 | U26: 0 | V26: 0 | W26: 0
A27: Consumo | B27: =Inputs!B9*Inputs!$B$48 -> 0 | C27: =Inputs!C9*Inputs!$B$48 -> 0 | D27: =Inputs!D9*Inputs!$B$48 -> 0 | E27: =Inputs!E9*Inputs!$B$48 -> 0 | F27: =Inputs!F9*Inputs!$B$48 -> 0 | G27: =Inputs!G9*Inputs!$B$48 -> 0 | H27: =Inputs!H9*Inputs!$B$48 -> 0 | I27: =Inputs!I9*Inputs!$B$48 -> 0 | O27: Consumo | P27: =Inputs!$B$18*Inputs!$B$49 -> 0 | Q27: =Inputs!$B$18*Inputs!$B$49 -> 0 | R27: =Inputs!$B$18*Inputs!$B$49 -> 0 | S27: =Inputs!$B$18*Inputs!$B$49 -> 0 | T27: =Inputs!$B$18*Inputs!$B$49 -> 0 | U27: =Inputs!$B$18*Inputs!$B$49 -> 0 | V27: =Inputs!$B$18*Inputs!$B$49 -> 0 | W27: =Inputs!$B$18*Inputs!$B$49 -> 0
A28: Inv_Final | B28: =B25+(B26*$L$25)-B27 -> 0 | C28: =C25+(C26*$L$25)-C27 -> 0 | D28: =D25+(D26*$L$25)-D27 -> 0 | E28: =E25+(E26*$L$25)-E27 -> 0 | F28: =F25+(F26*$L$25)-F27 -> 0 | G28: =G25+(G26*$L$25)-G27 -> 0 | H28: =H25+(H26*$L$25)-H27 -> 0 | I28: =I25+(I26*$L$25)-I27 -> 0 | O28: Inv_Final | P28: =P25+(P26*$Z$7)-P27 -> 0 | Q28: =Q25+(Q26*$Z$7)-Q27 -> 0 | R28: =R25+(R26*$Z$7)-R27 -> 0 | S28: =S25+(S26*$Z$7)-S27 -> 0 | T28: =T25+(T26*$Z$7)-T27 -> 0 | U28: =U25+(U26*$Z$7)-U27 -> 0 | V28: =V25+(V26*$Z$7)-V27 -> 0 | W28: =W25+(W26*$Z$7)-W27 -> 0
A29: Planta South | O29: Planta South
A30: Concepto | B30: Q1 | C30: Q2 | D30: Q3 | E30: Q4 | F30: Q5 | G30: Q6 | H30: Q7 | I30: Q8 | O30: Concepto | P30: Q1 | Q30: Q2 | R30: Q3 | S30: Q4 | T30: Q5 | U30: Q6 | V30: Q7 | W30: Q8
A31: Inv_Inicial | B31: =Inputs!F32 -> 0 | C31: =B34 -> 0 | D31: =C34 -> 0 | E31: =D34 -> 0 | F31: =E34 -> 0 | G31: =F34 -> 0 | H31: =G34 -> 0 | I31: =H34 -> 0 | O31: Inv_Inicial | P31: =Inputs!E33 -> 0 | Q31: =P34 -> 0 | R31: =Q34 -> 0 | S31: =R34 -> 0 | T31: =S34 -> 0 | U31: =T34 -> 0 | V31: =U34 -> 0 | W31: =V34 -> 0
A32: Recepciones | B32: 0 | C32: 0 | D32: 0 | E32: 0 | F32: 0 | G32: 0 | H32: 0 | I32: 0 | O32: Recepciones | P32: 0 | Q32: 0 | R32: 0 | S32: 0 | T32: 0 | U32: 0 | V32: 0 | W32: 0
A33: Consumo | B33: =Inputs!B10*Inputs!$B$48 -> 0 | C33: =Inputs!C10*Inputs!$B$48 -> 0 | D33: =Inputs!D10*Inputs!$B$48 -> 0 | E33: =Inputs!E10*Inputs!$B$48 -> 0 | F33: =Inputs!F10*Inputs!$B$48 -> 0 | G33: =Inputs!G10*Inputs!$B$48 -> 0 | H33: =Inputs!H10*Inputs!$B$48 -> 0 | I33: =Inputs!I10*Inputs!$B$48 -> 0 | O33: Consumo | P33: =Inputs!$B$19*Inputs!$B$49 -> 0 | Q33: =Inputs!$B$19*Inputs!$B$49 -> 0 | R33: =Inputs!$B$19*Inputs!$B$49 -> 0 | S33: =Inputs!$B$19*Inputs!$B$49 -> 0 | T33: =Inputs!$B$19*Inputs!$B$49 -> 0 | U33: =Inputs!$B$19*Inputs!$B$49 -> 0 | V33: =Inputs!$B$19*Inputs!$B$49 -> 0 | W33: =Inputs!$B$19*Inputs!$B$49 -> 0
A34: Inv_Final | B34: =B31+(B32*$L$13)-B33 -> 0 | C34: =C31+(C32*$L$13)-C33 -> 0 | D34: =D31+(D32*$L$13)-D33 -> 0 | E34: =E31+(E32*$L$13)-E33 -> 0 | F34: =F31+(F32*$L$13)-F33 -> 0 | G34: =G31+(G32*$L$13)-G33 -> 0 | H34: =H31+(H32*$L$13)-H33 -> 0 | I34: =I31+(I32*$L$13)-I33 -> 0 | O34: Inv_Final | P34: =P31+(P32*$Z$7)-P33 -> 0 | Q34: =Q31+(Q32*$Z$7)-Q33 -> 0 | R34: =R31+(R32*$Z$7)-R33 -> 0 | S34: =S31+(S32*$Z$7)-S33 -> 0 | T34: =T31+(T32*$Z$7)-T33 -> 0 | U34: =U31+(U32*$Z$7)-U33 -> 0 | V34: =V31+(V32*$Z$7)-V33 -> 0 | W34: =W31+(W32*$Z$7)-W33 -> 0
J35: Totales | M35: =SUM(M14,M8) -> 0
A36: Costo | O36: Costo
A37: Holding | B37: =SUM(B10+B16+B22+B28+B34)*Inputs!$C$95 -> 9416.4 | C37: =SUM(C10+C16+C22+C28+C34)*Inputs!$C$95 -> 8508 | D37: =SUM(D10+D16+D22+D28+D34)*Inputs!$C$95 -> 7599.6 | E37: =SUM(E10+E16+E22+E28+E34)*Inputs!$C$95 -> 6691.2 | F37: =SUM(F10+F16+F22+F28+F34)*Inputs!$C$95 -> 5782.8 | G37: =SUM(G10+G16+G22+G28+G34)*Inputs!$C$95 -> 4874.4 | H37: =SUM(H10+H16+H22+H28+H34)*Inputs!$C$95 -> 3966 | I37: =SUM(I10+I16+I22+I28+I34)*Inputs!$C$95 -> 3057.6 | J37: =SUM(B37:I37) -> 49896 | O37: Holding | P37: =SUM(P10+P16+P22+P28+P34)*Inputs!$C$95 -> 5858.94 | Q37: =SUM(Q10+Q16+Q22+Q28+Q34)*Inputs!$C$95 -> 5677.38 | R37: =SUM(R10+R16+R22+R28+R34)*Inputs!$C$95 -> 5495.82 | S37: =SUM(S10+S16+S22+S28+S34)*Inputs!$C$95 -> 5555.46 | T37: =SUM(T10+T16+T22+T28+T34)*Inputs!$C$95 -> 5373.9 | U37: =SUM(U10+U16+U22+U28+U34)*Inputs!$C$95 -> 5192.34 | V37: =SUM(V10+V16+V22+V28+V34)*Inputs!$C$95 -> 5251.98 | W37: =SUM(W10+W16+W22+W28+W34)*Inputs!$C$95 -> 5070.42
A38: Ordering | B38: =B39*Inputs!$B$95 -> 0 | C38: =C39*Inputs!$B$95 -> 0 | D38: =D39*Inputs!$B$95 -> 0 | E38: =E39*Inputs!$B$95 -> 0 | F38: =F39*Inputs!$B$95 -> 0 | G38: =G39*Inputs!$B$95 -> 0 | H38: =H39*Inputs!$B$95 -> 0 | I38: =I39*Inputs!$B$95 -> 0 | J38: =SUM(B38:I38) -> 0 | O38: Ordering | P38: =P39*Inputs!$B$96 -> 6000 | Q38: =Q39*Inputs!$B$96 -> 0 | R38: =R39*Inputs!$B$96 -> 0 | S38: =S39*Inputs!$B$96 -> 6000 | T38: =T39*Inputs!$B$96 -> 0 | U38: =U39*Inputs!$B$96 -> 0 | V38: =V39*Inputs!$B$96 -> 6000 | W38: =W39*Inputs!$B$96 -> 0
A39: Ordenes | B39: =+COUNTIF(B42:B46,">0") -> 0 | C39: =+COUNTIF(C42:C46,">0") -> 0 | D39: =+COUNTIF(D42:D46,">0") -> 0 | E39: =+COUNTIF(E42:E46,">0") -> 0 | F39: =+COUNTIF(F42:F46,">0") -> 0 | G39: =+COUNTIF(G42:G46,">0") -> 0 | H39: =+COUNTIF(H42:H46,">0") -> 0 | I39: =+COUNTIF(I42:I46,">0") -> 0 | O39: Ordenes | P39: =+COUNTIF(P42:P46,">0") -> 1 | Q39: =+COUNTIF(Q42:Q46,">0") -> 0 | R39: =+COUNTIF(R42:R46,">0") -> 0 | S39: =+COUNTIF(S42:S46,">0") -> 1 | T39: =+COUNTIF(T42:T46,">0") -> 0 | U39: =+COUNTIF(U42:U46,">0") -> 0 | V39: =+COUNTIF(V42:V46,">0") -> 1 | W39: =+COUNTIF(W42:W46,">0") -> 0
J40: =+SUM(J37:J38) -> 49896
A41: Recepciones | O41: Recepciones
...

Sheet Costos
A1: Holding and Ordering
B2: Q0 | C2: Q1 | D2: Q2 | E2: Q3 | F2: Q4 | G2: Q5 | H2: Q6 | I2: Q7 | J2: Q8 | K2: CashFlow | L2: Costo de proveedor
A3: Ordering
A4: Parte A | C4: =Inventario_Dinamico!B38 -> 0 | D4: =Inventario_Dinamico!C38 -> 0 | E4: =Inventario_Dinamico!D38 -> 0 | F4: =Inventario_Dinamico!E38 -> 0 | G4: =Inventario_Dinamico!F38 -> 0 | H4: =Inventario_Dinamico!G38 -> 0 | I4: =Inventario_Dinamico!H38 -> 0 | J4: =Inventario_Dinamico!I38 -> 0
A5: Parte B | C5: =Inventario_Dinamico!P38 -> 6000 | D5: =Inventario_Dinamico!Q38 -> 0 | E5: =Inventario_Dinamico!R38 -> 0 | F5: =Inventario_Dinamico!S38 -> 6000 | G5: =Inventario_Dinamico!T38 -> 0 | H5: =Inventario_Dinamico!U38 -> 0 | I5: =Inventario_Dinamico!V38 -> 6000 | J5: =Inventario_Dinamico!W38 -> 0
C6: =SUM(C4:C5) -> 6000 | D6: =SUM(D4:D5) -> 0 | E6: =SUM(E4:E5) -> 0 | F6: =SUM(F4:F5) -> 6000 | G6: =SUM(G4:G5) -> 0 | H6: =SUM(H4:H5) -> 0 | I6: =SUM(I4:I5) -> 6000 | J6: =SUM(J4:J5) -> 0
A7: Holding
A8: Parte A | C8: =Inventario_Dinamico!B37 -> 9416.4 | D8: =Inventario_Dinamico!C37 -> 8508 | E8: =Inventario_Dinamico!D37 -> 7599.6 | F8: =Inventario_Dinamico!E37 -> 6691.2 | G8: =Inventario_Dinamico!F37 -> 5782.8 | H8: =Inventario_Dinamico!G37 -> 4874.4 | I8: =Inventario_Dinamico!H37 -> 3966 | J8: =Inventario_Dinamico!I37 -> 3057.6 | K8: =+VLOOKUP(Inputs!B110,Inputs!A107:C109,3,FALSE) -> Inmediato (0Q)
A9: Parte B | C9: =Inventario_Dinamico!P37 -> 5858.94 | D9: =Inventario_Dinamico!Q37 -> 5677.38 | E9: =Inventario_Dinamico!R37 -> 5495.82 | F9: =Inventario_Dinamico!S37 -> 5555.46 | G9: =Inventario_Dinamico!T37 -> 5373.9 | H9: =Inventario_Dinamico!U37 -> 5192.34 | I9: =Inventario_Dinamico!V37 -> 5251.98 | J9: =Inventario_Dinamico!W37 -> 5070.42 | K9: =VLOOKUP(Inputs!B118,Inputs!A114:C117,3,FALSE) -> Inmediato (0Q)
C10: =+SUM(C8:C9) -> 15275.34 | D10: =+SUM(D8:D9) -> 14185.38 | E10: =+SUM(E8:E9) -> 13095.42 | F10: =+SUM(F8:F9) -> 12246.66 | G10: =+SUM(G8:G9) -> 11156.7 | H10: =+SUM(H8:H9) -> 10066.74 | I10: =+SUM(I8:I9) -> 9217.98 | J10: =+SUM(J8:J9) -> 8128.02
A11: Raw Materials | N11: Recuerda que pusiste en el pasado
A12: Parte A | C12: =(Inventario_Dinamico!B8+Inventario_Dinamico!B14+Inventario_Dinamico!B20+Inventario_Dinamico!B26+Inventario_Dinamico!B32)*$L$12 -> 0 | D12: =(Inventario_Dinamico!C8+Inventario_Dinamico!C14+Inventario_Dinamico!C20+Inventario_Dinamico!C26+Inventario_Dinamico!C32)*$L$12 -> 0 | E12: =(Inventario_Dinamico!D8+Inventario_Dinamico!D14+Inventario_Dinamico!D20+Inventario_Dinamico!D26+Inventario_Dinamico!D32)*$L$12 -> 0 | F12: =(Inventario_Dinamico!E8+Inventario_Dinamico!E14+Inventario_Dinamico!E20+Inventario_Dinamico!E26+Inventario_Dinamico!E32)*$L$12 -> 0 | G12: =(Inventario_Dinamico!F8+Inventario_Dinamico!F14+Inventario_Dinamico!F20+Inventario_Dinamico!F26+Inventario_Dinamico!F32)*$L$12 -> 0 | H12: =(Inventario_Dinamico!G8+Inventario_Dinamico!G14+Inventario_Dinamico!G20+Inventario_Dinamico!G26+Inventario_Dinamico!G32)*$L$12 -> 0 | I12: =(Inventario_Dinamico!H8+Inventario_Dinamico!H14+Inventario_Dinamico!H20+Inventario_Dinamico!H26+Inventario_Dinamico!H32)*$L$12 -> 0 | J12: =(Inventario_Dinamico!I8+Inventario_Dinamico!I14+Inventario_Dinamico!I20+Inventario_Dinamico!I26+Inventario_Dinamico!I32)*$L$12 -> 0 | L12: =+VLOOKUP(Inputs!B110,Inputs!A107:B109,2,FALSE) -> 125
A13: Parte B | C13: =(Inventario_Dinamico!P8+Inventario_Dinamico!P14+Inventario_Dinamico!P20+Inventario_Dinamico!P26+Inventario_Dinamico!P32)*$L$13 -> 22110 | D13: =(Inventario_Dinamico!Q8+Inventario_Dinamico!Q14+Inventario_Dinamico!Q20+Inventario_Dinamico!Q26+Inventario_Dinamico!Q32)*$L$13 -> 0 | E13: =(Inventario_Dinamico!R8+Inventario_Dinamico!R14+Inventario_Dinamico!R20+Inventario_Dinamico!R26+Inventario_Dinamico!R32)*$L$13 -> 0 | F13: =(Inventario_Dinamico!S8+Inventario_Dinamico!S14+Inventario_Dinamico!S20+Inventario_Dinamico!S26+Inventario_Dinamico!S32)*$L$13 -> 22110 | G13: =(Inventario_Dinamico!T8+Inventario_Dinamico!T14+Inventario_Dinamico!T20+Inventario_Dinamico!T26+Inventario_Dinamico!T32)*$L$13 -> 0 | H13: =(Inventario_Dinamico!U8+Inventario_Dinamico!U14+Inventario_Dinamico!U20+Inventario_Dinamico!U26+Inventario_Dinamico!U32)*$L$13 -> 0 | I13: =(Inventario_Dinamico!V8+Inventario_Dinamico!V14+Inventario_Dinamico!V20+Inventario_Dinamico!V26+Inventario_Dinamico!V32)*$L$13 -> 22110 | J13: =(Inventario_Dinamico!W8+Inventario_Dinamico!W14+Inventario_Dinamico!W20+Inventario_Dinamico!W26+Inventario_Dinamico!W32)*$L$13 -> 0 | L13: =+VLOOKUP(Inputs!B118,Inputs!A114:B117,2,FALSE) -> 330
A14: Pieza 1 | B14: =BOM_Consumo_Piezas!P6+BOM_Consumo_Piezas!P16+BOM_Consumo_Piezas!P26+BOM_Consumo_Piezas!P36+BOM_Consumo_Piezas!P46 -> 14580
A15: Pieza 2 | B15: =BOM_Consumo_Piezas!P7+BOM_Consumo_Piezas!P17+BOM_Consumo_Piezas!P27+BOM_Consumo_Piezas!P37+BOM_Consumo_Piezas!P47 -> 13391
A16: Pieza 3 | B16: =BOM_Consumo_Piezas!P8+BOM_Consumo_Piezas!P18+BOM_Consumo_Piezas!P28+BOM_Consumo_Piezas!P38+BOM_Consumo_Piezas!P48 -> 8712
A17: Pieza 4 | B17: =BOM_Consumo_Piezas!P9+BOM_Consumo_Piezas!P19+BOM_Consumo_Piezas!P29+BOM_Consumo_Piezas!P39+BOM_Consumo_Piezas!P49 -> 5808
A18: Pieza 5 | B18: =BOM_Consumo_Piezas!P10+BOM_Consumo_Piezas!P20+BOM_Consumo_Piezas!P30+BOM_Consumo_Piezas!P40+BOM_Consumo_Piezas!P50 -> 14520
A19: Pieza 6 | B19: =BOM_Consumo_Piezas!P11+BOM_Consumo_Piezas!P21+BOM_Consumo_Piezas!P31+BOM_Consumo_Piezas!P41+BOM_Consumo_Piezas!P51 -> 3388
B20: =SUM(B12:B19) -> 60399 | C20: =SUM(C12:C19) -> 22110 | D20: =SUM(D12:D19) -> 0 | E20: =SUM(E12:E19) -> 0 | F20: =SUM(F12:F19) -> 22110 | G20: =SUM(G12:G19) -> 0 | H20: =SUM(H12:H19) -> 0 | I20: =SUM(I12:I19) -> 22110 | J20: =SUM(J12:J19) -> 0

Sheet Proveedor B
A1: Holding and Ordering
B2: Q0 | C2: Q1 | D2: Q2 | E2: Q3 | F2: Q4 | G2: Q5 | H2: Q6 | I2: Q7 | J2: Q8 | K2: CashFlow | L2: Costo de proveedor
A3: Ordering
A4: Parte A | C4: =Inventario_Dinamico!B38 -> 0 | D4: =Inventario_Dinamico!C38 -> 0 | E4: =Inventario_Dinamico!D38 -> 0 | F4: =Inventario_Dinamico!E38 -> 0 | G4: =Inventario_Dinamico!F38 -> 0 | H4: =Inventario_Dinamico!G38 -> 0 | I4: =Inventario_Dinamico!H38 -> 0 | J4: =Inventario_Dinamico!I38 -> 0
A5: Parte B | C5: =Inventario_Dinamico!P38 -> 6000 | D5: =Inventario_Dinamico!Q38 -> 0 | E5: =Inventario_Dinamico!R38 -> 0 | F5: =Inventario_Dinamico!S38 -> 6000 | G5: =Inventario_Dinamico!T38 -> 0 | H5: =Inventario_Dinamico!U38 -> 0 | I5: =Inventario_Dinamico!V38 -> 6000 | J5: =Inventario_Dinamico!W38 -> 0
C6: =SUM(C4:C5) -> 6000 | D6: =SUM(D4:D5) -> 0 | E6: =SUM(E4:E5) -> 0 | F6: =SUM(F4:F5) -> 6000 | G6: =SUM(G4:G5) -> 0 | H6: =SUM(H4:H5) -> 0 | I6: =SUM(I4:I5) -> 6000 | J6: =SUM(J4:J5) -> 0
A7: Holding
A8: Parte A | C8: =Inventario_Dinamico!B37 -> 9416.4 | D8: =Inventario_Dinamico!C37 -> 8508 | E8: =Inventario_Dinamico!D37 -> 7599.6 | F8: =Inventario_Dinamico!E37 -> 6691.2 | G8: =Inventario_Dinamico!F37 -> 5782.8 | H8: =Inventario_Dinamico!G37 -> 4874.4 | I8: =Inventario_Dinamico!H37 -> 3966 | J8: =Inventario_Dinamico!I37 -> 3057.6 | K8: =+VLOOKUP(Inputs!B110,Inputs!A107:C109,3,FALSE) -> Inmediato (0Q)
A9: Parte B | C9: =Inventario_Dinamico!P37 -> 5858.94 | D9: =Inventario_Dinamico!Q37 -> 5677.38 | E9: =Inventario_Dinamico!R37 -> 5495.82 | F9: =Inventario_Dinamico!S37 -> 5555.46 | G9: =Inventario_Dinamico!T37 -> 5373.9 | H9: =Inventario_Dinamico!U37 -> 5192.34 | I9: =Inventario_Dinamico!V37 -> 5251.98 | J9: =Inventario_Dinamico!W37 -> 5070.42 | K9: =VLOOKUP(Inputs!B118,Inputs!A114:C117,3,FALSE) -> Inmediato (0Q)
C10: =+SUM(C8:C9) -> 15275.34 | D10: =+SUM(D8:D9) -> 14185.38 | E10: =+SUM(E8:E9) -> 13095.42 | F10: =+SUM(F8:F9) -> 12246.66 | G10: =+SUM(G8:G9) -> 11156.7 | H10: =+SUM(H8:H9) -> 10066.74 | I10: =+SUM(I8:I9) -> 9217.98 | J10: =+SUM(J8:J9) -> 8128.02
A11: Raw Materials
A12: Parte A | C12: =(Inventario_Dinamico!B8+Inventario_Dinamico!B14+Inventario_Dinamico!B20+Inventario_Dinamico!B26+Inventario_Dinamico!B32)*$L$12 -> 0 | D12: =(Inventario_Dinamico!C8+Inventario_Dinamico!C14+Inventario_Dinamico!C20+Inventario_Dinamico!C26+Inventario_Dinamico!C32)*$L$12 -> 0 | E12: =(Inventario_Dinamico!D8+Inventario_Dinamico!D14+Inventario_Dinamico!D20+Inventario_Dinamico!D26+Inventario_Dinamico!D32)*$L$12 -> 0 | F12: =(Inventario_Dinamico!E8+Inventario_Dinamico!E14+Inventario_Dinamico!E20+Inventario_Dinamico!E26+Inventario_Dinamico!E32)*$L$12 -> 0 | G12: =(Inventario_Dinamico!F8+Inventario_Dinamico!F14+Inventario_Dinamico!F20+Inventario_Dinamico!F26+Inventario_Dinamico!F32)*$L$12 -> 0 | H12: =(Inventario_Dinamico!G8+Inventario_Dinamico!G14+Inventario_Dinamico!G20+Inventario_Dinamico!G26+Inventario_Dinamico!G32)*$L$12 -> 0 | I12: =(Inventario_Dinamico!H8+Inventario_Dinamico!H14+Inventario_Dinamico!H20+Inventario_Dinamico!H26+Inventario_Dinamico!H32)*$L$12 -> 0 | J12: =(Inventario_Dinamico!I8+Inventario_Dinamico!I14+Inventario_Dinamico!I20+Inventario_Dinamico!I26+Inventario_Dinamico!I32)*$L$12 -> 0 | L12: =+VLOOKUP(Inputs!B110,Inputs!A107:B109,2,FALSE) -> 125
A13: Parte B | C13: =(Inventario_Dinamico!P8+Inventario_Dinamico!P14+Inventario_Dinamico!P20+Inventario_Dinamico!P26+Inventario_Dinamico!P32)*$L$13 -> 22110 | D13: =(Inventario_Dinamico!Q8+Inventario_Dinamico!Q14+Inventario_Dinamico!Q20+Inventario_Dinamico!Q26+Inventario_Dinamico!Q32)*$L$13 -> 0 | E13: =(Inventario_Dinamico!R8+Inventario_Dinamico!R14+Inventario_Dinamico!R20+Inventario_Dinamico!R26+Inventario_Dinamico!R32)*$L$13 -> 0 | F13: =(Inventario_Dinamico!S8+Inventario_Dinamico!S14+Inventario_Dinamico!S20+Inventario_Dinamico!S26+Inventario_Dinamico!S32)*$L$13 -> 22110 | G13: =(Inventario_Dinamico!T8+Inventario_Dinamico!T14+Inventario_Dinamico!T20+Inventario_Dinamico!T26+Inventario_Dinamico!T32)*$L$13 -> 0 | H13: =(Inventario_Dinamico!U8+Inventario_Dinamico!U14+Inventario_Dinamico!U20+Inventario_Dinamico!U26+Inventario_Dinamico!U32)*$L$13 -> 0 | I13: =(Inventario_Dinamico!V8+Inventario_Dinamico!V14+Inventario_Dinamico!V20+Inventario_Dinamico!V26+Inventario_Dinamico!V32)*$L$13 -> 22110 | J13: =(Inventario_Dinamico!W8+Inventario_Dinamico!W14+Inventario_Dinamico!W20+Inventario_Dinamico!W26+Inventario_Dinamico!W32)*$L$13 -> 0 | L13: =+VLOOKUP(Inputs!B118,Inputs!A114:B117,2,FALSE) -> 330
A14: Pieza 1 | B14: =BOM_Consumo_Piezas!P6+BOM_Consumo_Piezas!P16+BOM_Consumo_Piezas!P26+BOM_Consumo_Piezas!P36+BOM_Consumo_Piezas!P46 -> 14580
A15: Pieza 2 | B15: =BOM_Consumo_Piezas!P7+BOM_Consumo_Piezas!P17+BOM_Consumo_Piezas!P27+BOM_Consumo_Piezas!P37+BOM_Consumo_Piezas!P47 -> 13391
A16: Pieza 3 | B16: =BOM_Consumo_Piezas!P8+BOM_Consumo_Piezas!P18+BOM_Consumo_Piezas!P28+BOM_Consumo_Piezas!P38+BOM_Consumo_Piezas!P48 -> 8712
