Workbook
Name tZeroValue: #REF!

Sheet Inputs
A1: INPUTS - PURCHASING MANAGER
A2: Solo inputs manuales. AZUL = modificar según tu estrategia. Sin fórmulas en esta hoja.
A4: 1. PRODUCCIÓN PLANEADA POR QUINCENA (Electroclean)
A5: Quincena → | B5: Q1 | C5: Q2 | D5: Q3 | E5: Q4 | F5: Q5 | G5: Q6 | H5: Q7 | I5: Q8 | J5: TOTAL
A6: Producción EC | B6: 2520 | C6: 2520 | D6: 2520 | E6: 2520 | F6: 2520 | G6: 2520 | H6: 2520 | I6: 2520 | J6: =SUM(B6:I6) -> 20160
A9: 2. INVENTARIO INICIAL (Fin Periodo Anterior)
A10: Material | B10: Inventario Inicial | C10: Unidad | D10: Fuente
A11: Parte A | B11: 4512 | C11: unidades | D11: Fin Periodo 6
A12: Parte B | B12: 1058 | C12: unidades | D12: Fin Periodo 6
A13: Pieza 1 | B13: 130 | C13: unidades | D13: Fin Periodo 6
A14: Pieza 2 | B14: 5268 | C14: unidades | D14: Fin Periodo 6
A15: Pieza 3 | B15: 4333 | C15: unidades | D15: Fin Periodo 6
A16: Pieza 4 | B16: 8487 | C16: unidades | D16: Fin Periodo 6
A17: Pieza 5 | B17: 23192 | C17: unidades | D17: Fin Periodo 6
A18: Pieza 6 | B18: 6035 | C18: unidades | D18: Fin Periodo 6
A21: 3. BILL OF MATERIALS (BOM) - Consumo por Electroclean
A22: Material | B22: Consumo por EC | C22: Unidad | D22: Observaciones
A23: Parte A | B23: 1 | C23: unidades/EC | D23: 1:1
A24: Parte B | B24: 0.2 | C24: unidades/EC | D24: 1:5
A25: Pieza 1 | B25: 0.01 | C25: unidades/EC | D25: 1:100
A26: Pieza 2 | B26: 8 | C26: unidades/EC | D26: 8:1
A27: Pieza 3 | B27: 0.3 | C27: unidades/EC | D27: 30%
A28: Pieza 4 | B28: 0.6 | C28: unidades/EC | D28: 60%
A29: Pieza 5 | B29: 2 | C29: unidades/EC | D29: 2:1
A30: Pieza 6 | B30: 0.75 | C30: unidades/EC | D30: 75%
A33: 4. BATCH SIZES (Tamaño de Lote)
A34: Material | B34: Batch Size | C34: MOQ (Batch Size) | D34: Observaciones
A35: Parte A | B35: 30 | C35: =B35 -> 30 | D35: Lote fijo
A36: Parte B | B36: 12 | C36: =B36 -> 12 | D36: Lote fijo
A37: Pieza 1 | B37: 1 | C37: =B37 -> 1 | D37: Individual
A38: Pieza 2 | B38: 100 | C38: =B38 -> 100 | D38: Caja 100
A39: Pieza 3 | B39: 30 | C39: =B39 -> 30 | D39: Lote 30
A40: Pieza 4 | B40: 60 | C40: =B40 -> 60 | D40: Lote 60
A41: Pieza 5 | B41: 100 | C41: =B41 -> 100 | D41: Lote 100
A42: Pieza 6 | B42: 150 | C42: =B42 -> 150 | D42: Pallet 150
B43: 125 | C43: =B43/B35 -> 4.1666667
B44: 330 | C44: =B44/B36 -> 27.5
A45: 5. PRECIOS POR BATCH
A46: Material | B46: 7 | C46: =B46/B38 -> 0.07 | D46: Moneda
A47: Parte A | B47: 125 | C47: =B47/B35 -> 4.1666667 | D47: $
...

Sheet Inventario_Dinamico
A1: INVENTARIO DINÁMICO - Control por Quincena
A2: Fórmula: Inv_Final_Q = Inv_Inicial_Q + Recepciones_Q - Consumo_Q
A3: AMARILLO = ingresar recepciones manualmente | ROJO = inventario negativo (ALERTA)
A5: Parte A
A6: Concepto | B6: Q1 | C6: Q2 | D6: Q3 | E6: Q4 | F6: Q5 | G6: Q6 | H6: Q7 | I6: Q8
A7: Inv_Inicial | B7: =#REF! -> #REF! | C7: =B10 -> #REF! | D7: =C10 -> #REF! | E7: =D10 -> #REF! | F7: =E10 -> #REF! | G7: =F10 -> #REF! | H7: =G10 -> #REF! | I7: =H10 -> #REF!
A8: Recepciones | B8: 2520 | C8: 2520 | D8: 2520 | E8: 2520 | F8: 0 | G8: 0 | H8: 0 | I8: 0
A9: Consumo | B9: =#REF! -> #REF! | C9: =#REF! -> #REF! | D9: =#REF! -> #REF! | E9: =#REF! -> #REF! | F9: =#REF! -> #REF! | G9: =#REF! -> #REF! | H9: =#REF! -> #REF! | I9: =#REF! -> #REF!
A10: Inv_Final | B10: =B7+B8-B9 -> #REF! | C10: =C7+C8-C9 -> #REF! | D10: =D7+D8-D9 -> #REF! | E10: =E7+E8-E9 -> #REF! | F10: =F7+F8-F9 -> #REF! | G10: =G7+G8-G9 -> #REF! | H10: =H7+H8-H9 -> #REF! | I10: =I7+I8-I9 -> #REF!
A11: Parte B
A12: Concepto | B12: Q1 | C12: Q2 | D12: Q3 | E12: Q4 | F12: Q5 | G12: Q6 | H12: Q7 | I12: Q8
A13: Inv_Inicial | B13: =#REF! -> #REF! | C13: =B16 -> #REF! | D13: =C16 -> #REF! | E13: =D16 -> #REF! | F13: =E16 -> #REF! | G13: =F16 -> #REF! | H13: =G16 -> #REF! | I13: =H16 -> #REF!
A14: Recepciones | B14: 504 | C14: 504 | D14: 504 | E14: 504 | F14: 504 | G14: 0 | H14: 0 | I14: 0
A15: Consumo | B15: =#REF! -> #REF! | C15: =#REF! -> #REF! | D15: =#REF! -> #REF! | E15: =#REF! -> #REF! | F15: =#REF! -> #REF! | G15: =#REF! -> #REF! | H15: =#REF! -> #REF! | I15: =#REF! -> #REF!
A16: Inv_Final | B16: =B13+B14-B15 -> #REF! | C16: =C13+C14-C15 -> #REF! | D16: =D13+D14-D15 -> #REF! | E16: =E13+E14-E15 -> #REF! | F16: =F13+F14-F15 -> #REF! | G16: =G13+G14-G15 -> #REF! | H16: =H13+H14-H15 -> #REF! | I16: =I13+I14-I15 -> #REF!
A17: Pieza 1
A18: Concepto | B18: Q1 | C18: Q2 | D18: Q3 | E18: Q4 | F18: Q5 | G18: Q6 | H18: Q7 | I18: Q8
A19: Inv_Inicial | B19: =#REF! -> #REF! | C19: =B22 -> #REF! | D19: =C22 -> #REF! | E19: =D22 -> #REF! | F19: =E22 -> #REF! | G19: =F22 -> #REF! | H19: =G22 -> #REF! | I19: =H22 -> #REF!
A20: Recepciones | B20: 25.2 | C20: 25.2 | D20: 25.2 | E20: 25.2 | F20: 25.2 | G20: 25.2 | H20: 25.2 | I20: 0
A21: Consumo | B21: =#REF! -> #REF! | C21: =#REF! -> #REF! | D21: =#REF! -> #REF! | E21: =#REF! -> #REF! | F21: =#REF! -> #REF! | G21: =#REF! -> #REF! | H21: =#REF! -> #REF! | I21: =#REF! -> #REF!
A22: Inv_Final | B22: =B19+B20-B21 -> #REF! | C22: =C19+C20-C21 -> #REF! | D22: =D19+D20-D21 -> #REF! | E22: =E19+E20-E21 -> #REF! | F22: =F19+F20-F21 -> #REF! | G22: =G19+G20-G21 -> #REF! | H22: =H19+H20-H21 -> #REF! | I22: =I19+I20-I21 -> #REF!
A23: Pieza 2
A24: Concepto | B24: Q1 | C24: Q2 | D24: Q3 | E24: Q4 | F24: Q5 | G24: Q6 | H24: Q7 | I24: Q8
A25: Inv_Inicial | B25: =#REF! -> #REF! | C25: =B28 -> #REF! | D25: =C28 -> #REF! | E25: =D28 -> #REF! | F25: =E28 -> #REF! | G25: =F28 -> #REF! | H25: =G28 -> #REF! | I25: =H28 -> #REF!
A26: Recepciones | B26: 20160 | C26: 20160 | D26: 20160 | E26: 20160 | F26: 20160 | G26: 20160 | H26: 20160 | I26: 0
A27: Consumo | B27: =#REF! -> #REF! | C27: =#REF! -> #REF! | D27: =#REF! -> #REF! | E27: =#REF! -> #REF! | F27: =#REF! -> #REF! | G27: =#REF! -> #REF! | H27: =#REF! -> #REF! | I27: =#REF! -> #REF!
A28: Inv_Final | B28: =B25+B26-B27 -> #REF! | C28: =C25+C26-C27 -> #REF! | D28: =D25+D26-D27 -> #REF! | E28: =E25+E26-E27 -> #REF! | F28: =F25+F26-F27 -> #REF! | G28: =G25+G26-G27 -> #REF! | H28: =H25+H26-H27 -> #REF! | I28: =I25+I26-I27 -> #REF!
A29: Pieza 3
A30: Concepto | B30: Q1 | C30: Q2 | D30: Q3 | E30: Q4 | F30: Q5 | G30: Q6 | H30: Q7 | I30: Q8
A31: Inv_Inicial | B31: =#REF! -> #REF! | C31: =B34 -> #REF! | D31: =C34 -> #REF! | E31: =D34 -> #REF! | F31: =E34 -> #REF! | G31: =F34 -> #REF! | H31: =G34 -> #REF! | I31: =H34 -> #REF!
A32: Recepciones | B32: 756 | C32: 756 | D32: 756 | E32: 756 | F32: 756 | G32: 756 | H32: 756 | I32: 0
A33: Consumo | B33: =#REF! -> #REF! | C33: =#REF! -> #REF! | D33: =#REF! -> #REF! | E33: =#REF! -> #REF! | F33: =#REF! -> #REF! | G33: =#REF! -> #REF! | H33: =#REF! -> #REF! | I33: =#REF! -> #REF!
A34: Inv_Final | B34: =B31+B32-B33 -> #REF! | C34: =C31+C32-C33 -> #REF! | D34: =D31+D32-D33 -> #REF! | E34: =E31+E32-E33 -> #REF! | F34: =F31+F32-F33 -> #REF! | G34: =G31+G32-G33 -> #REF! | H34: =H31+H32-H33 -> #REF! | I34: =I31+I32-I33 -> #REF!
A35: Pieza 4
A36: Concepto | B36: Q1 | C36: Q2 | D36: Q3 | E36: Q4 | F36: Q5 | G36: Q6 | H36: Q7 | I36: Q8
A37: Inv_Inicial | B37: =#REF! -> #REF! | C37: =B40 -> #REF! | D37: =C40 -> #REF! | E37: =D40 -> #REF! | F37: =E40 -> #REF! | G37: =F40 -> #REF! | H37: =G40 -> #REF! | I37: =H40 -> #REF!
A38: Recepciones | B38: 1512 | C38: 1512 | D38: 1512 | E38: 1512 | F38: 1512 | G38: 1512 | H38: 1512 | I38: 0
A39: Consumo | B39: =#REF! -> #REF! | C39: =#REF! -> #REF! | D39: =#REF! -> #REF! | E39: =#REF! -> #REF! | F39: =#REF! -> #REF! | G39: =#REF! -> #REF! | H39: =#REF! -> #REF! | I39: =#REF! -> #REF!
A40: Inv_Final | B40: =B37+B38-B39 -> #REF! | C40: =C37+C38-C39 -> #REF! | D40: =D37+D38-D39 -> #REF! | E40: =E37+E38-E39 -> #REF! | F40: =F37+F38-F39 -> #REF! | G40: =G37+G38-G39 -> #REF! | H40: =H37+H38-H39 -> #REF! | I40: =I37+I38-I39 -> #REF!
A41: Pieza 5
...

Sheet MRP_LeadTimes
A1: MRP - PRODUCCIÓN POR SECCIÓN
A2: 5 secciones (S1-S5), cada una tarda 1 quincena. WIP entre secciones.
A4: FLUJO DE PRODUCCIÓN
A5: Sección | B5: Input | C5: Process | D5: Output | E5: Lead Time
A6: S1 | B6: Parte A | C6: Ensambla Piezas | D6: Semi A | E6: 1Q
A7: S2 | B7: Parte B | C7: Ensambla Piezas | D7: Semi B | E7: 1Q
A8: S3 | B8: - | C8: Pieza 3 | D8: Semi C | E8: 1Q
A9: S4 | B9: - | C9: Pieza 6 | D9: Semi D | E9: 1Q
A10: S5 | B10: Semis | C10: Ensambla final | D10: Electroclean | E10: 1Q
A12: CALENDARIO POR SECCION (Lead Time 1Q)
A13: Seccion | B13: Q1 | C13: Q2 | D13: Q3 | E13: Q4 | F13: Q5 | G13: Q6 | H13: Q7 | I13: Q8
A14: S5 - Final (EC) | B14: =Inputs!B6*Inputs!$B$101 -> #REF! | C14: =Inputs!C6*Inputs!$B$101 -> #REF! | D14: =Inputs!D6*Inputs!$B$101 -> #REF! | E14: =Inputs!E6*Inputs!$B$101 -> #REF! | F14: =Inputs!F6*Inputs!$B$101 -> #REF! | G14: =Inputs!G6*Inputs!$B$101 -> #REF! | H14: =Inputs!H6*Inputs!$B$101 -> #REF! | I14: =Inputs!I6*Inputs!$B$101 -> #REF!
A15: S4 - Piezas | B15: =IFERROR(C14,0) -> 0 | C15: =IFERROR(D14,0) -> 0 | D15: =IFERROR(E14,0) -> 0 | E15: =IFERROR(F14,0) -> 0 | F15: =IFERROR(G14,0) -> 0 | G15: =IFERROR(H14,0) -> 0 | H15: =IFERROR(I14,0) -> 0 | I15: =IFERROR(J14,0) -> 0
A16: S3 - Semi | B16: =IFERROR(C15,0) -> 0 | C16: =IFERROR(D15,0) -> 0 | D16: =IFERROR(E15,0) -> 0 | E16: =IFERROR(F15,0) -> 0 | F16: =IFERROR(G15,0) -> 0 | G16: =IFERROR(H15,0) -> 0 | H16: =IFERROR(I15,0) -> 0 | I16: =IFERROR(J15,0) -> 0
A17: S2 - Parte B | B17: =IFERROR(C16,0) -> 0 | C17: =IFERROR(D16,0) -> 0 | D17: =IFERROR(E16,0) -> 0 | E17: =IFERROR(F16,0) -> 0 | F17: =IFERROR(G16,0) -> 0 | G17: =IFERROR(H16,0) -> 0 | H17: =IFERROR(I16,0) -> 0 | I17: =IFERROR(J16,0) -> 0
A18: S1 - Parte A | B18: =IFERROR(C17,0) -> 0 | C18: =IFERROR(D17,0) -> 0 | D18: =IFERROR(E17,0) -> 0 | E18: =IFERROR(F17,0) -> 0 | F18: =IFERROR(G17,0) -> 0 | G18: =IFERROR(H17,0) -> 0 | H18: =IFERROR(I17,0) -> 0 | I18: =IFERROR(J17,0) -> 0
